Workbook

Sheet 00_サマリー
A1: WineBank クルージング事業参入 投資リターン／営業リターン サマリー
A2: 2026-08-24 出典: 0824事業計画PDF(43p)／クルーザーデザインPJ図面／V2_0810契約進行表 単位: 万円
A4: ■ 投資リターン（TKへの出資）
C5: TK① 造船 | D5: TK② 会員権 | F5: 前提
B6: 出資額 | C6: ='02_投資リターン_造船TK'!C16 | D6: ='01_前提条件'!C9 | F6: TK①=造船原価2億円／TK②=船舶取得4億円
B7: 投資期間（年） | C7: ='01_前提条件'!C35 | D7: ='01_前提条件'!C13 | F7: TK①=造船24か月／TK②=会員権20年
B8: 倍率（税前 MOIC） | C8: ='02_投資リターン_造船TK'!C18 | D8: ='03_投資リターン_会員権TK'!F18 | F8: TK①=按分なし／TK②=完売2年
B9: IRR（税前） | C9: ='02_投資リターン_造船TK'!C19 | D9: ='03_投資リターン_会員権TK'!C19
B10: IRR（税前・50:50按分時） | C10: ='02_投資リターン_造船TK'!D19 | D10: — | F10: p16の按分がTK①譲渡益に及ぶ場合
B11: IRR（税後・実効34%） | C11: ='02_投資リターン_造船TK'!C23 | D11: — | F11: TK②は償却スキームのため別途
B12: 20年累計CF | C12: — | D12: ='03_投資リターン_会員権TK'!C18 | F12: TK②のみ。単純年平均利回り2.0%
B13: 下振れ：50口止まり | C13: — | D13: -14000 | F13: 20年累計CF △1.4億円／未回収
B14: 下振れ：維持費2,000万/年 | C14: — | D14: ='03_投資リターン_会員権TK'!H23 | F14: 20年累計CF △8,000万円
A15: ■ 営業リターン（WineBank F&B事業・グループ4）
C16: 保守 | D16: 基本 | E16: 強気 | F16: 前提
B17: F&B実施運航回数 | C17: ='04_営業リターン_FB'!C24 | D17: ='04_営業リターン_FB'!D24 | E17: ='04_営業リターン_FB'!E24 | F17: 稼働300日×1.2/2.0/3.0枠 × F&B実施率70/80/90%
B18: F&B売上 | C18: ='04_営業リターン_FB'!C25 | D18: ='04_営業リターン_FB'!D25 | E18: ='04_営業リターン_FB'!E25 | F18: 回数 × 乗船8/10/12名 × 客単価2.0/3.0/4.0万円
B19: 限界利益 | C19: ='04_営業リターン_FB'!C29 | D19: ='04_営業リターン_FB'!D29 | E19: ='04_営業リターン_FB'!E29 | F19: F&B売上 −原価33% −人件費8万/運航 −物流1.5万/運航
B20: コーディネーションフィー | C20: ='04_営業リターン_FB'!C31 | D20: ='04_営業リターン_FB'!D31 | E20: ='04_営業リターン_FB'!E31 | F20: F&B売上×10%（p28）
B21: 固定費 | C21: ='04_営業リターン_FB'!C33 | D21: ='04_営業リターン_FB'!D33 | E21: ='04_営業リターン_FB'!E33 | F21: 統括MGR900＋事務300＋什器償却300＋在庫金利100＋保険等200＋本部按分300
B22: 営業利益 | C22: ='04_営業リターン_FB'!C34 | D22: ='04_営業リターン_FB'!D34 | E22: ='04_営業リターン_FB'!E34
B23: 営業利益率 | C23: ='04_営業リターン_FB'!C36 | D23: ='04_営業リターン_FB'!D36 | E23: ='04_営業リターン_FB'!E36 | F23: 対 総収益（F&B売上＋フィー）
B24: 税後利益 | C24: ='04_営業リターン_FB'!C37 | D24: ='04_営業リターン_FB'!D37 | E24: ='04_営業リターン_FB'!E37 | F24: 実効税率34%
B25: 初期投資ROI | C25: ='04_営業リターン_FB'!C38 | D25: ='04_営業リターン_FB'!D38 | E25: ='04_営業リターン_FB'!E38 | F25: 初期投資1,500万円（什器・食器・グラス・初期ワイン在庫）に対して
B26: 損益分岐F&B運航回数 | C26: ='04_営業リターン_FB'!C39 | D26: ='04_営業リターン_FB'!D39 | E26: ='04_営業リターン_FB'!E39 | F26: 固定費 ÷ 1運航あたり貢献利益
C27: ='04_営業リターン_FB'!C39 | D27: ='04_営業リターン_FB'!D39 | E27: ='04_営業リターン_FB'!E39
A28: ■ 結論
B29: ① 営業リターン（F&B）は入るべき。基本ケースで営業利益4,428万円・税後2,922万円、初期投資1,500万円に対しROI 295%（回収4.1か月）。
B30: 船舶リスク・造船リスク・会員権販売リスクをいずれも負わないアセットライト構造で、WineBankの既存仕入力とシェフ網がそのまま効く。
B31: 損益分岐は「1運航あたりF&B売上12.3万円 かつ 年154回」。稼働300日で1日0.51枠なので、ハードルは低い。
B33: ② ただし1運航あたり売上が15万円を下回ると年750回運航しても赤字。招聘シェフ人件費8万円/運航が回数比例でかかるため。
B34: → 契約交渉では「最低乗船人数」または「1運航あたり最低保証額」を必ず取ること。ここが営業リターンの生命線。
B36: ③ 投資リターン（TK出資）は現時点では判断不能。TK①は税後IRR 14.2〜26.9%だが按分定義とAM報酬が未開示で、上記はすべて上限値。
B37: TK②はIRR 30.4%に見えるが20年通算では1.40倍（年率2.0%）に過ぎず、未計上の年間維持費が1,600万円を超えるとゼロになる。
B38: → 高重要度の指摘7件（移転価格／償却前提の二重記載／リース区分／消費税／維持費／年会費帰属／発行口数）が解消されるまで出資は保留を推奨。
B40: ④ 最優先で確認すべき3点：(a) 年会費 年1.5億円の帰属 (b) 船舶4億円の第三者鑑定 (c) AM報酬・組成費用のフィーテーブル

Sheet 01_前提条件
A1: WineBank クルージング事業 投資リターン／営業リターン試算モデル
A2: 作成日 2026-08-24 ／ 出典: 0824事業計画PDF(43p)・クルーザーデザインPJ図面・V2_0810契約進行表
B4: 凡例 | C4: 入力値 | E4: 黄=入力セル（変更可） ／ 赤字=資料に記載がなく推計した項目（要確認）
A6: ■ A. 資料から確定している数値（0824事業計画PDF）
B7: 項目 | C7: 単位/値 | E7: 出典・備考
B8: 船舶取得原価（造船TKが負担） | C8: 20000 | D8: 万円 | E8: p21/p34「2億円で造船し、4億円で売却」
B9: TK②への船舶売却価格 | C9: 40000 | D9: 万円 | E9: p21/p26/p34。TK②の減価償却基礎額
B10: 会員権 販売口数 | C10: 100 | D10: 口 | E10: p21/p27/p29
B11: 会員権 1口あたり販売価格 | C11: 1000 | D11: 万円 | E11: p21/p27。20年権利・年10回利用
B12: UMITO 販売受託手数料率 | C12: 0.4 | D12: % | E12: p36「40%（400万円）の手数料を受領」
B13: 会員権 権利期間 | C13: 20 | D13: 年 | E13: p21/p39
B14: 会員 年間利用回数 | C14: 10 | D14: 回 | E14: p21/p39
B15: 会員 都度利用料（90分） | C15: 13 | D15: 万円 | E15: p36/p37。原価10万＋TWW利益3万
B16: うち 人件費（船長）10,000円/h×5h | C16: 5 | D16: 万円 | E16: p17
B17: うち 人件費（船員）6,000円/h×5h | C17: 3 | D17: 万円 | E17: p17
B18: うち 桟橋使用料（往復） | C18: 0.3 | D18: 万円 | E18: p17
B19: うち 燃料費（230円/ℓ） | C19: 1.7 | D19: 万円 | E19: p17。15ℓ/h×5h×230円=17,250円との丸め差△250円
... B24: 延長料金（30分） | C24: 2 | D24: 万円 | E24: p18
B25: 収益按分（1号船）UMITO:投資家 | C25: 50:50 | D25: - | E25: p16
B26: 船舶 法定耐用年数（新造） | C26: 4 | D26: 年 | E26: p12。200%定率法 50/25/12.5/12.5%
B27: 船舶 耐用年数（築2年中古・簡便法） | C27: 2 | D27: 年 | E27: p13。(4-2)+2×20%=2.4→2年、初年度100%
B28: 年会費相当額（1口1,000万円の場合） | C28: 150 | D28: 万円 | E28: p39。100口なら年1.5億円だが帰属先が図に無い
B29: 船内席＋テラス席（Plan A〜D） | C29: 12〜18 | D29: 席 | E29: 設計図面 A02/A03。最大搭載人員44名(旅客44名)
A31: ■ B. 資料に記載がなく、本試算で置いた前提（★要確認）
B32: 項目 | C32: 値 | D32: 単位 | E32: 根拠・確認先
B33: TK① AM報酬・組成費用 合計 | C33: 1500 | D33: 万円 | E33: YN&C/東京WW/れいわ/TMI/三井デザインテック等。金額未開示→出資額の7.5%と仮置き
B34: 法人実効税率 | C34: 0.34 | D34: % | E34: 資本金1億円超の東京都所在法人を想定
B35: 造船期間（＝TK①の投資期間） | C35: 2 | D35: 年 | E35: p8「新築造船期間：24か月想定」
B36: TK② 年間維持費（係留/保険/JCI船検/整備/GK維持） | C36: 800 | D36: 万円 | E36: 資料に一切記載なし。12t旅客船の実勢から推計
B37: 一般売り 想定回数 | C37: 300 | D37: 回/年 | E37: 修繕積立(2万/回)の原資
B38: 年間稼働可能日数 | C38: 300 | D38: 日 | E38: 荒天・強風・整備・年末年始で65日停止を想定
B39: F&B 食材・飲料 原価率 | C39: 0.33 | D39: % | E39: 料理30%・ワイン40%の加重。WineBankの仕入力を反映
B40: F&B 1運航あたり調理・サービス人件費 | C40: 8 | D40: 万円 | E40: 招聘シェフ5万＋サービス2名×1.5万
B41: F&B 1運航あたり物流・消耗品 | C41: 1.5 | D41: 万円 | E41: 食材輸送・リネン・消耗品
B42: コーディネーションフィー率 | C42: 0.1 | D42: % | E42: p28「コーディネーションフィー（売上高の10%)」。母数の定義が曖昧→F&B売上に対して適用
B43: F&B 年間固定費 | C43: 2100 | D43: 万円 | E43: 統括MGR900+事務按分300+什器償却300+在庫金利100+保険許認可200+本部按分300
B44: WineBank 初期投資 | C44: 1500 | D44: 万円 | E44: 什器・食器・グラス・初期ワイン在庫

Sheet 02_投資リターン_造船TK
A1: 【投資リターン ①】造船匿名組合（GK①/TK①）への出資
A2: 役割：船の企画＋造船 → TK②へ引渡し。メリット：引渡によるキャピタルゲイン（p26）。投資期間＝造船24か月（p8）
A4: ■ 1. 損益の構成
B5: 項目 | C5: 金額(万円) | G5: 算式・出典
B6: 船舶取得・改装原価 | C6: ='01_前提条件'!$C$8 | G6: p34 ①建設仮勘定 200,000,000
B7: TK②への売却価格 | C7: ='01_前提条件'!$C$9 | G7: p34 ②売却時 現預金 400,000,000
B8: 船舶譲渡益 | C8: =C7-C6 | G8: p34「（貸）船舶譲渡益 200,000,000」
B9: AM報酬・組成費用（★推計） | C9: =-'01_前提条件'!$C$33 | G9: YN&C/東京WW/れいわ/TMI/三井DT。★資料に金額記載なし
B10: 分配可能利益 | C10: =C8+C9 | G10: 譲渡益 − 組成費用
A12: ■ 2. 投資家リターン（出資額＝造船原価2億円をTK①投資家が全額拠出する前提）
C13: ケースA：按分なし | D13: ケースB：50:50按分 | G13: 備考
B14: 投資家への分配率 | C14: =1 | D14: =0.5 | G14: p16「1号船は収益を50%(UMITO):50%(投資家)で按分」。按分対象がTK①の譲渡益を含むか要確認
B15: 投資家取分（税前） | C15: =$C$10*C14 | D15: =$C$10*D14
B16: 出資額 | C16: ='01_前提条件'!$C$8 | D16: ='01_前提条件'!$C$8
B17: 回収額（税前） | C17: =C16+C15 | D17: =D16+D15 | G17: 元本＋分配
B18: 倍率（税前 MOIC） | C18: =C17/C16 | D18: =D17/D16
B19: IRR（税前・2年） | C19: =(C18)^(1/'01_前提条件'!$C$35)-1 | D19: =(D18)^(1/'01_前提条件'!$C$35)-1 | G19: 中間CFなし → MOIC^(1/年数)-1
B20: 投資家取分（税後） | C20: =C15*(1-'01_前提条件'!$C$34) | D20: =D15*(1-'01_前提条件'!$C$34) | G20: 匿名組合分配は出資者(法人)側で益金
B21: 回収額（税後） | C21: =C16+C20 | D21: =D16+D20
B22: 倍率（税後 MOIC） | C22: =C21/C16 | D22: =D21/D16
B23: IRR（税後・2年） | C23: =(C22)^(1/'01_前提条件'!$C$35)-1 | D23: =(D22)^(1/'01_前提条件'!$C$35)-1
B25: ▼ 結論
B26: ・按分が譲渡益に及ばない場合：税前IRR 38.7%／税後IRR 26.9%（2年）。
B27: ・p16の50:50按分が譲渡益にも及ぶ場合：税前IRR 20.9%／税後IRR 14.2%（2年）。倍半分違う。
B28: ・ただしAM報酬・組成費用の実額が未開示のため、上記はいずれも『上限値』。契約23本(V2_0810)の報酬総額の開示が必須。
B29: ・最大リスクは「原価2億の船を4億で関連者へ売却」＝100%マークアップの移転価格。第三者船舶鑑定なしでは寄附金認定リスク。

Sheet 03_投資リターン_会員権TK
A1: 【投資リターン ②】会員権発行匿名組合（GK②/TK②・船主）への出資
A2: 役割：船舶の所有＋会員権発行。メリット：減価償却の計上／会員権の発行利益。責任：会員への20年間の役務提供義務（p26/p30）
A4: ■ 1. 会員権の設計（p21/p27/p29）
B5: 販売口数（口） | C5: ='01_前提条件'!$C$10 | E5: 1口価格（万円） | F5: ='01_前提条件'!$C$11
B6: 販売総額（万円） | C6: =C5*F5 | E6: UMITO手数料 | F6: =C6*'01_前提条件'!$C$12
B7: TK②ネット入金（万円） | C7: =C6-F6 | E7: 年間売上振替（万円） | F7: =C7/'01_前提条件'!$C$13
A9: ■ 2. 20年キャッシュフロー（完売まで2年ケース）
B10: 年度 | C10: 0 | D10: 1 | E10: 2 | F10: 3 | G10: 4 | H10: 5 | I10: 6 | J10: 7 | K10: 8 | L10: 9 | M10: 10 | N10: 11 | O10: 12 | P10: 13 | Q10: 14 | R10: 15 | S10: 16 | T10: 17 | U10: 18 | V10: 19 | W10: 20
B11: 船舶取得（△4億） | C11: =-'01_前提条件'!$C$9 | D11: 0 | E11: 0 | F11: 0 | G11: 0 | H11: 0 | I11: 0 | J11: 0 | K11: 0 | L11: 0 | M11: 0 | N11: 0 | O11: 0 | P11: 0 | Q11: 0 | R11: 0 | S11: 0 | T11: 0 | U11: 0 | V11: 0 | W11: 0
B12: 会員権ネット入金 | C12: 0 | D12: =$C$7/2 | E12: =$C$7/2 | F12: 0 | G12: 0 | H12: 0 | I12: 0 | J12: 0 | K12: 0 | L12: 0 | M12: 0 | N12: 0 | O12: 0 | P12: 0 | Q12: 0 | R12: 0 | S12: 0 | T12: 0 | U12: 0 | V12: 0 | W12: 0
B13: 一般売り修繕積立(+) | C13: 0 | D13: ='01_前提条件'!$C$22*'01_前提条件'!$C$37 | E13: ='01_前提条件'!$C$22*'01_前提条件'!$C$37 | F13: ='01_前提条件'!$C$22*'01_前提条件'!$C$37 | G13: ='01_前提条件'!$C$22*'01_前提条件'!$C$37 | H13: ='01_前提条件'!$C$22*'01_前提条件'!$C$37 | I13: ='01_前提条件'!$C$22*'01_前提条件'!$C$37 | J13: ='01_前提条件'!$C$22*'01_前提条件'!$C$37 | K13: ='01_前提条件'!$C$22*'01_前提条件'!$C$37 | ... W13: ='01_前提条件'!$C$22*'01_前提条件'!$C$37
B14: 維持費（★推計・資料記載なし） | C14: 0 | D14: =-'01_前提条件'!$C$36 | E14: =-'01_前提条件'!$C$36 | F14: =-'01_前提条件'!$C$36 | G14: =-'01_前提条件'!$C$36 | H14: =-'01_前提条件'!$C$36 | I14: =-'01_前提条件'!$C$36 | J14: =-'01_前提条件'!$C$36 | K14: =-'01_前提条件'!$C$36 | ... W14: =-'01_前提条件'!$C$36
B15: 年次ネットCF | C15: =SUM(C11:C14) | D15: =SUM(D11:D14) | E15: =SUM(E11:E14) | F15: =SUM(F11:F14) | G15: =SUM(G11:G14) | H15: =SUM(H11:H14) | I15: =SUM(I11:I14) | J15: =SUM(J11:J14) | ... W15: =SUM(W11:W14)
B16: 累計CF | C16: =C15 | D16: =C16+D15 | E16: =D16+E15 | F16: =E16+F15 | G16: =F16+G15 | H16: =G16+H15 | I16: =H16+I15 | J16: =I16+J15 | K16: =J16+K15 | ... W16: =V16+W15
B18: 20年累計CF（万円） | C18: =W16 | E18: 出資倍率 | F18: =(C18+'01_前提条件'!$C$9)/'01_前提条件'!$C$9
B19: IRR | C19: =IRR(C15:W15) | E19: 単純年平均利回り | F19: =C18/'01_前提条件'!$C$9/20
A21: ■ 3. 感応度：年間維持費（資料に一切記載がない最重要の未定項目）
B22: 年間維持費(万円) | C22: 0 | D22: 400 | E22: 800 | F22: 1200 | G22: 1600 | H22: 2000
B23: 20年累計CF(万円) | C23: =$C$7-'01_前提条件'!$C$9+('01_前提条件'!$C$22*'01_前提条件'!$C$37-C22)*20 | D23: =$C$7-'01_前提条件'!$C$9+('01_前提条件'!$C$22*'01_前提条件'!$C$37-D22)*20 | E23: =$C$7-'01_前提条件'!$C$9+('01_前提条件'!$C$22*'01_前提条件'!$C$37-E22)*20 | F23: =$C$7-'01_前提条件'!$C$9+('01_前提条件'!$C$22*'01_前提条件'!$C$37-F22)*20 | G23: =$C$7-'01_前提条件'!$C$9+('01_前提条件'!$C$22*'01_前提条件'!$C$37-G22)*20 | H23: =$C$7-'01_前提条件'!$C$9+('01_前提条件'!$C$22*'01_前提条件'!$C$37-H22)*20
B24: IRR（実測値） | C24: 0.359 | D24: 0.333 | E24: 0.304 | F24: 0.27 | G24: 0.228 | H24: 0.09
B26: ▼ 結論
B27: ・完売2年なら IRR 30.4%／20年累計CF +1.6億／出資倍率1.40倍。IRRが高いのは『4億払って2年で6億回収』の前倒し構造による見かけ。
B28: ・20年通算の絶対リターンは1.40倍＝単純年率2.0%に過ぎない。維持費が年1,600万を超えると20年累計CFはゼロになる。IRRではなく累計CFで判断すべき。
B29: ・70口止まりで20年累計CFは△2,000万、50口止まりで△1.4億。リターンは『会員権が売れるか』の一点に集約される。
B30: ・p26の「減価償却費の計上」は永久節税ではなく課税の繰延。20年通算の課税所得は6億−4億−維持費＋積立＝約1.6億で変わらない。
A32: ■ 4. 減価償却スケジュール（資料の2案）
B33: 年度 | C33: 1 | D33: 2 | E33: 3 | F33: 4 | G33: 5 | H33: 出典
B34: 案A 新造・耐用4年・200%定率 | C34: ='01_前提条件'!$C$9*0.5 | D34: ='01_前提条件'!$C$9*0.25 | E34: ='01_前提条件'!$C$9*0.125 | F34: ='01_前提条件'!$C$9*0.125 | G34: ='01_前提条件'!$C$9*0 | H34: p12。償却率0.500/保証率0.12499で検算済＝資料どおり
B35: 案B 築2年中古・耐用2年・簡便法 | C35: ='01_前提条件'!$C$9*1.0 | D35: ='01_前提条件'!$C$9*0 | E35: ='01_前提条件'!$C$9*0 | F35: ='01_前提条件'!$C$9*0 | G35: ='01_前提条件'!$C$9*0 | H35: p13。(4-2)+2×20%=2.4→2年、償却率1.000＝資料どおり
B36: 年間売上振替（前受金取崩） | C36: =$C$7/'01_前提条件'!$C$13 | D36: =$C$7/'01_前提条件'!$C$13 | E36: =$C$7/'01_前提条件'!$C$13 | F36: =$C$7/'01_前提条件'!$C$13 | G36: =$C$7/'01_前提条件'!$C$13 | H36: p32/p35
B38: ★ 案A（新造・4億・24か月）と案B（築2年中古）が同一資料に併記され、どちらが本件の前提か未確定。償却スピードが2倍違う。
B39: ★ 定率法は月割償却。期首取得でなければ案Bの初年度100%償却は成立しない（例：12月決算8月取得なら5/12＝41.7%）。
B40: ★ p13の「事業開始日：2024年7月31日」は本件（2026年）と不整合。他案件の記載が残存している可能性。

Sheet 04_営業リターン_FB
A1: 【営業リターン】WineBank の F&B 事業（グループ4）
A2: 役割：F&B業務（飲食物提供・シェフ手配）／食品衛生管理 収益：F&Bの売上高＋コーディネーションフィー（売上高の10%） 責任：食中毒リスク・品質管理・顧客満足度の維持（p28）
A4: ■ 1. 1運航あたりユニットエコノミクス（基本ケース：10名 × 客単価3.0万円）
B5: 項目 | C5: 金額(万円) | D5: 構成比 | E5: 算式
B6: 乗船人数（名） | C6: 10 | E6: 設計図面: 船内4〜8席＋テラス8〜10席
B7: F&B客単価（万円/名） | C7: 3 | E7: 料理1.8万＋ワイン1.2万を想定
B8: F&B売上 | C8: =C6*C7 | D8: 1
B9: 食材・飲料原価 | C9: =-C8*'01_前提条件'!$C$39 | D9: =C9/C8
B10: 調理・サービス人件費 | C10: =-'01_前提条件'!$C$40 | D10: =C10/C8 | E10: ★招聘シェフ5万＋サービス2名×1.5万（推計）
B11: 物流・消耗品 | C11: =-'01_前提条件'!$C$41 | D11: =C11/C8
B12: 限界利益 | C12: =SUM(C8:C11) | D12: =C12/C8
B13: コーディネーションフィー(10%) | C13: =C8*'01_前提条件'!$C$42 | D13: =C13/C8 | E13: ★母数の定義（F&B売上か運航売上か）要確認
B14: 1運航あたり貢献利益 | C14: =C12+C13 | D14: =C14/C8
B16: 1運航あたり損益分岐売上 | C16: =('01_前提条件'!$C$40+'01_前提条件'!$C$41)/(1-'01_前提条件'!$C$39+'01_前提条件'!$C$42) | E16: ＝(人件費+物流)÷(1−原価率+フィー率)。10名なら客単価12,338円が損益分岐
A18: ■ 2. シナリオ別 年間P/L
B19: 項目 | C19: 保守 | D19: 基本 | E19: 強気
B20: 年間総運航回数 | C20: 360 | D20: 600 | E20: 900 | F20: 稼働300日 × 1.2 / 2.0 / 3.0 枠/日
B21: F&B実施率 | C21: 0.7 | D21: 0.8 | E21: 0.9 | F21: 一般売り枠の一部はF&Bなし
B22: 乗船人数（名） | C22: 8 | D22: 10 | E22: 12
B23: F&B客単価（万円） | C23: 2 | D23: 3 | E23: 4
B24: F&B実施運航回数 | C24: =C20*C21 | D24: =D20*D21 | E24: =E20*E21
B25: F&B売上 | C25: =C24*C22*C23 | D25: =D24*D22*D23 | E25: =E24*E22*E23
B26: 食材・飲料原価 | C26: =-C25*'01_前提条件'!$C$39 | D26: =-D25*'01_前提条件'!$C$39 | E26: =-E25*'01_前提条件'!$C$39
B27: 調理・サービス人件費 | C27: =-C24*'01_前提条件'!$C$40 | D27: =-D24*'01_前提条件'!$C$40 | E27: =-E24*'01_前提条件'!$C$40
B28: 物流・消耗品 | C28: =-C24*'01_前提条件'!$C$41 | D28: =-D24*'01_前提条件'!$C$41 | E28: =-E24*'01_前提条件'!$C$41
B29: 限界利益 | C29: =SUM(C25:C28) | D29: =SUM(D25:D28) | E29: =SUM(E25:E28)
B30: 限界利益率 | C30: =C29/C25 | D30: =D29/D25 | E30: =E29/E25
B31: コーディネーションフィー | C31: =C25*'01_前提条件'!$C$42 | D31: =D25*'01_前提条件'!$C$42 | E31: =E25*'01_前提条件'!$C$42
B32: 貢献利益 | C32: =C29+C31 | D32: =D29+D31 | E32: =E29+E31
B33: 固定費 | C33: =-'01_前提条件'!$C$43 | D33: =-'01_前提条件'!$C$43 | E33: =-'01_前提条件'!$C$43
B34: 営業利益 | C34: =C32+C33 | D34: =D32+D33 | E34: =E32+E33
B35: 総収益（F&B売上＋フィー） | C35: =C25+C31 | D35: =D25+D31 | E35: =E25+E31
B36: 営業利益率 | C36: =C34/C35 | D36: =D34/D35 | E36: =E34/E35
B37: 税後利益 | C37: =C34*(1-'01_前提条件'!$C$34) | D37: =D34*(1-'01_前提条件'!$C$34) | E37: =E34*(1-'01_前提条件'!$C$34)
B38: 初期投資に対するROI | C38: =C34/'01_前提条件'!$C$44 | D38: =D34/'01_前提条件'!$C$44 | E38: =E34/'01_前提条件'!$C$44
B39: 損益分岐 F&B運航回数 | C39: ='01_前提条件'!$C$43/(C22*C23*(1-'01_前提条件'!$C$39+'01_前提条件'!$C$42)-'01_前提条件'!$C$40-'01_前提条件'!$C$41) | D39: ='01_前提条件'!$C$43/(D22*D23*(1-'01_前提条件'!$C$39+'01_前提条件'!$C$42)-'01_前提条件'!$C$40-'01_前提条件'!$C$41) | E39: ='01_前提条件'!$C$43/(E22*E23*(1-'01_前提条件'!$C$39+'01_前提条件'!$C$42)-'01_前提条件'!$C$40-'01_前提条件'!$C$41)
B41: ★ 保守ケースが赤字になる理由：招聘シェフ体制の人件費8万円/運航は運航回数に比例するため、
B42: 8名×2万円＝16万円/運航では貢献利益が2.8万円/運航しか出ず、固定費2,100万円を賄えない（黒字化に年745回必要＝供給上限1,500枠に対し非現実的）。
B43: → 低単価帯に落ちる場合は「招聘シェフ都度手配」ではなく「常駐1名＋陸上仕込み集中」へ体制を切り替える必要がある。
A45: ■ 3. 損益分岐マトリクス：年間営業利益（万円） 縦＝F&B実施運航回数／横＝1運航あたりF&B売上（万円）
...

Sheet 05_キャパシティ検証
A1: 【整合性検証】発行口数と供給キャパシティ／関係者インセンティブ
A3: ■ 1. 会員需要 vs 運航枠の供給
B4: 会員需要（口数×年間利用回数） | C4: ='01_前提条件'!$C$10*'01_前提条件'!$C$14 | D4: 回/年 | H4: p21「販売口数100口／年間利用10回」
B6: 年間稼働可能日数 | C6: 365 | D6: 330 | E6: 300 | F6: 260 | H6: 荒天・強風・JCI船検・整備・年末年始による停止を控除
B7: 供給枠（5枠/日） | C7: =C6*'01_前提条件'!$C$23 | D7: =D6*'01_前提条件'!$C$23 | E7: =E6*'01_前提条件'!$C$23 | F7: =F6*'01_前提条件'!$C$23
B8: 会員需要による占有率 | C8: =$C$4/C7 | D8: =$C$4/D7 | E8: =$C$4/E7 | F8: =$C$4/F7
B9: 一般売りに回せる枠 | C9: =C7-$C$4 | D9: =D7-$C$4 | E9: =E7-$C$4 | F9: =F7-$C$4
B11: ★ 会員需要だけで供給の55〜77%を占有する。しかも需要は花火大会7イベント（5/30足立・7/25隅田川・8/1江戸川・8/11江東・10/24東京湾・12/24・12/25）と
B12: 桜シーズン（3月下旬〜4月上旬）・週末の18時／20時枠に集中する（p6）。ピーク日の予約充足は構造的に不可能で、会員クレーム・解約の主因になる。
B13: → 1隻あたりの発行口数上限の設計根拠（ピーク日の会員1人あたり予約可能回数）を示す必要がある。100口は検証されていない。
A15: ■ 2. 東京ウォータウェイズのインセンティブ（枠の奪い合い）
C16: 会員運航 | D16: 一般売り | H16: 出典
B17: 収入（万円/運航） | C17: ='01_前提条件'!$C$15 | D17: ='01_前提条件'!$C$21 | H17: p36 13万円 / p37 定価30万円
B18: 運航原価（万円） | C18: =-'01_前提条件'!$C$15+'01_前提条件'!$C$20 | D18: =-'01_前提条件'!$C$15+'01_前提条件'!$C$20 | H18: p17 小計10万円
B19: TK②への修繕積立（万円） | C19: =0 | D19: =-'01_前提条件'!$C$22 | H19: p37 一般売り時のみ2万円
B20: TWWの1運航利益（万円） | C20: =SUM(C17:C19) | D20: =SUM(D17:D19)
B21: 一般売り／会員運航 の倍率 | C21: =D20/C20
B23: ★ 東京ウォータウェイズは一般売りを優先する経済合理性を持つ（利益が6倍）。会員が繁忙日に予約できない構造的な利益相反。
B24: → 「再運航委託契約（UMITO⇒東京ウォータウェイズ）」に会員優先予約のSLA（例：〇日前まで会員優先／繁忙日は会員枠を◯枠確保／未達時のペナルティ）を明記する必要がある。
A26: ■ 3. 年会費の帰属（スキーム最大のリカーリング収益が図に無い）
B27: 年会費相当額（万円/口） | C27: ='01_前提条件'!$C$28 | H27: p39「年会費相当額：150万円／販売価格に対する年会費比率15%」
B28: 口数 | C28: ='01_前提条件'!$C$10
B29: 年会費 年間総額（万円） | C29: =C27*C28 | H29: ＝年1.5億円。TK②の年間売上振替3,000万円の5倍
B30: 20年累計（万円） | C30: =C29*'01_前提条件'!$C$13
B32: ★ p27/p28の図では年会費の徴収者はUMITO。p36は「会員から徴収する年会費と外注費にプラスの差額が生じる場合は利益として計上」とするのみで、
B33: TK②（投資家）への配分が定義されていない。年1.5億円×20年＝30億円がp16の50:50按分の対象外だとすれば、投資家リターンの前提が根本から変わる。最優先で確認すべき論点。
A35: ■ 4. 会員1人あたりの20年総負担（会員権が売れるかの検証）
B36: 費目 | C36: 金額(万円) | H36: 内訳
B37: 会員権 取得価格 | C37: ='01_前提条件'!$C$11 | H37: p21
B38: 年会費 20年分 | C38: ='01_前提条件'!$C$28*'01_前提条件'!$C$13 | H38: p39 150万×20年
B39: 都度利用料 20年分 | C39: ='01_前提条件'!$C$15*'01_前提条件'!$C$14*'01_前提条件'!$C$13 | H39: p36 13万×10回×20年
B40: F&B 20年分（10名×3万×10回） | C40: =10*3*'01_前提条件'!$C$14*'01_前提条件'!$C$13 | H40: 本試算の基本ケース単価
B41: 20年総負担 | C41: =SUM(C37:C40)
B42: 1回（90分）あたり実質負担 | C42: =C41/('01_前提条件'!$C$14*'01_前提条件'!$C$13)
B44: ★ 会員1人あたり20年総負担は1億2,600万円、90分のクルーズ1回あたり実質63万円（10名で割ると1人6.3万円）。この価格で100口を売り切れるかが、全関係者のリターンを決める唯一の変数。

Sheet 06_ダブルチェック指摘
A1: 【ダブルチェック】指摘事項一覧
A2: 対象：0824事業計画PDF(43p)／クルーザーデザインPJ図面2点／V2_0810契約進行表
B4: No. | C4: 重要度 | D4: 論点 | E4: 内容 | F4: WineBankとしての対応・確認先
B5: 1 | C5: 高 | D5: 移転価格 | E5: 原価2億円の船を関連者間で4億円で売却（100%マークアップ）。TK②の減価償却基礎額4億円はこの価格に依存する。時価が否認されると譲渡益課税・寄附金認定に加え、償却額も縮みスキームの核が崩れる。 | F5: 第三者による船舶鑑定評価書を必須要件に。TMI総合法律事務所・れいわ税理士法人の書面意見を取得。
B6: 2 | C6: 高 | D6: 償却前提の二重記載 | E6: p8/p12は「新築造船4億円・24か月・耐用4年（50/25/12.5/12.5%）」、p13は「築2年中古・耐用2年・初年度100%」。実際の図面（ELMO 2024/06/19）は既存船WATERWAYSⅢの『改造工事』。どれが本件の前提か未確定で、償却スピードが2倍違う。 | F6: 新造か中古改装かを確定させ、投資家向け資料を一本化。
B7: 3 | C7: 高 | D7: リース区分の自己矛盾 | E7: p31は「リース期間が経済的耐用年数の75%以上ならファイナンスリース」とする一方、p12/p13は耐用年数を4年／2年としている。20年（10年更新）のリースは4年の500%。『償却は速く、リースはオペレーティング』は両立しない可能性が高い。 | F7: ファイナンスリース判定を受けるとTK②で償却できず、スキームの前提が消滅。書面意見必須。
B8: 4 | C8: 高 | D8: 消費税の欠落 | E8: p32が「消費税は加味せず」と明記。会員権（施設利用権）の販売は課税資産の譲渡等で、10億円の販売なら仮受消費税1億円が原則販売時に発生。法人税の20年按分と消費税の課税時期は別物。船4億円の仮払4,000万円を控除しても初年度に約6,000万円の納税キャッシュアウト。 | F8: TK②の資金繰り表に消費税を反映。前受金処理と課税時期の税務見解を取得。
B9: 5 | C9: 高 | D9: TK②の維持費が未計上 | E9: 係留料・船舶保険・JCI船舶検査・定期整備・船外機交換（YAMAHA225PS×2、8〜12年で更新）・GK/TK維持コスト（役員派遣・税務・会計）が資料に一切ない。年1,600万円を超えると20年累計CFはゼロになる。 | F9: 20年の維持費・大規模修繕計画（DCF）の提出を求める。
B10: 6 | C10: 高 | D10: 年会費の帰属が未定義 | E10: p39の年会費相当額150万円×100口＝年1.5億円（20年で30億円）。p27/p28では徴収者はUMITOと図示されるのみで、TK②（投資家）への配分が定義されていない。p16の50:50按分の対象外なら投資家リターンの前提が根本から変わる。 | F10: 本スキーム最大のリカーリング収益。按分対象に含まれるかを最優先で確認。
B11: 7 | C11: 高 | D11: 発行口数と供給の不整合 | E11: 100口×年10回＝年1,000運航の権利に対し、供給は5枠/日×稼働300日＝1,500枠。会員需要だけで67%を占有し、需要は花火7イベント・桜・週末夜に集中。ピーク日の予約充足は構造的に不可能。 | F11: 1隻あたり発行口数の上限根拠（ピーク日の充足シミュレーション）を要求。
B12: 8 | C12: 中 | D12: TWWの利益相反 | E12: 会員運航の利益は3万円/運航、一般売りは18万円/運航で6倍。東京ウォータウェイズは一般売りを優先する経済合理性を持つ。 | F12: 「再運航委託契約」に会員優先予約のSLAとペナルティを明記。
B13: 9 | C13: 中 | D13: 按分の対象が不明確 | E13: p16「1号船は収益を50%(UMITO):50%(投資家)で按分」の『収益』が、TK①の譲渡益なのかTK②の会員権利益なのか、両方なのかが定義されていない。投資家IRRが20.9%と38.7%で倍半分違う。 | F13: 按分対象・計算基礎・控除項目を匿名組合契約で定義。
B14: 10 | C14: 中 | D14: AM報酬・組成費用が全面未開示 | E14: YN&C（ストラクチャリングAM）、東京ウォータウェイズ（造船AM）、れいわ税理士法人（役員派遣・出納）、UMITO子会社（AM②）、サブAM（TBD）、TMI（リーガル）、三井デザインテック（デザイン監修）。契約23本の報酬総額がゼロ記載。 | F14: 現状の投資リターン試算はすべて『上限値』。フィーテーブルの開示を要求。
B15: 11 | C15: 中 | D15: UMITO手数料40%の水準 | E15: 会員権販売の受託手数料4億円（40%）は極めて高い。p36自身が「一部を前受収益として20年按分するよう指導される可能性」を認めている。按分となればUMITOの資金繰りとTK②への6億円送金タイミングが連動する。 | F15: 送金条件（エスクロー／分割送金の可否）を販売委託契約で確認。
B16: 12 | C16: 中 | D16: コーディネーションフィーの母数 | E16: p28「コーディネーションフィー（売上高の10%)」の『売上高』がF&B売上か運航売上かで、WineBankの収益が大きく変わる（基本ケースでF&B売上基準1,440万円 vs 運航売上基準は別途）。 | F16: F&B業務委託契約（東京ウォータウェイズ⇒WineBank）で母数を明文化。
... B19: 15 | C19: 低 | D19: p8の「新築造船費用4億円」 | E19: 4億円はTK②への売却価格であって造船原価ではない（原価は2億円）。参考事例（野村不動産×ヤンマー×Fairmont）と自社原価が同一ページ上で混在し、誤読を招く。 | F19: 投資家向け資料で明確に区分。
B21: ■ 検算が資料どおりで問題なかった項目
B22: ・会員権 100口×1,000万円＝10億円／UMITO手数料40%＝4億円／TK②ネット6億円／年間売上振替 6億÷20年＝3,000万円
B23: ・1口あたり償却 1,000万÷20年＝50万円／1回あたり 50万÷10回＝5万円
B24: ・運航原価 船長5万＋船員3万＋桟橋0.3万＋燃料1.7万＝10万円／＋TWW利益3万＝都度利用料13万円
B25: ・200%定率法（耐用4年）50%/25%/12.5%/12.5% … 償却率0.500・保証率0.12499で再計算して一致
B26: ・中古資産の簡便法 (4年−2年)+2年×20%＝2.4年→2年（切捨） … 一致
B27: ・造船TK譲渡益 4億−2億＝2億円／年会費比率 150万÷1,000万＝15%、100万÷2,000万＝5%
