Workbook

Sheet ①3年サマリー
B1: 3か年計画 FY2027〜FY2029（プランD）
B2: FY2026は吉田さん作成の着地見込（2026/10/13版）。FY2027以降は2026年10月20日の中野指示ベース。単位：円（税別）
B4: 【全社損益】
B5: 科目 | C5: FY2026 着地見込 | D5: FY2027 | E5: FY2028 | F5: FY2029 | G5: CAGR 27→29 | H5: コメント
B6: 売上高 | C6: =④FY2026着地!H6 -> 816573602 | D6: =②シナリオ比較!$F$10 -> 770173797 | E6: =②シナリオ比較!$G$10 -> 800173797 | F6: =②シナリオ比較!$H$10 -> 800173797 | G6: =IF(D6>0,(F6/D6)^(1/2)-1,"") -> 0.01929007 | H6: FY2026は私募ファンド等257.3百万円を含む
B7: 売上総利益 | C7: =④FY2026着地!H7 -> 350898010 | D7: =②シナリオ比較!$F$11 -> 3.855887e+08 | E7: =②シナリオ比較!$G$11 -> 4.155887e+08 | F7: =②シナリオ比較!$H$11 -> 4.155887e+08 | G7: =IF(D7>0,(F7/D7)^(1/2)-1,"") -> 0.038172967
B8: 売上総利益率 | C8: =C7/C6 -> 0.42972 | D8: =②シナリオ比較!$F$12 -> 0.50065154 | E8: =②シナリオ比較!$G$12 -> 0.51937304 | F8: =②シナリオ比較!$H$12 -> 0.51937304
B9: 販管費 | C9: =④FY2026着地!H8 -> 350037032 | D9: =②シナリオ比較!$F$15 -> 321629734 | E9: =②シナリオ比較!$G$15 -> 3.2399794e+08 | F9: =②シナリオ比較!$H$15 -> 3.2643719e+08 | H9: 人件費のみ昇給3%（FY2028〜）
B10: 営業利益 | C10: =④FY2026着地!H9 -> 860978 | D10: =②シナリオ比較!$F$16 -> 63958967 | E10: =②シナリオ比較!$G$16 -> 91590762 | F10: =②シナリオ比較!$H$16 -> 89151511 | G10: =IF(D10>0,(F10/D10)^(1/2)-1,"") -> 0.18062951
B11: 営業外費用 | C11: =④FY2026着地!H11 -> 14015424 | D11: =②シナリオ比較!$F$17 -> 12000000 | E11: =②シナリオ比較!$G$17 -> 10000000 | F11: =②シナリオ比較!$H$17 -> 8000000 | H11: 借入返済に合わせ逓減
B12: 経常利益 | C12: =④FY2026着地!H12 -> -12722025 | D12: =②シナリオ比較!$F$18 -> 51958967 | E12: =②シナリオ比較!$G$18 -> 81590762 | F12: =②シナリオ比較!$H$18 -> 81151511 | G12: =IF(D12>0,(F12/D12)^(1/2)-1,"") -> 0.24973534
B13: 法人税等 | D13: =②シナリオ比較!$F$22 -> 0 | E13: =②シナリオ比較!$G$22 -> 70000 | F13: =②シナリオ比較!$H$22 -> 11193101 | H13: 繰越欠損金の使い切り後に課税
B14: 当期純利益 | C14: =④FY2026着地!H14 -> -54622025 | D14: =②シナリオ比較!$F$23 -> 51958967 | E14: =②シナリオ比較!$G$23 -> 81520762 | F14: =②シナリオ比較!$H$23 -> 69958410 | H14: FY2026は税引前（特別損失41.9百万円を含む）
B15: 繰越欠損金 期末残高 | C15: =④FY2026着地!$H$19 -> 181986237 | D15: =②シナリオ比較!$F$21 -> 1.3002727e+08 | E15: =②シナリオ比較!$G$21 -> 48436508 | F15: =②シナリオ比較!$H$21 -> 0
B17: 【部門別】プランD
B18: 部門 | D18: FY2027 | E18: FY2028 | F18: FY2029
B19: 売上
B20: 本部 | D20: =⑤部門別損益!C10 -> 92500000 | E20: =⑤部門別損益!C28 -> 122500000 | F20: =⑤部門別損益!C46 -> 122500000
B21: EC/酒販店卸 | D21: =⑤部門別損益!D10 -> 1.9115387e+08 | E21: =⑤部門別損益!D28 -> 1.9115387e+08 | F21: =⑤部門別損益!D46 -> 1.9115387e+08
B22: ワインテック | D22: =⑤部門別損益!E10 -> 3.0262794e+08 | E22: =⑤部門別損益!E28 -> 3.0262794e+08 | F22: =⑤部門別損益!E46 -> 3.0262794e+08
B23: その他 | D23: =⑤部門別損益!F10 -> 1.8389199e+08 | E23: =⑤部門別損益!F28 -> 1.8389199e+08 | F23: =⑤部門別損益!F46 -> 1.8389199e+08
B24: 合計 | D24: =⑤部門別損益!G10 -> 770173797 | E24: =⑤部門別損益!G28 -> 800173797 | F24: =⑤部門別損益!G46 -> 800173797
B25: 粗利
B26: 本部 | D26: =⑤部門別損益!C14 -> 92500000 | E26: =⑤部門別損益!C32 -> 122500000 | F26: =⑤部門別損益!C50 -> 122500000
B27: EC/酒販店卸 | D27: =⑤部門別損益!D14 -> 47620405 | E27: =⑤部門別損益!D32 -> 47620405 | F27: =⑤部門別損益!D50 -> 47620405
B28: ワインテック | D28: =⑤部門別損益!E14 -> 81334021 | E28: =⑤部門別損益!E32 -> 81334021 | F28: =⑤部門別損益!E50 -> 81334021
B29: その他 | D29: =⑤部門別損益!F14 -> 1.6413428e+08 | E29: =⑤部門別損益!F32 -> 1.6413428e+08 | F29: =⑤部門別損益!F50 -> 1.6413428e+08
B30: 合計 | D30: =⑤部門別損益!G14 -> 3.855887e+08 | E30: =⑤部門別損益!G32 -> 4.155887e+08 | F30: =⑤部門別損益!G50 -> 4.155887e+08
B31: 部門利益（配賦前）
B32: 本部 | D32: =⑤部門別損益!C18 -> 16759525 | E32: =⑤部門別損益!C36 -> 45764943 | F32: =⑤部門別損益!C54 -> 44740524
B33: EC/酒販店卸 | D33: =⑤部門別損益!D18 -> 3443270.5 | E33: =⑤部門別損益!D36 -> 3040443.7 | F33: =⑤部門別損益!D54 -> 2625532.2
B34: ワインテック | D34: =⑤部門別損益!E18 -> 347426.1 | E34: =⑤部門別損益!E36 -> -417598.84 | F34: =⑤部門別損益!E54 -> -1205574.5
B35: その他 | D35: =⑤部門別損益!F18 -> 43408746 | E35: =⑤部門別損益!F36 -> 43202974 | F35: =⑤部門別損益!F54 -> 42991029
B36: 合計 | D36: =⑤部門別損益!G18 -> 63958967 | E36: =⑤部門別損益!G36 -> 91590762 | F36: =⑤部門別損益!G54 -> 89151511
B38: 【参考】プランE（私募ファンドを上乗せ）と資金
B39: 項目 | D39: FY2027 | E39: FY2028 | F39: FY2029
B40: プランE 売上高 | D40: =②シナリオ比較!$I$10 -> 1470173797 | E40: =②シナリオ比較!$J$10 -> 1800173797 | F40: =②シナリオ比較!$K$10 -> 1800173797
B41: プランE 経常利益 | D41: =②シナリオ比較!$I$18 -> 86958967 | E41: =②シナリオ比較!$J$18 -> 1.3159076e+08 | F41: =②シナリオ比較!$K$18 -> 1.3115151e+08
B42: プランD 期末現預金 | D42: =⑦資金繰り・在庫!C17 -> 55398539 | E42: =⑦資金繰り・在庫!D17 -> 1.1035887e+08 | F42: =⑦資金繰り・在庫!E17 -> 1.5375686e+08
B43: プランE 期末現預金 | D43: =⑦資金繰り・在庫!F17 -> 90398539 | E43: =⑦資金繰り・在庫!G17 -> 1.8292729e+08 | F43: =⑦資金繰り・在庫!H17 -> 2.4285686e+08
...

Sheet ③前提
B1: 3か年計画 FY2027〜FY2029 前提条件
B2: 黄色＝入力セル（変えると全シートに反映）。2026年10月20日の中野指示ベース。単位：円（税別）
B4: 【1】FY2026着地 出典：吉田さん「見込_20261013.xlsx」（10/13メール）
B5: 科目 | C5: 実績 2025/10-2026/08 | D5: 見込 2026/09 | E5: 私募ファンド等 （当初） | F5: 10/13修正 | G5: 決算整理
B6: 売上高 | C6: 493424693 | D6: 69058000 | E6: 257272727 | F6: -3181818 | G6: 0
B7: 売上総利益 | C7: 211358428 | D7: 17721400 | E7: 105000000 | F7: 16818182 | G7: 0
B8: 販管費 | C8: 330563234 | D8: 26495862 | E8: 0 | F8: -1222064 | G8: -5800000
B9: 営業外収益 | C9: 432421 | D9: 0 | E9: 0 | F9: 0 | G9: 0
B10: 営業外費用 | C10: 11673492 | D10: 1341932 | E10: 0 | F10: 0 | G10: 1000000
B11: 特別損失 | C11: 900000 | D11: 0 | E11: 0 | F11: 0 | G11: 41000000
B12: ※私募ファンド等（当初）：私募ファンド 181.8（粗利30.0）＋45.5（粗利45.0）＋アピシウス20.0＋経営指導料10.0＝売上257.3／粗利105.0百万円
B13: ※10/13修正：経営指導料▲3.2（請求書変更）、オークション原価▲20.0、費用▲1.2（精算）。決算整理：ソフトウェア償却▲6.5＋償却費0.7を特別損失41.0へ、営業外費用＋1.0
B15: 2026/08-09 売上原価（私募ファンド等・修正を含む） | C15: 212763013 | I15: 同上（8月実績＋9月見込＋私募＋修正）。在庫の算定に使用
B16: 繰越欠損金 FY2025末残高 | C16: 127364212 | I16: 決算報告書 第54期
B17: 2026/07末 商品在庫 | C17: 721162328 | I17: 試算表 貸借対照表
B18: 2026/08-09 商品仕入 | C18: 55000000 | I18: ★中野指示：50〜60百万円の中央値。実績に差し替え
B20: 【2】ベース：再編後の実力値（2026/04-08 実績の月平均×12。吉田さん10/13版）
B21: 横ばい 売上（年） | C21: 510160224 | I21: 4月32.1／5月35.0／6月32.4／7月63.9／8月49.2百万円
B22: 横ばい 売上総利益（年） | C22: 228834629 | I22: 粗利率44.9%
B23: 横ばい 販管費（年） 調整前 | C23: 327429734 | I23: 撤退3店舗を含まない5か月
B24: システム償却の減少（特別損失処理後） | C24: -5800000 | I24: ★決算整理と同額（ソフトウェア償却▲6.5＋償却費0.7）。FY2027以降も発生しない前提
B25: 横ばい 販管費（年） | C25: =C23+C24 -> 321629734
B26: うち 人件費（年） | C26: 78940164 | I26: 吉田さん10/13版の人件費行（4-8月）
B28: 【3】既存事業 売上
B29: 項目 | D29: FY2027 | E29: FY2028 | F29: FY2029
B30: FY2025 売上高（実績） | C30: 752864901 | I30: 決算報告書 第54期
B31: 既存事業 前年比成長率 | D31: — | E31: 0 | F31: 0 | I31: FY2027は前期・前々期の売上平均。FY2028以降はFY2027水準からの成長率（初期値0%＝横ばい）
B32: 差額売上の粗利率 | C32: 0.3 | I32: 横ばい実力値から売上平均までの差額に適用。FY2025 26.8%・実績を踏まえ保守的に30%
B34: 【4】上乗せ案件（原価なし）
B35: 案件 | D35: FY2027 | E35: FY2028 | F35: FY2029 | G35: 計上部門 | H35: 計上月 | I35: 計上月はFY2027月次用：0＝12か月按分／1〜12＝10月からの月番号
B36: グループ経営指導料 間接グループ5社 | D36: 80000000 | E36: 110000000 | F36: 110000000 | G36: 本部 | H36: 0 | I36: 中野指示（10/20）：本来110百万円超、うち30百万円を前期に前倒しのため今期80百万円程度。FY2028以降は110百万円
B37: コンサルティング料 Thierry Marx | D37: 2500000 | E37: 2500000 | F37: 2500000 | G37: 本部 | H37: 0 | I37: 契約更新が前提
B38: コンサルティング料 Apicius | D38: 10000000 | E38: 10000000 | F38: 10000000 | G38: 本部 | H38: 0 | I38: 契約更新が前提
B39: M&A仲介（アピシウス） | D39: 0 | E39: 0 | F39: 0 | G39: 本部 | H39: 0 | I39: ★削除：一発だけの案件で、FY2026に20百万円を計上済みのため0（中野確認 10/25）
B40: クルーザー×ワイン事業 | D40: 20000000 | E40: 20000000 | F40: 20000000 | G40: その他 | H40: 0 | I40: 年2回（3月・9月）各10百万円。月次は按分で表示
B41: 上乗せ案件 合計 | D41: =SUM(D36:D40) -> 112500000 | E41: =SUM(E36:E40) -> 142500000 | F41: =SUM(F36:F40) -> 142500000
B43: 【5】私募ファンド（プランEのみ）
B44: 項目 | D44: FY2027 | E44: FY2028 | F44: FY2029
B45: 私募ファンド 売上 | D45: 700000000 | E45: 1000000000 | F45: 1000000000 | I45: 中野指示（10/20）：残り7億円程度を今期計上。FY2028以降は戸髙さん版の各10億円
B46: 私募ファンド 粗利率 | D46: 0.05 | E46: 0.05 | F46: 0.05 | I46: 戸髙さん版と同じ5%（保守的）。FY2026の計上実績は粗利75.0百万円／売上227.3百万円＝33.0%
...

Sheet ④FY2026着地
B1: FY2026（2026年9月期）着地見込み
B2: 吉田さん作成「見込_20261013.xlsx」（2026/10/13）の通り。数字は③前提【1】に入力。単位：円
B4: 【1】損益
B5: 科目 | C5: 実績 10-8月 | D5: 見込 9月 | E5: 私募ファンド等 | F5: 10/13修正 | G5: 決算整理 | H5: 通期 着地
B6: 売上高 | C6: =③前提!$C$6 -> 493424693 | D6: =③前提!$D$6 -> 69058000 | E6: =③前提!$E$6 -> 257272727 | F6: =③前提!$F$6 -> -3181818 | G6: =③前提!$G$6 -> 0 | H6: =SUM(C6:G6) -> 816573602
B7: 売上総利益 | C7: =③前提!$C$7 -> 211358428 | D7: =③前提!$D$7 -> 17721400 | E7: =③前提!$E$7 -> 105000000 | F7: =③前提!$F$7 -> 16818182 | G7: =③前提!$G$7 -> 0 | H7: =SUM(C7:G7) -> 350898010
B8: 販管費 | C8: =③前提!$C$8 -> 330563234 | D8: =③前提!$D$8 -> 26495862 | E8: =③前提!$E$8 -> 0 | F8: =③前提!$F$8 -> -1222064 | G8: =③前提!$G$8 -> -5800000 | H8: =SUM(C8:G8) -> 350037032
B9: 営業利益 | C9: =C7-C8 -> -119204806 | D9: =D7-D8 -> -8774462 | E9: =E7-E8 -> 105000000 | F9: =F7-F8 -> 18040246 | G9: =G7-G8 -> 5800000 | H9: =H7-H8 -> 860978
B10: 営業外収益 | C10: =③前提!$C$9 -> 432421 | D10: =③前提!$D$9 -> 0 | E10: =③前提!$E$9 -> 0 | F10: =③前提!$F$9 -> 0 | G10: =③前提!$G$9 -> 0 | H10: =SUM(C10:G10) -> 432421
B11: 営業外費用 | C11: =③前提!$C$10 -> 11673492 | D11: =③前提!$D$10 -> 1341932 | E11: =③前提!$E$10 -> 0 | F11: =③前提!$F$10 -> 0 | G11: =③前提!$G$10 -> 1000000 | H11: =SUM(C11:G11) -> 14015424
B12: 経常利益 | C12: =C9+C10-C11 -> -130445877 | D12: =D9+D10-D11 -> -10116394 | E12: =E9+E10-E11 -> 105000000 | F12: =F9+F10-F11 -> 18040246 | G12: =G9+G10-G11 -> 4800000 | H12: =H9+H10-H11 -> -12722025
B13: 特別損失 | C13: =③前提!$C$11 -> 900000 | D13: =③前提!$D$11 -> 0 | E13: =③前提!$E$11 -> 0 | F13: =③前提!$F$11 -> 0 | G13: =③前提!$G$11 -> 41000000 | H13: =SUM(C13:G13) -> 41900000
B14: 税引前当期純利益 | C14: =C12-C13 -> -131345877 | D14: =D12-D13 -> -10116394 | E14: =E12-E13 -> 105000000 | F14: =F12-F13 -> 18040246 | G14: =G12-G13 -> -36200000 | H14: =H12-H13 -> -54622025
B15: （参考）吉田さん版の通期 | C15: 営業 860,978円／経常 -12,722,025円／税引前 -54,622,025円
B17: 既存事業 売上（私募ファンド等を除く） | H17: =H6-E6-F6 -> 562482693
B18: FY2027の2期平均の算定に使用。私募ファンド・アピシウス・経営指導料（修正後）は一過性・別建てのため除外
B19: 繰越欠損金 FY2026末残高 | H19: =③前提!$C$16+MAX(0,-H14) -> 181986237
B20: FY2025末残高＋FY2026の税引前損失（特別損失を含む）。税務上の加減算は未反映
B21: 商品在庫 2026/09末 | H21: =③前提!$C$17+③前提!$C$18-③前提!$C$15 -> 563399315
B22: 7月末在庫＋8-9月仕入（暫定）−8-9月の売上原価（私募の原価を含む）
B24: 【2】前回（10/25版）からの修正
B25: 前回は試算表10か月実績に「8-9月トントン＋私募200百万円（粗利率5%）＋経営指導料30百万円」を積み上げ、営業利益▲64.0百万円としていました。
B26: 吉田さんの10/13版（8月実績・9月見込・私募ファンド等105百万円の粗利・10/13修正・決算整理）に置き換え、営業利益＋0.9／経常▲12.7／税引前▲54.6百万円です。
B27: 私募ファンドの粗利は5%ではなく、181.8百万円分で30.0、45.5百万円分で45.0の計75.0百万円です。

Sheet ②シナリオ比較
B1: 3か年シナリオ比較（横ばい実力値／プランD／プランE）
B2: 3シナリオを同時に計算。前提はすべて③前提。単位：円（税別）
C4: 横ばい実力値（参考） | F4: プランD メイン | I4: プランE 上振れ
B5: 科目 | C5: FY2027 | D5: FY2028 | E5: FY2029 | F5: FY2027 | G5: FY2028 | H5: FY2029 | I5: FY2027 | J5: FY2028 | K5: FY2029
B6: 既存事業 売上 | C6: =③前提!$C$21 -> 510160224 | D6: =③前提!$C$21 -> 510160224 | E6: =③前提!$C$21 -> 510160224 | F6: =(③前提!$C$30+④FY2026着地!$H$17)/2 -> 657673797 | G6: =F6*(1+③前提!$E$31) -> 657673797 | H6: =G6*(1+③前提!$F$31) -> 657673797 | I6: =(③前提!$C$30+④FY2026着地!$H$17)/2 -> 657673797 | J6: =I6*(1+③前提!$E$31) -> 657673797 | K6: =J6*(1+③前提!$F$31) -> 657673797
B7: うち 差額売上 | C7: =C6-③前提!$C$21 -> 0 | D7: =D6-③前提!$C$21 -> 0 | E7: =E6-③前提!$C$21 -> 0 | F7: =F6-③前提!$C$21 -> 147513573 | G7: =G6-③前提!$C$21 -> 147513573 | H7: =H6-③前提!$C$21 -> 147513573 | I7: =I6-③前提!$C$21 -> 147513573 | J7: =J6-③前提!$C$21 -> 147513573 | K7: =K6-③前提!$C$21 -> 147513573
B8: 私募ファンド | C8: 0 | D8: 0 | E8: 0 | F8: 0 | G8: 0 | H8: 0 | I8: =③前提!$D$45 -> 700000000 | J8: =③前提!$E$45 -> 1000000000 | K8: =③前提!$F$45 -> 1000000000
B9: 上乗せ案件 | C9: 0 | D9: 0 | E9: 0 | F9: =③前提!$D$41 -> 112500000 | G9: =③前提!$E$41 -> 142500000 | H9: =③前提!$F$41 -> 142500000 | I9: =③前提!$D$41 -> 112500000 | J9: =③前提!$E$41 -> 142500000 | K9: =③前提!$F$41 -> 142500000
B10: 売上高 合計 | C10: =C6+C8+C9 -> 510160224 | D10: =D6+D8+D9 -> 510160224 | E10: =E6+E8+E9 -> 510160224 | F10: =F6+F8+F9 -> 770173797 | G10: =G6+G8+G9 -> 800173797 | H10: =H6+H8+H9 -> 800173797 | I10: =I6+I8+I9 -> 1470173797 | J10: =J6+J8+J9 -> 1800173797 | K10: =K6+K8+K9 -> 1800173797
B11: 売上総利益 | C11: =③前提!$C$22+C7*③前提!$C$32+C8*③前提!$D$46+C9 -> 228834629 | D11: =③前提!$C$22+D7*③前提!$C$32+D8*③前提!$E$46+D9 -> 228834629 | E11: =③前提!$C$22+E7*③前提!$C$32+E8*③前提!$F$46+E9 -> 228834629 | F11: =③前提!$C$22+F7*③前提!$C$32+F8*③前提!$D$46+F9 -> 3.855887e+08 | G11: =③前提!$C$22+G7*③前提!$C$32+G8*③前提!$E$46+G9 -> 4.155887e+08 | H11: =③前提!$C$22+H7*③前提!$C$32+H8*③前提!$F$46+H9 -> 4.155887e+08 | I11: =③前提!$C$22+I7*③前提!$C$32+I8*③前提!$D$46+I9 -> 4.205887e+08 | J11: =③前提!$C$22+J7*③前提!$C$32+J8*③前提!$E$46+J9 -> 4.655887e+08 | K11: =③前提!$C$22+K7*③前提!$C$32+K8*③前提!$F$46+K9 -> 4.655887e+08
B12: 売上総利益率 | C12: =C11/C10 -> 0.44855443 | D12: =D11/D10 -> 0.44855443 | E12: =E11/E10 -> 0.44855443 | F12: =F11/F10 -> 0.50065154 | G12: =G11/G10 -> 0.51937304 | H12: =H11/H10 -> 0.51937304 | I12: =I11/I10 -> 0.28608094 | J12: =J11/J10 -> 0.25863542 | K12: =K11/K10 -> 0.25863542
B13: 人件費 | C13: =③前提!$C$26*(1+③前提!$D$50) -> 78940164 | D13: =C13*(1+③前提!$E$50) -> 81308369 | E13: =D13*(1+③前提!$F$50) -> 83747620 | F13: =③前提!$C$26*(1+③前提!$D$50) -> 78940164 | G13: =F13*(1+③前提!$E$50) -> 81308369 | H13: =G13*(1+③前提!$F$50) -> 83747620 | I13: =③前提!$C$26*(1+③前提!$D$50) -> 78940164 | J13: =I13*(1+③前提!$E$50) -> 81308369 | K13: =J13*(1+③前提!$F$50) -> 83747620
B14: その他販管費 | C14: =(③前提!$C$25-③前提!$C$26)*(1+③前提!$D$51) -> 242689570 | D14: =C14*(1+③前提!$E$51) -> 242689570 | E14: =D14*(1+③前提!$F$51) -> 242689570 | F14: =(③前提!$C$25-③前提!$C$26)*(1+③前提!$D$51) -> 242689570 | G14: =F14*(1+③前提!$E$51) -> 242689570 | H14: =G14*(1+③前提!$F$51) -> 242689570 | I14: =(③前提!$C$25-③前提!$C$26)*(1+③前提!$D$51) -> 242689570 | J14: =I14*(1+③前提!$E$51) -> 242689570 | K14: =J14*(1+③前提!$F$51) -> 242689570
B15: 販管費 合計 | C15: =C13+C14 -> 321629734 | D15: =D13+D14 -> 3.2399794e+08 | E15: =E13+E14 -> 3.2643719e+08 | F15: =F13+F14 -> 321629734 | G15: =G13+G14 -> 3.2399794e+08 | H15: =H13+H14 -> 3.2643719e+08 | I15: =I13+I14 -> 321629734 | J15: =J13+J14 -> 3.2399794e+08 | K15: =K13+K14 -> 3.2643719e+08
B16: 営業利益 | C16: =C11-C15 -> -92795105 | D16: =D11-D15 -> -95163310 | E16: =E11-E15 -> -97602561 | F16: =F11-F15 -> 63958967 | G16: =G11-G15 -> 91590762 | H16: =H11-H15 -> 89151511 | I16: =I11-I15 -> 98958967 | J16: =J11-J15 -> 1.4159076e+08 | K16: =K11-K15 -> 1.3915151e+08
B17: 営業外費用 | C17: =③前提!$D$52 -> 12000000 | D17: =③前提!$E$52 -> 10000000 | E17: =③前提!$F$52 -> 8000000 | F17: =③前提!$D$52 -> 12000000 | G17: =③前提!$E$52 -> 10000000 | H17: =③前提!$F$52 -> 8000000 | I17: =③前提!$D$52 -> 12000000 | J17: =③前提!$E$52 -> 10000000 | K17: =③前提!$F$52 -> 8000000
B18: 経常利益 | C18: =C16-C17 -> -104795105 | D18: =D16-D17 -> -1.0516331e+08 | E18: =E16-E17 -> -1.0560256e+08 | F18: =F16-F17 -> 51958967 | G18: =G16-G17 -> 81590762 | H18: =H16-H17 -> 81151511 | I18: =I16-I17 -> 86958967 | J18: =J16-J17 -> 1.3159076e+08 | K18: =K16-K17 -> 1.3115151e+08
B19: 繰越欠損金 期首 | C19: =④FY2026着地!$H$19 -> 181986237 | D19: =C21 -> 286781342 | E19: =D21 -> 3.9194465e+08 | F19: =④FY2026着地!$H$19 -> 181986237 | G19: =F21 -> 1.3002727e+08 | H19: =G21 -> 48436508 | I19: =④FY2026着地!$H$19 -> 181986237 | J19: =I21 -> 95027270 | K19: =J21 -> 0
B20: 繰越欠損金 当期使用 | C20: =MIN(C19,MAX(0,C18)) -> 0 | D20: =MIN(D19,MAX(0,D18)) -> 0 | E20: =MIN(E19,MAX(0,E18)) -> 0 | F20: =MIN(F19,MAX(0,F18)) -> 51958967 | G20: =MIN(G19,MAX(0,G18)) -> 81590762 | H20: =MIN(H19,MAX(0,H18)) -> 48436508 | I20: =MIN(I19,MAX(0,I18)) -> 86958967 | J20: =MIN(J19,MAX(0,J18)) -> 95027270 | K20: =MIN(K19,MAX(0,K18)) -> 0
B21: 繰越欠損金 期末 | C21: =C19-C20+MAX(0,-C18) -> 286781342 | D21: =D19-D20+MAX(0,-D18) -> 3.9194465e+08 | E21: =E19-E20+MAX(0,-E18) -> 4.9754721e+08 | F21: =F19-F20+MAX(0,-F18) -> 1.3002727e+08 | G21: =G19-G20+MAX(0,-G18) -> 48436508 | H21: =H19-H20+MAX(0,-H18) -> 0 | I21: =I19-I20+MAX(0,-I18) -> 95027270 | J21: =J19-J20+MAX(0,-J18) -> 0 | K21: =K19-K20+MAX(0,-K18) -> 0
B22: 法人税等 | C22: =MAX(0,C18-C20)*③前提!$D$53+③前提!$D$54 -> 0 | D22: =MAX(0,D18-D20)*③前提!$E$53+③前提!$E$54 -> 70000 | E22: =MAX(0,E18-E20)*③前提!$F$53+③前提!$F$54 -> 70000 | F22: =MAX(0,F18-F20)*③前提!$D$53+③前提!$D$54 -> 0 | G22: =MAX(0,G18-G20)*③前提!$E$53+③前提!$E$54 -> 70000 | H22: =MAX(0,H18-H20)*③前提!$F$53+③前提!$F$54 -> 11193101 | I22: =MAX(0,I18-I20)*③前提!$D$53+③前提!$D$54 -> 0 | J22: =MAX(0,J18-J20)*③前提!$E$53+③前提!$E$54 -> 12501587 | K22: =MAX(0,K18-K20)*③前提!$F$53+③前提!$F$54 -> 44661514
B23: 当期純利益 | C23: =C18-C22 -> -104795105 | D23: =D18-D22 -> -1.0523331e+08 | E23: =E18-E22 -> -1.0567256e+08 | F23: =F18-F22 -> 51958967 | G23: =G18-G22 -> 81520762 | H23: =H18-H22 -> 69958410 | I23: =I18-I22 -> 86958967 | J23: =J18-J22 -> 1.1908917e+08 | K23: =K18-K22 -> 86489997
B24: 売上原価（参考） | C24: =C10-C11 -> 281325595 | D24: =D10-D11 -> 281325595 | E24: =E10-E11 -> 281325595 | F24: =F10-F11 -> 3.845851e+08 | G24: =G10-G11 -> 3.845851e+08 | H24: =H10-H11 -> 3.845851e+08 | I24: =I10-I11 -> 1.0495851e+09 | J24: =J10-J11 -> 1.3345851e+09 | K24: =K10-K11 -> 1.3345851e+09
B26: ※横ばい実力値は上乗せ案件を含めない参考値（2026/04-08の実績をそのまま延ばした場合）。
B27: ※プランDの既存事業：FY2027は前期・前々期の売上平均。FY2028以降は「直前2期平均」ではなく、FY2027水準からの成長率で置いています。
B28: （実績の弱いFY2026が平均に入ると、計画が年々目減りするため）
B29: ※プランEはDに私募ファンドを上乗せ。私募の粗利率は③前提【5】。

Sheet ⑤部門別損益
B1: 部門別損益（プランD・年次）
B2: 部門比率は③前提【8】、上乗せ案件の計上部門は③前提【4】。単位：円
B5: 【FY2027】
B6: 科目 | C6: 本部 | D6: EC/酒販店卸 | E6: ワインテック | F6: その他 | G6: 合計
B7: 売上（横ばい分） | C7: =③前提!$C$21*③前提!C$65 -> 0 | D7: =③前提!$C$21*③前提!D$65 -> 1.9115387e+08 | E7: =③前提!$C$21*③前提!E$65 -> 1.5511436e+08 | F7: =③前提!$C$21*③前提!F$65 -> 1.6389199e+08 | G7: =SUM(C7:F7) -> 510160224
B8: 差額売上 | C8: =0 -> 0 | D8: =0 -> 0 | E8: =②シナリオ比較!$F$7 -> 147513573 | F8: =0 -> 0 | G8: =SUM(C8:F8) -> 147513573
B9: 上乗せ案件 | C9: =SUMIF(③前提!$G$36:$G$40,"本部",③前提!D$36:D$40) -> 92500000 | D9: =SUMIF(③前提!$G$36:$G$40,"EC/酒販店卸",③前提!D$36:D$40) -> 0 | E9: =SUMIF(③前提!$G$36:$G$40,"ワインテック",③前提!D$36:D$40) -> 0 | F9: =SUMIF(③前提!$G$36:$G$40,"その他",③前提!D$36:D$40) -> 20000000 | G9: =SUM(C9:F9) -> 112500000
B10: 売上 計 | C10: =SUM(C7:C9) -> 92500000 | D10: =SUM(D7:D9) -> 1.9115387e+08 | E10: =SUM(E7:E9) -> 3.0262794e+08 | F10: =SUM(F7:F9) -> 1.8389199e+08 | G10: =SUM(C10:F10) -> 770173797
B11: 粗利（横ばい分） | C11: =③前提!$C$22*③前提!C$66 -> 0 | D11: =③前提!$C$22*③前提!D$66 -> 47620405 | E11: =③前提!$C$22*③前提!E$66 -> 37079949 | F11: =③前提!$C$22*③前提!F$66 -> 1.4413428e+08 | G11: =SUM(C11:F11) -> 228834629
B12: 差額売上の粗利 | C12: =C8*③前提!$C$32 -> 0 | D12: =D8*③前提!$C$32 -> 0 | E12: =E8*③前提!$C$32 -> 44254072 | F12: =F8*③前提!$C$32 -> 0 | G12: =SUM(C12:F12) -> 44254072
B13: 上乗せ案件の粗利 | C13: =C9 -> 92500000 | D13: =D9 -> 0 | E13: =E9 -> 0 | F13: =F9 -> 20000000 | G13: =SUM(C13:F13) -> 112500000
B14: 粗利 計 | C14: =SUM(C11:C13) -> 92500000 | D14: =SUM(D11:D13) -> 47620405 | E14: =SUM(E11:E13) -> 81334021 | F14: =SUM(F11:F13) -> 1.6413428e+08 | G14: =SUM(C14:F14) -> 3.855887e+08
B15: 人件費 | C15: =②シナリオ比較!$F$13*③前提!C$67 -> 33152711 | D15: =②シナリオ比較!$F$13*③前提!D$67 -> 13427558 | E15: =②シナリオ比較!$F$13*③前提!E$67 -> 25500831 | F15: =②シナリオ比較!$F$13*③前提!F$67 -> 6859063.4 | G15: =SUM(C15:F15) -> 78940164
B16: その他販管費 | C16: =②シナリオ比較!$F$14*③前提!C$68 -> 42587764 | D16: =②シナリオ比較!$F$14*③前提!D$68 -> 30749576 | E16: =②シナリオ比較!$F$14*③前提!E$68 -> 55485763 | F16: =②シナリオ比較!$F$14*③前提!F$68 -> 1.1386647e+08 | G16: =SUM(C16:F16) -> 242689570
B17: 販管費 計 | C17: =C15+C16 -> 75740475 | D17: =D15+D16 -> 44177134 | E17: =E15+E16 -> 80986595 | F17: =F15+F16 -> 1.2072553e+08 | G17: =SUM(C17:F17) -> 321629734
B18: 部門利益（配賦前） | C18: =C14-C17 -> 16759525 | D18: =D14-D17 -> 3443270.5 | E18: =E14-E17 -> 347426.1 | F18: =F14-F17 -> 43408746 | G18: =SUM(C18:F18) -> 63958967
B19: 本部費の配賦（粗利比） | C19: =$C17 -> 75740475 | D19: =-$C17*D14/SUM($D14:$F14) -> -12306145 | E19: =-$C17*E14/SUM($D14:$F14) -> -21018475 | F19: =-$C17*F14/SUM($D14:$F14) -> -42415856 | G19: =SUM(C19:F19) -> 0
B20: 部門利益（配賦後） | C20: =C18+C19 -> 92500000 | D20: =D18+D19 -> -8862874.7 | E20: =E18+E19 -> -20671048 | F20: =F18+F19 -> 992890.12 | G20: =SUM(C20:F20) -> 63958967
B21: チェック：部門合計−全社営業利益 | G21: =G18-②シナリオ比較!$F$16 -> 0
B23: 【FY2028】
B24: 科目 | C24: 本部 | D24: EC/酒販店卸 | E24: ワインテック | F24: その他 | G24: 合計
B25: 売上（横ばい分） | C25: =③前提!$C$21*③前提!C$65 -> 0 | D25: =③前提!$C$21*③前提!D$65 -> 1.9115387e+08 | E25: =③前提!$C$21*③前提!E$65 -> 1.5511436e+08 | F25: =③前提!$C$21*③前提!F$65 -> 1.6389199e+08 | G25: =SUM(C25:F25) -> 510160224
B26: 差額売上 | C26: =0 -> 0 | D26: =0 -> 0 | E26: =②シナリオ比較!$G$7 -> 147513573 | F26: =0 -> 0 | G26: =SUM(C26:F26) -> 147513573
B27: 上乗せ案件 | C27: =SUMIF(③前提!$G$36:$G$40,"本部",③前提!E$36:E$40) -> 122500000 | D27: =SUMIF(③前提!$G$36:$G$40,"EC/酒販店卸",③前提!E$36:E$40) -> 0 | E27: =SUMIF(③前提!$G$36:$G$40,"ワインテック",③前提!E$36:E$40) -> 0 | F27: =SUMIF(③前提!$G$36:$G$40,"その他",③前提!E$36:E$40) -> 20000000 | G27: =SUM(C27:F27) -> 142500000
B28: 売上 計 | C28: =SUM(C25:C27) -> 122500000 | D28: =SUM(D25:D27) -> 1.9115387e+08 | E28: =SUM(E25:E27) -> 3.0262794e+08 | F28: =SUM(F25:F27) -> 1.8389199e+08 | G28: =SUM(C28:F28) -> 800173797
B29: 粗利（横ばい分） | C29: =③前提!$C$22*③前提!C$66 -> 0 | D29: =③前提!$C$22*③前提!D$66 -> 47620405 | E29: =③前提!$C$22*③前提!E$66 -> 37079949 | F29: =③前提!$C$22*③前提!F$66 -> 1.4413428e+08 | G29: =SUM(C29:F29) -> 228834629
B30: 差額売上の粗利 | C30: =C26*③前提!$C$32 -> 0 | D30: =D26*③前提!$C$32 -> 0 | E30: =E26*③前提!$C$32 -> 44254072 | F30: =F26*③前提!$C$32 -> 0 | G30: =SUM(C30:F30) -> 44254072
B31: 上乗せ案件の粗利 | C31: =C27 -> 122500000 | D31: =D27 -> 0 | E31: =E27 -> 0 | F31: =F27 -> 20000000 | G31: =SUM(C31:F31) -> 142500000
B32: 粗利 計 | C32: =SUM(C29:C31) -> 122500000 | D32: =SUM(D29:D31) -> 47620405 | E32: =SUM(E29:E31) -> 81334021 | F32: =SUM(F29:F31) -> 1.6413428e+08 | G32: =SUM(C32:F32) -> 4.155887e+08
B33: 人件費 | C33: =②シナリオ比較!$G$13*③前提!C$67 -> 34147293 | D33: =②シナリオ比較!$G$13*③前提!D$67 -> 13830385 | E33: =②シナリオ比較!$G$13*③前提!E$67 -> 26265856 | F33: =②シナリオ比較!$G$13*③前提!F$67 -> 7064835.3 | G33: =SUM(C33:F33) -> 81308369
B34: その他販管費 | C34: =②シナリオ比較!$G$14*③前提!C$68 -> 42587764 | D34: =②シナリオ比較!$G$14*③前提!D$68 -> 30749576 | E34: =②シナリオ比較!$G$14*③前提!E$68 -> 55485763 | F34: =②シナリオ比較!$G$14*③前提!F$68 -> 1.1386647e+08 | G34: =SUM(C34:F34) -> 242689570
B35: 販管費 計 | C35: =C33+C34 -> 76735057 | D35: =D33+D34 -> 44579961 | E35: =E33+E34 -> 81751620 | F35: =F33+F34 -> 1.209313e+08 | G35: =SUM(C35:F35) -> 3.2399794e+08
B36: 部門利益（配賦前） | C36: =C32-C35 -> 45764943 | D36: =D32-D35 -> 3040443.7 | E36: =E32-E35 -> -417598.84 | F36: =F32-F35 -> 43202974 | G36: =SUM(C36:F36) -> 91590762
B37: 本部費の配賦（粗利比） | C37: =$C35 -> 76735057 | D37: =-$C35*D32/SUM($D32:$F32) -> -12467743 | E37: =-$C35*E32/SUM($D32:$F32) -> -21294477 | F37: =-$C35*F32/SUM($D32:$F32) -> -42972837 | G37: =SUM(C37:F37) -> 0
B38: 部門利益（配賦後） | C38: =C36+C37 -> 122500000 | D38: =D36+D37 -> -9427298.9 | E38: =E36+E37 -> -21712076 | F38: =F36+F37 -> 230137.05 | G38: =SUM(C38:F38) -> 91590762
B39: チェック：部門合計−全社営業利益 | G39: =G36-②シナリオ比較!$G$16 -> 0
B41: 【FY2029】
B42: 科目 | C42: 本部 | D42: EC/酒販店卸 | E42: ワインテック | F42: その他 | G42: 合計
B43: 売上（横ばい分） | C43: =③前提!$C$21*③前提!C$65 -> 0 | D43: =③前提!$C$21*③前提!D$65 -> 1.9115387e+08 | E43: =③前提!$C$21*③前提!E$65 -> 1.5511436e+08 | F43: =③前提!$C$21*③前提!F$65 -> 1.6389199e+08 | G43: =SUM(C43:F43) -> 510160224
B44: 差額売上 | C44: =0 -> 0 | D44: =0 -> 0 | E44: =②シナリオ比較!$H$7 -> 147513573 | F44: =0 -> 0 | G44: =SUM(C44:F44) -> 147513573
...

Sheet ⑥部門別月次_FY2027
B1: 部門別月次予算 FY2027（プランD）
B2: 経常的な項目は12か月均等。上乗せ案件は③前提【4】の計上月（0＝按分）。単位：円
B5: 【本部】
B6: 科目 | C6: 10月 | D6: 11月 | E6: 12月 | F6: 1月 | G6: 2月 | H6: 3月 | I6: 4月 | J6: 5月 | K6: 6月 | L6: 7月 | M6: 8月 | N6: 9月 | O6: 通期
B7: 売上 | C7: =(⑤部門別損益!C7+⑤部門別損益!C8)/12+IF(③前提!$G$36="本部",IF(③前提!$H$36=0,③前提!$D$36/12,IF(③前提!$H$36=1,③前提!$D$36,0)),0)+IF(③前提!$G$37="本部",IF(③前提!$H$37=0,③前提!$D$37/12,IF(③前提!$H$37=1,③前提!$D$37,0)),0)+IF(③前提!$G$38="本部",IF(③前提!$H$38=0,③前提!$D$38/12,IF(③前提!$H$38=1,③前提!$D$38,0)),0)+IF(③前提!$G$39="本部",IF(③前提!$H$39=0,③前提!$D$39/12,IF(③前提!$H$39=1,③前提!$D$39,0)),0)+IF(③前提!$G$40="本部",IF(③前提!$H$40=0,③前提!$D$40/12,IF(③前提!$H$40=1,③前提!$D$40,0)),0) -> 7708333.3 | D7: =(⑤部門別損益!C7+⑤部門別損益!C8)/12+IF(③前提!$G$36="本部",IF(③前提!$H$36=0,③前提!$D$36/12,IF(③前提!$H$36=2,③前提!$D$36,0)),0)+IF(③前提!$G$37="本部",IF(③前提!$H$37=0,③前提!$D$37/12,IF(③前提!$H$37=2,③前提!$D$37,0)),0)+IF(③前提!$G$38="本部",IF(③前提!$H$38=0,③前提!$D$38/12,IF(③前提!$H$38=2,③前提!$D$38,0)),0)+IF(③前提!$G$39="本部",IF(③前提!$H$39=0,③前提!$D$39/12,IF(③前提!$H$39=2,③前提!$D$39,0)),0)+IF(③前提!$G$40="本部",IF(③前提!$H$40=0,③前提!$D$40/12,IF(③前提!$H$40=2,③前提!$D$40,0)),0) -> 7708333.3 | E7: =(⑤部門別損益!C7+⑤部門別損益!C8)/12+IF(③前提!$G$36="本部",IF(③前提!$H$36=0,③前提!$D$36/12,IF(③前提!$H$36=3,③前提!$D$36,0)),0)+IF(③前提!$G$37="本部",IF(③前提!$H$37=0,③前提!$D$37/12,IF(③前提!$H$37=3,③前提!$D$37,0)),0)+IF(③前提!$G$38="本部",IF(③前提!$H$38=0,③前提!$D$38/12,IF(③前提!$H$38=3,③前提!$D$38,0)),0)+IF(③前提!$G$39="本部",IF(③前提!$H$39=0,③前提!$D$39/12,IF(③前提!$H$39=3,③前提!$D$39,0)),0)+IF(③前提!$G$40="本部",IF(③前提!$H$40=0,③前提!$D$40/12,IF(③前提!$H$40=3,③前提!$D$40,0)),0) -> 7708333.3 | F7: =(⑤部門別損益!C7+⑤部門別損益!C8)/12+IF(③前提!$G$36="本部",IF(③前提!$H$36=0,③前提!$D$36/12,IF(③前提!$H$36=4,③前提!$D$36,0)),0)+IF(③前提!$G$37="本部",IF(③前提!$H$37=0,③前提!$D$37/12,IF(③前提!$H$37=4,③前提!$D$37,0)),0)+IF(③前提!$G$38="本部",IF(③前提!$H$38=0,③前提!$D$38/12,IF(③前提!$H$38=4,③前提!$D$38,0)),0)+IF(③前提!$G$39="本部",IF(③前提!$H$39=0,③前提!$D$39/12,IF(③前提!$H$39=4,③前提!$D$39,0)),0)+IF(③前提!$G$40="本部",IF(③前提!$H$40=0,③前提!$D$40/12,IF(③前提!$H$40=4,③前提!$D$40,0)),0) -> 7708333.3 | G7: =(⑤部門別損益!C7+⑤部門別損益!C8)/12+IF(③前提!$G$36="本部",IF(③前提!$H$36=0,③前提!$D$36/12,IF(③前提!$H$36=5,③前提!$D$36,0)),0)+IF(③前提!$G$37="本部",IF(③前提!$H$37=0,③前提!$D$37/12,IF(③前提!$H$37=5,③前提!$D$37,0)),0)+IF(③前提!$G$38="本部",IF(③前提!$H$38=0,③前提!$D$38/12,IF(③前提!$H$38=5,③前提!$D$38,0)),0)+IF(③前提!$G$39="本部",IF(③前提!$H$39=0,③前提!$D$39/12,IF(③前提!$H$39=5,③前提!$D$39,0)),0)+IF(③前提!$G$40="本部",IF(③前提!$H$40=0,③前提!$D$40/12,IF(③前提!$H$40=5,③前提!$D$40,0)),0) -> 7708333.3 | H7: =(⑤部門別損益!C7+⑤部門別損益!C8)/12+IF(③前提!$G$36="本部",IF(③前提!$H$36=0,③前提!$D$36/12,IF(③前提!$H$36=6,③前提!$D$36,0)),0)+IF(③前提!$G$37="本部",IF(③前提!$H$37=0,③前提!$D$37/12,IF(③前提!$H$37=6,③前提!$D$37,0)),0)+IF(③前提!$G$38="本部",IF(③前提!$H$38=0,③前提!$D$38/12,IF(③前提!$H$38=6,③前提!$D$38,0)),0)+IF(③前提!$G$39="本部",IF(③前提!$H$39=0,③前提!$D$39/12,IF(③前提!$H$39=6,③前提!$D$39,0)),0)+IF(③前提!$G$40="本部",IF(③前提!$H$40=0,③前提!$D$40/12,IF(③前提!$H$40=6,③前提!$D$40,0)),0) -> 7708333.3 | I7: =(⑤部門別損益!C7+⑤部門別損益!C8)/12+IF(③前提!$G$36="本部",IF(③前提!$H$36=0,③前提!$D$36/12,IF(③前提!$H$36=7,③前提!$D$36,0)),0)+IF(③前提!$G$37="本部",IF(③前提!$H$37=0,③前提!$D$37/12,IF(③前提!$H$37=7,③前提!$D$37,0)),0)+IF(③前提!$G$38="本部",IF(③前提!$H$38=0,③前提!$D$38/12,IF(③前提!$H$38=7,③前提!$D$38,0)),0)+IF(③前提!$G$39="本部",IF(③前提!$H$39=0,③前提!$D$39/12,IF(③前提!$H$39=7,③前提!$D$39,0)),0)+IF(③前提!$G$40="本部",IF(③前提!$H$40=0,③前提!$D$40/12,IF(③前提!$H$40=7,③前提!$D$40,0)),0) -> 7708333.3 | J7: =(⑤部門別損益!C7+⑤部門別損益!C8)/12+IF(③前提!$G$36="本部",IF(③前提!$H$36=0,③前提!$D$36/12,IF(③前提!$H$36=8,③前提!$D$36,0)),0)+IF(③前提!$G$37="本部",IF(③前提!$H$37=0,③前提!$D$37/12,IF(③前提!$H$37=8,③前提!$D$37,0)),0)+IF(③前提!$G$38="本部",IF(③前提!$H$38=0,③前提!$D$38/12,IF(③前提!$H$38=8,③前提!$D$38,0)),0)+IF(③前提!$G$39="本部",IF(③前提!$H$39=0,③前提!$D$39/12,IF(③前提!$H$39=8,③前提!$D$39,0)),0)+IF(③前提!$G$40="本部",IF(③前提!$H$40=0,③前提!$D$40/12,IF(③前提!$H$40=8,③前提!$D$40,0)),0) -> 7708333.3 | K7: =(⑤部門別損益!C7+⑤部門別損益!C8)/12+IF(③前提!$G$36="本部",IF(③前提!$H$36=0,③前提!$D$36/12,IF(③前提!$H$36=9,③前提!$D$36,0)),0)+IF(③前提!$G$37="本部",IF(③前提!$H$37=0,③前提!$D$37/12,IF(③前提!$H$37=9,③前提!$D$37,0)),0)+IF(③前提!$G$38="本部",IF(③前提!$H$38=0,③前提!$D$38/12,IF(③前提!$H$38=9,③前提!$D$38,0)),0)+IF(③前提!$G$39="本部",IF(③前提!$H$39=0,③前提!$D$39/12,IF(③前提!$H$39=9,③前提!$D$39,0)),0)+IF(③前提!$G$40="本部",IF(③前提!$H$40=0,③前提!$D$40/12,IF(③前提!$H$40=9,③前提!$D$40,0)),0) -> 7708333.3 | L7: =(⑤部門別損益!C7+⑤部門別損益!C8)/12+IF(③前提!$G$36="本部",IF(③前提!$H$36=0,③前提!$D$36/12,IF(③前提!$H$36=10,③前提!$D$36,0)),0)+IF(③前提!$G$37="本部",IF(③前提!$H$37=0,③前提!$D$37/12,IF(③前提!$H$37=10,③前提!$D$37,0)),0)+IF(③前提!$G$38="本部",IF(③前提!$H$38=0,③前提!$D$38/12,IF(③前提!$H$38=10,③前提!$D$38,0)),0)+IF(③前提!$G$39="本部",IF(③前提!$H$39=0,③前提!$D$39/12,IF(③前提!$H$39=10,③前提!$D$39,0)),0)+IF(③前提!$G$40="本部",IF(③前提!$H$40=0,③前提!$D$40/12,IF(③前提!$H$40=10,③前提!$D$40,0)),0) -> 7708333.3 | M7: =(⑤部門別損益!C7+⑤部門別損益!C8)/12+IF(③前提!$G$36="本部",IF(③前提!$H$36=0,③前提!$D$36/12,IF(③前提!$H$36=11,③前提!$D$36,0)),0)+IF(③前提!$G$37="本部",IF(③前提!$H$37=0,③前提!$D$37/12,IF(③前提!$H$37=11,③前提!$D$37,0)),0)+IF(③前提!$G$38="本部",IF(③前提!$H$38=0,③前提!$D$38/12,IF(③前提!$H$38=11,③前提!$D$38,0)),0)+IF(③前提!$G$39="本部",IF(③前提!$H$39=0,③前提!$D$39/12,IF(③前提!$H$39=11,③前提!$D$39,0)),0)+IF(③前提!$G$40="本部",IF(③前提!$H$40=0,③前提!$D$40/12,IF(③前提!$H$40=11,③前提!$D$40,0)),0) -> 7708333.3 | N7: =(⑤部門別損益!C7+⑤部門別損益!C8)/12+IF(③前提!$G$36="本部",IF(③前提!$H$36=0,③前提!$D$36/12,IF(③前提!$H$36=12,③前提!$D$36,0)),0)+IF(③前提!$G$37="本部",IF(③前提!$H$37=0,③前提!$D$37/12,IF(③前提!$H$37=12,③前提!$D$37,0)),0)+IF(③前提!$G$38="本部",IF(③前提!$H$38=0,③前提!$D$38/12,IF(③前提!$H$38=12,③前提!$D$38,0)),0)+IF(③前提!$G$39="本部",IF(③前提!$H$39=0,③前提!$D$39/12,IF(③前提!$H$39=12,③前提!$D$39,0)),0)+IF(③前提!$G$40="本部",IF(③前提!$H$40=0,③前提!$D$40/12,IF(③前提!$H$40=12,③前提!$D$40,0)),0) -> 7708333.3 | O7: =SUM(C7:N7) -> 92500000
B8: 粗利 | C8: =(⑤部門別損益!C11+⑤部門別損益!C12)/12+IF(③前提!$G$36="本部",IF(③前提!$H$36=0,③前提!$D$36/12,IF(③前提!$H$36=1,③前提!$D$36,0)),0)+IF(③前提!$G$37="本部",IF(③前提!$H$37=0,③前提!$D$37/12,IF(③前提!$H$37=1,③前提!$D$37,0)),0)+IF(③前提!$G$38="本部",IF(③前提!$H$38=0,③前提!$D$38/12,IF(③前提!$H$38=1,③前提!$D$38,0)),0)+IF(③前提!$G$39="本部",IF(③前提!$H$39=0,③前提!$D$39/12,IF(③前提!$H$39=1,③前提!$D$39,0)),0)+IF(③前提!$G$40="本部",IF(③前提!$H$40=0,③前提!$D$40/12,IF(③前提!$H$40=1,③前提!$D$40,0)),0) -> 7708333.3 | D8: =(⑤部門別損益!C11+⑤部門別損益!C12)/12+IF(③前提!$G$36="本部",IF(③前提!$H$36=0,③前提!$D$36/12,IF(③前提!$H$36=2,③前提!$D$36,0)),0)+IF(③前提!$G$37="本部",IF(③前提!$H$37=0,③前提!$D$37/12,IF(③前提!$H$37=2,③前提!$D$37,0)),0)+IF(③前提!$G$38="本部",IF(③前提!$H$38=0,③前提!$D$38/12,IF(③前提!$H$38=2,③前提!$D$38,0)),0)+IF(③前提!$G$39="本部",IF(③前提!$H$39=0,③前提!$D$39/12,IF(③前提!$H$39=2,③前提!$D$39,0)),0)+IF(③前提!$G$40="本部",IF(③前提!$H$40=0,③前提!$D$40/12,IF(③前提!$H$40=2,③前提!$D$40,0)),0) -> 7708333.3 | E8: =(⑤部門別損益!C11+⑤部門別損益!C12)/12+IF(③前提!$G$36="本部",IF(③前提!$H$36=0,③前提!$D$36/12,IF(③前提!$H$36=3,③前提!$D$36,0)),0)+IF(③前提!$G$37="本部",IF(③前提!$H$37=0,③前提!$D$37/12,IF(③前提!$H$37=3,③前提!$D$37,0)),0)+IF(③前提!$G$38="本部",IF(③前提!$H$38=0,③前提!$D$38/12,IF(③前提!$H$38=3,③前提!$D$38,0)),0)+IF(③前提!$G$39="本部",IF(③前提!$H$39=0,③前提!$D$39/12,IF(③前提!$H$39=3,③前提!$D$39,0)),0)+IF(③前提!$G$40="本部",IF(③前提!$H$40=0,③前提!$D$40/12,IF(③前提!$H$40=3,③前提!$D$40,0)),0) -> 7708333.3 | F8: =(⑤部門別損益!C11+⑤部門別損益!C12)/12+IF(③前提!$G$36="本部",IF(③前提!$H$36=0,③前提!$D$36/12,IF(③前提!$H$36=4,③前提!$D$36,0)),0)+IF(③前提!$G$37="本部",IF(③前提!$H$37=0,③前提!$D$37/12,IF(③前提!$H$37=4,③前提!$D$37,0)),0)+IF(③前提!$G$38="本部",IF(③前提!$H$38=0,③前提!$D$38/12,IF(③前提!$H$38=4,③前提!$D$38,0)),0)+IF(③前提!$G$39="本部",IF(③前提!$H$39=0,③前提!$D$39/12,IF(③前提!$H$39=4,③前提!$D$39,0)),0)+IF(③前提!$G$40="本部",IF(③前提!$H$40=0,③前提!$D$40/12,IF(③前提!$H$40=4,③前提!$D$40,0)),0) -> 7708333.3 | G8: =(⑤部門別損益!C11+⑤部門別損益!C12)/12+IF(③前提!$G$36="本部",IF(③前提!$H$36=0,③前提!$D$36/12,IF(③前提!$H$36=5,③前提!$D$36,0)),0)+IF(③前提!$G$37="本部",IF(③前提!$H$37=0,③前提!$D$37/12,IF(③前提!$H$37=5,③前提!$D$37,0)),0)+IF(③前提!$G$38="本部",IF(③前提!$H$38=0,③前提!$D$38/12,IF(③前提!$H$38=5,③前提!$D$38,0)),0)+IF(③前提!$G$39="本部",IF(③前提!$H$39=0,③前提!$D$39/12,IF(③前提!$H$39=5,③前提!$D$39,0)),0)+IF(③前提!$G$40="本部",IF(③前提!$H$40=0,③前提!$D$40/12,IF(③前提!$H$40=5,③前提!$D$40,0)),0) -> 7708333.3 | H8: =(⑤部門別損益!C11+⑤部門別損益!C12)/12+IF(③前提!$G$36="本部",IF(③前提!$H$36=0,③前提!$D$36/12,IF(③前提!$H$36=6,③前提!$D$36,0)),0)+IF(③前提!$G$37="本部",IF(③前提!$H$37=0,③前提!$D$37/12,IF(③前提!$H$37=6,③前提!$D$37,0)),0)+IF(③前提!$G$38="本部",IF(③前提!$H$38=0,③前提!$D$38/12,IF(③前提!$H$38=6,③前提!$D$38,0)),0)+IF(③前提!$G$39="本部",IF(③前提!$H$39=0,③前提!$D$39/12,IF(③前提!$H$39=6,③前提!$D$39,0)),0)+IF(③前提!$G$40="本部",IF(③前提!$H$40=0,③前提!$D$40/12,IF(③前提!$H$40=6,③前提!$D$40,0)),0) -> 7708333.3 | I8: =(⑤部門別損益!C11+⑤部門別損益!C12)/12+IF(③前提!$G$36="本部",IF(③前提!$H$36=0,③前提!$D$36/12,IF(③前提!$H$36=7,③前提!$D$36,0)),0)+IF(③前提!$G$37="本部",IF(③前提!$H$37=0,③前提!$D$37/12,IF(③前提!$H$37=7,③前提!$D$37,0)),0)+IF(③前提!$G$38="本部",IF(③前提!$H$38=0,③前提!$D$38/12,IF(③前提!$H$38=7,③前提!$D$38,0)),0)+IF(③前提!$G$39="本部",IF(③前提!$H$39=0,③前提!$D$39/12,IF(③前提!$H$39=7,③前提!$D$39,0)),0)+IF(③前提!$G$40="本部",IF(③前提!$H$40=0,③前提!$D$40/12,IF(③前提!$H$40=7,③前提!$D$40,0)),0) -> 7708333.3 | J8: =(⑤部門別損益!C11+⑤部門別損益!C12)/12+IF(③前提!$G$36="本部",IF(③前提!$H$36=0,③前提!$D$36/12,IF(③前提!$H$36=8,③前提!$D$36,0)),0)+IF(③前提!$G$37="本部",IF(③前提!$H$37=0,③前提!$D$37/12,IF(③前提!$H$37=8,③前提!$D$37,0)),0)+IF(③前提!$G$38="本部",IF(③前提!$H$38=0,③前提!$D$38/12,IF(③前提!$H$38=8,③前提!$D$38,0)),0)+IF(③前提!$G$39="本部",IF(③前提!$H$39=0,③前提!$D$39/12,IF(③前提!$H$39=8,③前提!$D$39,0)),0)+IF(③前提!$G$40="本部",IF(③前提!$H$40=0,③前提!$D$40/12,IF(③前提!$H$40=8,③前提!$D$40,0)),0) -> 7708333.3 | K8: =(⑤部門別損益!C11+⑤部門別損益!C12)/12+IF(③前提!$G$36="本部",IF(③前提!$H$36=0,③前提!$D$36/12,IF(③前提!$H$36=9,③前提!$D$36,0)),0)+IF(③前提!$G$37="本部",IF(③前提!$H$37=0,③前提!$D$37/12,IF(③前提!$H$37=9,③前提!$D$37,0)),0)+IF(③前提!$G$38="本部",IF(③前提!$H$38=0,③前提!$D$38/12,IF(③前提!$H$38=9,③前提!$D$38,0)),0)+IF(③前提!$G$39="本部",IF(③前提!$H$39=0,③前提!$D$39/12,IF(③前提!$H$39=9,③前提!$D$39,0)),0)+IF(③前提!$G$40="本部",IF(③前提!$H$40=0,③前提!$D$40/12,IF(③前提!$H$40=9,③前提!$D$40,0)),0) -> 7708333.3 | L8: =(⑤部門別損益!C11+⑤部門別損益!C12)/12+IF(③前提!$G$36="本部",IF(③前提!$H$36=0,③前提!$D$36/12,IF(③前提!$H$36=10,③前提!$D$36,0)),0)+IF(③前提!$G$37="本部",IF(③前提!$H$37=0,③前提!$D$37/12,IF(③前提!$H$37=10,③前提!$D$37,0)),0)+IF(③前提!$G$38="本部",IF(③前提!$H$38=0,③前提!$D$38/12,IF(③前提!$H$38=10,③前提!$D$38,0)),0)+IF(③前提!$G$39="本部",IF(③前提!$H$39=0,③前提!$D$39/12,IF(③前提!$H$39=10,③前提!$D$39,0)),0)+IF(③前提!$G$40="本部",IF(③前提!$H$40=0,③前提!$D$40/12,IF(③前提!$H$40=10,③前提!$D$40,0)),0) -> 7708333.3 | M8: =(⑤部門別損益!C11+⑤部門別損益!C12)/12+IF(③前提!$G$36="本部",IF(③前提!$H$36=0,③前提!$D$36/12,IF(③前提!$H$36=11,③前提!$D$36,0)),0)+IF(③前提!$G$37="本部",IF(③前提!$H$37=0,③前提!$D$37/12,IF(③前提!$H$37=11,③前提!$D$37,0)),0)+IF(③前提!$G$38="本部",IF(③前提!$H$38=0,③前提!$D$38/12,IF(③前提!$H$38=11,③前提!$D$38,0)),0)+IF(③前提!$G$39="本部",IF(③前提!$H$39=0,③前提!$D$39/12,IF(③前提!$H$39=11,③前提!$D$39,0)),0)+IF(③前提!$G$40="本部",IF(③前提!$H$40=0,③前提!$D$40/12,IF(③前提!$H$40=11,③前提!$D$40,0)),0) -> 7708333.3 | N8: =(⑤部門別損益!C11+⑤部門別損益!C12)/12+IF(③前提!$G$36="本部",IF(③前提!$H$36=0,③前提!$D$36/12,IF(③前提!$H$36=12,③前提!$D$36,0)),0)+IF(③前提!$G$37="本部",IF(③前提!$H$37=0,③前提!$D$37/12,IF(③前提!$H$37=12,③前提!$D$37,0)),0)+IF(③前提!$G$38="本部",IF(③前提!$H$38=0,③前提!$D$38/12,IF(③前提!$H$38=12,③前提!$D$38,0)),0)+IF(③前提!$G$39="本部",IF(③前提!$H$39=0,③前提!$D$39/12,IF(③前提!$H$39=12,③前提!$D$39,0)),0)+IF(③前提!$G$40="本部",IF(③前提!$H$40=0,③前提!$D$40/12,IF(③前提!$H$40=12,③前提!$D$40,0)),0) -> 7708333.3 | O8: =SUM(C8:N8) -> 92500000
B9: 販管費 | C9: =⑤部門別損益!C17/12 -> 6311706.3 | D9: =⑤部門別損益!C17/12 -> 6311706.3 | E9: =⑤部門別損益!C17/12 -> 6311706.3 | F9: =⑤部門別損益!C17/12 -> 6311706.3 | G9: =⑤部門別損益!C17/12 -> 6311706.3 | H9: =⑤部門別損益!C17/12 -> 6311706.3 | I9: =⑤部門別損益!C17/12 -> 6311706.3 | J9: =⑤部門別損益!C17/12 -> 6311706.3 | K9: =⑤部門別損益!C17/12 -> 6311706.3 | L9: =⑤部門別損益!C17/12 -> 6311706.3 | M9: =⑤部門別損益!C17/12 -> 6311706.3 | N9: =⑤部門別損益!C17/12 -> 6311706.3 | O9: =SUM(C9:N9) -> 75740475
B10: 部門利益（配賦前） | C10: =C8-C9 -> 1396627 | D10: =D8-D9 -> 1396627 | E10: =E8-E9 -> 1396627 | F10: =F8-F9 -> 1396627 | G10: =G8-G9 -> 1396627 | H10: =H8-H9 -> 1396627 | I10: =I8-I9 -> 1396627 | J10: =J8-J9 -> 1396627 | ... N10: =N8-N9 -> 1396627 | O10: =SUM(C10:N10) -> 16759525
B12: 【EC/酒販店卸】
B13: 科目 | C13: 10月 | D13: 11月 | E13: 12月 | F13: 1月 | G13: 2月 | H13: 3月 | I13: 4月 | J13: 5月 | K13: 6月 | L13: 7月 | M13: 8月 | N13: 9月 | O13: 通期
B14: 売上 | C14: =(⑤部門別損益!D7+⑤部門別損益!D8)/12+IF(③前提!$G$36="EC/酒販店卸",IF(③前提!$H$36=0,③前提!$D$36/12,IF(③前提!$H$36=1,③前提!$D$36,0)),0)+IF(③前提!$G$37="EC/酒販店卸",IF(③前提!$H$37=0,③前提!$D$37/12,IF(③前提!$H$37=1,③前提!$D$37,0)),0)+IF(③前提!$G$38="EC/酒販店卸",IF(③前提!$H$38=0,③前提!$D$38/12,IF(③前提!$H$38=1,③前提!$D$38,0)),0)+IF(③前提!$G$39="EC/酒販店卸",IF(③前提!$H$39=0,③前提!$D$39/12,IF(③前提!$H$39=1,③前提!$D$39,0)),0)+IF(③前提!$G$40="EC/酒販店卸",IF(③前提!$H$40=0,③前提!$D$40/12,IF(③前提!$H$40=1,③前提!$D$40,0)),0) -> 15929489 | D14: =(⑤部門別損益!D7+⑤部門別損益!D8)/12+IF(③前提!$G$36="EC/酒販店卸",IF(③前提!$H$36=0,③前提!$D$36/12,IF(③前提!$H$36=2,③前提!$D$36,0)),0)+IF(③前提!$G$37="EC/酒販店卸",IF(③前提!$H$37=0,③前提!$D$37/12,IF(③前提!$H$37=2,③前提!$D$37,0)),0)+IF(③前提!$G$38="EC/酒販店卸",IF(③前提!$H$38=0,③前提!$D$38/12,IF(③前提!$H$38=2,③前提!$D$38,0)),0)+IF(③前提!$G$39="EC/酒販店卸",IF(③前提!$H$39=0,③前提!$D$39/12,IF(③前提!$H$39=2,③前提!$D$39,0)),0)+IF(③前提!$G$40="EC/酒販店卸",IF(③前提!$H$40=0,③前提!$D$40/12,IF(③前提!$H$40=2,③前提!$D$40,0)),0) -> 15929489 | E14: =(⑤部門別損益!D7+⑤部門別損益!D8)/12+IF(③前提!$G$36="EC/酒販店卸",IF(③前提!$H$36=0,③前提!$D$36/12,IF(③前提!$H$36=3,③前提!$D$36,0)),0)+IF(③前提!$G$37="EC/酒販店卸",IF(③前提!$H$37=0,③前提!$D$37/12,IF(③前提!$H$37=3,③前提!$D$37,0)),0)+IF(③前提!$G$38="EC/酒販店卸",IF(③前提!$H$38=0,③前提!$D$38/12,IF(③前提!$H$38=3,③前提!$D$38,0)),0)+IF(③前提!$G$39="EC/酒販店卸",IF(③前提!$H$39=0,③前提!$D$39/12,IF(③前提!$H$39=3,③前提!$D$39,0)),0)+IF(③前提!$G$40="EC/酒販店卸",IF(③前提!$H$40=0,③前提!$D$40/12,IF(③前提!$H$40=3,③前提!$D$40,0)),0) -> 15929489 | F14: =(⑤部門別損益!D7+⑤部門別損益!D8)/12+IF(③前提!$G$36="EC/酒販店卸",IF(③前提!$H$36=0,③前提!$D$36/12,IF(③前提!$H$36=4,③前提!$D$36,0)),0)+IF(③前提!$G$37="EC/酒販店卸",IF(③前提!$H$37=0,③前提!$D$37/12,IF(③前提!$H$37=4,③前提!$D$37,0)),0)+IF(③前提!$G$38="EC/酒販店卸",IF(③前提!$H$38=0,③前提!$D$38/12,IF(③前提!$H$38=4,③前提!$D$38,0)),0)+IF(③前提!$G$39="EC/酒販店卸",IF(③前提!$H$39=0,③前提!$D$39/12,IF(③前提!$H$39=4,③前提!$D$39,0)),0)+IF(③前提!$G$40="EC/酒販店卸",IF(③前提!$H$40=0,③前提!$D$40/12,IF(③前提!$H$40=4,③前提!$D$40,0)),0) -> 15929489 | G14: =(⑤部門別損益!D7+⑤部門別損益!D8)/12+IF(③前提!$G$36="EC/酒販店卸",IF(③前提!$H$36=0,③前提!$D$36/12,IF(③前提!$H$36=5,③前提!$D$36,0)),0)+IF(③前提!$G$37="EC/酒販店卸",IF(③前提!$H$37=0,③前提!$D$37/12,IF(③前提!$H$37=5,③前提!$D$37,0)),0)+IF(③前提!$G$38="EC/酒販店卸",IF(③前提!$H$38=0,③前提!$D$38/12,IF(③前提!$H$38=5,③前提!$D$38,0)),0)+IF(③前提!$G$39="EC/酒販店卸",IF(③前提!$H$39=0,③前提!$D$39/12,IF(③前提!$H$39=5,③前提!$D$39,0)),0)+IF(③前提!$G$40="EC/酒販店卸",IF(③前提!$H$40=0,③前提!$D$40/12,IF(③前提!$H$40=5,③前提!$D$40,0)),0) -> 15929489 | H14: =(⑤部門別損益!D7+⑤部門別損益!D8)/12+IF(③前提!$G$36="EC/酒販店卸",IF(③前提!$H$36=0,③前提!$D$36/12,IF(③前提!$H$36=6,③前提!$D$36,0)),0)+IF(③前提!$G$37="EC/酒販店卸",IF(③前提!$H$37=0,③前提!$D$37/12,IF(③前提!$H$37=6,③前提!$D$37,0)),0)+IF(③前提!$G$38="EC/酒販店卸",IF(③前提!$H$38=0,③前提!$D$38/12,IF(③前提!$H$38=6,③前提!$D$38,0)),0)+IF(③前提!$G$39="EC/酒販店卸",IF(③前提!$H$39=0,③前提!$D$39/12,IF(③前提!$H$39=6,③前提!$D$39,0)),0)+IF(③前提!$G$40="EC/酒販店卸",IF(③前提!$H$40=0,③前提!$D$40/12,IF(③前提!$H$40=6,③前提!$D$40,0)),0) -> 15929489 | I14: =(⑤部門別損益!D7+⑤部門別損益!D8)/12+IF(③前提!$G$36="EC/酒販店卸",IF(③前提!$H$36=0,③前提!$D$36/12,IF(③前提!$H$36=7,③前提!$D$36,0)),0)+IF(③前提!$G$37="EC/酒販店卸",IF(③前提!$H$37=0,③前提!$D$37/12,IF(③前提!$H$37=7,③前提!$D$37,0)),0)+IF(③前提!$G$38="EC/酒販店卸",IF(③前提!$H$38=0,③前提!$D$38/12,IF(③前提!$H$38=7,③前提!$D$38,0)),0)+IF(③前提!$G$39="EC/酒販店卸",IF(③前提!$H$39=0,③前提!$D$39/12,IF(③前提!$H$39=7,③前提!$D$39,0)),0)+IF(③前提!$G$40="EC/酒販店卸",IF(③前提!$H$40=0,③前提!$D$40/12,IF(③前提!$H$40=7,③前提!$D$40,0)),0) -> 15929489 | J14: =(⑤部門別損益!D7+⑤部門別損益!D8)/12+IF(③前提!$G$36="EC/酒販店卸",IF(③前提!$H$36=0,③前提!$D$36/12,IF(③前提!$H$36=8,③前提!$D$36,0)),0)+IF(③前提!$G$37="EC/酒販店卸",IF(③前提!$H$37=0,③前提!$D$37/12,IF(③前提!$H$37=8,③前提!$D$37,0)),0)+IF(③前提!$G$38="EC/酒販店卸",IF(③前提!$H$38=0,③前提!$D$38/12,IF(③前提!$H$38=8,③前提!$D$38,0)),0)+IF(③前提!$G$39="EC/酒販店卸",IF(③前提!$H$39=0,③前提!$D$39/12,IF(③前提!$H$39=8,③前提!$D$39,0)),0)+IF(③前提!$G$40="EC/酒販店卸",IF(③前提!$H$40=0,③前提!$D$40/12,IF(③前提!$H$40=8,③前提!$D$40,0)),0) -> 15929489 | K14: =(⑤部門別損益!D7+⑤部門別損益!D8)/12+IF(③前提!$G$36="EC/酒販店卸",IF(③前提!$H$36=0,③前提!$D$36/12,IF(③前提!$H$36=9,③前提!$D$36,0)),0)+IF(③前提!$G$37="EC/酒販店卸",IF(③前提!$H$37=0,③前提!$D$37/12,IF(③前提!$H$37=9,③前提!$D$37,0)),0)+IF(③前提!$G$38="EC/酒販店卸",IF(③前提!$H$38=0,③前提!$D$38/12,IF(③前提!$H$38=9,③前提!$D$38,0)),0)+IF(③前提!$G$39="EC/酒販店卸",IF(③前提!$H$39=0,③前提!$D$39/12,IF(③前提!$H$39=9,③前提!$D$39,0)),0)+IF(③前提!$G$40="EC/酒販店卸",IF(③前提!$H$40=0,③前提!$D$40/12,IF(③前提!$H$40=9,③前提!$D$40,0)),0) -> 15929489 | L14: =(⑤部門別損益!D7+⑤部門別損益!D8)/12+IF(③前提!$G$36="EC/酒販店卸",IF(③前提!$H$36=0,③前提!$D$36/12,IF(③前提!$H$36=10,③前提!$D$36,0)),0)+IF(③前提!$G$37="EC/酒販店卸",IF(③前提!$H$37=0,③前提!$D$37/12,IF(③前提!$H$37=10,③前提!$D$37,0)),0)+IF(③前提!$G$38="EC/酒販店卸",IF(③前提!$H$38=0,③前提!$D$38/12,IF(③前提!$H$38=10,③前提!$D$38,0)),0)+IF(③前提!$G$39="EC/酒販店卸",IF(③前提!$H$39=0,③前提!$D$39/12,IF(③前提!$H$39=10,③前提!$D$39,0)),0)+IF(③前提!$G$40="EC/酒販店卸",IF(③前提!$H$40=0,③前提!$D$40/12,IF(③前提!$H$40=10,③前提!$D$40,0)),0) -> 15929489 | M14: =(⑤部門別損益!D7+⑤部門別損益!D8)/12+IF(③前提!$G$36="EC/酒販店卸",IF(③前提!$H$36=0,③前提!$D$36/12,IF(③前提!$H$36=11,③前提!$D$36,0)),0)+IF(③前提!$G$37="EC/酒販店卸",IF(③前提!$H$37=0,③前提!$D$37/12,IF(③前提!$H$37=11,③前提!$D$37,0)),0)+IF(③前提!$G$38="EC/酒販店卸",IF(③前提!$H$38=0,③前提!$D$38/12,IF(③前提!$H$38=11,③前提!$D$38,0)),0)+IF(③前提!$G$39="EC/酒販店卸",IF(③前提!$H$39=0,③前提!$D$39/12,IF(③前提!$H$39=11,③前提!$D$39,0)),0)+IF(③前提!$G$40="EC/酒販店卸",IF(③前提!$H$40=0,③前提!$D$40/12,IF(③前提!$H$40=11,③前提!$D$40,0)),0) -> 15929489 | N14: =(⑤部門別損益!D7+⑤部門別損益!D8)/12+IF(③前提!$G$36="EC/酒販店卸",IF(③前提!$H$36=0,③前提!$D$36/12,IF(③前提!$H$36=12,③前提!$D$36,0)),0)+IF(③前提!$G$37="EC/酒販店卸",IF(③前提!$H$37=0,③前提!$D$37/12,IF(③前提!$H$37=12,③前提!$D$37,0)),0)+IF(③前提!$G$38="EC/酒販店卸",IF(③前提!$H$38=0,③前提!$D$38/12,IF(③前提!$H$38=12,③前提!$D$38,0)),0)+IF(③前提!$G$39="EC/酒販店卸",IF(③前提!$H$39=0,③前提!$D$39/12,IF(③前提!$H$39=12,③前提!$D$39,0)),0)+IF(③前提!$G$40="EC/酒販店卸",IF(③前提!$H$40=0,③前提!$D$40/12,IF(③前提!$H$40=12,③前提!$D$40,0)),0) -> 15929489 | O14: =SUM(C14:N14) -> 1.9115387e+08
B15: 粗利 | C15: =(⑤部門別損益!D11+⑤部門別損益!D12)/12+IF(③前提!$G$36="EC/酒販店卸",IF(③前提!$H$36=0,③前提!$D$36/12,IF(③前提!$H$36=1,③前提!$D$36,0)),0)+IF(③前提!$G$37="EC/酒販店卸",IF(③前提!$H$37=0,③前提!$D$37/12,IF(③前提!$H$37=1,③前提!$D$37,0)),0)+IF(③前提!$G$38="EC/酒販店卸",IF(③前提!$H$38=0,③前提!$D$38/12,IF(③前提!$H$38=1,③前提!$D$38,0)),0)+IF(③前提!$G$39="EC/酒販店卸",IF(③前提!$H$39=0,③前提!$D$39/12,IF(③前提!$H$39=1,③前提!$D$39,0)),0)+IF(③前提!$G$40="EC/酒販店卸",IF(③前提!$H$40=0,③前提!$D$40/12,IF(③前提!$H$40=1,③前提!$D$40,0)),0) -> 3968367.1 | D15: =(⑤部門別損益!D11+⑤部門別損益!D12)/12+IF(③前提!$G$36="EC/酒販店卸",IF(③前提!$H$36=0,③前提!$D$36/12,IF(③前提!$H$36=2,③前提!$D$36,0)),0)+IF(③前提!$G$37="EC/酒販店卸",IF(③前提!$H$37=0,③前提!$D$37/12,IF(③前提!$H$37=2,③前提!$D$37,0)),0)+IF(③前提!$G$38="EC/酒販店卸",IF(③前提!$H$38=0,③前提!$D$38/12,IF(③前提!$H$38=2,③前提!$D$38,0)),0)+IF(③前提!$G$39="EC/酒販店卸",IF(③前提!$H$39=0,③前提!$D$39/12,IF(③前提!$H$39=2,③前提!$D$39,0)),0)+IF(③前提!$G$40="EC/酒販店卸",IF(③前提!$H$40=0,③前提!$D$40/12,IF(③前提!$H$40=2,③前提!$D$40,0)),0) -> 3968367.1 | E15: =(⑤部門別損益!D11+⑤部門別損益!D12)/12+IF(③前提!$G$36="EC/酒販店卸",IF(③前提!$H$36=0,③前提!$D$36/12,IF(③前提!$H$36=3,③前提!$D$36,0)),0)+IF(③前提!$G$37="EC/酒販店卸",IF(③前提!$H$37=0,③前提!$D$37/12,IF(③前提!$H$37=3,③前提!$D$37,0)),0)+IF(③前提!$G$38="EC/酒販店卸",IF(③前提!$H$38=0,③前提!$D$38/12,IF(③前提!$H$38=3,③前提!$D$38,0)),0)+IF(③前提!$G$39="EC/酒販店卸",IF(③前提!$H$39=0,③前提!$D$39/12,IF(③前提!$H$39=3,③前提!$D$39,0)),0)+IF(③前提!$G$40="EC/酒販店卸",IF(③前提!$H$40=0,③前提!$D$40/12,IF(③前提!$H$40=3,③前提!$D$40,0)),0) -> 3968367.1 | F15: =(⑤部門別損益!D11+⑤部門別損益!D12)/12+IF(③前提!$G$36="EC/酒販店卸",IF(③前提!$H$36=0,③前提!$D$36/12,IF(③前提!$H$36=4,③前提!$D$36,0)),0)+IF(③前提!$G$37="EC/酒販店卸",IF(③前提!$H$37=0,③前提!$D$37/12,IF(③前提!$H$37=4,③前提!$D$37,0)),0)+IF(③前提!$G$38="EC/酒販店卸",IF(③前提!$H$38=0,③前提!$D$38/12,IF(③前提!$H$38=4,③前提!$D$38,0)),0)+IF(③前提!$G$39="EC/酒販店卸",IF(③前提!$H$39=0,③前提!$D$39/12,IF(③前提!$H$39=4,③前提!$D$39,0)),0)+IF(③前提!$G$40="EC/酒販店卸",IF(③前提!$H$40=0,③前提!$D$40/12,IF(③前提!$H$40=4,③前提!$D$40,0)),0) -> 3968367.1 | G15: =(⑤部門別損益!D11+⑤部門別損益!D12)/12+IF(③前提!$G$36="EC/酒販店卸",IF(③前提!$H$36=0,③前提!$D$36/12,IF(③前提!$H$36=5,③前提!$D$36,0)),0)+IF(③前提!$G$37="EC/酒販店卸",IF(③前提!$H$37=0,③前提!$D$37/12,IF(③前提!$H$37=5,③前提!$D$37,0)),0)+IF(③前提!$G$38="EC/酒販店卸",IF(③前提!$H$38=0,③前提!$D$38/12,IF(③前提!$H$38=5,③前提!$D$38,0)),0)+IF(③前提!$G$39="EC/酒販店卸",IF(③前提!$H$39=0,③前提!$D$39/12,IF(③前提!$H$39=5,③前提!$D$39,0)),0)+IF(③前提!$G$40="EC/酒販店卸",IF(③前提!$H$40=0,③前提!$D$40/12,IF(③前提!$H$40=5,③前提!$D$40,0)),0) -> 3968367.1 | H15: =(⑤部門別損益!D11+⑤部門別損益!D12)/12+IF(③前提!$G$36="EC/酒販店卸",IF(③前提!$H$36=0,③前提!$D$36/12,IF(③前提!$H$36=6,③前提!$D$36,0)),0)+IF(③前提!$G$37="EC/酒販店卸",IF(③前提!$H$37=0,③前提!$D$37/12,IF(③前提!$H$37=6,③前提!$D$37,0)),0)+IF(③前提!$G$38="EC/酒販店卸",IF(③前提!$H$38=0,③前提!$D$38/12,IF(③前提!$H$38=6,③前提!$D$38,0)),0)+IF(③前提!$G$39="EC/酒販店卸",IF(③前提!$H$39=0,③前提!$D$39/12,IF(③前提!$H$39=6,③前提!$D$39,0)),0)+IF(③前提!$G$40="EC/酒販店卸",IF(③前提!$H$40=0,③前提!$D$40/12,IF(③前提!$H$40=6,③前提!$D$40,0)),0) -> 3968367.1 | I15: =(⑤部門別損益!D11+⑤部門別損益!D12)/12+IF(③前提!$G$36="EC/酒販店卸",IF(③前提!$H$36=0,③前提!$D$36/12,IF(③前提!$H$36=7,③前提!$D$36,0)),0)+IF(③前提!$G$37="EC/酒販店卸",IF(③前提!$H$37=0,③前提!$D$37/12,IF(③前提!$H$37=7,③前提!$D$37,0)),0)+IF(③前提!$G$38="EC/酒販店卸",IF(③前提!$H$38=0,③前提!$D$38/12,IF(③前提!$H$38=7,③前提!$D$38,0)),0)+IF(③前提!$G$39="EC/酒販店卸",IF(③前提!$H$39=0,③前提!$D$39/12,IF(③前提!$H$39=7,③前提!$D$39,0)),0)+IF(③前提!$G$40="EC/酒販店卸",IF(③前提!$H$40=0,③前提!$D$40/12,IF(③前提!$H$40=7,③前提!$D$40,0)),0) -> 3968367.1 | J15: =(⑤部門別損益!D11+⑤部門別損益!D12)/12+IF(③前提!$G$36="EC/酒販店卸",IF(③前提!$H$36=0,③前提!$D$36/12,IF(③前提!$H$36=8,③前提!$D$36,0)),0)+IF(③前提!$G$37="EC/酒販店卸",IF(③前提!$H$37=0,③前提!$D$37/12,IF(③前提!$H$37=8,③前提!$D$37,0)),0)+IF(③前提!$G$38="EC/酒販店卸",IF(③前提!$H$38=0,③前提!$D$38/12,IF(③前提!$H$38=8,③前提!$D$38,0)),0)+IF(③前提!$G$39="EC/酒販店卸",IF(③前提!$H$39=0,③前提!$D$39/12,IF(③前提!$H$39=8,③前提!$D$39,0)),0)+IF(③前提!$G$40="EC/酒販店卸",IF(③前提!$H$40=0,③前提!$D$40/12,IF(③前提!$H$40=8,③前提!$D$40,0)),0) -> 3968367.1 | K15: =(⑤部門別損益!D11+⑤部門別損益!D12)/12+IF(③前提!$G$36="EC/酒販店卸",IF(③前提!$H$36=0,③前提!$D$36/12,IF(③前提!$H$36=9,③前提!$D$36,0)),0)+IF(③前提!$G$37="EC/酒販店卸",IF(③前提!$H$37=0,③前提!$D$37/12,IF(③前提!$H$37=9,③前提!$D$37,0)),0)+IF(③前提!$G$38="EC/酒販店卸",IF(③前提!$H$38=0,③前提!$D$38/12,IF(③前提!$H$38=9,③前提!$D$38,0)),0)+IF(③前提!$G$39="EC/酒販店卸",IF(③前提!$H$39=0,③前提!$D$39/12,IF(③前提!$H$39=9,③前提!$D$39,0)),0)+IF(③前提!$G$40="EC/酒販店卸",IF(③前提!$H$40=0,③前提!$D$40/12,IF(③前提!$H$40=9,③前提!$D$40,0)),0) -> 3968367.1 | L15: =(⑤部門別損益!D11+⑤部門別損益!D12)/12+IF(③前提!$G$36="EC/酒販店卸",IF(③前提!$H$36=0,③前提!$D$36/12,IF(③前提!$H$36=10,③前提!$D$36,0)),0)+IF(③前提!$G$37="EC/酒販店卸",IF(③前提!$H$37=0,③前提!$D$37/12,IF(③前提!$H$37=10,③前提!$D$37,0)),0)+IF(③前提!$G$38="EC/酒販店卸",IF(③前提!$H$38=0,③前提!$D$38/12,IF(③前提!$H$38=10,③前提!$D$38,0)),0)+IF(③前提!$G$39="EC/酒販店卸",IF(③前提!$H$39=0,③前提!$D$39/12,IF(③前提!$H$39=10,③前提!$D$39,0)),0)+IF(③前提!$G$40="EC/酒販店卸",IF(③前提!$H$40=0,③前提!$D$40/12,IF(③前提!$H$40=10,③前提!$D$40,0)),0) -> 3968367.1 | M15: =(⑤部門別損益!D11+⑤部門別損益!D12)/12+IF(③前提!$G$36="EC/酒販店卸",IF(③前提!$H$36=0,③前提!$D$36/12,IF(③前提!$H$36=11,③前提!$D$36,0)),0)+IF(③前提!$G$37="EC/酒販店卸",IF(③前提!$H$37=0,③前提!$D$37/12,IF(③前提!$H$37=11,③前提!$D$37,0)),0)+IF(③前提!$G$38="EC/酒販店卸",IF(③前提!$H$38=0,③前提!$D$38/12,IF(③前提!$H$38=11,③前提!$D$38,0)),0)+IF(③前提!$G$39="EC/酒販店卸",IF(③前提!$H$39=0,③前提!$D$39/12,IF(③前提!$H$39=11,③前提!$D$39,0)),0)+IF(③前提!$G$40="EC/酒販店卸",IF(③前提!$H$40=0,③前提!$D$40/12,IF(③前提!$H$40=11,③前提!$D$40,0)),0) -> 3968367.1 | N15: =(⑤部門別損益!D11+⑤部門別損益!D12)/12+IF(③前提!$G$36="EC/酒販店卸",IF(③前提!$H$36=0,③前提!$D$36/12,IF(③前提!$H$36=12,③前提!$D$36,0)),0)+IF(③前提!$G$37="EC/酒販店卸",IF(③前提!$H$37=0,③前提!$D$37/12,IF(③前提!$H$37=12,③前提!$D$37,0)),0)+IF(③前提!$G$38="EC/酒販店卸",IF(③前提!$H$38=0,③前提!$D$38/12,IF(③前提!$H$38=12,③前提!$D$38,0)),0)+IF(③前提!$G$39="EC/酒販店卸",IF(③前提!$H$39=0,③前提!$D$39/12,IF(③前提!$H$39=12,③前提!$D$39,0)),0)+IF(③前提!$G$40="EC/酒販店卸",IF(③前提!$H$40=0,③前提!$D$40/12,IF(③前提!$H$40=12,③前提!$D$40,0)),0) -> 3968367.1 | O15: =SUM(C15:N15) -> 47620405
B16: 販管費 | C16: =⑤部門別損益!D17/12 -> 3681427.9 | D16: =⑤部門別損益!D17/12 -> 3681427.9 | E16: =⑤部門別損益!D17/12 -> 3681427.9 | F16: =⑤部門別損益!D17/12 -> 3681427.9 | G16: =⑤部門別損益!D17/12 -> 3681427.9 | H16: =⑤部門別損益!D17/12 -> 3681427.9 | I16: =⑤部門別損益!D17/12 -> 3681427.9 | J16: =⑤部門別損益!D17/12 -> 3681427.9 | K16: =⑤部門別損益!D17/12 -> 3681427.9 | L16: =⑤部門別損益!D17/12 -> 3681427.9 | M16: =⑤部門別損益!D17/12 -> 3681427.9 | N16: =⑤部門別損益!D17/12 -> 3681427.9 | O16: =SUM(C16:N16) -> 44177134
B17: 部門利益（配賦前） | C17: =C15-C16 -> 286939.2 | D17: =D15-D16 -> 286939.2 | E17: =E15-E16 -> 286939.2 | F17: =F15-F16 -> 286939.2 | G17: =G15-G16 -> 286939.2 | H17: =H15-H16 -> 286939.2 | I17: =I15-I16 -> 286939.2 | J17: =J15-J16 -> 286939.2 | ... N17: =N15-N16 -> 286939.2 | O17: =SUM(C17:N17) -> 3443270.5
B19: 【ワインテック】
B20: 科目 | C20: 10月 | D20: 11月 | E20: 12月 | F20: 1月 | G20: 2月 | H20: 3月 | I20: 4月 | J20: 5月 | K20: 6月 | L20: 7月 | M20: 8月 | N20: 9月 | O20: 通期
B21: 売上 | C21: =(⑤部門別損益!E7+⑤部門別損益!E8)/12+IF(③前提!$G$36="ワインテック",IF(③前提!$H$36=0,③前提!$D$36/12,IF(③前提!$H$36=1,③前提!$D$36,0)),0)+IF(③前提!$G$37="ワインテック",IF(③前提!$H$37=0,③前提!$D$37/12,IF(③前提!$H$37=1,③前提!$D$37,0)),0)+IF(③前提!$G$38="ワインテック",IF(③前提!$H$38=0,③前提!$D$38/12,IF(③前提!$H$38=1,③前提!$D$38,0)),0)+IF(③前提!$G$39="ワインテック",IF(③前提!$H$39=0,③前提!$D$39/12,IF(③前提!$H$39=1,③前提!$D$39,0)),0)+IF(③前提!$G$40="ワインテック",IF(③前提!$H$40=0,③前提!$D$40/12,IF(③前提!$H$40=1,③前提!$D$40,0)),0) -> 25218995 | D21: =(⑤部門別損益!E7+⑤部門別損益!E8)/12+IF(③前提!$G$36="ワインテック",IF(③前提!$H$36=0,③前提!$D$36/12,IF(③前提!$H$36=2,③前提!$D$36,0)),0)+IF(③前提!$G$37="ワインテック",IF(③前提!$H$37=0,③前提!$D$37/12,IF(③前提!$H$37=2,③前提!$D$37,0)),0)+IF(③前提!$G$38="ワインテック",IF(③前提!$H$38=0,③前提!$D$38/12,IF(③前提!$H$38=2,③前提!$D$38,0)),0)+IF(③前提!$G$39="ワインテック",IF(③前提!$H$39=0,③前提!$D$39/12,IF(③前提!$H$39=2,③前提!$D$39,0)),0)+IF(③前提!$G$40="ワインテック",IF(③前提!$H$40=0,③前提!$D$40/12,IF(③前提!$H$40=2,③前提!$D$40,0)),0) -> 25218995 | E21: =(⑤部門別損益!E7+⑤部門別損益!E8)/12+IF(③前提!$G$36="ワインテック",IF(③前提!$H$36=0,③前提!$D$36/12,IF(③前提!$H$36=3,③前提!$D$36,0)),0)+IF(③前提!$G$37="ワインテック",IF(③前提!$H$37=0,③前提!$D$37/12,IF(③前提!$H$37=3,③前提!$D$37,0)),0)+IF(③前提!$G$38="ワインテック",IF(③前提!$H$38=0,③前提!$D$38/12,IF(③前提!$H$38=3,③前提!$D$38,0)),0)+IF(③前提!$G$39="ワインテック",IF(③前提!$H$39=0,③前提!$D$39/12,IF(③前提!$H$39=3,③前提!$D$39,0)),0)+IF(③前提!$G$40="ワインテック",IF(③前提!$H$40=0,③前提!$D$40/12,IF(③前提!$H$40=3,③前提!$D$40,0)),0) -> 25218995 | F21: =(⑤部門別損益!E7+⑤部門別損益!E8)/12+IF(③前提!$G$36="ワインテック",IF(③前提!$H$36=0,③前提!$D$36/12,IF(③前提!$H$36=4,③前提!$D$36,0)),0)+IF(③前提!$G$37="ワインテック",IF(③前提!$H$37=0,③前提!$D$37/12,IF(③前提!$H$37=4,③前提!$D$37,0)),0)+IF(③前提!$G$38="ワインテック",IF(③前提!$H$38=0,③前提!$D$38/12,IF(③前提!$H$38=4,③前提!$D$38,0)),0)+IF(③前提!$G$39="ワインテック",IF(③前提!$H$39=0,③前提!$D$39/12,IF(③前提!$H$39=4,③前提!$D$39,0)),0)+IF(③前提!$G$40="ワインテック",IF(③前提!$H$40=0,③前提!$D$40/12,IF(③前提!$H$40=4,③前提!$D$40,0)),0) -> 25218995 | G21: =(⑤部門別損益!E7+⑤部門別損益!E8)/12+IF(③前提!$G$36="ワインテック",IF(③前提!$H$36=0,③前提!$D$36/12,IF(③前提!$H$36=5,③前提!$D$36,0)),0)+IF(③前提!$G$37="ワインテック",IF(③前提!$H$37=0,③前提!$D$37/12,IF(③前提!$H$37=5,③前提!$D$37,0)),0)+IF(③前提!$G$38="ワインテック",IF(③前提!$H$38=0,③前提!$D$38/12,IF(③前提!$H$38=5,③前提!$D$38,0)),0)+IF(③前提!$G$39="ワインテック",IF(③前提!$H$39=0,③前提!$D$39/12,IF(③前提!$H$39=5,③前提!$D$39,0)),0)+IF(③前提!$G$40="ワインテック",IF(③前提!$H$40=0,③前提!$D$40/12,IF(③前提!$H$40=5,③前提!$D$40,0)),0) -> 25218995 | H21: =(⑤部門別損益!E7+⑤部門別損益!E8)/12+IF(③前提!$G$36="ワインテック",IF(③前提!$H$36=0,③前提!$D$36/12,IF(③前提!$H$36=6,③前提!$D$36,0)),0)+IF(③前提!$G$37="ワインテック",IF(③前提!$H$37=0,③前提!$D$37/12,IF(③前提!$H$37=6,③前提!$D$37,0)),0)+IF(③前提!$G$38="ワインテック",IF(③前提!$H$38=0,③前提!$D$38/12,IF(③前提!$H$38=6,③前提!$D$38,0)),0)+IF(③前提!$G$39="ワインテック",IF(③前提!$H$39=0,③前提!$D$39/12,IF(③前提!$H$39=6,③前提!$D$39,0)),0)+IF(③前提!$G$40="ワインテック",IF(③前提!$H$40=0,③前提!$D$40/12,IF(③前提!$H$40=6,③前提!$D$40,0)),0) -> 25218995 | I21: =(⑤部門別損益!E7+⑤部門別損益!E8)/12+IF(③前提!$G$36="ワインテック",IF(③前提!$H$36=0,③前提!$D$36/12,IF(③前提!$H$36=7,③前提!$D$36,0)),0)+IF(③前提!$G$37="ワインテック",IF(③前提!$H$37=0,③前提!$D$37/12,IF(③前提!$H$37=7,③前提!$D$37,0)),0)+IF(③前提!$G$38="ワインテック",IF(③前提!$H$38=0,③前提!$D$38/12,IF(③前提!$H$38=7,③前提!$D$38,0)),0)+IF(③前提!$G$39="ワインテック",IF(③前提!$H$39=0,③前提!$D$39/12,IF(③前提!$H$39=7,③前提!$D$39,0)),0)+IF(③前提!$G$40="ワインテック",IF(③前提!$H$40=0,③前提!$D$40/12,IF(③前提!$H$40=7,③前提!$D$40,0)),0) -> 25218995 | J21: =(⑤部門別損益!E7+⑤部門別損益!E8)/12+IF(③前提!$G$36="ワインテック",IF(③前提!$H$36=0,③前提!$D$36/12,IF(③前提!$H$36=8,③前提!$D$36,0)),0)+IF(③前提!$G$37="ワインテック",IF(③前提!$H$37=0,③前提!$D$37/12,IF(③前提!$H$37=8,③前提!$D$37,0)),0)+IF(③前提!$G$38="ワインテック",IF(③前提!$H$38=0,③前提!$D$38/12,IF(③前提!$H$38=8,③前提!$D$38,0)),0)+IF(③前提!$G$39="ワインテック",IF(③前提!$H$39=0,③前提!$D$39/12,IF(③前提!$H$39=8,③前提!$D$39,0)),0)+IF(③前提!$G$40="ワインテック",IF(③前提!$H$40=0,③前提!$D$40/12,IF(③前提!$H$40=8,③前提!$D$40,0)),0) -> 25218995 | K21: =(⑤部門別損益!E7+⑤部門別損益!E8)/12+IF(③前提!$G$36="ワインテック",IF(③前提!$H$36=0,③前提!$D$36/12,IF(③前提!$H$36=9,③前提!$D$36,0)),0)+IF(③前提!$G$37="ワインテック",IF(③前提!$H$37=0,③前提!$D$37/12,IF(③前提!$H$37=9,③前提!$D$37,0)),0)+IF(③前提!$G$38="ワインテック",IF(③前提!$H$38=0,③前提!$D$38/12,IF(③前提!$H$38=9,③前提!$D$38,0)),0)+IF(③前提!$G$39="ワインテック",IF(③前提!$H$39=0,③前提!$D$39/12,IF(③前提!$H$39=9,③前提!$D$39,0)),0)+IF(③前提!$G$40="ワインテック",IF(③前提!$H$40=0,③前提!$D$40/12,IF(③前提!$H$40=9,③前提!$D$40,0)),0) -> 25218995 | L21: =(⑤部門別損益!E7+⑤部門別損益!E8)/12+IF(③前提!$G$36="ワインテック",IF(③前提!$H$36=0,③前提!$D$36/12,IF(③前提!$H$36=10,③前提!$D$36,0)),0)+IF(③前提!$G$37="ワインテック",IF(③前提!$H$37=0,③前提!$D$37/12,IF(③前提!$H$37=10,③前提!$D$37,0)),0)+IF(③前提!$G$38="ワインテック",IF(③前提!$H$38=0,③前提!$D$38/12,IF(③前提!$H$38=10,③前提!$D$38,0)),0)+IF(③前提!$G$39="ワインテック",IF(③前提!$H$39=0,③前提!$D$39/12,IF(③前提!$H$39=10,③前提!$D$39,0)),0)+IF(③前提!$G$40="ワインテック",IF(③前提!$H$40=0,③前提!$D$40/12,IF(③前提!$H$40=10,③前提!$D$40,0)),0) -> 25218995 | M21: =(⑤部門別損益!E7+⑤部門別損益!E8)/12+IF(③前提!$G$36="ワインテック",IF(③前提!$H$36=0,③前提!$D$36/12,IF(③前提!$H$36=11,③前提!$D$36,0)),0)+IF(③前提!$G$37="ワインテック",IF(③前提!$H$37=0,③前提!$D$37/12,IF(③前提!$H$37=11,③前提!$D$37,0)),0)+IF(③前提!$G$38="ワインテック",IF(③前提!$H$38=0,③前提!$D$38/12,IF(③前提!$H$38=11,③前提!$D$38,0)),0)+IF(③前提!$G$39="ワインテック",IF(③前提!$H$39=0,③前提!$D$39/12,IF(③前提!$H$39=11,③前提!$D$39,0)),0)+IF(③前提!$G$40="ワインテック",IF(③前提!$H$40=0,③前提!$D$40/12,IF(③前提!$H$40=11,③前提!$D$40,0)),0) -> 25218995 | N21: =(⑤部門別損益!E7+⑤部門別損益!E8)/12+IF(③前提!$G$36="ワインテック",IF(③前提!$H$36=0,③前提!$D$36/12,IF(③前提!$H$36=12,③前提!$D$36,0)),0)+IF(③前提!$G$37="ワインテック",IF(③前提!$H$37=0,③前提!$D$37/12,IF(③前提!$H$37=12,③前提!$D$37,0)),0)+IF(③前提!$G$38="ワインテック",IF(③前提!$H$38=0,③前提!$D$38/12,IF(③前提!$H$38=12,③前提!$D$38,0)),0)+IF(③前提!$G$39="ワインテック",IF(③前提!$H$39=0,③前提!$D$39/12,IF(③前提!$H$39=12,③前提!$D$39,0)),0)+IF(③前提!$G$40="ワインテック",IF(③前提!$H$40=0,③前提!$D$40/12,IF(③前提!$H$40=12,③前提!$D$40,0)),0) -> 25218995 | O21: =SUM(C21:N21) -> 3.0262794e+08
B22: 粗利 | C22: =(⑤部門別損益!E11+⑤部門別損益!E12)/12+IF(③前提!$G$36="ワインテック",IF(③前提!$H$36=0,③前提!$D$36/12,IF(③前提!$H$36=1,③前提!$D$36,0)),0)+IF(③前提!$G$37="ワインテック",IF(③前提!$H$37=0,③前提!$D$37/12,IF(③前提!$H$37=1,③前提!$D$37,0)),0)+IF(③前提!$G$38="ワインテック",IF(③前提!$H$38=0,③前提!$D$38/12,IF(③前提!$H$38=1,③前提!$D$38,0)),0)+IF(③前提!$G$39="ワインテック",IF(③前提!$H$39=0,③前提!$D$39/12,IF(③前提!$H$39=1,③前提!$D$39,0)),0)+IF(③前提!$G$40="ワインテック",IF(③前提!$H$40=0,③前提!$D$40/12,IF(③前提!$H$40=1,③前提!$D$40,0)),0) -> 6777835.1 | D22: =(⑤部門別損益!E11+⑤部門別損益!E12)/12+IF(③前提!$G$36="ワインテック",IF(③前提!$H$36=0,③前提!$D$36/12,IF(③前提!$H$36=2,③前提!$D$36,0)),0)+IF(③前提!$G$37="ワインテック",IF(③前提!$H$37=0,③前提!$D$37/12,IF(③前提!$H$37=2,③前提!$D$37,0)),0)+IF(③前提!$G$38="ワインテック",IF(③前提!$H$38=0,③前提!$D$38/12,IF(③前提!$H$38=2,③前提!$D$38,0)),0)+IF(③前提!$G$39="ワインテック",IF(③前提!$H$39=0,③前提!$D$39/12,IF(③前提!$H$39=2,③前提!$D$39,0)),0)+IF(③前提!$G$40="ワインテック",IF(③前提!$H$40=0,③前提!$D$40/12,IF(③前提!$H$40=2,③前提!$D$40,0)),0) -> 6777835.1 | E22: =(⑤部門別損益!E11+⑤部門別損益!E12)/12+IF(③前提!$G$36="ワインテック",IF(③前提!$H$36=0,③前提!$D$36/12,IF(③前提!$H$36=3,③前提!$D$36,0)),0)+IF(③前提!$G$37="ワインテック",IF(③前提!$H$37=0,③前提!$D$37/12,IF(③前提!$H$37=3,③前提!$D$37,0)),0)+IF(③前提!$G$38="ワインテック",IF(③前提!$H$38=0,③前提!$D$38/12,IF(③前提!$H$38=3,③前提!$D$38,0)),0)+IF(③前提!$G$39="ワインテック",IF(③前提!$H$39=0,③前提!$D$39/12,IF(③前提!$H$39=3,③前提!$D$39,0)),0)+IF(③前提!$G$40="ワインテック",IF(③前提!$H$40=0,③前提!$D$40/12,IF(③前提!$H$40=3,③前提!$D$40,0)),0) -> 6777835.1 | F22: =(⑤部門別損益!E11+⑤部門別損益!E12)/12+IF(③前提!$G$36="ワインテック",IF(③前提!$H$36=0,③前提!$D$36/12,IF(③前提!$H$36=4,③前提!$D$36,0)),0)+IF(③前提!$G$37="ワインテック",IF(③前提!$H$37=0,③前提!$D$37/12,IF(③前提!$H$37=4,③前提!$D$37,0)),0)+IF(③前提!$G$38="ワインテック",IF(③前提!$H$38=0,③前提!$D$38/12,IF(③前提!$H$38=4,③前提!$D$38,0)),0)+IF(③前提!$G$39="ワインテック",IF(③前提!$H$39=0,③前提!$D$39/12,IF(③前提!$H$39=4,③前提!$D$39,0)),0)+IF(③前提!$G$40="ワインテック",IF(③前提!$H$40=0,③前提!$D$40/12,IF(③前提!$H$40=4,③前提!$D$40,0)),0) -> 6777835.1 | G22: =(⑤部門別損益!E11+⑤部門別損益!E12)/12+IF(③前提!$G$36="ワインテック",IF(③前提!$H$36=0,③前提!$D$36/12,IF(③前提!$H$36=5,③前提!$D$36,0)),0)+IF(③前提!$G$37="ワインテック",IF(③前提!$H$37=0,③前提!$D$37/12,IF(③前提!$H$37=5,③前提!$D$37,0)),0)+IF(③前提!$G$38="ワインテック",IF(③前提!$H$38=0,③前提!$D$38/12,IF(③前提!$H$38=5,③前提!$D$38,0)),0)+IF(③前提!$G$39="ワインテック",IF(③前提!$H$39=0,③前提!$D$39/12,IF(③前提!$H$39=5,③前提!$D$39,0)),0)+IF(③前提!$G$40="ワインテック",IF(③前提!$H$40=0,③前提!$D$40/12,IF(③前提!$H$40=5,③前提!$D$40,0)),0) -> 6777835.1 | H22: =(⑤部門別損益!E11+⑤部門別損益!E12)/12+IF(③前提!$G$36="ワインテック",IF(③前提!$H$36=0,③前提!$D$36/12,IF(③前提!$H$36=6,③前提!$D$36,0)),0)+IF(③前提!$G$37="ワインテック",IF(③前提!$H$37=0,③前提!$D$37/12,IF(③前提!$H$37=6,③前提!$D$37,0)),0)+IF(③前提!$G$38="ワインテック",IF(③前提!$H$38=0,③前提!$D$38/12,IF(③前提!$H$38=6,③前提!$D$38,0)),0)+IF(③前提!$G$39="ワインテック",IF(③前提!$H$39=0,③前提!$D$39/12,IF(③前提!$H$39=6,③前提!$D$39,0)),0)+IF(③前提!$G$40="ワインテック",IF(③前提!$H$40=0,③前提!$D$40/12,IF(③前提!$H$40=6,③前提!$D$40,0)),0) -> 6777835.1 | I22: =(⑤部門別損益!E11+⑤部門別損益!E12)/12+IF(③前提!$G$36="ワインテック",IF(③前提!$H$36=0,③前提!$D$36/12,IF(③前提!$H$36=7,③前提!$D$36,0)),0)+IF(③前提!$G$37="ワインテック",IF(③前提!$H$37=0,③前提!$D$37/12,IF(③前提!$H$37=7,③前提!$D$37,0)),0)+IF(③前提!$G$38="ワインテック",IF(③前提!$H$38=0,③前提!$D$38/12,IF(③前提!$H$38=7,③前提!$D$38,0)),0)+IF(③前提!$G$39="ワインテック",IF(③前提!$H$39=0,③前提!$D$39/12,IF(③前提!$H$39=7,③前提!$D$39,0)),0)+IF(③前提!$G$40="ワインテック",IF(③前提!$H$40=0,③前提!$D$40/12,IF(③前提!$H$40=7,③前提!$D$40,0)),0) -> 6777835.1 | J22: =(⑤部門別損益!E11+⑤部門別損益!E12)/12+IF(③前提!$G$36="ワインテック",IF(③前提!$H$36=0,③前提!$D$36/12,IF(③前提!$H$36=8,③前提!$D$36,0)),0)+IF(③前提!$G$37="ワインテック",IF(③前提!$H$37=0,③前提!$D$37/12,IF(③前提!$H$37=8,③前提!$D$37,0)),0)+IF(③前提!$G$38="ワインテック",IF(③前提!$H$38=0,③前提!$D$38/12,IF(③前提!$H$38=8,③前提!$D$38,0)),0)+IF(③前提!$G$39="ワインテック",IF(③前提!$H$39=0,③前提!$D$39/12,IF(③前提!$H$39=8,③前提!$D$39,0)),0)+IF(③前提!$G$40="ワインテック",IF(③前提!$H$40=0,③前提!$D$40/12,IF(③前提!$H$40=8,③前提!$D$40,0)),0) -> 6777835.1 | K22: =(⑤部門別損益!E11+⑤部門別損益!E12)/12+IF(③前提!$G$36="ワインテック",IF(③前提!$H$36=0,③前提!$D$36/12,IF(③前提!$H$36=9,③前提!$D$36,0)),0)+IF(③前提!$G$37="ワインテック",IF(③前提!$H$37=0,③前提!$D$37/12,IF(③前提!$H$37=9,③前提!$D$37,0)),0)+IF(③前提!$G$38="ワインテック",IF(③前提!$H$38=0,③前提!$D$38/12,IF(③前提!$H$38=9,③前提!$D$38,0)),0)+IF(③前提!$G$39="ワインテック",IF(③前提!$H$39=0,③前提!$D$39/12,IF(③前提!$H$39=9,③前提!$D$39,0)),0)+IF(③前提!$G$40="ワインテック",IF(③前提!$H$40=0,③前提!$D$40/12,IF(③前提!$H$40=9,③前提!$D$40,0)),0) -> 6777835.1 | L22: =(⑤部門別損益!E11+⑤部門別損益!E12)/12+IF(③前提!$G$36="ワインテック",IF(③前提!$H$36=0,③前提!$D$36/12,IF(③前提!$H$36=10,③前提!$D$36,0)),0)+IF(③前提!$G$37="ワインテック",IF(③前提!$H$37=0,③前提!$D$37/12,IF(③前提!$H$37=10,③前提!$D$37,0)),0)+IF(③前提!$G$38="ワインテック",IF(③前提!$H$38=0,③前提!$D$38/12,IF(③前提!$H$38=10,③前提!$D$38,0)),0)+IF(③前提!$G$39="ワインテック",IF(③前提!$H$39=0,③前提!$D$39/12,IF(③前提!$H$39=10,③前提!$D$39,0)),0)+IF(③前提!$G$40="ワインテック",IF(③前提!$H$40=0,③前提!$D$40/12,IF(③前提!$H$40=10,③前提!$D$40,0)),0) -> 6777835.1 | M22: =(⑤部門別損益!E11+⑤部門別損益!E12)/12+IF(③前提!$G$36="ワインテック",IF(③前提!$H$36=0,③前提!$D$36/12,IF(③前提!$H$36=11,③前提!$D$36,0)),0)+IF(③前提!$G$37="ワインテック",IF(③前提!$H$37=0,③前提!$D$37/12,IF(③前提!$H$37=11,③前提!$D$37,0)),0)+IF(③前提!$G$38="ワインテック",IF(③前提!$H$38=0,③前提!$D$38/12,IF(③前提!$H$38=11,③前提!$D$38,0)),0)+IF(③前提!$G$39="ワインテック",IF(③前提!$H$39=0,③前提!$D$39/12,IF(③前提!$H$39=11,③前提!$D$39,0)),0)+IF(③前提!$G$40="ワインテック",IF(③前提!$H$40=0,③前提!$D$40/12,IF(③前提!$H$40=11,③前提!$D$40,0)),0) -> 6777835.1 | N22: =(⑤部門別損益!E11+⑤部門別損益!E12)/12+IF(③前提!$G$36="ワインテック",IF(③前提!$H$36=0,③前提!$D$36/12,IF(③前提!$H$36=12,③前提!$D$36,0)),0)+IF(③前提!$G$37="ワインテック",IF(③前提!$H$37=0,③前提!$D$37/12,IF(③前提!$H$37=12,③前提!$D$37,0)),0)+IF(③前提!$G$38="ワインテック",IF(③前提!$H$38=0,③前提!$D$38/12,IF(③前提!$H$38=12,③前提!$D$38,0)),0)+IF(③前提!$G$39="ワインテック",IF(③前提!$H$39=0,③前提!$D$39/12,IF(③前提!$H$39=12,③前提!$D$39,0)),0)+IF(③前提!$G$40="ワインテック",IF(③前提!$H$40=0,③前提!$D$40/12,IF(③前提!$H$40=12,③前提!$D$40,0)),0) -> 6777835.1 | O22: =SUM(C22:N22) -> 81334021
B23: 販管費 | C23: =⑤部門別損益!E17/12 -> 6748882.9 | D23: =⑤部門別損益!E17/12 -> 6748882.9 | E23: =⑤部門別損益!E17/12 -> 6748882.9 | F23: =⑤部門別損益!E17/12 -> 6748882.9 | G23: =⑤部門別損益!E17/12 -> 6748882.9 | H23: =⑤部門別損益!E17/12 -> 6748882.9 | I23: =⑤部門別損益!E17/12 -> 6748882.9 | J23: =⑤部門別損益!E17/12 -> 6748882.9 | K23: =⑤部門別損益!E17/12 -> 6748882.9 | L23: =⑤部門別損益!E17/12 -> 6748882.9 | M23: =⑤部門別損益!E17/12 -> 6748882.9 | N23: =⑤部門別損益!E17/12 -> 6748882.9 | O23: =SUM(C23:N23) -> 80986595
B24: 部門利益（配賦前） | C24: =C22-C23 -> 28952.175 | D24: =D22-D23 -> 28952.175 | E24: =E22-E23 -> 28952.175 | F24: =F22-F23 -> 28952.175 | G24: =G22-G23 -> 28952.175 | H24: =H22-H23 -> 28952.175 | I24: =I22-I23 -> 28952.175 | J24: =J22-J23 -> 28952.175 | ... N24: =N22-N23 -> 28952.175 | O24: =SUM(C24:N24) -> 347426.1
B26: 【その他】
B27: 科目 | C27: 10月 | D27: 11月 | E27: 12月 | F27: 1月 | G27: 2月 | H27: 3月 | I27: 4月 | J27: 5月 | K27: 6月 | L27: 7月 | M27: 8月 | N27: 9月 | O27: 通期
