Workbook

Sheet FY2026未達要因
B1: FY2026（2026年9月期）が計画未達となった要因
B2: 単位：円（税別） 経常利益ベース
B4: 【1】未達要因の内訳
B5: 項目 | C5: 金額 | D5: 累計 | E5: 内容
B6: FY2026 経常利益（見込） | C6: -124793431 | D6: =C6 -> -124793431 | E6: 現行計画の今期着地見込
B7: ① SBI証券との公募ファンドの大幅遅延 | C7: 200000000 | D7: =D6+C7 -> 75206569 | E7: ★最大の未達要因。計画では売上約700百万円・粗利200百万円超を見込んでいたが、審査・制度対応の長期化により当期中の組成に至らず。
B8: ② 私募ファンドの期ズレ | C8: 30000000 | D8: =D7+C8 -> 105206569 | E8: 特殊な契約形態のため当期は原価が先行し粗利率は約5%にとどまる。来期の販売実績に応じ、販売手数料を含め約30百万円の粗利を来期計上。
B9: ③ 不採算飲食3店舗の営業赤字 | C9: 0 | D9: =D8+C9 -> 105206569 | E9: ★店舗別の確定値をご入力ください。撤退により消滅した固定費は年102.9百万円（月8,577,274円×12）で、こちらは勘定科目レベルで検証済み。
B10: これらが計画どおりであった場合の経常利益 | D10: =D9 -> 105206569 | E10: ①〜③はいずれも一過性または期ズレの要因であり、既存事業の収益力そのものの毀損ではない。
B12: 【2】挽回策の実績と来期の方針
B13: 挽回策（FY2026） | C13: 私募ファンドで約300百万円を組成し、公募の遅延分を部分的に巻き返した。ただし着手が後手に回り、通期の未達は補いきれなかった。
B14: 来期の方針① | C14: 公募ファンドは優先しない。制度対応・審査期間が当社の管理外にあり、資金繰りと収益計画を左右させない。
B15: 来期の方針② | C15: 私募ファンドを毎年継続的に組成する。FY2026の約300百万円は実績値であり、これを反復可能な収益源として計画の中心に据える。
B16: 来期の方針③ | C16: オークション事業を私募と並ぶ販売チャネルとして立ち上げ、プランEの上振れ余地とする。
B17: 来期の方針④ | C17: 不採算飲食3店舗の撤退は2026年3月に完了済み。WineBankテラスはWineBank CLUBのフラッグシップ店として改善のうえ継続。
B19: ※①の粗利200百万円超は、公募ファンド組成時に見込んでいた売上約700百万円に対応する粗利。金額は貴社ご確認値。
B20: ※③は店舗別PLが社内資料から特定できなかったため、確定値のご入力までは0としています（黄色セル）。

Sheet ①サマリー
B1: FY2027（2027年9月期）利益予測 プランD（メイン）／プランE（上振れ）
B2: ベース：再編後の実力値（2026/04-06 実績3か月平均）を横ばい延伸し、そこから積み上げ
B3: 単位：円（税別） 出典：事業計画202608（銀行様）月次／決算報告書 第54期
B5: 科目 | C5: FY2026 見込 | D5: 横ばい実力値 （参考） | E5: プランD メインシナリオ | F5: プランE 上振れシナリオ | G5: コメント
B6: 既存事業 売上 | C6: 708205820 | D6: =②前提!$C$6*12 -> 389140768 | E6: =②前提!$C$55 -> 730535360 | F6: =②前提!$C$62 -> 1030535360 | G6: Dは前期・今期の売上平均そのもの。Eは私募＋オークション300百万円を上積み
B7: 売上総利益（既存事業） | C7: 229139405 | D7: =②前提!$C$7*12 -> 200601928 | E7: =D7+②前提!$C$57 -> 3.0302031e+08 | F7: =D7+②前提!$C$64 -> 3.9302031e+08 | G7: 横ばいからの差額売上の粗利率は保守的に30%
B8: ＋上乗せ案件（営業収益） | C8: 0 | D8: 0 | E8: =②前提!$C$20 -> 132500000 | F8: =②前提!$C$20 -> 132500000 | G8: コンサルティング料92.5＋M&A仲介20＋クルーザー×ワイン事業20
B9: 売上高（上乗せ含む） | C9: 708205820 | D9: =D6 -> 389140768 | E9: =②前提!$C$59 -> 863035360 | F9: =②前提!$C$66 -> 1163035360 | G9: D＝863.0百万円、E＝1,163.0百万円
B10: 売上総利益 合計 | C10: 229139405 | D10: =D7 -> 200601928 | E10: =②前提!$C$58 -> 4.3552031e+08 | F10: =②前提!$C$65 -> 5.2552031e+08
B11: 販管費 | C11: 343932836 | D11: =②前提!$C$8*12 -> 300161064 | E11: =D11 -> 300161064 | F11: =D11 -> 300161064 | G11: 2026/04-06実績の月平均×12。EもDと同額で据置き
B12: 営業利益 | C12: -114793431 | D12: =D10-D11 -> -99559136 | E12: =E10-E11 -> 1.3535924e+08 | F12: =F10-F11 -> 2.2535924e+08
B13: 営業外収益 | C13: 0 | D13: 0 | E13: 0 | F13: 0 | G13: クルーザー×ワイン事業は営業収益に計上
B14: 営業外費用 | C14: 10000000 | D14: =②前提!$C$24 -> 15000000 | E14: =②前提!$C$24 -> 15000000 | F14: =②前提!$C$24 -> 15000000
B15: 経常利益 | C15: -124793431 | D15: =D12+D13-D14 -> -114559136 | E15: =E12+E13-E14 -> 1.2035924e+08 | F15: =F12+F13-F14 -> 2.1035924e+08
B16: 法人税等 | C16: 0 | D16: 0 | E16: 0 | F16: 0 | G16: 繰越欠損金 約252百万円により実質非課税
B17: 当期純利益 | C17: -124793431 | D17: =D15-D16 -> -114559136 | E17: =E15-E16 -> 1.2035924e+08 | F17: =F15-F16 -> 2.1035924e+08
B21: 【横ばい実力値からの差額売上】
C22: 差額売上 | D22: 新規顧客売上計画 1,066百万円に対する比率
B23: プランD：前期・今期の売上平均まで戻す | C23: =②前提!$C$56 -> 341394592 | D23: =C23/②前提!$C$29 -> 0.32025759
B24: プランE：Dに私募＋オークション300百万円を上積み | C24: =②前提!$C$63 -> 641394592 | D24: =C24/②前提!$C$29 -> 0.60168348
B27: 【判定】
B28: 横ばい実力値（参考）：再編後の4-6月実績をそのまま延ばすだけでは営業利益▲99.6百万円・経常利益▲114.6百万円。
B29: プランD（メインシナリオ）：既存事業を前期・今期の売上平均730.5百万円に戻し、契約ベースの上乗せ案件132.5百万円を
B30: 外数で加算。売上863.0百万円・営業利益＋135.4百万円・経常利益＋120.4百万円。
B31: プランE（上振れシナリオ）：Dに私募ファンド＋オークションで300百万円（粗利率30%）を上積み。
B32: 売上1,163.0百万円・営業利益＋225.4百万円・経常利益＋210.4百万円。
B34: ※Dの既存事業売上730.5百万円は過去2期の実績平均そのもので、新規の前提を置いていない。
B35: ※Eの300百万円は、FY2026にSBI公募の遅延を私募で約300百万円巻き返した実績と同水準。
B36: ※差額売上の粗利率30%はFY2025 26.8%・FY2026 32.4%の実績水準。4-6月実績の51.5%は用いない。

Sheet ④FY2026月次実績
B1: FY2026（2025年10月-2026年9月）月次 実績／見込
B2: 青字＝実績（2026/06まで） 灰字斜体＝見込（2026/07以降・同一値が並ぶプラグ） 出典：事業計画202608（銀行様）全社シート
B3: 不採算3店舗の撤退により、2026/04以降が再編後の実力値。WineBankテラスはWineBank CLUBのフラッグシップ店として改善のうえ継続。
B5: 科目 | C5: 2025/10 | D5: 2025/11 | E5: 2025/12 | F5: 2026/01 | G5: 2026/02 | H5: 2026/03 | I5: 2026/04 | J5: 2026/05 | K5: 2026/06 | L5: 2026/07 | M5: 2026/08 | N5: 2026/09 | O5: 通期 | P5: ①10-3月 平均 | Q5: ②4-6月 平均 | R5: 差 ②-①
B6: 売上 | C6: 32789307 | D6: 96919229 | E6: 43039844 | F6: 32477958 | G6: 41290432 | H6: 33033585 | I6: 31863679 | J6: 33917025 | K6: 31504488 | L6: 60489854 | M6: 37962048 | N6: 232918371 | O6: =SUM(C6:N6) -> 708205820 | P6: =AVERAGE(C6:H6) -> 46591726 | Q6: =AVERAGE(I6:K6) -> 32428397 | R6: =Q6-P6 -> -14163328
B7: 売上原価 | C7: 18502877 | D7: 69212121 | E7: 21085289 | F7: 16521949 | G7: 21070367 | H7: 18454664 | I7: 16184238 | J7: 15777832 | K7: 15172640 | L7: 38396406 | M7: 23721353 | N7: 204966678 | O7: =SUM(C7:N7) -> 479066414 | P7: =AVERAGE(C7:H7) -> 27474544 | Q7: =AVERAGE(I7:K7) -> 15711570 | R7: =Q7-P7 -> -11762974
B8: 売上総利益 | C8: 14286430 | D8: 27707108 | E8: 21954555 | F8: 15956009 | G8: 20220065 | H8: 14578921 | I8: 15679441 | J8: 18139193 | K8: 16331848 | L8: 22093448 | M8: 14240695 | N8: 27951692 | O8: =SUM(C8:N8) -> 229139405 | P8: =AVERAGE(C8:H8) -> 19117181 | Q8: =AVERAGE(I8:K8) -> 16716827 | R8: =Q8-P8 -> -2400354
B10: 【販売費及び一般管理費 内訳】
B11: 役員報酬 | C11: 1450000 | D11: 1450000 | E11: 2104000 | F11: 2104000 | G11: 2104000 | H11: 2104000 | I11: 2104000 | J11: 2104000 | K11: 2104000 | L11: 1140000 | M11: 1140000 | N11: 1140000 | O11: =SUM(C11:N11) -> 21048000 | P11: =AVERAGE(C11:H11) -> 1886000 | Q11: =AVERAGE(I11:K11) -> 2104000 | R11: =Q11-P11 -> 218000
B12: 従業員給与 | C12: 5733907 | D12: 5680516 | E12: 5686530 | F12: 5159687 | G12: 4194202 | H12: 2811830 | I12: 2863712 | J12: 2818448 | K12: 2851646 | L12: 3360996 | M12: 3360996 | N12: 3360996 | O12: =SUM(C12:N12) -> 47883466 | P12: =AVERAGE(C12:H12) -> 4877778.7 | Q12: =AVERAGE(I12:K12) -> 2844602 | R12: =Q12-P12 -> -2033176.7
B13: 雑給 | C13: 2678253 | D13: 2351213 | E13: 2399853 | F13: 2289298 | G13: 1935062 | H13: 206640 | I13: 203576 | J13: 177120 | K13: 213529 | L13: 300000 | M13: 300000 | N13: 300000 | O13: =SUM(C13:N13) -> 13354544 | P13: =AVERAGE(C13:H13) -> 1976719.8 | Q13: =AVERAGE(I13:K13) -> 198075 | R13: =Q13-P13 -> -1778644.8
B14: 法定福利費 | C14: 932201 | D14: 691553 | E14: 306078 | F14: 504694 | G14: 261086 | H14: 270455 | I14: 1046339 | J14: 1511149 | K14: 272080 | L14: 700959 | M14: 700959 | N14: 700959 | O14: =SUM(C14:N14) -> 7898512 | P14: =AVERAGE(C14:H14) -> 494344.5 | Q14: =AVERAGE(I14:K14) -> 943189.33 | R14: =Q14-P14 -> 448844.83
B15: 広告宣伝費・販売促進費 | C15: 53900 | D15: 154236 | E15: 130336 | F15: 100336 | G15: 371711 | H15: 939098 | I15: 379233 | J15: 480196 | K15: 702798 | L15: 1101461 | M15: 2190787 | N15: 2207913 | O15: =SUM(C15:N15) -> 8812005 | P15: =AVERAGE(C15:H15) -> 291602.83 | Q15: =AVERAGE(I15:K15) -> 520742.33 | R15: =Q15-P15 -> 229139.5
B16: 発送配達費 | C16: 234134 | D16: 1115528 | E16: 1228240 | F16: 483409 | G16: 804329 | H16: 985484 | I16: 1222432 | J16: 825807 | K16: 910690 | L16: 728319 | M16: 1204454 | N16: 814324 | O16: =SUM(C16:N16) -> 10557150 | P16: =AVERAGE(C16:H16) -> 808520.67 | Q16: =AVERAGE(I16:K16) -> 986309.67 | R16: =Q16-P16 -> 177789
B17: 支払手数料 | C17: 2786025 | D17: 892984 | E17: 6616700 | F17: 3819686 | G17: 3382365 | H17: 7232976 | I17: 4246967 | J17: 2708814 | K17: 2821069 | L17: 1197015 | M17: 1315343 | N17: 1218389 | O17: =SUM(C17:N17) -> 38238333 | P17: =AVERAGE(C17:H17) -> 4121789.3 | Q17: =AVERAGE(I17:K17) -> 3258950 | R17: =Q17-P17 -> -862839.33
B18: 地代家賃 | C18: 4193310 | D18: 4996110 | E18: 5069142 | F18: 5753005 | G18: 6089658 | H18: 3904683 | I18: 3293026 | J18: 3902041 | K18: 3970041 | L18: 1300000 | M18: 1300000 | N18: 1300000 | O18: =SUM(C18:N18) -> 45071016 | P18: =AVERAGE(C18:H18) -> 5000984.7 | Q18: =AVERAGE(I18:K18) -> 3721702.7 | R18: =Q18-P18 -> -1279282
B19: 通信交通費 | C19: 298477 | D19: 502722 | E19: 616408 | F19: 275333 | G19: 458134 | H19: 252956 | I19: 125644 | J19: 272015 | K19: 802423 | L19: 172511 | M19: 172511 | N19: 172511 | O19: =SUM(C19:N19) -> 4121645 | P19: =AVERAGE(C19:H19) -> 400671.67 | Q19: =AVERAGE(I19:K19) -> 400027.33 | R19: =Q19-P19 -> -644.33333
B20: 水道光熱費 | C20: 956603 | D20: 757648 | E20: 986948 | F20: 1221393 | G20: 1130296 | H20: 792518 | I20: 751741 | J20: 903801 | K20: 406947 | L20: 400000 | M20: 400000 | N20: 400000 | O20: =SUM(C20:N20) -> 9107895 | P20: =AVERAGE(C20:H20) -> 974234.33 | Q20: =AVERAGE(I20:K20) -> 687496.33 | R20: =Q20-P20 -> -286738
B21: 接待交際費 | C21: 385679 | D21: 409461 | E21: 423594 | F21: 48463 | G21: 455455 | H21: 6275 | I21: 224456 | J21: 0 | K21: 237941 | L21: 0 | M21: 0 | N21: 0 | O21: =SUM(C21:N21) -> 2191324 | P21: =AVERAGE(C21:H21) -> 288154.5 | Q21: =AVERAGE(I21:K21) -> 154132.33 | R21: =Q21-P21 -> -134022.17
B22: 保険料 | C22: 163840 | D22: 163840 | E22: 163840 | F22: 163840 | G22: 134106 | H22: 111575 | I22: 147305 | J22: 112235 | K22: 109311 | L22: 112868 | M22: 114508 | N22: 114868 | O22: =SUM(C22:N22) -> 1612136 | P22: =AVERAGE(C22:H22) -> 150173.5 | Q22: =AVERAGE(I22:K22) -> 122950.33 | R22: =Q22-P22 -> -27223.167
... B33: 倉庫＆保管・移設代 | C33: 419018 | D33: 1656111 | E33: 825810 | F33: 1670919 | G33: 742917 | H33: 10153686 | I33: 515140 | J33: 619350 | K33: -317039 | L33: 5546051 | M33: 5910511 | N33: 5571711 | O33: =SUM(C33:N33) -> 33314185 | P33: =AVERAGE(C33:H33) -> 2578076.8 | Q33: =AVERAGE(I33:K33) -> 272483.67 | R33: =Q33-P33 -> -2305593.2
B34: 販管費 合計 | C34: =SUM(C11:C33) -> 25374892 | D34: =SUM(D11:D33) -> 30963282 | E34: =SUM(E11:E33) -> 38572456 | F34: =SUM(F11:F33) -> 33761779 | G34: =SUM(G11:G33) -> 34133901 | H34: =SUM(H11:H33) -> 38737868 | I34: =SUM(I11:I33) -> 25883967 | J34: =SUM(J11:J33) -> 24529013 | ... N34: =SUM(N11:N33) -> 22414578 | O34: =SUM(C34:N34) -> 343932833 | P34: =AVERAGE(C34:H34) -> 33590696 | Q34: =AVERAGE(I34:K34) -> 25013422 | R34: =Q34-P34 -> -8577274.3
B35: 営業利益 | C35: =C8-C34 -> -11088462 | D35: =D8-D34 -> -3256174 | E35: =E8-E34 -> -16617901 | F35: =F8-F34 -> -17805770 | G35: =G8-G34 -> -13913836 | H35: =H8-H34 -> -24158947 | I35: =I8-I34 -> -10204526 | J35: =J8-J34 -> -6389820 | ... N35: =N8-N34 -> 5537114 | O35: =SUM(C35:N35) -> -114793428
B37: ※「差 ②-①」がマイナスの科目＝不採算3店舗の撤退および固定費削減により減少した費用。合計で月▲8.58百万円（年▲103百万円）。

Sheet ②前提
B1: FY2027（2027年9月期）利益予測モデル － 前提条件
B2: 青字＝入力セル／黄色＝主要前提／黒字＝計算式 単位：円（税別） 作成日 2026/08/21
B4: 【1】ベース：再編後の実力値（2026/04-06 実績3か月平均）
B5: 項目 | C5: 月次平均
B6: 売上 | C6: =AVERAGE(④FY2026月次実績!I6:K6) -> 32428397 | F6: 2026/03以前は撤退した不採算3店舗の売上・費用を含むため基準から除外（貴社ご指摘）。
B7: 売上総利益 | C7: =AVERAGE(④FY2026月次実績!I8:K8) -> 16716827
B8: 販管費 | C8: =AVERAGE(④FY2026月次実績!I34:K34) -> 25013422
B9: 売上総利益率 | C9: =C7/C6 -> 0.51549965
B11: 【2】上乗せ案件（2026/09-2027/08）
B12: 区分・案件 | C12: 金額 | D12: 取引先 | E12: 損益計上区分
B13: コンサルティング料 間接グループ5社 | C13: 80000000 | D13: 中野出資 | E13: 営業収益（12か月按分）
B14: コンサルティング料 Thierry Marx（2026年4月開業） | C14: 2500000 | D14: Apiciusグループ | E14: 営業収益（12か月按分）
B15: コンサルティング料 Apicius | C15: 10000000 | D15: 中野出資 | E15: 営業収益（12か月按分）
B16: M&A仲介 | C16: 20000000 | D16: 外部 | E16: 営業収益（一時）
B17: クルーザー×ワイン事業 1回目 | C17: 10000000 | D17: 外部 | E17: 営業収益（一時）
B18: クルーザー×ワイン事業 2回目 | C18: 10000000 | D18: 外部 | E18: 営業収益（一時）
B19: 合計 | C19: =SUM(C13:C18) -> 132500000 | F19: ※期間表記は2026/09-2027/08。決算期(2026/10-2027/09)と1か月ズレるため全額FY2027帰属で試算。
B20: うち 営業収益 | C20: =SUM(C13:C18) -> 132500000 | F20: ※グループ内 92.5百万円（中野出資90.0＋Apiciusグループ2.5）／外部 40.0百万円（M&A仲介20.0＋クルーザー×ワイン事業20.0）。
B21: うち 営業外収益 | C21: 0 | F21: ※クルーザー×ワイン事業は投資業ではなく事業収益のため、全額を営業収益に計上。営業外収益は0。
B23: 【3】その他前提
B24: 営業外費用（支払利息等・年額） | C24: 15000000 | F24: 事業計画FY2027計画値
B25: M&A仲介 計上月（1〜12） | C25: 6 | F25: 6＝2027年3月
B26: クルーザー×ワイン事業 1回目 計上月 | C26: 6 | F26: 6＝2027年3月
B27: クルーザー×ワイン事業 2回目 計上月 | C27: 12 | F27: 12＝2027年9月（期末までに計上）
B28: （未使用） | C28: 0 | F28: —
B29: 新規顧客売上 計画額（FY2027） | C29: 1066000000 | F29: 事業計画のワイン投資 新規顧客計画 合計
B30: シナリオ選択（1＝横ばい／2＝プランD／3＝プランE） | C30: 2 | F30: ③月次推移・⑦資金繰り表に反映
B31: ワイン仕入 方針（1＝在庫横ばい／2＝FY2026と同額） | C31: 2 | F31: ⑥仕入・在庫計画に反映
B32: FY2026 年間仕入額 | C32: 419066414 | F32: 売上原価479,066,414＋在庫増減▲60,000,000（480→420百万円）
B33: 法人税等 | C33: 均等割のみ | F33: 繰越欠損金 約252百万円（FY2025▲127.4＋FY2026▲124.8）。資本金1,000万円の中小法人は所得の100%控除可。
B35: 【6】消費税の算定 ※FY2027の資金繰りに乗るのはFY2026分の確定納付と当期の中間納付
B36: 消費税率 | C36: 0.1
B37: FY2026 課税売上高 | C37: 708205820 | F37: 事業計画FY2026見込の売上高
B38: FY2026 ワイン仕入（課税仕入） | C38: =C32 -> 419066414 | F38: 売上原価479,066,414＋在庫増減▲60,000,000
B39: FY2026 販管費のうち課税仕入 | C39: 208594315 | F39: 販管費343,932,836−人件費・減価償却・租税公課等135,338,521
B40: 仮受消費税 | C40: =C37*C36 -> 70820582
B41: 仮払消費税 | C41: =(C38+C39)*C36 -> 62766073
B42: FY2026 確定消費税額 | C42: =C40-C41 -> 8054509.1 | F42: 仮受−仮払。赤字でも人件費・減価償却は仕入税額控除できないため納付が生じる
B43: うちFY2026中に中間納付済 | C43: 4500000 | F43: FY2025確定額ベースの中間納付（年3回）の概算。実績値に差し替えてください
B44: 2026/11 確定納付額 | C44: =C42-C43 -> 3554509.1 | F44: FY2027の資金繰りに計上
...

Sheet ③FY2027月次推移
B1: FY2027（2026年10月-2027年9月）月次推移表 ②前提の「シナリオ選択」で 横ばい／プランD／プランE を切替
B2: C列＝月次ベース（2026/04-06実績平均、④シートから自動リンク）。D列以降は同額で横ばい。緑字＝他シートからのリンク
B4: 科目 | C4: 月次ベース (26/4-6平均) | D4: 2026/10 | E4: 2026/11 | F4: 2026/12 | G4: 2027/01 | H4: 2027/02 | I4: 2027/03 | J4: 2027/04 | K4: 2027/05 | L4: 2027/06 | M4: 2027/07 | N4: 2027/08 | O4: 2027/09 | P4: 通期合計
B5: 【収益】
B6: 既存事業 売上 | C6: =②前提!$C$6 -> 32428397 | D6: =$C$6 -> 32428397 | E6: =$C$6 -> 32428397 | F6: =$C$6 -> 32428397 | G6: =$C$6 -> 32428397 | H6: =$C$6 -> 32428397 | I6: =$C$6 -> 32428397 | J6: =$C$6 -> 32428397 | K6: =$C$6 -> 32428397 | ... O6: =$C$6 -> 32428397 | P6: =SUM(D6:O6) -> 389140768
B7: 差額売上（プランD／E） | C7: =IF(②前提!$C$30=3,②前提!$C$63/12,IF(②前提!$C$30=2,②前提!$C$56/12,0)) -> 28449549 | D7: =IF(②前提!$C$30=3,②前提!$C$63/12,IF(②前提!$C$30=2,②前提!$C$56/12,0)) -> 28449549 | E7: =IF(②前提!$C$30=3,②前提!$C$63/12,IF(②前提!$C$30=2,②前提!$C$56/12,0)) -> 28449549 | F7: =IF(②前提!$C$30=3,②前提!$C$63/12,IF(②前提!$C$30=2,②前提!$C$56/12,0)) -> 28449549 | G7: =IF(②前提!$C$30=3,②前提!$C$63/12,IF(②前提!$C$30=2,②前提!$C$56/12,0)) -> 28449549 | H7: =IF(②前提!$C$30=3,②前提!$C$63/12,IF(②前提!$C$30=2,②前提!$C$56/12,0)) -> 28449549 | I7: =IF(②前提!$C$30=3,②前提!$C$63/12,IF(②前提!$C$30=2,②前提!$C$56/12,0)) -> 28449549 | J7: =IF(②前提!$C$30=3,②前提!$C$63/12,IF(②前提!$C$30=2,②前提!$C$56/12,0)) -> 28449549 | ... O7: =IF(②前提!$C$30=3,②前提!$C$63/12,IF(②前提!$C$30=2,②前提!$C$56/12,0)) -> 28449549 | P7: =SUM(D7:O7) -> 341394592
B8: 売上 合計 | C8: =C6+C7 -> 60877947 | D8: =D6+D7 -> 60877947 | E8: =E6+E7 -> 60877947 | F8: =F6+F7 -> 60877947 | G8: =G6+G7 -> 60877947 | H8: =H6+H7 -> 60877947 | I8: =I6+I7 -> 60877947 | J8: =J6+J7 -> 60877947 | ... O8: =O6+O7 -> 60877947 | P8: =SUM(D8:O8) -> 730535360
B9: 売上原価 | C9: =C8-C10-C11 -> 35626255 | D9: =D8-D10-D11 -> 35626255 | E9: =E8-E10-E11 -> 35626255 | F9: =F8-F10-F11 -> 35626255 | G9: =G8-G10-G11 -> 35626255 | H9: =H8-H10-H11 -> 35626255 | I9: =I8-I10-I11 -> 35626255 | J9: =J8-J10-J11 -> 35626255 | ... O9: =O8-O10-O11 -> 35626255 | P9: =SUM(D9:O9) -> 4.2751505e+08
B10: 既存事業 売上総利益 | C10: =②前提!$C$7 -> 16716827 | D10: =$C$10 -> 16716827 | E10: =$C$10 -> 16716827 | F10: =$C$10 -> 16716827 | G10: =$C$10 -> 16716827 | H10: =$C$10 -> 16716827 | I10: =$C$10 -> 16716827 | J10: =$C$10 -> 16716827 | K10: =$C$10 -> 16716827 | ... O10: =$C$10 -> 16716827 | P10: =SUM(D10:O10) -> 200601928
B11: 追加売上 総利益 | C11: =C7*②前提!$C$51 -> 8534864.8 | D11: =D7*②前提!$C$51 -> 8534864.8 | E11: =E7*②前提!$C$51 -> 8534864.8 | F11: =F7*②前提!$C$51 -> 8534864.8 | G11: =G7*②前提!$C$51 -> 8534864.8 | H11: =H7*②前提!$C$51 -> 8534864.8 | I11: =I7*②前提!$C$51 -> 8534864.8 | J11: =J7*②前提!$C$51 -> 8534864.8 | ... O11: =O7*②前提!$C$51 -> 8534864.8 | P11: =SUM(D11:O11) -> 1.0241838e+08
B12: ＋コンサルティング料 間接グループ5社 | C12: =②前提!$C$13/12 -> 6666666.7 | D12: =$C$12 -> 6666666.7 | E12: =$C$12 -> 6666666.7 | F12: =$C$12 -> 6666666.7 | G12: =$C$12 -> 6666666.7 | H12: =$C$12 -> 6666666.7 | I12: =$C$12 -> 6666666.7 | J12: =$C$12 -> 6666666.7 | K12: =$C$12 -> 6666666.7 | ... O12: =$C$12 -> 6666666.7 | P12: =SUM(D12:O12) -> 80000000
B13: ＋コンサルティング料 Thierry Marx | C13: =②前提!$C$14/12 -> 208333.33 | D13: =$C$13 -> 208333.33 | E13: =$C$13 -> 208333.33 | F13: =$C$13 -> 208333.33 | G13: =$C$13 -> 208333.33 | H13: =$C$13 -> 208333.33 | I13: =$C$13 -> 208333.33 | J13: =$C$13 -> 208333.33 | K13: =$C$13 -> 208333.33 | ... O13: =$C$13 -> 208333.33 | P13: =SUM(D13:O13) -> 2500000
B14: ＋コンサルティング料 Apicius | C14: =②前提!$C$15/12 -> 833333.33 | D14: =$C$14 -> 833333.33 | E14: =$C$14 -> 833333.33 | F14: =$C$14 -> 833333.33 | G14: =$C$14 -> 833333.33 | H14: =$C$14 -> 833333.33 | I14: =$C$14 -> 833333.33 | J14: =$C$14 -> 833333.33 | K14: =$C$14 -> 833333.33 | ... O14: =$C$14 -> 833333.33 | P14: =SUM(D14:O14) -> 10000000
B15: ＋M&A仲介 | D15: =IF(1=②前提!$C$25,②前提!$C$16,0) -> 0 | E15: =IF(2=②前提!$C$25,②前提!$C$16,0) -> 0 | F15: =IF(3=②前提!$C$25,②前提!$C$16,0) -> 0 | G15: =IF(4=②前提!$C$25,②前提!$C$16,0) -> 0 | H15: =IF(5=②前提!$C$25,②前提!$C$16,0) -> 0 | I15: =IF(6=②前提!$C$25,②前提!$C$16,0) -> 20000000 | J15: =IF(7=②前提!$C$25,②前提!$C$16,0) -> 0 | K15: =IF(8=②前提!$C$25,②前提!$C$16,0) -> 0 | L15: =IF(9=②前提!$C$25,②前提!$C$16,0) -> 0 | M15: =IF(10=②前提!$C$25,②前提!$C$16,0) -> 0 | N15: =IF(11=②前提!$C$25,②前提!$C$16,0) -> 0 | O15: =IF(12=②前提!$C$25,②前提!$C$16,0) -> 0 | P15: =SUM(D15:O15) -> 20000000
B16: ＋クルーザー×ワイン事業 | D16: =IF(1=②前提!$C$26,②前提!$C$17,0)+IF(1=②前提!$C$27,②前提!$C$18,0) -> 0 | E16: =IF(2=②前提!$C$26,②前提!$C$17,0)+IF(2=②前提!$C$27,②前提!$C$18,0) -> 0 | F16: =IF(3=②前提!$C$26,②前提!$C$17,0)+IF(3=②前提!$C$27,②前提!$C$18,0) -> 0 | G16: =IF(4=②前提!$C$26,②前提!$C$17,0)+IF(4=②前提!$C$27,②前提!$C$18,0) -> 0 | H16: =IF(5=②前提!$C$26,②前提!$C$17,0)+IF(5=②前提!$C$27,②前提!$C$18,0) -> 0 | I16: =IF(6=②前提!$C$26,②前提!$C$17,0)+IF(6=②前提!$C$27,②前提!$C$18,0) -> 10000000 | J16: =IF(7=②前提!$C$26,②前提!$C$17,0)+IF(7=②前提!$C$27,②前提!$C$18,0) -> 0 | K16: =IF(8=②前提!$C$26,②前提!$C$17,0)+IF(8=②前提!$C$27,②前提!$C$18,0) -> 0 | L16: =IF(9=②前提!$C$26,②前提!$C$17,0)+IF(9=②前提!$C$27,②前提!$C$18,0) -> 0 | M16: =IF(10=②前提!$C$26,②前提!$C$17,0)+IF(10=②前提!$C$27,②前提!$C$18,0) -> 0 | N16: =IF(11=②前提!$C$26,②前提!$C$17,0)+IF(11=②前提!$C$27,②前提!$C$18,0) -> 0 | O16: =IF(12=②前提!$C$26,②前提!$C$17,0)+IF(12=②前提!$C$27,②前提!$C$18,0) -> 10000000 | P16: =SUM(D16:O16) -> 20000000
B17: 売上総利益 合計 | C17: =C10+C11+SUM(C12:C14) -> 32960025 | D17: =D10+D11+SUM(D12:D16) -> 32960025 | E17: =E10+E11+SUM(E12:E16) -> 32960025 | F17: =F10+F11+SUM(F12:F16) -> 32960025 | G17: =G10+G11+SUM(G12:G16) -> 32960025 | H17: =H10+H11+SUM(H12:H16) -> 32960025 | I17: =I10+I11+SUM(I12:I16) -> 62960025 | J17: =J10+J11+SUM(J12:J16) -> 32960025 | K17: =K10+K11+SUM(K12:K16) -> 32960025 | ... O17: =O10+O11+SUM(O12:O16) -> 42960025 | P17: =SUM(D17:O17) -> 4.3552031e+08
B19: 【販売費及び一般管理費】
B20: 役員報酬 | C20: =AVERAGE(④FY2026月次実績!I11:K11) -> 2104000 | D20: =$C$20 -> 2104000 | E20: =$C$20 -> 2104000 | F20: =$C$20 -> 2104000 | G20: =$C$20 -> 2104000 | H20: =$C$20 -> 2104000 | I20: =$C$20 -> 2104000 | J20: =$C$20 -> 2104000 | K20: =$C$20 -> 2104000 | ... O20: =$C$20 -> 2104000 | P20: =SUM(D20:O20) -> 25248000
B21: 従業員給与 | C21: =AVERAGE(④FY2026月次実績!I12:K12) -> 2844602 | D21: =$C$21 -> 2844602 | E21: =$C$21 -> 2844602 | F21: =$C$21 -> 2844602 | G21: =$C$21 -> 2844602 | H21: =$C$21 -> 2844602 | I21: =$C$21 -> 2844602 | J21: =$C$21 -> 2844602 | K21: =$C$21 -> 2844602 | ... O21: =$C$21 -> 2844602 | P21: =SUM(D21:O21) -> 34135224
B22: 雑給 | C22: =AVERAGE(④FY2026月次実績!I13:K13) -> 198075 | D22: =$C$22 -> 198075 | E22: =$C$22 -> 198075 | F22: =$C$22 -> 198075 | G22: =$C$22 -> 198075 | H22: =$C$22 -> 198075 | I22: =$C$22 -> 198075 | J22: =$C$22 -> 198075 | K22: =$C$22 -> 198075 | ... O22: =$C$22 -> 198075 | P22: =SUM(D22:O22) -> 2376900
B23: 法定福利費 | C23: =AVERAGE(④FY2026月次実績!I14:K14) -> 943189.33 | D23: =$C$23 -> 943189.33 | E23: =$C$23 -> 943189.33 | F23: =$C$23 -> 943189.33 | G23: =$C$23 -> 943189.33 | H23: =$C$23 -> 943189.33 | I23: =$C$23 -> 943189.33 | J23: =$C$23 -> 943189.33 | K23: =$C$23 -> 943189.33 | ... O23: =$C$23 -> 943189.33 | P23: =SUM(D23:O23) -> 11318272
B24: 広告宣伝費・販売促進費 | C24: =AVERAGE(④FY2026月次実績!I15:K15) -> 520742.33 | D24: =$C$24 -> 520742.33 | E24: =$C$24 -> 520742.33 | F24: =$C$24 -> 520742.33 | G24: =$C$24 -> 520742.33 | H24: =$C$24 -> 520742.33 | I24: =$C$24 -> 520742.33 | J24: =$C$24 -> 520742.33 | K24: =$C$24 -> 520742.33 | ... O24: =$C$24 -> 520742.33 | P24: =SUM(D24:O24) -> 6248908
B25: 発送配達費 | C25: =AVERAGE(④FY2026月次実績!I16:K16) -> 986309.67 | D25: =$C$25 -> 986309.67 | E25: =$C$25 -> 986309.67 | F25: =$C$25 -> 986309.67 | G25: =$C$25 -> 986309.67 | H25: =$C$25 -> 986309.67 | I25: =$C$25 -> 986309.67 | J25: =$C$25 -> 986309.67 | K25: =$C$25 -> 986309.67 | ... O25: =$C$25 -> 986309.67 | P25: =SUM(D25:O25) -> 11835716
B26: 支払手数料 | C26: =AVERAGE(④FY2026月次実績!I17:K17) -> 3258950 | D26: =$C$26 -> 3258950 | E26: =$C$26 -> 3258950 | F26: =$C$26 -> 3258950 | G26: =$C$26 -> 3258950 | H26: =$C$26 -> 3258950 | I26: =$C$26 -> 3258950 | J26: =$C$26 -> 3258950 | K26: =$C$26 -> 3258950 | ... O26: =$C$26 -> 3258950 | P26: =SUM(D26:O26) -> 39107400
B27: 地代家賃 | C27: =AVERAGE(④FY2026月次実績!I18:K18) -> 3721702.7 | D27: =$C$27 -> 3721702.7 | E27: =$C$27 -> 3721702.7 | F27: =$C$27 -> 3721702.7 | G27: =$C$27 -> 3721702.7 | H27: =$C$27 -> 3721702.7 | I27: =$C$27 -> 3721702.7 | J27: =$C$27 -> 3721702.7 | K27: =$C$27 -> 3721702.7 | ... O27: =$C$27 -> 3721702.7 | P27: =SUM(D27:O27) -> 44660432
B28: 通信交通費 | C28: =AVERAGE(④FY2026月次実績!I19:K19) -> 400027.33 | D28: =$C$28 -> 400027.33 | E28: =$C$28 -> 400027.33 | F28: =$C$28 -> 400027.33 | G28: =$C$28 -> 400027.33 | H28: =$C$28 -> 400027.33 | I28: =$C$28 -> 400027.33 | J28: =$C$28 -> 400027.33 | K28: =$C$28 -> 400027.33 | ... O28: =$C$28 -> 400027.33 | P28: =SUM(D28:O28) -> 4800328
B29: 水道光熱費 | C29: =AVERAGE(④FY2026月次実績!I20:K20) -> 687496.33 | D29: =$C$29 -> 687496.33 | E29: =$C$29 -> 687496.33 | F29: =$C$29 -> 687496.33 | G29: =$C$29 -> 687496.33 | H29: =$C$29 -> 687496.33 | I29: =$C$29 -> 687496.33 | J29: =$C$29 -> 687496.33 | K29: =$C$29 -> 687496.33 | ... O29: =$C$29 -> 687496.33 | P29: =SUM(D29:O29) -> 8249956
B30: 接待交際費 | C30: =AVERAGE(④FY2026月次実績!I21:K21) -> 154132.33 | D30: =$C$30 -> 154132.33 | E30: =$C$30 -> 154132.33 | F30: =$C$30 -> 154132.33 | G30: =$C$30 -> 154132.33 | H30: =$C$30 -> 154132.33 | I30: =$C$30 -> 154132.33 | J30: =$C$30 -> 154132.33 | K30: =$C$30 -> 154132.33 | ... O30: =$C$30 -> 154132.33 | P30: =SUM(D30:O30) -> 1849588
B31: 保険料 | C31: =AVERAGE(④FY2026月次実績!I22:K22) -> 122950.33 | D31: =$C$31 -> 122950.33 | E31: =$C$31 -> 122950.33 | F31: =$C$31 -> 122950.33 | G31: =$C$31 -> 122950.33 | H31: =$C$31 -> 122950.33 | I31: =$C$31 -> 122950.33 | J31: =$C$31 -> 122950.33 | K31: =$C$31 -> 122950.33 | ... O31: =$C$31 -> 122950.33 | P31: =SUM(D31:O31) -> 1475404
B32: 研修採用費 | C32: =AVERAGE(④FY2026月次実績!I23:K23) -> 0 | D32: =$C$32 -> 0 | E32: =$C$32 -> 0 | F32: =$C$32 -> 0 | G32: =$C$32 -> 0 | H32: =$C$32 -> 0 | I32: =$C$32 -> 0 | J32: =$C$32 -> 0 | K32: =$C$32 -> 0 | ... O32: =$C$32 -> 0 | P32: =SUM(D32:O32) -> 0
B33: 備品消耗品費 | C33: =AVERAGE(④FY2026月次実績!I24:K24) -> 246493.67 | D33: =$C$33 -> 246493.67 | E33: =$C$33 -> 246493.67 | F33: =$C$33 -> 246493.67 | G33: =$C$33 -> 246493.67 | H33: =$C$33 -> 246493.67 | I33: =$C$33 -> 246493.67 | J33: =$C$33 -> 246493.67 | K33: =$C$33 -> 246493.67 | ... O33: =$C$33 -> 246493.67 | P33: =SUM(D33:O33) -> 2957924
B34: 管理諸費 | C34: =AVERAGE(④FY2026月次実績!I25:K25) -> 1213002 | D34: =$C$34 -> 1213002 | E34: =$C$34 -> 1213002 | F34: =$C$34 -> 1213002 | G34: =$C$34 -> 1213002 | H34: =$C$34 -> 1213002 | I34: =$C$34 -> 1213002 | J34: =$C$34 -> 1213002 | K34: =$C$34 -> 1213002 | ... O34: =$C$34 -> 1213002 | P34: =SUM(D34:O34) -> 14556024
B35: 清掃費 | C35: =AVERAGE(④FY2026月次実績!I26:K26) -> 0 | D35: =$C$35 -> 0 | E35: =$C$35 -> 0 | F35: =$C$35 -> 0 | G35: =$C$35 -> 0 | H35: =$C$35 -> 0 | I35: =$C$35 -> 0 | J35: =$C$35 -> 0 | K35: =$C$35 -> 0 | ... O35: =$C$35 -> 0 | P35: =SUM(D35:O35) -> 0
B36: 業務委託費 | C36: =AVERAGE(④FY2026月次実績!I27:K27) -> 3250243.3 | D36: =$C$36 -> 3250243.3 | E36: =$C$36 -> 3250243.3 | F36: =$C$36 -> 3250243.3 | G36: =$C$36 -> 3250243.3 | H36: =$C$36 -> 3250243.3 | I36: =$C$36 -> 3250243.3 | J36: =$C$36 -> 3250243.3 | K36: =$C$36 -> 3250243.3 | ... O36: =$C$36 -> 3250243.3 | P36: =SUM(D36:O36) -> 39002920
B37: 会議費 | C37: =AVERAGE(④FY2026月次実績!I28:K28) -> 49855.667 | D37: =$C$37 -> 49855.667 | E37: =$C$37 -> 49855.667 | F37: =$C$37 -> 49855.667 | G37: =$C$37 -> 49855.667 | H37: =$C$37 -> 49855.667 | I37: =$C$37 -> 49855.667 | J37: =$C$37 -> 49855.667 | K37: =$C$37 -> 49855.667 | ... O37: =$C$37 -> 49855.667 | P37: =SUM(D37:O37) -> 598268
B38: 雑費 | C38: =AVERAGE(④FY2026月次実績!I29:K29) -> 6666.6667 | D38: =$C$38 -> 6666.6667 | E38: =$C$38 -> 6666.6667 | F38: =$C$38 -> 6666.6667 | G38: =$C$38 -> 6666.6667 | H38: =$C$38 -> 6666.6667 | I38: =$C$38 -> 6666.6667 | J38: =$C$38 -> 6666.6667 | K38: =$C$38 -> 6666.6667 | ... O38: =$C$38 -> 6666.6667 | P38: =SUM(D38:O38) -> 80000
B39: 租税公課 | C39: =AVERAGE(④FY2026月次実績!I30:K30) -> 394626.67 | D39: =$C$39 -> 394626.67 | E39: =$C$39 -> 394626.67 | F39: =$C$39 -> 394626.67 | G39: =$C$39 -> 394626.67 | H39: =$C$39 -> 394626.67 | I39: =$C$39 -> 394626.67 | J39: =$C$39 -> 394626.67 | K39: =$C$39 -> 394626.67 | ... O39: =$C$39 -> 394626.67 | P39: =SUM(D39:O39) -> 4735520
B40: 諸会費 | C40: =AVERAGE(④FY2026月次実績!I31:K31) -> 0 | D40: =$C$40 -> 0 | E40: =$C$40 -> 0 | F40: =$C$40 -> 0 | G40: =$C$40 -> 0 | H40: =$C$40 -> 0 | I40: =$C$40 -> 0 | J40: =$C$40 -> 0 | K40: =$C$40 -> 0 | ... O40: =$C$40 -> 0 | P40: =SUM(D40:O40) -> 0
B41: 減価償却費 | C41: =AVERAGE(④FY2026月次実績!I32:K32) -> 3637873 | D41: =$C$41 -> 3637873 | E41: =$C$41 -> 3637873 | F41: =$C$41 -> 3637873 | G41: =$C$41 -> 3637873 | H41: =$C$41 -> 3637873 | I41: =$C$41 -> 3637873 | J41: =$C$41 -> 3637873 | K41: =$C$41 -> 3637873 | ... O41: =$C$41 -> 3637873 | P41: =SUM(D41:O41) -> 43654476
B42: 倉庫＆保管・移設代 | C42: =AVERAGE(④FY2026月次実績!I33:K33) -> 272483.67 | D42: =$C$42 -> 272483.67 | E42: =$C$42 -> 272483.67 | F42: =$C$42 -> 272483.67 | G42: =$C$42 -> 272483.67 | H42: =$C$42 -> 272483.67 | I42: =$C$42 -> 272483.67 | J42: =$C$42 -> 272483.67 | K42: =$C$42 -> 272483.67 | ... O42: =$C$42 -> 272483.67 | P42: =SUM(D42:O42) -> 3269804
...

Sheet ⑤利益ブリッジ
B1: FY2026 → FY2027 営業利益ブリッジ（プランD）
B2: 単位：円（税別）
B4: 項目 | C4: 増減 | D4: 累計 | E4: 内容
B5: FY2026 営業利益（見込） | C5: -114793431 | D5: =C5 -> -114793431 | E5: 現行計画の今期着地見込
B6: ① 既存事業 粗利の減少（横ばい実力値ベース） | C6: =②前提!$C$7*12-229139405 -> -28537477 | D6: =D5+C6 -> -143330908 | E6: FY2026は2025/11・2026/09の大口を含む。撤退後の4-6月実力値ベースでは減少
B7: ② 販管費の削減 | C7: =343932836-②前提!$C$8*12 -> 43771772 | D7: =D6+C7 -> -99559136 | E7: 不採算3店舗の撤退＋固定費削減。10-3月平均比で月▲8.58百万円
B8: ③ 差額売上の粗利（売上平均への回復） | C8: =②前提!$C$57 -> 1.0241838e+08 | D8: =D7+C8 -> 2859241.6 | E8: 既存事業を前期・今期の売上平均730.5百万円に戻す。差額341.4百万円×粗利率30%
B9: ④ 上乗せ案件（営業収益） | C9: =②前提!$C$20 -> 132500000 | D9: =D8+C9 -> 1.3535924e+08 | E9: コンサルティング料92.5＋M&A仲介20＋クルーザー×ワイン事業20
B10: FY2027 営業利益（プランD） | D10: =D9 -> 1.3535924e+08 | E10: ①〜④の合計
B12: ⑤ 私募＋オークションの上積み（プランE） | C12: =②前提!$C$64-②前提!$C$57 -> 90000000 | D12: =D10+C12 -> 2.2535924e+08 | E12: 追加売上300百万円×粗利率30%＝90百万円
B13: FY2027 営業利益（プランE） | D13: =D12 -> 2.2535924e+08
B15: 【横ばい実力値からの差額売上】
B16: プランD（粗利率30%） | C16: =①サマリー!C23 -> 341394592 | D16: =①サマリー!D23 -> 0.32025759 | E16: 新規顧客売上計画1,066百万円に対する比率
B17: プランE（粗利率30%） | C17: =①サマリー!C24 -> 641394592 | D17: =①サマリー!D24 -> 0.60168348 | E17: 新規顧客売上計画1,066百万円に対する比率

Sheet ⑥ワイン仕入・在庫計画
B1: ワイン仕入・自社在庫計画（FY2027）
B2: ワイン仕入は「売上原価（出庫）＋在庫増減」がキャッシュアウト。PLに現れない在庫積み増しが資金繰りの最大論点。
B4: 【1】自社在庫（簿価）の実績推移 単位：百万円
B5: 時点 | C5: 2024/12末 | D5: 2025/07末 | E5: 2025/09末 | F5: 2025/12末 | G5: 2026/03末
B6: 自社在庫 簿価 | C6: 560 | D6: 470 | E6: 480 | F6: 530 | G6: 620
B7: 2025/09末→2026/03末の増加 | C7: =G6-E6 -> 140 | D7: 百万円 / 6か月 | E7: =C7/6 -> 23.333333 | F7: 百万円/月のキャッシュアウト
B8: 出典：2026年7月度 取締役会資料「ワイン預かり残高推移KPI」（税抜・簿価）
B10: 【2】FY2027 仕入・在庫計画（税抜）
B11: 科目 | C11: 月次ベース | D11: 2026/10 | E11: 2026/11 | F11: 2026/12 | G11: 2027/01 | H11: 2027/02 | I11: 2027/03 | J11: 2027/04 | K11: 2027/05 | L11: 2027/06 | M11: 2027/07 | N11: 2027/08 | O11: 2027/09 | P11: 通期
B12: 期首在庫 | C12: 420000000 | Q12: 2026/03末実績620百万円 −2026/09の在庫販売200百万円＝420百万円。2026/04-08の増減は横ばいと仮定。
B13: 在庫方針（月次 増減額） | C13: 0 | Q13: 0＝在庫横ばい（仕入＝売上原価）。積み増す場合は月額を入力。
B14: スポット大口仕入 | D14: 0 | E14: 0 | F14: 0 | G14: 0 | H14: 0 | I14: 0 | J14: 0 | K14: 0 | L14: 0 | M14: 0 | N14: 0 | O14: 0 | P14: =SUM(D14:O14) -> 0 | Q14: 野村ユニソン等のロット仕入。発生月に入力。
B15: プリムール等 前払仕入 | D15: 0 | E15: 0 | F15: 0 | G15: 0 | H15: 0 | I15: 0 | J15: 0 | K15: 0 | L15: 0 | M15: 0 | N15: 0 | O15: 0 | P15: =SUM(D15:O15) -> 0 | Q15: 引渡し前の前払。発生月に入力。
B16: 通常仕入 | D16: =IF(②前提!$C$31=2,②前提!$C$32/12,D18) -> 34922201 | E16: =IF(②前提!$C$31=2,②前提!$C$32/12,E18) -> 34922201 | F16: =IF(②前提!$C$31=2,②前提!$C$32/12,F18) -> 34922201 | G16: =IF(②前提!$C$31=2,②前提!$C$32/12,G18) -> 34922201 | H16: =IF(②前提!$C$31=2,②前提!$C$32/12,H18) -> 34922201 | I16: =IF(②前提!$C$31=2,②前提!$C$32/12,I18) -> 34922201 | J16: =IF(②前提!$C$31=2,②前提!$C$32/12,J18) -> 34922201 | K16: =IF(②前提!$C$31=2,②前提!$C$32/12,K18) -> 34922201 | ... O16: =IF(②前提!$C$31=2,②前提!$C$32/12,O18) -> 34922201 | P16: =SUM(D16:O16) -> 419066414 | Q16: 方針1＝売上原価と同額（在庫横ばい）／方針2＝FY2026の年間仕入額を12等分。
B17: 仕入 合計（入庫） | D17: =D16+$C$13+D14+D15 -> 34922201 | E17: =E16+$C$13+E14+E15 -> 34922201 | F17: =F16+$C$13+F14+F15 -> 34922201 | G17: =G16+$C$13+G14+G15 -> 34922201 | H17: =H16+$C$13+H14+H15 -> 34922201 | I17: =I16+$C$13+I14+I15 -> 34922201 | J17: =J16+$C$13+J14+J15 -> 34922201 | K17: =K16+$C$13+K14+K15 -> 34922201 | ... O17: =O16+$C$13+O14+O15 -> 34922201 | P17: =SUM(D17:O17) -> 419066414
B18: 売上原価（出庫） | D18: =③FY2027月次推移!D9 -> 35626255 | E18: =③FY2027月次推移!E9 -> 35626255 | F18: =③FY2027月次推移!F9 -> 35626255 | G18: =③FY2027月次推移!G9 -> 35626255 | H18: =③FY2027月次推移!H9 -> 35626255 | I18: =③FY2027月次推移!I9 -> 35626255 | J18: =③FY2027月次推移!J9 -> 35626255 | K18: =③FY2027月次推移!K9 -> 35626255 | L18: =③FY2027月次推移!L9 -> 35626255 | M18: =③FY2027月次推移!M9 -> 35626255 | N18: =③FY2027月次推移!N9 -> 35626255 | O18: =③FY2027月次推移!O9 -> 35626255 | P18: =SUM(D18:O18) -> 4.2751505e+08
B19: 期末在庫 | D19: =$C$12+D17-D18 -> 4.1929595e+08 | E19: =D19+E17-E18 -> 4.1859189e+08 | F19: =E19+F17-F18 -> 4.1788784e+08 | G19: =F19+G17-G18 -> 4.1718379e+08 | H19: =G19+H17-H18 -> 4.1647973e+08 | I19: =H19+I17-I18 -> 4.1577568e+08 | J19: =I19+J17-J18 -> 4.1507163e+08 | K19: =J19+K17-K18 -> 4.1436757e+08 | L19: =K19+L17-L18 -> 4.1366352e+08 | ... O19: =N19+O17-O18 -> 4.1155136e+08 | P19: =O19 -> 4.1155136e+08
B21: ※仕入方針2（FY2026と同額419.1百万円）では、売上原価との差額が在庫増となり、その分がキャッシュアウトになります。
B22: ※スポット大口仕入・プリムール前払は、売上計上より先に支払が発生するため、資金繰り上は最も注意を要する項目。
B23: ※2026/09に在庫200百万円を販売（削減）し、その代金をみずほ銀行への融資返済200百万円に充当する前提。期首在庫はその後の残高。

Sheet ⑦FY2027資金繰り表
B1: FY2027（2026年10月-2027年9月）月次資金繰り表
B2: 単位：円（税込ベース） プランD（②前提の「シナリオ選択」に連動）／ワイン仕入FY2026同額の前提 青字＝入力セル・緑字＝他シートからのリンク
B4: 【前提】
B5: 期首現預金（2026/09末） | C5: 30000000 | D5: 2026/09末にみずほ銀行へ200百万円を返済した後のキャッシュポジション（貴社ご指定）。
B6: 消費税率 | C6: =②前提!$C$36 -> 0.1 | D6: ②前提の【6】消費税の算定から自動参照
B7: 売上 回収サイト（か月） | C7: 1 | D7: 売掛金回転32.2日（2025/09末BS）より1.06か月→1.0か月と設定。
B8: 仕入 支払サイト（か月） | C8: 1 | D8: 買掛金回転23.5日（2025/09末BS）より0.77か月→1.0か月と設定。
B9: 長期借入金 約定返済（月額） | C9: 2662179 | D9: ★要差替え。長期借入423,623,000円−みずほ一括返済200,000,000円＝223,623,000円を7年均等返済と仮定した暫定値。
B10: 短期借入金 純増減（月額） | C10: 0 | D10: 短期借入162,440,980円は同額借換（継続）を前提。
B12: 科目 | C12: 月次ベース | D12: 2026/10 | E12: 2026/11 | F12: 2026/12 | G12: 2027/01 | H12: 2027/02 | I12: 2027/03 | J12: 2027/04 | K12: 2027/05 | L12: 2027/06 | M12: 2027/07 | N12: 2027/08 | O12: 2027/09 | P12: 通期
B13: 【営業収入】
B14: 売上入金（税込） | D14: =③FY2027月次推移!D8*(1+$C$6) -> 66965741 | E14: =③FY2027月次推移!E8*(1+$C$6) -> 66965741 | F14: =③FY2027月次推移!F8*(1+$C$6) -> 66965741 | G14: =③FY2027月次推移!G8*(1+$C$6) -> 66965741 | H14: =③FY2027月次推移!H8*(1+$C$6) -> 66965741 | I14: =③FY2027月次推移!I8*(1+$C$6) -> 66965741 | J14: =③FY2027月次推移!J8*(1+$C$6) -> 66965741 | K14: =③FY2027月次推移!K8*(1+$C$6) -> 66965741 | L14: =③FY2027月次推移!L8*(1+$C$6) -> 66965741 | M14: =③FY2027月次推移!M8*(1+$C$6) -> 66965741 | N14: =③FY2027月次推移!N8*(1+$C$6) -> 66965741 | O14: =③FY2027月次推移!O8*(1+$C$6) -> 66965741 | P14: =SUM(D14:O14) -> 803588896
B15: コンサルティング料 入金（税込） | D15: =SUM(③FY2027月次推移!D12:D14)*(1+$C$6) -> 8479166.7 | E15: =SUM(③FY2027月次推移!E12:E14)*(1+$C$6) -> 8479166.7 | F15: =SUM(③FY2027月次推移!F12:F14)*(1+$C$6) -> 8479166.7 | G15: =SUM(③FY2027月次推移!G12:G14)*(1+$C$6) -> 8479166.7 | H15: =SUM(③FY2027月次推移!H12:H14)*(1+$C$6) -> 8479166.7 | I15: =SUM(③FY2027月次推移!I12:I14)*(1+$C$6) -> 8479166.7 | J15: =SUM(③FY2027月次推移!J12:J14)*(1+$C$6) -> 8479166.7 | K15: =SUM(③FY2027月次推移!K12:K14)*(1+$C$6) -> 8479166.7 | L15: =SUM(③FY2027月次推移!L12:L14)*(1+$C$6) -> 8479166.7 | M15: =SUM(③FY2027月次推移!M12:M14)*(1+$C$6) -> 8479166.7 | N15: =SUM(③FY2027月次推移!N12:N14)*(1+$C$6) -> 8479166.7 | O15: =SUM(③FY2027月次推移!O12:O14)*(1+$C$6) -> 8479166.7 | P15: =SUM(D15:O15) -> 101750000
B16: M&A仲介 入金（税込） | D16: =③FY2027月次推移!D15*(1+$C$6) -> 0 | E16: =③FY2027月次推移!E15*(1+$C$6) -> 0 | F16: =③FY2027月次推移!F15*(1+$C$6) -> 0 | G16: =③FY2027月次推移!G15*(1+$C$6) -> 0 | H16: =③FY2027月次推移!H15*(1+$C$6) -> 0 | I16: =③FY2027月次推移!I15*(1+$C$6) -> 22000000 | J16: =③FY2027月次推移!J15*(1+$C$6) -> 0 | K16: =③FY2027月次推移!K15*(1+$C$6) -> 0 | L16: =③FY2027月次推移!L15*(1+$C$6) -> 0 | M16: =③FY2027月次推移!M15*(1+$C$6) -> 0 | N16: =③FY2027月次推移!N15*(1+$C$6) -> 0 | O16: =③FY2027月次推移!O15*(1+$C$6) -> 0 | P16: =SUM(D16:O16) -> 22000000
B17: 前期末売掛金 回収 | D17: 0 | E17: 0 | F17: 0 | G17: 0 | H17: 0 | I17: 0 | J17: 0 | K17: 0 | L17: 0 | M17: 0 | N17: 0 | O17: 0 | P17: =SUM(D17:O17) -> 0 | Q17: 2026/09の在庫販売200百万円の代金回収およびみずほ銀行への返済は2026/09末までに完了済み（期首現預金30百万円に反映）。
B18: クルーザー×ワイン事業 入金（税込） | D18: =③FY2027月次推移!D16*(1+$C$6) -> 0 | E18: =③FY2027月次推移!E16*(1+$C$6) -> 0 | F18: =③FY2027月次推移!F16*(1+$C$6) -> 0 | G18: =③FY2027月次推移!G16*(1+$C$6) -> 0 | H18: =③FY2027月次推移!H16*(1+$C$6) -> 0 | I18: =③FY2027月次推移!I16*(1+$C$6) -> 11000000 | J18: =③FY2027月次推移!J16*(1+$C$6) -> 0 | K18: =③FY2027月次推移!K16*(1+$C$6) -> 0 | L18: =③FY2027月次推移!L16*(1+$C$6) -> 0 | M18: =③FY2027月次推移!M16*(1+$C$6) -> 0 | N18: =③FY2027月次推移!N16*(1+$C$6) -> 0 | O18: =③FY2027月次推移!O16*(1+$C$6) -> 11000000 | P18: =SUM(D18:O18) -> 22000000 | Q18: 新規クルーザー事業。2027/03と2027/09に各10百万円。課税取引として税込入金と仮定。
B19: 営業収入 計 | D19: =SUM(D14:D18) -> 75444908 | E19: =SUM(E14:E18) -> 75444908 | F19: =SUM(F14:F18) -> 75444908 | G19: =SUM(G14:G18) -> 75444908 | H19: =SUM(H14:H18) -> 75444908 | I19: =SUM(I14:I18) -> 108444908 | J19: =SUM(J14:J18) -> 75444908 | K19: =SUM(K14:K18) -> 75444908 | ... O19: =SUM(O14:O18) -> 86444908 | P19: =SUM(D19:O19) -> 949338896
B21: 【営業支出】
B22: ワイン仕入 支払（税込） | D22: =⑥ワイン仕入・在庫計画!D17*(1+$C$6) -> 38414421 | E22: =⑥ワイン仕入・在庫計画!D17*(1+$C$6) -> 38414421 | F22: =⑥ワイン仕入・在庫計画!E17*(1+$C$6) -> 38414421 | G22: =⑥ワイン仕入・在庫計画!F17*(1+$C$6) -> 38414421 | H22: =⑥ワイン仕入・在庫計画!G17*(1+$C$6) -> 38414421 | I22: =⑥ワイン仕入・在庫計画!H17*(1+$C$6) -> 38414421 | J22: =⑥ワイン仕入・在庫計画!I17*(1+$C$6) -> 38414421 | K22: =⑥ワイン仕入・在庫計画!J17*(1+$C$6) -> 38414421 | L22: =⑥ワイン仕入・在庫計画!K17*(1+$C$6) -> 38414421 | ... O22: =⑥ワイン仕入・在庫計画!N17*(1+$C$6) -> 38414421 | P22: =SUM(D22:O22) -> 4.6097306e+08
B23: 人件費（役員報酬・給与・雑給・法定福利） | D23: =AVERAGE(④FY2026月次実績!I11:K11)+AVERAGE(④FY2026月次実績!I12:K12)+AVERAGE(④FY2026月次実績!I13:K13)+AVERAGE(④FY2026月次実績!I14:K14) -> 6089866.3 | E23: =AVERAGE(④FY2026月次実績!I11:K11)+AVERAGE(④FY2026月次実績!I12:K12)+AVERAGE(④FY2026月次実績!I13:K13)+AVERAGE(④FY2026月次実績!I14:K14) -> 6089866.3 | F23: =AVERAGE(④FY2026月次実績!I11:K11)+AVERAGE(④FY2026月次実績!I12:K12)+AVERAGE(④FY2026月次実績!I13:K13)+AVERAGE(④FY2026月次実績!I14:K14) -> 6089866.3 | G23: =AVERAGE(④FY2026月次実績!I11:K11)+AVERAGE(④FY2026月次実績!I12:K12)+AVERAGE(④FY2026月次実績!I13:K13)+AVERAGE(④FY2026月次実績!I14:K14) -> 6089866.3 | H23: =AVERAGE(④FY2026月次実績!I11:K11)+AVERAGE(④FY2026月次実績!I12:K12)+AVERAGE(④FY2026月次実績!I13:K13)+AVERAGE(④FY2026月次実績!I14:K14) -> 6089866.3 | I23: =AVERAGE(④FY2026月次実績!I11:K11)+AVERAGE(④FY2026月次実績!I12:K12)+AVERAGE(④FY2026月次実績!I13:K13)+AVERAGE(④FY2026月次実績!I14:K14) -> 6089866.3 | J23: =AVERAGE(④FY2026月次実績!I11:K11)+AVERAGE(④FY2026月次実績!I12:K12)+AVERAGE(④FY2026月次実績!I13:K13)+AVERAGE(④FY2026月次実績!I14:K14) -> 6089866.3 | K23: =AVERAGE(④FY2026月次実績!I11:K11)+AVERAGE(④FY2026月次実績!I12:K12)+AVERAGE(④FY2026月次実績!I13:K13)+AVERAGE(④FY2026月次実績!I14:K14) -> 6089866.3 | L23: =AVERAGE(④FY2026月次実績!I11:K11)+AVERAGE(④FY2026月次実績!I12:K12)+AVERAGE(④FY2026月次実績!I13:K13)+AVERAGE(④FY2026月次実績!I14:K14) -> 6089866.3 | M23: =AVERAGE(④FY2026月次実績!I11:K11)+AVERAGE(④FY2026月次実績!I12:K12)+AVERAGE(④FY2026月次実績!I13:K13)+AVERAGE(④FY2026月次実績!I14:K14) -> 6089866.3 | N23: =AVERAGE(④FY2026月次実績!I11:K11)+AVERAGE(④FY2026月次実績!I12:K12)+AVERAGE(④FY2026月次実績!I13:K13)+AVERAGE(④FY2026月次実績!I14:K14) -> 6089866.3 | O23: =AVERAGE(④FY2026月次実績!I11:K11)+AVERAGE(④FY2026月次実績!I12:K12)+AVERAGE(④FY2026月次実績!I13:K13)+AVERAGE(④FY2026月次実績!I14:K14) -> 6089866.3 | P23: =SUM(D23:O23) -> 73078396
B24: その他販管費（税込・減価償却除く） | D24: =((③FY2027月次推移!D43-AVERAGE(④FY2026月次実績!I32:K32)-(AVERAGE(④FY2026月次実績!I11:K11)+AVERAGE(④FY2026月次実績!I12:K12)+AVERAGE(④FY2026月次実績!I13:K13)+AVERAGE(④FY2026月次実績!I14:K14))-(AVERAGE(④FY2026月次実績!I30:K30)+AVERAGE(④FY2026月次実績!I22:K22)))*(1+$C$6))+(AVERAGE(④FY2026月次実績!I30:K30)+AVERAGE(④FY2026月次実績!I22:K22)) -> 16762493 | E24: =((③FY2027月次推移!E43-AVERAGE(④FY2026月次実績!I32:K32)-(AVERAGE(④FY2026月次実績!I11:K11)+AVERAGE(④FY2026月次実績!I12:K12)+AVERAGE(④FY2026月次実績!I13:K13)+AVERAGE(④FY2026月次実績!I14:K14))-(AVERAGE(④FY2026月次実績!I30:K30)+AVERAGE(④FY2026月次実績!I22:K22)))*(1+$C$6))+(AVERAGE(④FY2026月次実績!I30:K30)+AVERAGE(④FY2026月次実績!I22:K22)) -> 16762493 | F24: =((③FY2027月次推移!F43-AVERAGE(④FY2026月次実績!I32:K32)-(AVERAGE(④FY2026月次実績!I11:K11)+AVERAGE(④FY2026月次実績!I12:K12)+AVERAGE(④FY2026月次実績!I13:K13)+AVERAGE(④FY2026月次実績!I14:K14))-(AVERAGE(④FY2026月次実績!I30:K30)+AVERAGE(④FY2026月次実績!I22:K22)))*(1+$C$6))+(AVERAGE(④FY2026月次実績!I30:K30)+AVERAGE(④FY2026月次実績!I22:K22)) -> 16762493 | G24: =((③FY2027月次推移!G43-AVERAGE(④FY2026月次実績!I32:K32)-(AVERAGE(④FY2026月次実績!I11:K11)+AVERAGE(④FY2026月次実績!I12:K12)+AVERAGE(④FY2026月次実績!I13:K13)+AVERAGE(④FY2026月次実績!I14:K14))-(AVERAGE(④FY2026月次実績!I30:K30)+AVERAGE(④FY2026月次実績!I22:K22)))*(1+$C$6))+(AVERAGE(④FY2026月次実績!I30:K30)+AVERAGE(④FY2026月次実績!I22:K22)) -> 16762493 | H24: =((③FY2027月次推移!H43-AVERAGE(④FY2026月次実績!I32:K32)-(AVERAGE(④FY2026月次実績!I11:K11)+AVERAGE(④FY2026月次実績!I12:K12)+AVERAGE(④FY2026月次実績!I13:K13)+AVERAGE(④FY2026月次実績!I14:K14))-(AVERAGE(④FY2026月次実績!I30:K30)+AVERAGE(④FY2026月次実績!I22:K22)))*(1+$C$6))+(AVERAGE(④FY2026月次実績!I30:K30)+AVERAGE(④FY2026月次実績!I22:K22)) -> 16762493 | I24: =((③FY2027月次推移!I43-AVERAGE(④FY2026月次実績!I32:K32)-(AVERAGE(④FY2026月次実績!I11:K11)+AVERAGE(④FY2026月次実績!I12:K12)+AVERAGE(④FY2026月次実績!I13:K13)+AVERAGE(④FY2026月次実績!I14:K14))-(AVERAGE(④FY2026月次実績!I30:K30)+AVERAGE(④FY2026月次実績!I22:K22)))*(1+$C$6))+(AVERAGE(④FY2026月次実績!I30:K30)+AVERAGE(④FY2026月次実績!I22:K22)) -> 16762493 | J24: =((③FY2027月次推移!J43-AVERAGE(④FY2026月次実績!I32:K32)-(AVERAGE(④FY2026月次実績!I11:K11)+AVERAGE(④FY2026月次実績!I12:K12)+AVERAGE(④FY2026月次実績!I13:K13)+AVERAGE(④FY2026月次実績!I14:K14))-(AVERAGE(④FY2026月次実績!I30:K30)+AVERAGE(④FY2026月次実績!I22:K22)))*(1+$C$6))+(AVERAGE(④FY2026月次実績!I30:K30)+AVERAGE(④FY2026月次実績!I22:K22)) -> 16762493 | K24: =((③FY2027月次推移!K43-AVERAGE(④FY2026月次実績!I32:K32)-(AVERAGE(④FY2026月次実績!I11:K11)+AVERAGE(④FY2026月次実績!I12:K12)+AVERAGE(④FY2026月次実績!I13:K13)+AVERAGE(④FY2026月次実績!I14:K14))-(AVERAGE(④FY2026月次実績!I30:K30)+AVERAGE(④FY2026月次実績!I22:K22)))*(1+$C$6))+(AVERAGE(④FY2026月次実績!I30:K30)+AVERAGE(④FY2026月次実績!I22:K22)) -> 16762493 | L24: =((③FY2027月次推移!L43-AVERAGE(④FY2026月次実績!I32:K32)-(AVERAGE(④FY2026月次実績!I11:K11)+AVERAGE(④FY2026月次実績!I12:K12)+AVERAGE(④FY2026月次実績!I13:K13)+AVERAGE(④FY2026月次実績!I14:K14))-(AVERAGE(④FY2026月次実績!I30:K30)+AVERAGE(④FY2026月次実績!I22:K22)))*(1+$C$6))+(AVERAGE(④FY2026月次実績!I30:K30)+AVERAGE(④FY2026月次実績!I22:K22)) -> 16762493 | M24: =((③FY2027月次推移!M43-AVERAGE(④FY2026月次実績!I32:K32)-(AVERAGE(④FY2026月次実績!I11:K11)+AVERAGE(④FY2026月次実績!I12:K12)+AVERAGE(④FY2026月次実績!I13:K13)+AVERAGE(④FY2026月次実績!I14:K14))-(AVERAGE(④FY2026月次実績!I30:K30)+AVERAGE(④FY2026月次実績!I22:K22)))*(1+$C$6))+(AVERAGE(④FY2026月次実績!I30:K30)+AVERAGE(④FY2026月次実績!I22:K22)) -> 16762493 | N24: =((③FY2027月次推移!N43-AVERAGE(④FY2026月次実績!I32:K32)-(AVERAGE(④FY2026月次実績!I11:K11)+AVERAGE(④FY2026月次実績!I12:K12)+AVERAGE(④FY2026月次実績!I13:K13)+AVERAGE(④FY2026月次実績!I14:K14))-(AVERAGE(④FY2026月次実績!I30:K30)+AVERAGE(④FY2026月次実績!I22:K22)))*(1+$C$6))+(AVERAGE(④FY2026月次実績!I30:K30)+AVERAGE(④FY2026月次実績!I22:K22)) -> 16762493 | O24: =((③FY2027月次推移!O43-AVERAGE(④FY2026月次実績!I32:K32)-(AVERAGE(④FY2026月次実績!I11:K11)+AVERAGE(④FY2026月次実績!I12:K12)+AVERAGE(④FY2026月次実績!I13:K13)+AVERAGE(④FY2026月次実績!I14:K14))-(AVERAGE(④FY2026月次実績!I30:K30)+AVERAGE(④FY2026月次実績!I22:K22)))*(1+$C$6))+(AVERAGE(④FY2026月次実績!I30:K30)+AVERAGE(④FY2026月次実績!I22:K22)) -> 16762493 | P24: =SUM(D24:O24) -> 2.0114992e+08
B25: 支払利息 | D25: =③FY2027月次推移!D48 -> 1250000 | E25: =③FY2027月次推移!E48 -> 1250000 | F25: =③FY2027月次推移!F48 -> 1250000 | G25: =③FY2027月次推移!G48 -> 1250000 | H25: =③FY2027月次推移!H48 -> 1250000 | I25: =③FY2027月次推移!I48 -> 1250000 | J25: =③FY2027月次推移!J48 -> 1250000 | K25: =③FY2027月次推移!K48 -> 1250000 | L25: =③FY2027月次推移!L48 -> 1250000 | M25: =③FY2027月次推移!M48 -> 1250000 | N25: =③FY2027月次推移!N48 -> 1250000 | O25: =③FY2027月次推移!O48 -> 1250000 | P25: =SUM(D25:O25) -> 15000000
B26: 消費税 納付 | D26: 0 | E26: =②前提!$C$44 -> 3554509.1 | F26: 0 | G26: 0 | H26: =②前提!$C$45 -> 2013627.3 | I26: 0 | J26: 0 | K26: =②前提!$C$45 -> 2013627.3 | L26: 0 | M26: 0 | N26: =②前提!$C$45 -> 2013627.3 | O26: 0 | P26: =SUM(D26:O26) -> 9595390.9 | Q26: ②前提【6】の算定結果を参照。2026/11＝FY2026分の確定納付、2027/02・05・08＝当期の中間納付（年3回）。
B27: 法人税等（均等割） | D27: 0 | E27: 463105 | F27: 0 | G27: 0 | H27: 0 | I27: 0 | J27: 0 | K27: 0 | L27: 0 | M27: 0 | N27: 0 | O27: 0 | P27: =SUM(D27:O27) -> 463105
B28: 営業支出 計 | D28: =SUM(D22:D27) -> 62516781 | E28: =SUM(E22:E27) -> 66534395 | F28: =SUM(F22:F27) -> 62516781 | G28: =SUM(G22:G27) -> 62516781 | H28: =SUM(H22:H27) -> 64530408 | I28: =SUM(I22:I27) -> 62516781 | J28: =SUM(J22:J27) -> 62516781 | K28: =SUM(K22:K27) -> 64530408 | ... O28: =SUM(O22:O27) -> 62516781 | P28: =SUM(D28:O28) -> 7.6025987e+08
B29: 経常収支 | D29: =D19-D28 -> 12928127 | E29: =E19-E28 -> 8910513.1 | F29: =F19-F28 -> 12928127 | G29: =G19-G28 -> 12928127 | H29: =H19-H28 -> 10914500 | I29: =I19-I28 -> 45928127 | J29: =J19-J28 -> 12928127 | K29: =K19-K28 -> 10914500 | ... O29: =O19-O28 -> 23928127 | P29: =SUM(D29:O29) -> 1.8907903e+08
B31: 【財務収支】
B32: 長期借入金 約定返済 | D32: =-$C$9 -> -2662179 | E32: =-$C$9 -> -2662179 | F32: =-$C$9 -> -2662179 | G32: =-$C$9 -> -2662179 | H32: =-$C$9 -> -2662179 | I32: =-$C$9 -> -2662179 | J32: =-$C$9 -> -2662179 | K32: =-$C$9 -> -2662179 | ... O32: =-$C$9 -> -2662179 | P32: =SUM(D32:O32) -> -31946148
B33: 短期借入金 純増減 | D33: =$C$10 -> 0 | E33: =$C$10 -> 0 | F33: =$C$10 -> 0 | G33: =$C$10 -> 0 | H33: =$C$10 -> 0 | I33: =$C$10 -> 0 | J33: =$C$10 -> 0 | K33: =$C$10 -> 0 | ... O33: =$C$10 -> 0 | P33: =SUM(D33:O33) -> 0
B34: 新規調達（借入・増資） | D34: 0 | E34: 0 | F34: 0 | G34: 0 | H34: 0 | I34: 0 | J34: 0 | K34: 0 | L34: 0 | M34: 0 | N34: 0 | O34: 0 | P34: =SUM(D34:O34) -> 0
B35: みずほ銀行 融資返済 | D35: 0 | E35: 0 | F35: 0 | G35: 0 | H35: 0 | I35: 0 | J35: 0 | K35: 0 | L35: 0 | M35: 0 | N35: 0 | O35: 0 | P35: =SUM(D35:O35) -> 0 | Q35: 2026/09末に200百万円を返済済みのためFY2027には計上しない。
B36: 財務収支 計 | D36: =SUM(D32:D35) -> -2662179 | E36: =SUM(E32:E35) -> -2662179 | F36: =SUM(F32:F35) -> -2662179 | G36: =SUM(G32:G35) -> -2662179 | H36: =SUM(H32:H35) -> -2662179 | I36: =SUM(I32:I35) -> -2662179 | J36: =SUM(J32:J35) -> -2662179 | K36: =SUM(K32:K35) -> -2662179 | ... O36: =SUM(O32:O35) -> -2662179 | P36: =SUM(D36:O36) -> -31946148
B38: 当月収支 | D38: =D29+D36 -> 10265948 | E38: =E29+E36 -> 6248334 | F38: =F29+F36 -> 10265948 | G38: =G29+G36 -> 10265948 | H38: =H29+H36 -> 8252320.9 | I38: =I29+I36 -> 43265948 | J38: =J29+J36 -> 10265948 | K38: =K29+K36 -> 8252320.9 | ... O38: =O29+O36 -> 21265948 | P38: =SUM(D38:O38) -> 1.5713288e+08
B39: 前月繰越 現預金 | D39: =$C$5 -> 30000000 | E39: =D40 -> 40265948 | F39: =E40 -> 46514282 | G39: =F40 -> 56780230 | H39: =G40 -> 67046178 | I39: =H40 -> 75298499 | J39: =I40 -> 1.1856445e+08 | K39: =J40 -> 1.288304e+08 | L39: =K40 -> 1.3708272e+08 | ... O39: =N40 -> 1.6586693e+08
B40: 翌月繰越 現預金 | D40: =D39+D38 -> 40265948 | E40: =E39+E38 -> 46514282 | F40: =F39+F38 -> 56780230 | G40: =G39+G38 -> 67046178 | H40: =H39+H38 -> 75298499 | I40: =I39+I38 -> 1.1856445e+08 | J40: =J39+J38 -> 1.288304e+08 | K40: =K39+K38 -> 1.3708272e+08 | ... O40: =O39+O38 -> 1.8713288e+08 | P40: =O40 -> 1.8713288e+08
B41: 資金不足額（マイナス時） | D41: =IF(D40<0,D40,0) -> 0 | E41: =IF(E40<0,E40,0) -> 0 | F41: =IF(F40<0,F40,0) -> 0 | G41: =IF(G40<0,G40,0) -> 0 | H41: =IF(H40<0,H40,0) -> 0 | I41: =IF(I40<0,I40,0) -> 0 | J41: =IF(J40<0,J40,0) -> 0 | K41: =IF(K40<0,K40,0) -> 0 | ... O41: =IF(O40<0,O40,0) -> 0 | P41: =MIN(D41:O41) -> 0 | Q41: 通期列＝最大不足額（必要調達額の下限）
B43: ※売上・仕入とも回収／支払サイト1.0か月。既存事業の売上は横ばい前提のため、月ズレの影響は通期では相殺されます。
B44: ※ワイン仕入の支払は前月仕入額を当月に支払う前提（⑥シートで仕入月を入力すると、翌月に資金流出として反映されます）。
B45: ※減価償却費（月3.6百万円）は資金支出を伴わないため、営業支出から除外しています。
B46: ※消費税納付・法人税等は暫定値です。税理士確定額に差し替えてください。
...
