Workbook

Sheet ダッシュボード
A1: WineBank ワインマイル｜3か年PL ダッシュボード
A2: 成功報酬は未実現のため経常利益と分けて表示。単位：万円
A4: 3年末 預かり資産 | C4: 3年末 会員数 | E4: 3年累計 売上高 | G4: 3年累計 経常利益
A5: =会員・預かり資産!D28 -> 40200 | C5: =会員・預かり資産!D22 -> 192 | E5: =損益計算書!E9 -> 42423 | G5: =損益計算書!E28 -> 9469.9522
A7: 3年累計 経済利益（成功報酬込） | C7: 発行1マイル 当社期待原価 | E7: ストック利幅（成功報酬前） | G7: ストック利幅（成功報酬込）
A8: =損益計算書!E33 -> 10701.152 | C8: =前提!$B$51 -> 0.4753 | E8: =会員・預かり資産!D42 -> -0.0011501841 | G8: =会員・預かり資産!D43 -> 0.016849816
A10: 100万会員 実質メリット率 | C10: フロー（販売粗利）依存度 | E10: 3年累計 純キャッシュフロー | G10: 損益分岐マイル原価 vs 実績
A11: =会員メリット!B17 -> 0.00778 | C11: =損益計算書!E41 -> 1.1431331 | E11: =キャッシュフロー!E11 -> -2074.2254 | G11: =TEXT(損益計算書!D48,"0.000")&" / "&TEXT(損益計算書!D49,"0.000") -> 0.452 / 0.475
A14: ■ 年度別サマリ
A15: 指標 | B15: 1年目 | C15: 2年目 | D15: 3年目 | E15: 3年累計
A16: 売上高 | B16: =損益計算書!B9 -> 7743.75 | C16: =損益計算書!C9 -> 13872.75 | D16: =損益計算書!D9 -> 20806.5 | E16: =SUM(B16:D16) -> 42423
A17: 営業利益 | B17: =損益計算書!B24 -> 1898.5155 | C17: =損益計算書!C24 -> 3455.6741 | D17: =損益計算書!D24 -> 5195.7626 | E17: =SUM(B17:D17) -> 10549.952
A18: 経常利益 | B18: =損益計算書!B28 -> 1538.5155 | C18: =損益計算書!C28 -> 3095.6741 | D18: =損益計算書!D28 -> 4835.7626 | E18: =SUM(B18:D18) -> 9469.9522
A19: 経済利益（成功報酬発生込） | B19: =損益計算書!B33 -> 1673.5155 | C19: =損益計算書!C33 -> 3468.2741 | D19: =損益計算書!D33 -> 5559.3626 | E19: =SUM(B19:D19) -> 10701.152
A20: ストック損益（成功報酬前） | B20: =会員・預かり資産!B40 -> -8.4845 | C20: =会員・預かり資産!C40 -> -21.3259 | D20: =会員・預かり資産!D40 -> -46.2374 | E20: =SUM(B20:D20) -> -76.0478
A21: ストック経済損益（成功報酬込） | B21: =会員・預かり資産!B41 -> 126.5155 | C21: =会員・預かり資産!C41 -> 351.2741 | D21: =会員・預かり資産!D41 -> 677.3626 | E21: =SUM(B21:D21) -> 1155.1522
A22: マイル費用（P/L） | B22: =マイル計算!B13 -> 173.4845 | C22: =マイル計算!C13 -> 476.7259 | D22: =マイル計算!D13 -> 930.6374 | E22: =SUM(B22:D22) -> 1580.8478
A23: 実利用マイル原価（現金） | B23: =マイル計算!B14 -> 88.5125 | C23: =マイル計算!C14 -> 328.1995 | D23: =マイル計算!D14 -> 708.3134 | E23: =SUM(B23:D23) -> 1125.0254
A24: 純キャッシュフロー | B24: =キャッシュフロー!B11 -> -10376.513 | C24: =キャッシュフロー!C11 -> 3244.2005 | D24: =キャッシュフロー!D11 -> 5058.0866 | E24: =SUM(B24:D24) -> -2074.2254
A25: 期末預かり資産 | B25: =会員・預かり資産!B28 -> 7500 | C25: =会員・預かり資産!C28 -> 20700 | D25: =会員・預かり資産!D28 -> 40200 | E25: =D25 -> 40200
A27: ■ 中谷氏コメントへの回答
A28: ="Q1「レストランは1.0でなく0.8でもよいのでは」→ 感度分析Aの通り、0.8にすると当社利幅は改善するが、"&"100万会員の実質メリットは "&TEXT(感度分析!F6,"#,##0")&"円 → "&TEXT(感度分析!F8,"#,##0")&"円へ縮小する。" -> Q1「レストランは1.0でなく0.8でもよいのでは」→ 感度分析Aの通り、0.8にすると当社利幅は改善するが、100万会員の実質メリットは 7,780円 → 5,600円へ縮小する。
A29: =" 代わりに感度分析Bの通り、レートは1.0のまま原価率を90%→55%（平日オフピーク枠に限定）にすれば、"&"利幅は "&TEXT(感度分析!C6,"0.00%")&" → "&TEXT(感度分析!C15,"0.00%")&" と、0.8にする以上の改善を会員メリットを一切削らずに得られる。" -> 代わりに感度分析Bの通り、レートは1.0のまま原価率を90%→55%（平日オフピーク枠に限定）にすれば、利幅は -0.11% → 0.35% と、0.8にする以上の改善を会員メリットを一切削らずに得られる。
A30: Q2「マイル消化98%＋新規流入を織り込んでも回るか」→ 全費目が預かり資産に対して線形のため、ストック利幅は規模によらず一定。上表の通り3年とも同水準。
A31: ="Q3「PL上で回収できるか」→ フロー（ワイン販売粗利）依存度は "&TEXT(損益計算書!E41,"0.0%")&"。"&"100%を下回るほどストック単体で自立していることを意味する。" -> Q3「PL上で回収できるか」→ フロー（ワイン販売粗利）依存度は 114.3%。100%を下回るほどストック単体で自立していることを意味する。
A32: 前提の更新点：保管料1.5%→1.05%（鈴与実額）／還元率3・4・5%→3.5・4.5・5.5%／成功報酬30%→25%／オークション買い手手数料を収益計上／ワインスクール・交流イベント（原価率50%）を交換先に追加。
A33: 本ファイルは事業採算確認用の管理PLです。法定会計ではマイルを履行義務として収益繰延する可能性があるため、税理士・会計士の確認が必要です。

Sheet 前提
A1: WineBank ワインマイル｜3か年PL 前提条件
A2: 黄色セル＝入力値（変更可）。金額単位：万円。中谷氏作成版の構造を踏襲し、8/31以降に合意した前提へ更新。
A4: ■ ランク別プラン・3か年販売計画
A5: ランク | B5: 1人あたり預かり額 | C5: 管理・保管手数料率 | D5: マイル還元率 | E5: 1年目 新規人数 | F5: 2年目 新規人数 | G5: 3年目 新規人数 | H5: 出典・備考
A6: PRESTIGE | B6: 100 | C6: 0.0275 | D6: 0.04 | E6: 30 | F6: 52 | G6: 70 | H6: 還元率は 3.5/4.5/5.5%（100万会員の額面メリットを1.0%確保するため引上げ済）
A7: GOLD | B7: 500 | C7: 0.0275 | D7: 0.05 | E7: 5 | F7: 10 | G7: 15 | H7: 還元率は 3.5/4.5/5.5%（100万会員の額面メリットを1.0%確保するため引上げ済）
A8: SIGNATURE | B8: 1000 | C8: 0.0275 | D8: 0.06 | E8: 2 | F8: 3 | G8: 5 | H8: 還元率は 3.5/4.5/5.5%（100万会員の額面メリットを1.0%確保するため引上げ済）
A9: 合計新規会員数 | E9: =SUM(E6:E8) -> 37 | F9: =SUM(F6:F8) -> 65 | G9: =SUM(G6:G8) -> 90
A10: 新規預かり資産／販売対象額 | E10: =$B$6*E6+$B$7*E7+$B$8*E8 -> 7500 | F10: =$B$6*F6+$B$7*F7+$B$8*F8 -> 13200 | G10: =$B$6*G6+$B$7*G7+$B$8*G8 -> 19500
A11: 加重平均マイル還元率 | E11: =IF(E10=0,0,($B$6*$D$6*E6+$B$7*$D$7*E7+$B$8*$D$8*E8)/E10) -> 0.048666667 | F11: =IF(F10=0,0,($B$6*$D$6*F6+$B$7*$D$7*F7+$B$8*$D$8*F8)/F10) -> 0.048333333 | G11: =IF(G10=0,0,($B$6*$D$6*G6+$B$7*$D$7*G7+$B$8*$D$8*G8)/G10) -> 0.048974359
A12: ワイン販売を伴う比率 | E12: 1 | F12: 1 | G12: 1 | H12: 100%＝全件WineBank販売。既存ワイン持込型は比率を下げる
A13: ワイン販売売上 | E13: =E10*E12 -> 7500 | F13: =F10*F12 -> 13200 | G13: =G10*G12 -> 19500
A15: ■ 事業・獲得前提
A16: 販売粗利率 | B16: 0.3 | H16: 売価ベース30%
A17: ワイン値上がり率（年） | B17: 0.06 | H17: 実績6%
A18: 成功報酬率 | B18: 0.3 | H18: 値上がり益に対する成功報酬。合意値は25%
A19: 預かり資産の保管・保険原価率（年） | B19: 0.0105 | H19: 鈴与実額 210円/本/年 ÷ 平均単価20,000円＝1.05%（倉持案の1億＝約7,619本より）
A20: 年間預かり継続率 | B20: 1 | H20: 基本100%。解約を織り込む場合はここを下げる
A21: 行動マイル追加発行率（対 預かり資産） | B21: 0 | H21: 落札・会食等の限定マイルは数量前提がないため0%
A22: CPL（1リード獲得費・万円） | B22: 0.8 | H22: 8,000円
A23: CPA（1会員獲得費・営業込み・万円） | B23: 5 | H23: 50,000円。CPLを内包し二重計上しない
A24: 想定リード→会員CVR | B24: =IF(B23=0,0,B22/B23) -> 0.16
A25: 1会員獲得に必要なリード数 | B25: =IF(B22=0,0,B23/B22) -> 6.25
A27: ■ オークション（売り手手数料0・買い手課金モデル）
A28: 年間在庫回転率（対 預かり資産） | B28: 0.1 | H28: 預かり資産のうち年間で売却に回る比率
A29: 当社ルート通過率 | B29: 0.5 | H29: 他ルート売却の可能性を織り込み保守的に50%
A30: 買い手手数料率 | B30: 0.1 | H30: 落札者から10%
A31: 売り手手数料率 | B31: 0 | H31: 会員（売り手）からは取らない
A32: オークション収益率（対 預かり資産） | B32: =B28*B29*(B30+B31) -> 0.005 | H32: 回転率 × 当社ルート率 ×（買い手＋売り手手数料率）
A34: ■ マイル消化前提（1年以内にほぼ利用）
A35: 最終利用率（1年以内） | B35: 0.98 | H35: 中谷案を踏襲。失効益をあてにしない保守設計
A36: 付与年度内の利用率 | B36: 0.5 | H36: 年間で均等獲得する前提
A37: 翌年度の利用率 | B37: 0.48 | H37: 残りを翌年度中に利用
A38: 失効率 | B38: 0.02 | H38: 1年経過時点で未利用分が失効
A39: 合計チェック（100%） | B39: =SUM(B36:B38) -> 1
A41: ■ 利用先ミックス（利用マイル100%に対する構成）
A42: 交換先 | B42: 構成比（入力） | C42: 利用マイル内構成比 | D42: 交換レート | E42: 当社原価率 | F42: 利用1マイル当たり原価 | G42: 利用1マイル当たり会員価値 | H42: 備考
A43: 系列レストラン | B43: 27.8 | C43: =IF(SUM($B$43:$B$49)=0,0,B43/SUM($B$43:$B$49)) -> 0.278 | D43: 1 | E43: 0.9 | F43: =D43*E43 -> 0.9 | G43: =D43 -> 1 | H43: 額面×1.0。原価率はオフピーク枠運用で引下げ余地あり（感度分析B参照）
A44: グランメゾン（1P=0.5円） | B44: 20 | C44: =IF(SUM($B$43:$B$49)=0,0,B44/SUM($B$43:$B$49)) -> 0.2 | D44: 0.5 | E44: 0.9 | F44: =D44*E44 -> 0.45 | G44: =D44 -> 0.5 | H44: 権威性チャネル。レート0.5で当社負担を抑制
A45: WineBank CLUB 会費充当 | B45: 13.3 | C45: =IF(SUM($B$43:$B$49)=0,0,B45/SUM($B$43:$B$49)) -> 0.133 | D45: 1 | E45: 0 | F45: =D45*E45 -> 0 | G45: =D45 -> 1 | H45: 内部振替。原価ほぼ0でレート1.0
...

Sheet 会員・預かり資産
A1: 会員数・預かり資産｜3か年推移
A2: 前提シートの年度別会員数を反映。獲得年から手数料・マイルを満額計上。単位：万円
A4: ■ 新規獲得・ファネル
A5: 項目 | B5: 1年目 | C5: 2年目 | D5: 3年目 | E5: 備考
A6: PRESTIGE 新規会員数 | B6: =前提!E6 -> 30 | C6: =前提!F6 -> 52 | D6: =前提!G6 -> 70
A7: GOLD 新規会員数 | B7: =前提!E7 -> 5 | C7: =前提!F7 -> 10 | D7: =前提!G7 -> 15
A8: SIGNATURE 新規会員数 | B8: =前提!E8 -> 2 | C8: =前提!F8 -> 3 | D8: =前提!G8 -> 5
A9: 新規会員数 合計 | B9: =SUM(B6:B8) -> 37 | C9: =SUM(C6:C8) -> 65 | D9: =SUM(D6:D8) -> 90
A10: 必要リード数 | B10: =IF(前提!$B$22=0,0,B9*前提!$B$23/前提!$B$22) -> 231.25 | C10: =IF(前提!$B$22=0,0,C9*前提!$B$23/前提!$B$22) -> 406.25 | D10: =IF(前提!$B$22=0,0,D9*前提!$B$23/前提!$B$22) -> 562.5 | E10: CPL 0.8万／CPA 5万から逆算
A11: リード→会員CVR | B11: =IF(B10=0,0,B9/B10) -> 0.16 | C11: =IF(C10=0,0,C9/C10) -> 0.16 | D11: =IF(D10=0,0,D9/D10) -> 0.16
A12: ユーザー獲得費 | B12: =B9*前提!$B$23 -> 185 | C12: =C9*前提!$B$23 -> 325 | D12: =D9*前提!$B$23 -> 450 | E12: 新規会員数 × CPA 5万円
A13: 新規預かり資産 | B13: =前提!E10 -> 7500 | C13: =前提!F10 -> 13200 | D13: =前提!G10 -> 19500
A14: ワイン販売を伴う比率 | B14: =前提!E12 -> 1 | C14: =前提!F12 -> 1 | D14: =前提!G12 -> 1
A15: ワイン販売売上 | B15: =B13*B14 -> 7500 | C15: =C13*C14 -> 13200 | D15: =D13*D14 -> 19500
A16: 新規会員1人あたり預かり資産 | B16: =IF(B9=0,0,B13/B9) -> 202.7027 | C16: =IF(C9=0,0,C13/C9) -> 203.07692 | D16: =IF(D9=0,0,D13/D9) -> 216.66667
A18: ■ 期末会員数
A19: PRESTIGE 期末会員数 | B19: =B6 -> 30 | C19: =B19*前提!$B$20+C6 -> 82 | D19: =C19*前提!$B$20+D6 -> 152 | E19: 継続率反映
A20: GOLD 期末会員数 | B20: =B7 -> 5 | C20: =B20*前提!$B$20+C7 -> 15 | D20: =C20*前提!$B$20+D7 -> 30 | E20: 継続率反映
A21: SIGNATURE 期末会員数 | B21: =B8 -> 2 | C21: =B21*前提!$B$20+C8 -> 5 | D21: =C21*前提!$B$20+D8 -> 10 | E21: 継続率反映
A22: 期末会員数 合計 | B22: =SUM(B19:B21) -> 37 | C22: =SUM(C19:C21) -> 102 | D22: =SUM(D19:D21) -> 192
A24: ■ 預かり資産・ストック採算
A25: PRESTIGE 期末預かり資産 | B25: =B19*前提!$B$6 -> 3000 | C25: =C19*前提!$B$6 -> 8200 | D25: =D19*前提!$B$6 -> 15200
A26: GOLD 期末預かり資産 | B26: =B20*前提!$B$7 -> 2500 | C26: =C20*前提!$B$7 -> 7500 | D26: =D20*前提!$B$7 -> 15000
A27: SIGNATURE 期末預かり資産 | B27: =B21*前提!$B$8 -> 2000 | C27: =C21*前提!$B$8 -> 5000 | D27: =D21*前提!$B$8 -> 10000
A28: 期末預かり資産 合計 | B28: =SUM(B25:B27) -> 7500 | C28: =SUM(C25:C27) -> 20700 | D28: =SUM(D25:D27) -> 40200
A29: 期首預かり資産 | B29: 0 | C29: =B28 -> 7500 | D29: =C28 -> 20700
A30: 継続後の期首預かり資産 | B30: 0 | C30: =B28*前提!$B$20 -> 7500 | D30: =C28*前提!$B$20 -> 20700
A31: 新規預かり資産 | B31: =B13 -> 7500 | C31: =C13 -> 13200 | D31: =D13 -> 19500
A32: 資産ブリッジ差額（0確認） | B32: =B30+B31-B28 -> 0 | C32: =C30+C31-C28 -> 0 | D32: =D30+D31-D28 -> 0
A33: 管理・保管手数料収入 | B33: =B25*前提!$C$6+B26*前提!$C$7+B27*前提!$C$8 -> 206.25 | C33: =C25*前提!$C$6+C26*前提!$C$7+C27*前提!$C$8 -> 569.25 | D33: =D25*前提!$C$6+D26*前提!$C$7+D27*前提!$C$8 -> 1105.5 | E33: 期末預かり資産×2.5%
A34: 預かり資産の保管・保険原価 | B34: =B28*前提!$B$19 -> 78.75 | C34: =C28*前提!$B$19 -> 217.35 | D34: =D28*前提!$B$19 -> 422.1 | E34: 期末預かり資産×1.05%（鈴与実額）
A35: オークション手数料収入 | B35: =B28*前提!$B$32 -> 37.5 | C35: =C28*前提!$B$32 -> 103.5 | D35: =D28*前提!$B$32 -> 201 | E35: 買い手10%×当社ルート50%×回転10%
A36: マイル発行額（額面） | B36: =B25*前提!$D$6+B26*前提!$D$7+B27*前提!$D$8+B28*前提!$B$21 -> 365 | C36: =C25*前提!$D$6+C26*前提!$D$7+C27*前提!$D$8+C28*前提!$B$21 -> 1003 | D36: =D25*前提!$D$6+D26*前提!$D$7+D27*前提!$D$8+D28*前提!$B$21 -> 1958 | E36: ランク別還元率＋行動マイル
A37: 加重平均マイル発行率 | B37: =IF(B28=0,0,B36/B28) -> 0.048666667 | C37: =IF(C28=0,0,C36/C28) -> 0.048454106 | D37: =IF(D28=0,0,D36/D28) -> 0.048706468 | E37: 実績ミックスで変動
A38: 成功報酬の経済発生額（未実現） | B38: =B28*前提!$B$17*前提!$B$18 -> 135 | C38: =C28*前提!$B$17*前提!$B$18 -> 372.6 | D38: =D28*前提!$B$17*前提!$B$18 -> 723.6 | E38: 預かり資産×値上がり率6%×成功報酬率25%
A39: マイル費用（P/L見込計上） | B39: =B36*前提!$B$51 -> 173.4845 | C39: =C36*前提!$B$51 -> 476.7259 | D39: =D36*前提!$B$51 -> 930.6374 | E39: 発行額×発行1マイル期待原価
A40: ストック損益（成功報酬前） | B40: =B33-B34+B35-B39 -> -8.4845 | C40: =C33-C34+C35-C39 -> -21.3259 | D40: =D33-D34+D35-D39 -> -46.2374 | E40: 手数料－保管原価＋オークション－マイル費用
A41: ストック経済損益（成功報酬込） | B41: =B40+B38 -> 126.5155 | C41: =C40+C38 -> 351.2741 | D41: =D40+D38 -> 677.3626 | E41: 成功報酬の経済発生を加算
A42: ストック利幅（成功報酬前） | B42: =IF(B28=0,0,B40/B28) -> -0.0011312667 | C42: =IF(C28=0,0,C40/C28) -> -0.0010302367 | D42: =IF(D28=0,0,D40/D28) -> -0.0011501841 | E42: 現金・会計ベース
A43: ストック利幅（成功報酬込） | B43: =IF(B28=0,0,B41/B28) -> 0.016868733 | C43: =IF(C28=0,0,C41/C28) -> 0.016969763 | D43: =IF(D28=0,0,D41/D28) -> 0.016849816 | E43: 成功報酬を含む経済利幅

Sheet マイル計算
A1: マイル計算｜発行・利用・P/L費用・現金負担
A2: P/Lは発行時に最終利用率ベースの期待原価を計上。現金負担は実際に利用された年に表示。単位：万円
A4: ■ 発行・消化スケジュール
A5: 項目 | B5: 1年目 | C5: 2年目 | D5: 3年目 | J5: 備考
A6: 期首未使用マイル残高（額面） | B6: 0 | C6: =B12 -> 182.5 | D6: =C12 -> 501.5 | J6: 前年期末残高
A7: 当年マイル発行額（額面） | B7: =会員・預かり資産!B36 -> 365 | C7: =会員・預かり資産!C36 -> 1003 | D7: =会員・預かり資産!D36 -> 1958 | J7: 期末預かり資産×ランク別還元率
A8: 当年発行分の当年度利用 | B8: =B7*前提!$B$36 -> 182.5 | C8: =C7*前提!$B$36 -> 501.5 | D8: =D7*前提!$B$36 -> 979 | J8: 年間均等獲得の前提で50%
A9: 前年度発行分の翌年度利用 | B9: 0 | C9: =B7*前提!$B$37 -> 175.2 | D9: =C7*前提!$B$37 -> 481.44 | J9: 前年コホートの48%
A10: 当年度の利用額 合計（額面） | B10: =B8+B9 -> 182.5 | C10: =C8+C9 -> 676.7 | D10: =D8+D9 -> 1460.44 | J10: サービス利用に充当された額面
A11: 前年度発行分の失効 | B11: 0 | C11: =B7*前提!$B$38 -> 7.3 | D11: =C7*前提!$B$38 -> 20.06 | J11: 前年コホートの2%
A12: 期末未使用マイル残高（額面） | B12: =B6+B7-B10-B11 -> 182.5 | C12: =C6+C7-C10-C11 -> 501.5 | D12: =D6+D7-D10-D11 -> 979 | J12: 翌年度に利用または失効
A13: マイル費用（P/L見込計上） | B13: =B7*前提!$B$51 -> 173.4845 | C13: =C7*前提!$B$51 -> 476.7259 | D13: =D7*前提!$B$51 -> 930.6374 | J13: 将来利用分も含め発行年度に期待原価を計上
A14: 実利用による現金・原価負担 | B14: =B10*前提!$F$50 -> 88.5125 | C14: =C10*前提!$F$50 -> 328.1995 | D14: =D10*前提!$F$50 -> 708.3134 | J14: 実際にサービス利用された年の原価
A15: 未払マイル原価の増減 | B15: =B13-B14 -> 84.972 | C15: =C13-C14 -> 148.5264 | D15: =D13-D14 -> 222.324 | J15: P/L費用－実利用原価
A16: 期末未払マイル原価（負債） | B16: =B15 -> 84.972 | C16: =B16+C15 -> 233.4984 | D16: =C16+D15 -> 455.8224 | J16: 将来利用に備えた原価見込み
A17: コホート最終利用率 | B17: =前提!$B$35 -> 0.98 | C17: =前提!$B$35 -> 0.98 | D17: =前提!$B$35 -> 0.98
A19: ■ 利用先別の実利用額・実コスト
A20: 交換先 | B20: 利用マイル内構成比 | C20: 利用1マイル原価 | D20: 1年目 額面 | E20: 1年目 原価 | F20: 2年目 額面 | G20: 2年目 原価 | H20: 3年目 額面 | I20: 3年目 原価 | J20: 備考
A21: =前提!A43 -> 系列レストラン | B21: =前提!C43 -> 0.278 | C21: =前提!F43 -> 0.9 | D21: =$B$10*$B21 -> 50.735 | E21: =D21*$C21 -> 45.6615 | F21: =$C$10*$B21 -> 188.1226 | G21: =F21*$C21 -> 169.31034 | H21: =$D$10*$B21 -> 406.00232 | I21: =H21*$C21 -> 365.40209
A22: =前提!A44 -> グランメゾン（1P=0.5円） | B22: =前提!C44 -> 0.2 | C22: =前提!F44 -> 0.45 | D22: =$B$10*$B22 -> 36.5 | E22: =D22*$C22 -> 16.425 | F22: =$C$10*$B22 -> 135.34 | G22: =F22*$C22 -> 60.903 | H22: =$D$10*$B22 -> 292.088 | I22: =H22*$C22 -> 131.4396
A23: =前提!A45 -> WineBank CLUB 会費充当 | B23: =前提!C45 -> 0.133 | C23: =前提!F45 -> 0 | D23: =$B$10*$B23 -> 24.2725 | E23: =D23*$C23 -> 0 | F23: =$C$10*$B23 -> 90.0011 | G23: =F23*$C23 -> 0 | H23: =$D$10*$B23 -> 194.23852 | I23: =H23*$C23 -> 0
A24: =前提!A46 -> オークション参加 | B24: =前提!C46 -> 0.133 | C24: =前提!F46 -> 0 | D24: =$B$10*$B24 -> 24.2725 | E24: =D24*$C24 -> 0 | F24: =$C$10*$B24 -> 90.0011 | G24: =F24*$C24 -> 0 | H24: =$D$10*$B24 -> 194.23852 | I24: =H24*$C24 -> 0
A25: =前提!A47 -> ワインスクール | B25: =前提!C47 -> 0.111 | C25: =前提!F47 -> 0.5 | D25: =$B$10*$B25 -> 20.2575 | E25: =D25*$C25 -> 10.12875 | F25: =$C$10*$B25 -> 75.1137 | G25: =F25*$C25 -> 37.55685 | H25: =$D$10*$B25 -> 162.10884 | I25: =H25*$C25 -> 81.05442
A26: =前提!A48 -> 会員交流イベント | B26: =前提!C48 -> 0.089 | C26: =前提!F48 -> 0.5 | D26: =$B$10*$B26 -> 16.2425 | E26: =D26*$C26 -> 8.12125 | F26: =$C$10*$B26 -> 60.2263 | G26: =F26*$C26 -> 30.11315 | H26: =$D$10*$B26 -> 129.97916 | I26: =H26*$C26 -> 64.98958
A27: =前提!A49 -> ワイン追加購入 | B27: =前提!C49 -> 0.056 | C27: =前提!F49 -> 0.8 | D27: =$B$10*$B27 -> 10.22 | E27: =D27*$C27 -> 8.176 | F27: =$C$10*$B27 -> 37.8952 | G27: =F27*$C27 -> 30.31616 | H27: =$D$10*$B27 -> 81.78464 | I27: =H27*$C27 -> 65.427712
A28: 合計 | B28: =SUM(B21:B27) -> 1 | D28: =SUM(D21:D27) -> 182.5 | E28: =SUM(E21:E27) -> 88.5125 | F28: =SUM(F21:F27) -> 676.7 | G28: =SUM(G21:G27) -> 328.1995 | H28: =SUM(H21:H27) -> 1460.44 | I28: =SUM(I21:I27) -> 708.3134

Sheet 損益計算書
A1: 損益計算書｜WineBank ワインマイル事業 3か年
A2: 単位：万円。成功報酬は未実現のため営業利益と分けて表示。
B4: 1年目 | C4: 2年目 | D4: 3年目 | E4: 3年累計 | F4: 備考
A5: 【売上高】
A6: ワイン販売売上 | B6: =会員・預かり資産!B15 -> 7500 | C6: =会員・預かり資産!C15 -> 13200 | D6: =会員・預かり資産!D15 -> 19500 | E6: =SUM(B6:D6) -> 40200 | F6: 新規預かり資産×販売を伴う比率
A7: 管理・保管手数料収入 | B7: =会員・預かり資産!B33 -> 206.25 | C7: =会員・預かり資産!C33 -> 569.25 | D7: =会員・預かり資産!D33 -> 1105.5 | E7: =SUM(B7:D7) -> 1881 | F7: 期末預かり資産×2.5%
A8: オークション手数料収入 | B8: =会員・預かり資産!B35 -> 37.5 | C8: =会員・預かり資産!C35 -> 103.5 | D8: =会員・預かり資産!D35 -> 201 | E8: =SUM(B8:D8) -> 342 | F8: 買い手10%・売り手0%・当社ルート50%
A9: 売上高 計 | B9: =SUM(B6:B8) -> 7743.75 | C9: =SUM(C6:C8) -> 13872.75 | D9: =SUM(D6:D8) -> 20806.5 | E9: =SUM(B9:D9) -> 42423
A10: 【売上原価・売上総利益】
A11: ワイン売上原価 | B11: =B6*(1-前提!$B$16) -> 5250 | C11: =C6*(1-前提!$B$16) -> 9240 | D11: =D6*(1-前提!$B$16) -> 13650 | E11: =SUM(B11:D11) -> 28140 | F11: 販売粗利率30%
A12: 売上総利益 | B12: =B9-B11 -> 2493.75 | C12: =C9-C11 -> 4632.75 | D12: =D9-D11 -> 7156.5 | E12: =SUM(B12:D12) -> 14283
A13: 売上総利益率 | B13: =IF(B9=0,0,B12/B9) -> 0.3220339 | C13: =IF(C9=0,0,C12/C9) -> 0.33394605 | D13: =IF(D9=0,0,D12/D9) -> 0.34395501 | E13: =IF(E9=0,0,E12/E9) -> 0.33668057
A14: 【販売費及び一般管理費】
A15: マイル費用（P/L見込計上） | B15: =マイル計算!B13 -> 173.4845 | C15: =マイル計算!C13 -> 476.7259 | D15: =マイル計算!D13 -> 930.6374 | E15: =SUM(B15:D15) -> 1580.8478 | F15: 発行額×発行1マイル期待原価
A16: 預かり資産の保管・保険原価 | B16: =会員・預かり資産!B34 -> 78.75 | C16: =会員・預かり資産!C34 -> 217.35 | D16: =会員・預かり資産!D34 -> 422.1 | E16: =SUM(B16:D16) -> 718.2 | F16: 期末預かり資産×1.05%
A17: ユーザー獲得費 | B17: =会員・預かり資産!B12 -> 185 | C17: =会員・預かり資産!C12 -> 325 | D17: =会員・預かり資産!D12 -> 450 | E17: =SUM(B17:D17) -> 960 | F17: 新規会員数×CPA 5万円
A18: 人件費 | B18: =前提!B57 -> 0 | C18: =前提!C57 -> 0 | D18: =前提!D57 -> 0 | E18: =SUM(B18:D18) -> 0 | F18: 前提シート入力
A19: システム開発・保守費 | B19: =前提!B58 -> 0 | C19: =前提!C58 -> 0 | D19: =前提!D58 -> 0 | E19: =SUM(B19:D19) -> 0 | F19: 前提シート入力
A20: 交流イベント・コミュニティ費 | B20: =前提!B59 -> 0 | C20: =前提!C59 -> 0 | D20: =前提!D59 -> 0 | E20: =SUM(B20:D20) -> 0 | F20: 前提シート入力
A21: その他固定販管費 | B21: =前提!B60 -> 0 | C21: =前提!C60 -> 0 | D21: =前提!D60 -> 0 | E21: =SUM(B21:D21) -> 0 | F21: 前提シート入力
A22: 自社在庫の保管・保険料 | B22: =前提!B61 -> 158 | C22: =前提!C61 -> 158 | D22: =前提!D61 -> 158 | E22: =SUM(B22:D22) -> 474 | F22: 前提シート入力
A23: 販管費 計 | B23: =SUM(B15:B22) -> 595.2345 | C23: =SUM(C15:C22) -> 1177.0759 | D23: =SUM(D15:D22) -> 1960.7374 | E23: =SUM(B23:D23) -> 3733.0478
A24: 営業利益 | B24: =B12-B23 -> 1898.5155 | C24: =C12-C23 -> 3455.6741 | D24: =D12-D23 -> 5195.7626 | E24: =SUM(B24:D24) -> 10549.952
A25: 営業利益率 | B25: =IF(B9=0,0,B24/B9) -> 0.24516746 | C25: =IF(C9=0,0,C24/C9) -> 0.24909799 | D25: =IF(D9=0,0,D24/D9) -> 0.24971824 | E25: =IF(E9=0,0,E24/E9) -> 0.24868473
A26: 【営業外損益】
A27: 支払利息 | B27: =前提!B62 -> 360 | C27: =前提!C62 -> 360 | D27: =前提!D62 -> 360 | E27: =SUM(B27:D27) -> 1080 | F27: 買付借入1.2億×3%
A28: 経常利益 | B28: =B24-B27 -> 1538.5155 | C28: =C24-C27 -> 3095.6741 | D28: =D24-D27 -> 4835.7626 | E28: =SUM(B28:D28) -> 9469.9522
A29: 経常利益率 | B29: =IF(B9=0,0,B28/B9) -> 0.19867835 | C29: =IF(C9=0,0,C28/C9) -> 0.22314783 | D29: =IF(D9=0,0,D28/D9) -> 0.23241596 | E29: =IF(E9=0,0,E28/E9) -> 0.22322684
A31: 【参考：成功報酬の経済発生（契約終了時まで未実現）】
A32: 成功報酬の経済発生額 | B32: =会員・預かり資産!B38 -> 135 | C32: =会員・預かり資産!C38 -> 372.6 | D32: =会員・預かり資産!D38 -> 723.6 | E32: =SUM(B32:D32) -> 1231.2 | F32: 預かり資産×値上がり率6%×成功報酬率25%
A33: 経済利益（経常利益＋成功報酬発生） | B33: =B28+B32 -> 1673.5155 | C33: =C28+C32 -> 3468.2741 | D33: =D28+D32 -> 5559.3626 | E33: =SUM(B33:D33) -> 10701.152
A35: 【★利益の源泉分解｜フロー依存度の確認】
A36: ワイン販売粗利（フロー） | B36: =B6-B11 -> 2250 | C36: =C6-C11 -> 3960 | D36: =D6-D11 -> 5850 | E36: =SUM(B36:D36) -> 12060 | F36: 新規販売がある限りの利益
A37: ストック損益（成功報酬前） | B37: =会員・預かり資産!B40 -> -8.4845 | C37: =会員・預かり資産!C40 -> -21.3259 | D37: =会員・預かり資産!D40 -> -46.2374 | E37: =SUM(B37:D37) -> -76.0478 | F37: 手数料－保管－マイル＋オークション
A38: ユーザー獲得費 | B38: =-会員・預かり資産!B12 -> -185 | C38: =-会員・預かり資産!C12 -> -325 | D38: =-会員・預かり資産!D12 -> -450 | E38: =SUM(B38:D38) -> -960
A39: 固定費・自社在庫 | B39: =-SUM(B18:B22) -> -158 | C39: =-SUM(C18:C22) -> -158 | D39: =-SUM(D18:D22) -> -158 | E39: =SUM(B39:D39) -> -474
A40: 営業利益（検算） | B40: =SUM(B36:B39) -> 1898.5155 | C40: =SUM(C36:C39) -> 3455.6741 | D40: =SUM(D36:D39) -> 5195.7626 | E40: =SUM(B40:D40) -> 10549.952
A41: フロー（販売粗利）依存度 | B41: =IF(B24=0,0,B36/B24) -> 1.1851365 | C41: =IF(C24=0,0,C36/C24) -> 1.1459414 | D41: =IF(D24=0,0,D36/D24) -> 1.1259175 | E41: =IF(E24=0,0,E36/E24) -> 1.1431331 | F41: 100%超＝新規販売が止まると赤字。ストック単独で黒字化するほど依存度は下がる
A43: 【ストック部分だけの採算】
A44: ストック損益（成功報酬前） | B44: =会員・預かり資産!B40 -> -8.4845 | C44: =会員・預かり資産!C40 -> -21.3259 | D44: =会員・預かり資産!D40 -> -46.2374 | E44: =SUM(B44:D44) -> -76.0478
...

Sheet キャッシュフロー
A1: キャッシュフロー｜3か年
A2: 成功報酬は契約終了時まで現金化しないため本表に含めない。単位：万円
A4: 項目 | B4: 1年目 | C4: 2年目 | D4: 3年目 | E4: 3年累計 | F4: 備考
A5: 営業利益 | B5: =損益計算書!B24 -> 1898.5155 | C5: =損益計算書!C24 -> 3455.6741 | D5: =損益計算書!D24 -> 5195.7626 | E5: =SUM(B5:D5) -> 10549.952 | F5: P/Lより
A6: ＋マイル費用（P/L計上・非現金分） | B6: =マイル計算!B13 -> 173.4845 | C6: =マイル計算!C13 -> 476.7259 | D6: =マイル計算!D13 -> 930.6374 | E6: =SUM(B6:D6) -> 1580.8478 | F6: 発行時に費用計上した額を戻す
A7: ▲実利用マイル原価（現金流出） | B7: =-マイル計算!B14 -> -88.5125 | C7: =-マイル計算!C14 -> -328.1995 | D7: =-マイル計算!D14 -> -708.3134 | E7: =SUM(B7:D7) -> -1125.0254 | F7: 実際に使われた年の原価
A8: 営業キャッシュフロー（在庫投資前） | B8: =SUM(B5:B7) -> 1983.4875 | C8: =SUM(C5:C7) -> 3604.2005 | D8: =SUM(D5:D7) -> 5418.0866 | E8: =SUM(B8:D8) -> 11005.775
A9: ▲新規ワイン買付（在庫投資） | B9: =-前提!B65 -> -12000 | C9: =-前提!C65 -> 0 | D9: =-前提!D65 -> 0 | E9: =SUM(B9:D9) -> -12000 | F9: 1年目1.2億の買付
A10: ▲支払利息 | B10: =-損益計算書!B27 -> -360 | C10: =-損益計算書!C27 -> -360 | D10: =-損益計算書!D27 -> -360 | E10: =SUM(B10:D10) -> -1080
A11: 純キャッシュフロー | B11: =B8+B9+B10 -> -10376.513 | C11: =C8+C9+C10 -> 3244.2005 | D11: =D8+D9+D10 -> 5058.0866 | E11: =SUM(B11:D11) -> -2074.2254
A12: 累計キャッシュフロー | B12: =B11 -> -10376.513 | C12: =B12+C11 -> -7132.312 | D12: =C12+D11 -> -2074.2254
A14: 【参考：未実現の経済価値】
A15: 成功報酬の累計発生額 | B15: =損益計算書!B32 -> 135 | C15: =B15+損益計算書!C32 -> 507.6 | D15: =C15+損益計算書!D32 -> 1231.2 | F15: 契約終了時に精算。3年時点では現金化していない
A16: 期末未払マイル原価（将来の現金流出） | B16: =マイル計算!B16 -> 84.972 | C16: =マイル計算!C16 -> 233.4984 | D16: =マイル計算!D16 -> 455.8224 | F16: 翌年度以降に利用される分の原価見込み

Sheet 感度分析
A1: 感度分析｜交換レート・原価率・利用率・販売比率
A2: 中谷氏コメント「レストランは1.0でなく0.8でもよいのでは」への定量回答を含む。
A4: ■ A. 系列レストランの交換レート別（原価率は90%のまま）
A5: 交換レート | B5: 発行1マイル 当社原価 | C5: ストック利幅（成功報酬前） | D5: ストック利幅（成功報酬込） | E5: 100万会員の実質メリット率 | F5: 100万会員の実質メリット額（円）
A6: 1 | B6: =前提!$B$35*(前提!C43*$A6*前提!E43+SUMPRODUCT(前提!C44:C49,前提!D44:D49,前提!E44:E49)) -> 0.4753 | C6: =前提!$C$6-前提!$B$19+前提!$B$32-会員・預かり資産!$B$37*B6 -> -0.0011312667 | D6: =C6+前提!$B$17*前提!$B$18 -> 0.016868733 | E6: =前提!$D$6*(前提!$B$35*(前提!C43*$A6+SUMPRODUCT(前提!C44:C49,前提!D44:D49)))-前提!$C$6 -> 0.00778 | F6: =E6*前提!$B$6*10000 -> 7780 | H6: レートを下げると当社利幅は改善するが、会員メリットが同率で削られる。
A7: 0.9 | B7: =前提!$B$35*(前提!C43*$A7*前提!E43+SUMPRODUCT(前提!C44:C49,前提!D44:D49,前提!E44:E49)) -> 0.4507804 | C7: =前提!$C$6-前提!$B$19+前提!$B$32-会員・預かり資産!$B$37*B7 -> 6.2020533e-05 | D7: =C7+前提!$B$17*前提!$B$18 -> 0.018062021 | E7: =前提!$D$6*(前提!$B$35*(前提!C43*$A7+SUMPRODUCT(前提!C44:C49,前提!D44:D49)))-前提!$C$6 -> 0.00669024 | F7: =E7*前提!$B$6*10000 -> 6690.24 | H7: 系列レストランは会員が「1マイル＝1円」を実感する中核チャネルであり、
A8: 0.8 | B8: =前提!$B$35*(前提!C43*$A8*前提!E43+SUMPRODUCT(前提!C44:C49,前提!D44:D49,前提!E44:E49)) -> 0.4262608 | C8: =前提!$C$6-前提!$B$19+前提!$B$32-会員・預かり資産!$B$37*B8 -> 0.0012553077 | D8: =C8+前提!$B$17*前提!$B$18 -> 0.019255308 | E8: =前提!$D$6*(前提!$B$35*(前提!C43*$A8+SUMPRODUCT(前提!C44:C49,前提!D44:D49)))-前提!$C$6 -> 0.00560048 | F8: =E8*前提!$B$6*10000 -> 5600.48 | H8: ここを削ると訴求力が最も大きく毀損する。次表Bの方が費用対効果が高い。
A9: 0.7 | B9: =前提!$B$35*(前提!C43*$A9*前提!E43+SUMPRODUCT(前提!C44:C49,前提!D44:D49,前提!E44:E49)) -> 0.4017412 | C9: =前提!$C$6-前提!$B$19+前提!$B$32-会員・預かり資産!$B$37*B9 -> 0.0024485949 | D9: =C9+前提!$B$17*前提!$B$18 -> 0.020448595 | E9: =前提!$D$6*(前提!$B$35*(前提!C43*$A9+SUMPRODUCT(前提!C44:C49,前提!D44:D49)))-前提!$C$6 -> 0.00451072 | F9: =E9*前提!$B$6*10000 -> 4510.72
A11: ■ B. 系列レストランの当社原価率別（交換レートは1.0のまま）
A12: 当社原価率 | B12: 発行1マイル 当社原価 | C12: ストック利幅（成功報酬前） | D12: ストック利幅（成功報酬込） | E12: 100万会員の実質メリット率 | F12: 100万会員の実質メリット額（円）
A13: 0.9 | B13: =前提!$B$35*(前提!C43*前提!D43*$A13+SUMPRODUCT(前提!C44:C49,前提!D44:D49,前提!E44:E49)) -> 0.4753 | C13: =前提!$C$6-前提!$B$19+前提!$B$32-会員・預かり資産!$B$37*B13 -> -0.0011312667 | D13: =C13+前提!$B$17*前提!$B$18 -> 0.016868733 | E13: =前提!$D$6*(前提!$B$35*(前提!C43*前提!D43+SUMPRODUCT(前提!C44:C49,前提!D44:D49)))-前提!$C$6 -> 0.00778 | F13: =E13*前提!$B$6*10000 -> 7780 | H13: 満席・機会損失前提（現状の置き方）
A14: 0.7 | B14: =前提!$B$35*(前提!C43*前提!D43*$A14+SUMPRODUCT(前提!C44:C49,前提!D44:D49,前提!E44:E49)) -> 0.420812 | C14: =前提!$C$6-前提!$B$19+前提!$B$32-会員・預かり資産!$B$37*B14 -> 0.0015204827 | D14: =C14+前提!$B$17*前提!$B$18 -> 0.019520483 | E14: =前提!$D$6*(前提!$B$35*(前提!C43*前提!D43+SUMPRODUCT(前提!C44:C49,前提!D44:D49)))-前提!$C$6 -> 0.00778 | F14: =E14*前提!$B$6*10000 -> 7780 | H14: 一部を現金併用（マイル充当上限50%）
A15: 0.55 | B15: =前提!$B$35*(前提!C43*前提!D43*$A15+SUMPRODUCT(前提!C44:C49,前提!D44:D49,前提!E44:E49)) -> 0.379946 | C15: =前提!$C$6-前提!$B$19+前提!$B$32-会員・預かり資産!$B$37*B15 -> 0.0035092947 | D15: =C15+前提!$B$17*前提!$B$18 -> 0.021509295 | E15: =前提!$D$6*(前提!$B$35*(前提!C43*前提!D43+SUMPRODUCT(前提!C44:C49,前提!D44:D49)))-前提!$C$6 -> 0.00778 | F15: =E15*前提!$B$6*10000 -> 7780 | H15: 平日オフピーク枠に限定（変動費中心）
A16: 0.4 | B16: =前提!$B$35*(前提!C43*前提!D43*$A16+SUMPRODUCT(前提!C44:C49,前提!D44:D49,前提!E44:E49)) -> 0.33908 | C16: =前提!$C$6-前提!$B$19+前提!$B$32-会員・預かり資産!$B$37*B16 -> 0.0054981067 | D16: =C16+前提!$B$17*前提!$B$18 -> 0.023498107 | E16: =前提!$D$6*(前提!$B$35*(前提!C43*前提!D43+SUMPRODUCT(前提!C44:C49,前提!D44:D49)))-前提!$C$6 -> 0.00778 | F16: =E16*前提!$B$6*10000 -> 7780 | H16: F&B原価のみ（空席を埋める前提）
H17: 原価率を下げても会員メリット率は一切変わらない（E列は全行同値）のが要点。
A19: ■ C. 最終利用率別（失効益への依存度）
A20: 最終利用率 | B20: 発行1マイル 当社原価 | C20: ストック利幅（成功報酬前） | D20: ストック利幅（成功報酬込） | E20: 100万会員の実質メリット率
A21: 0.9 | B21: =$A21*前提!$F$50 -> 0.4365 | C21: =前提!$C$6-前提!$B$19+前提!$B$32-会員・預かり資産!$B$37*B21 -> 0.000757 | D21: =C21+前提!$B$17*前提!$B$18 -> 0.018757 | E21: =前提!$D$6*($A21*前提!$G$50)-前提!$C$6 -> 0.0049 | H21: 中谷氏の「3〜6か月失効でコミュニティ通貨として回す」設計は利用率を上げる＝コストも上がる。
A22: 0.95 | B22: =$A22*前提!$F$50 -> 0.46075 | C22: =前提!$C$6-前提!$B$19+前提!$B$32-会員・預かり資産!$B$37*B22 -> -0.00042316667 | D22: =C22+前提!$B$17*前提!$B$18 -> 0.017576833 | E22: =前提!$D$6*($A22*前提!$G$50)-前提!$C$6 -> 0.0067 | H22: 失効益をあてにしない98%前提でも黒字であることを確認するための表。
A23: 0.98 | B23: =$A23*前提!$F$50 -> 0.4753 | C23: =前提!$C$6-前提!$B$19+前提!$B$32-会員・預かり資産!$B$37*B23 -> -0.0011312667 | D23: =C23+前提!$B$17*前提!$B$18 -> 0.016868733 | E23: =前提!$D$6*($A23*前提!$G$50)-前提!$C$6 -> 0.00778
A24: 1 | B24: =$A24*前提!$F$50 -> 0.485 | C24: =前提!$C$6-前提!$B$19+前提!$B$32-会員・預かり資産!$B$37*B24 -> -0.0016033333 | D24: =C24+前提!$B$17*前提!$B$18 -> 0.016396667 | E24: =前提!$D$6*($A24*前提!$G$50)-前提!$C$6 -> 0.0085
A26: ■ D. ワイン販売を伴う比率別の営業利益（持込型が増えた場合）
A27: 販売を伴う比率 | B27: 1年目 | C27: 2年目 | D27: 3年目 | E27: 3年累計 | F27: 見方
A28: 0 | B28: =会員・預かり資産!B13*$A28*前提!$B$16+会員・預かり資産!B33+会員・預かり資産!B35-損益計算書!B23 -> -351.4845 | C28: =会員・預かり資産!C13*$A28*前提!$B$16+会員・預かり資産!C33+会員・預かり資産!C35-損益計算書!C23 -> -504.3259 | D28: =会員・預かり資産!D13*$A28*前提!$B$16+会員・預かり資産!D33+会員・預かり資産!D35-損益計算書!D23 -> -654.2374 | E28: =SUM(B28:D28) -> -1510.0478 | F28: 持込・預かりのみ
A29: 0.25 | B29: =会員・預かり資産!B13*$A29*前提!$B$16+会員・預かり資産!B33+会員・預かり資産!B35-損益計算書!B23 -> 211.0155 | C29: =会員・預かり資産!C13*$A29*前提!$B$16+会員・預かり資産!C33+会員・預かり資産!C35-損益計算書!C23 -> 485.6741 | D29: =会員・預かり資産!D13*$A29*前提!$B$16+会員・預かり資産!D33+会員・預かり資産!D35-損益計算書!D23 -> 808.2626 | E29: =SUM(B29:D29) -> 1504.9522 | F29: 販売粗利が一部発生
A30: 0.5 | B30: =会員・預かり資産!B13*$A30*前提!$B$16+会員・預かり資産!B33+会員・預かり資産!B35-損益計算書!B23 -> 773.5155 | C30: =会員・預かり資産!C13*$A30*前提!$B$16+会員・預かり資産!C33+会員・預かり資産!C35-損益計算書!C23 -> 1475.6741 | D30: =会員・預かり資産!D13*$A30*前提!$B$16+会員・預かり資産!D33+会員・預かり資産!D35-損益計算書!D23 -> 2270.7626 | E30: =SUM(B30:D30) -> 4519.9522 | F30: 販売と持込が半々
A31: 0.75 | B31: =会員・預かり資産!B13*$A31*前提!$B$16+会員・預かり資産!B33+会員・預かり資産!B35-損益計算書!B23 -> 1336.0155 | C31: =会員・預かり資産!C13*$A31*前提!$B$16+会員・預かり資産!C33+会員・預かり資産!C35-損益計算書!C23 -> 2465.6741 | D31: =会員・預かり資産!D13*$A31*前提!$B$16+会員・預かり資産!D33+会員・預かり資産!D35-損益計算書!D23 -> 3733.2626 | E31: =SUM(B31:D31) -> 7534.9522 | F31: 販売中心
A32: 1 | B32: =会員・預かり資産!B13*$A32*前提!$B$16+会員・預かり資産!B33+会員・預かり資産!B35-損益計算書!B23 -> 1898.5155 | C32: =会員・預かり資産!C13*$A32*前提!$B$16+会員・預かり資産!C33+会員・預かり資産!C35-損益計算書!C23 -> 3455.6741 | D32: =会員・預かり資産!D13*$A32*前提!$B$16+会員・預かり資産!D33+会員・預かり資産!D35-損益計算書!D23 -> 5195.7626 | E32: =SUM(B32:D32) -> 10549.952 | F32: 前提シートの100%ケース
A34: 営業利益が黒字となる最低の販売伴有率 | B34: =IF(SUM(会員・預かり資産!B13:D13)*前提!$B$16=0,0,MAX(0,(SUM(損益計算書!B23:D23)-SUM(会員・預かり資産!B33:D33)-SUM(会員・預かり資産!B35:D35))/(SUM(会員・預かり資産!B13:D13)*前提!$B$16))) -> 0.12521126
A36: ■ E. ランク別のストック採算（★還元率を上げた分、上位ランクほどストック単体は厳しい）
A37: ランク | B37: マイル還元率 | C37: マイル実費用（対預かり） | D37: ストック利幅（成功報酬前） | E37: ストック利幅（成功報酬込） | F37: 判定（成功報酬前）
A38: =前提!A6 -> PRESTIGE | B38: =前提!D6 -> 0.04 | C38: =前提!D6*前提!$B$51 -> 0.019012 | D38: =前提!C6-前提!$B$19+前提!$B$32-C38 -> 0.002988 | E38: =D38+前提!$B$17*前提!$B$18 -> 0.020988 | F38: =IF(D38>=0,"ストック単体で黒字","成功報酬前は赤字") -> ストック単体で黒字 | H38: 管理料2.5%は全ランク共通なのに還元率は3.5→5.5%と上がるため、
A39: =前提!A7 -> GOLD | B39: =前提!D7 -> 0.05 | C39: =前提!D7*前提!$B$51 -> 0.023765 | D39: =前提!C7-前提!$B$19+前提!$B$32-C39 -> -0.001765 | E39: =D39+前提!$B$17*前提!$B$18 -> 0.016235 | F39: =IF(D39>=0,"ストック単体で黒字","成功報酬前は赤字") -> 成功報酬前は赤字 | H39: 上位ランクほどストック単体の利幅は薄い。上位ランクは1人あたりの販売粗利と
A40: =前提!A8 -> SIGNATURE | B40: =前提!D8 -> 0.06 | C40: =前提!D8*前提!$B$51 -> 0.028518 | D40: =前提!C8-前提!$B$19+前提!$B$32-C40 -> -0.006518 | E40: =D40+前提!$B$17*前提!$B$18 -> 0.011482 | F40: =IF(D40>=0,"ストック単体で黒字","成功報酬前は赤字") -> 成功報酬前は赤字 | H40: 成功報酬額が大きいことで正当化される構造であり、ストック採算だけで評価してはいけない。
H41: SIGNATUREをストック単体で黒字にするには発行1マイル原価をB42まで下げる必要がある（原価率55%単独では届かない）。
A42: 参考：全ランクがストック単体で黒字となる発行1マイル期待原価の上限 | B42: =IF(前提!$D$8=0,0,(前提!$C$8-前提!$B$19+前提!$B$32)/前提!$D$8) -> 0.36666667 | C42: ="現在は "&TEXT(前提!$B$51,"0.000") -> 現在は 0.475 | H42: 感度分析Bの原価率引下げと、0円原価チャネル（CLUB充当・オークション参加）の構成比引上げの併用で到達できる。

Sheet 会員メリット
A1: 会員メリット｜ランク別 金額シミュレーション
A2: このシートのみ金額単位：円。会員1人あたり。
A4: ■ 年間の直接メリット
A5: 項目 | B5: PRESTIGE | C5: GOLD | D5: SIGNATURE | E5: 考え方・備考
A6: 預かり額 | B6: =前提!$B$6*10000 -> 1000000 | C6: =前提!$B$7*10000 -> 5000000 | D6: =前提!$B$8*10000 -> 10000000
A7: 管理・保管手数料率 | B7: =前提!$C$6 -> 0.0275 | C7: =前提!$C$7 -> 0.0275 | D7: =前提!$C$8 -> 0.0275
A8: 年間管理・保管手数料 | B8: =B6*B7 -> 27500 | C8: =C6*C7 -> 137500 | D8: =D6*D7 -> 275000
A9: マイル還元率 | B9: =前提!$D$6 -> 0.04 | C9: =前提!$D$7 -> 0.05 | D9: =前提!$D$8 -> 0.06 | E9: 3.5 / 4.5 / 5.5%
A10: 年間付与マイル（額面） | B10: =B6*B9 -> 40000 | C10: =C6*C9 -> 250000 | D10: =D6*D9 -> 600000
A11: 最終利用率（1年以内） | B11: =前提!$B$35 -> 0.98 | C11: =前提!$B$35 -> 0.98 | D11: =前提!$B$35 -> 0.98
A12: 利用1マイルの平均交換価値 | B12: =前提!$G$50 -> 0.9 | C12: =前提!$G$50 -> 0.9 | D12: =前提!$G$50 -> 0.9 | E12: 交換先ミックスの加重平均
A13: 発行1マイルの期待利用価値 | B13: =前提!$B$52 -> 0.882 | C13: =前提!$B$52 -> 0.882 | D13: =前提!$B$52 -> 0.882 | E13: 平均交換価値 × 最終利用率
A14: 実利用ベースの年間マイル価値 | B14: =B10*B13 -> 35280 | C14: =C10*C13 -> 220500 | D14: =D10*D13 -> 529200
A15: 額面ベースの年間差引メリット | B15: =B10-B8 -> 12500 | C15: =C10-C8 -> 112500 | D15: =D10-D8 -> 325000 | E15: 全マイルを1円相当として見た表示上の差引（＝還元率－手数料率）
A16: ★実利用ベースの年間差引メリット | B16: =B14-B8 -> 7780 | C16: =C14-C8 -> 83000 | D16: =D14-D8 -> 254200 | E16: 交換先ミックスと利用率を反映した実質差引
A17: ★実質メリット率（預かり額比） | B17: =IF(B6=0,0,B16/B6) -> 0.00778 | C17: =IF(C6=0,0,C16/C6) -> 0.0166 | D17: =IF(D6=0,0,D16/D6) -> 0.02542
A18: 1.0円交換先だけで使った場合の差引 | B18: =B10*B11-B8 -> 11700 | C18: =C10*C11-C8 -> 107500 | D18: =D10*D11-D8 -> 313000 | E18: グランメゾンを使わない会員の上限値
A19: 損益分岐となる平均交換価値 | B19: =IF(B10*B11=0,0,B8/(B10*B11)) -> 0.70153061 | C19: =IF(C10*C11=0,0,C8/(C10*C11)) -> 0.56122449 | D19: =IF(D10*D11=0,0,D8/(D10*D11)) -> 0.46768707 | E19: これを上回れば手数料を回収
A21: ■ 3年間保有した場合の会員メリット（経済価値ベース）
A22: 項目 | B22: PRESTIGE | C22: GOLD | D22: SIGNATURE | E22: 考え方・備考
A23: 3年後ワイン評価額 | B23: =B6*(1+前提!$B$17)^3 -> 1191016 | C23: =C6*(1+前提!$B$17)^3 -> 5955080 | D23: =D6*(1+前提!$B$17)^3 -> 11910160 | E23: 預かり額×(1+6%)^3
A24: 3年間の値上がり益 | B24: =B23-B6 -> 191016 | C24: =C23-C6 -> 955080 | D24: =D23-D6 -> 1910160
A25: 成功報酬率 | B25: =前提!$B$18 -> 0.3 | C25: =前提!$B$18 -> 0.3 | D25: =前提!$B$18 -> 0.3 | E25: 25%
A26: 成功報酬（当社取分） | B26: =B24*B25 -> 57304.8 | C26: =C24*C25 -> 286524 | D26: =D24*D25 -> 573048
A27: 会員に残る値上がり益 | B27: =B24-B26 -> 133711.2 | C27: =C24-C26 -> 668556 | D27: =D24-D26 -> 1337112
A28: 3年累計マイル利用価値 | B28: =B14*3 -> 105840 | C28: =C14*3 -> 661500 | D28: =D14*3 -> 1587600
A29: 3年累計管理・保管手数料 | B29: =B8*3 -> 82500 | C29: =C8*3 -> 412500 | D29: =D8*3 -> 825000
A30: 3年累計マイル差引メリット | B30: =B28-B29 -> 23340 | C30: =C28-C29 -> 249000 | D30: =D28-D29 -> 762600
A31: ★3年間の総合メリット | B31: =B27+B30 -> 157051.2 | C31: =C27+C30 -> 917556 | D31: =D27+D30 -> 2099712 | E31: 値上がり益（会員取分）＋マイル差引
A32: ★元本に対する総合メリット率 | B32: =IF(B6=0,0,B31/B6) -> 0.1570512 | C32: =IF(C6=0,0,C31/C6) -> 0.1835112 | D32: =IF(D6=0,0,D31/D6) -> 0.2099712
A33: 3年後の会員価値（元本＋総合メリット） | B33: =B6+B31 -> 1157051.2 | C33: =C6+C31 -> 5917556 | D33: =D6+D31 -> 12099712
A34: 年率換算（CAGR） | B34: =IF(B6=0,0,(B33/B6)^(1/3)-1) -> 0.049826487 | C34: =IF(C6=0,0,(C33/C6)^(1/3)-1) -> 0.057768892 | D34: =IF(D6=0,0,(D33/D6)^(1/3)-1) -> 0.065593782
A36: ■ 交換先別の会員価値（利用1万マイルあたり）
A37: 交換先 | B37: 利用マイル内構成比 | C37: 交換レート | D37: 1万マイルの価値（円） | E37: 構成比加重価値（円）
A38: =前提!A43 -> 系列レストラン | B38: =前提!C43 -> 0.278 | C38: =前提!D43 -> 1 | D38: =10000*C38 -> 10000 | E38: =10000*B38*C38 -> 2780
A39: =前提!A44 -> グランメゾン（1P=0.5円） | B39: =前提!C44 -> 0.2 | C39: =前提!D44 -> 0.5 | D39: =10000*C39 -> 5000 | E39: =10000*B39*C39 -> 1000
A40: =前提!A45 -> WineBank CLUB 会費充当 | B40: =前提!C45 -> 0.133 | C40: =前提!D45 -> 1 | D40: =10000*C40 -> 10000 | E40: =10000*B40*C40 -> 1330
A41: =前提!A46 -> オークション参加 | B41: =前提!C46 -> 0.133 | C41: =前提!D46 -> 1 | D41: =10000*C41 -> 10000 | E41: =10000*B41*C41 -> 1330
A42: =前提!A47 -> ワインスクール | B42: =前提!C47 -> 0.111 | C42: =前提!D47 -> 1 | D42: =10000*C42 -> 10000 | E42: =10000*B42*C42 -> 1110
A43: =前提!A48 -> 会員交流イベント | B43: =前提!C48 -> 0.089 | C43: =前提!D48 -> 1 | D43: =10000*C43 -> 10000 | E43: =10000*B43*C43 -> 890
...
