Workbook

Sheet サマリー
A1: カンテサンス CF計画 サマリー（三つ星維持ケース・IM計画ベース）
A2: 単位：百万円。数値はすべて各CFシートからの参照です。金利4%・7年元利均等。
A4: ケースA：借入15億円・7年
A5: 指標 | B5: 2027 | C5: 2028 | D5: 2029 | E5: 2030 | F5: 2031 | G5: 2032 | H5: 6年計
A6: 売上高 | B6: =CF_借入15億!C5 -> 1062 | C6: =CF_借入15億!D5 -> 1095 | D6: =CF_借入15億!E5 -> 1129 | E6: =CF_借入15億!F5 -> 1169.7774 | F6: =CF_借入15億!G5 -> 1212.0277 | G6: =CF_借入15億!H5 -> 1255.8039 | H6: =SUM(B6:G6) -> 6923.6091
A7: 営業利益（IM計画） | B7: =CF_借入15億!C7 -> 556 | C7: =CF_借入15億!D7 -> 576 | D7: =CF_借入15億!E7 -> 598 | E7: =CF_借入15億!F7 -> 623.338 | F7: =CF_借入15億!G7 -> 649.74961 | G7: =CF_借入15億!H7 -> 677.2803 | H7: =SUM(B7:G7) -> 3680.3679
A8: 当社想定のEBITDA | B8: =CF_借入15億!C15 -> 577.6 | C8: =CF_借入15億!D15 -> 582.6 | D8: =CF_借入15億!E15 -> 604.6 | E8: =CF_借入15億!F15 -> 249.938 | F8: =CF_借入15億!G15 -> 276.34961 | G8: =CF_借入15億!H15 -> 703.8803 | H8: =SUM(B8:G8) -> 2994.9679
A9: 当期純利益 | B9: =CF_借入15億!C21 -> 339.5456 | C9: =CF_借入15億!D21 -> 347.80895 | D9: =CF_借入15億!E21 -> 367.42364 | E9: =CF_借入15億!F21 -> 140.15537 | F9: =CF_借入15億!G21 -> 163.08698 | G9: =CF_借入15億!H21 -> 449.37693 | H9: =SUM(B9:G9) -> 1807.3975
A10: 借入返済後のCF | B10: =CF_借入15億!C30 -> 83.031182 | C10: =CF_借入15億!D30 -> 120.29796 | D10: =CF_借入15億!E30 -> 132.01221 | E10: =CF_借入15億!F30 -> -103.47252 | F10: =CF_借入15億!G30 -> -89.086031 | G10: =CF_借入15億!H30 -> 188.31701 | H10: =SUM(B10:G10) -> 331.0998
A11: 期末現金残高 | B11: =CF_借入15億!C31 -> 220.43118 | C11: =CF_借入15億!D31 -> 340.72914 | D11: =CF_借入15億!E31 -> 472.74135 | E11: =CF_借入15億!F31 -> 369.26883 | F11: =CF_借入15億!G31 -> 280.18279 | G11: =CF_借入15億!H31 -> 468.4998
A12: 借入金期末残高 | B12: =CF_借入15億!C39 -> 1310.0856 | C12: =CF_借入15億!D39 -> 1112.5746 | D12: =CF_借入15億!E39 -> 907.16315 | E12: =CF_借入15億!F39 -> 693.53526 | F12: =CF_借入15億!G39 -> 471.36225 | G12: =CF_借入15億!H39 -> 240.30233
A13: DSCR | B13: =CF_借入15億!C40 -> 1.4786886 | C13: =CF_借入15億!D40 -> 1.4813566 | D13: =CF_借入15億!E40 -> 1.5282297 | E13: =CF_借入15億!F40 -> 0.58596817 | F13: =CF_借入15億!G40 -> 0.64353385 | G13: =CF_借入15億!H40 -> 1.753526
A14: 最低DSCR | B14: =MIN(B13:G13) -> 0.58596817
A15: 期中の最低現金残高 | B15: =MIN(B11:G11) -> 220.43118
A16: 資金不足を避けるために必要な追加の留保現金 | B16: =MAX(0,-B15) -> 0
A18: ケースB：借入20億円・7年
A19: 指標 | B19: 2027 | C19: 2028 | D19: 2029 | E19: 2030 | F19: 2031 | G19: 2032 | H19: 6年計
A20: 売上高 | B20: =CF_借入20億!C5 -> 1062 | C20: =CF_借入20億!D5 -> 1095 | D20: =CF_借入20億!E5 -> 1129 | E20: =CF_借入20億!F5 -> 1169.7774 | F20: =CF_借入20億!G5 -> 1212.0277 | G20: =CF_借入20億!H5 -> 1255.8039 | H20: =SUM(B20:G20) -> 6923.6091
A21: 営業利益（IM計画） | B21: =CF_借入20億!C7 -> 556 | C21: =CF_借入20億!D7 -> 576 | D21: =CF_借入20億!E7 -> 598 | E21: =CF_借入20億!F7 -> 623.338 | F21: =CF_借入20億!G7 -> 649.74961 | G21: =CF_借入20億!H7 -> 677.2803 | H21: =SUM(B21:G21) -> 3680.3679
A22: 当社想定のEBITDA | B22: =CF_借入20億!C15 -> 577.6 | C22: =CF_借入20億!D15 -> 582.6 | D22: =CF_借入20億!E15 -> 604.6 | E22: =CF_借入20億!F15 -> 249.938 | F22: =CF_借入20億!G15 -> 276.34961 | G22: =CF_借入20億!H15 -> 703.8803 | H22: =SUM(B22:G22) -> 2994.9679
A23: 当期純利益 | B23: =CF_借入20億!C21 -> 326.4256 | C23: =CF_借入20億!D21 -> 336.35007 | D23: =CF_借入20億!E21 -> 357.69232 | E23: =CF_借入20億!F21 -> 132.22071 | F23: =CF_借入20億!G21 -> 157.02085 | G23: =CF_借入20億!H21 -> 445.25408 | H23: =SUM(B23:G23) -> 1754.9637
A24: 借入返済後のCF | B24: =CF_借入20億!C30 -> 6.6063759 | C24: =CF_借入20億!D30 -> 43.002079 | D24: =CF_借入20億!E30 -> 53.810411 | E24: =CF_借入20億!F30 -> -182.61647 | F24: =CF_借入20億!G30 -> -169.20982 | G24: =CF_借入20億!H30 -> 107.17418 | H24: =SUM(B24:G24) -> -141.23325
A25: 期末現金残高 | B25: =CF_借入20億!C31 -> 144.00638 | C25: =CF_借入20億!D31 -> 187.00846 | D25: =CF_借入20億!E31 -> 240.81887 | E25: =CF_借入20億!F31 -> 58.202391 | F25: =CF_借入20億!G31 -> -111.00743 | G25: =CF_借入20億!H31 -> -3.8332499
A26: 借入金期末残高 | B26: =CF_借入20億!C39 -> 1746.7808 | C26: =CF_借入20億!D39 -> 1483.4328 | D26: =CF_借入20億!E39 -> 1209.5509 | E26: =CF_借入20億!F39 -> 924.71368 | F26: =CF_借入20億!G39 -> 628.483 | G26: =CF_借入20億!H39 -> 320.4031
A27: DSCR | B27: =CF_借入20億!C40 -> 1.1296635 | C27: =CF_借入20億!D40 -> 1.1290504 | D27: =CF_借入20億!E40 -> 1.1614865 | E27: =CF_借入20億!F40 -> 0.45196297 | F27: =CF_借入20億!G40 -> 0.4921967 | G27: =CF_借入20億!H40 -> 1.3216326
A28: 最低DSCR | B28: =MIN(B27:G27) -> 0.45196297
A29: 期中の最低現金残高 | B29: =MIN(B25:G25) -> -111.00743
A30: 資金不足を避けるために必要な追加の留保現金 | B30: =MAX(0,-B29) -> 111.00743
A32: 売上高の年平均成長率（2030年以降に適用） | B32: =前提条件!B14 -> 0.036118194
A33: 営業利益の年平均成長率（2030年以降に適用） | B33: =前提条件!B15 -> 0.04237124
A34: 節税効果の6年累計（退職金・コンサル費） | B34: =CF_借入20億!H47 -> 352.6
A36: 【売上・営業利益】2027〜2029年はIM（2026年9月）42ページ「監修後）売上横ばいケース」の計画値（値上げ・サービス料12%化を織り込み済み）。2030〜2032年は、2026→2029年の年平均成長率（売上・営業利益それぞれ）で延長。
A37: 【岸田様へのお支払い】決済時に役員退職金2.25億円（対象会社が支給・2026年度に損金算入）。2030年・2031年に岸田様の法人へコンサルティング費として各4億円（対象会社の費用）。IMの営業利益は岸田氏の現行報酬（約1.03億円）控除後のため、取得後の報酬との差額を調整。
A38: 【税務上の留意点】退職金は賞与を含む実質月額での算定となるため否認リスクあり。コンサルティング費は役務提供の実態と対価の相当性が必要で、実態が伴わない場合は寄附金・株式対価の後払いと認定され損金不算入となるリスクが高い。双方の税理士の確認が前提。
A39: 【子会社】カンテサンスプラスの現預金（役員借入金返済後 約0.37億円）を決済時の手元資金に加算。ブリッジ返済原資21.4億円（プティ・ボノム単体の現預金17.4＋役員貸付金5.0−留保1.0）には含めていないため、SPCの必要資金を減らす方に使うこともできる。
A40: 【モデルの簡略化】運転資本の増減は無視。法人税は発生年度に納付（FY2026分のみ2027年に納付）。欠損金の繰越は考慮せず。消費税は除く。買収借入（15億円または20億円・7年・金利4%）は合併後の会社が返済する前提（WineBankで借りる形の場合は、借入返済後のCFが配当原資）。

Sheet 前提条件
A1: カンテサンス CF計画（2027〜2032年・三つ星維持ケース）前提条件
A2: 単位：百万円。青字＝入力値（変更可）、黒字＝計算式。黄色セルは主要な仮定です。
A4: 項目 | B4: FY2026／固定値 | C4: 2027 | D4: 2028 | E4: 2029 | F4: 2030 | G4: 2031 | H4: 2032 | I4: 出所・根拠
A5: ■ IM 42ページ「監修後）売上横ばいケース」の計画（2029年まで）
A6: 売上高(店舗) | B6: 949 | C6: 996 | D6: 1029 | E6: 1062 | I6: IM（2026年9月）42ページ 計画値
A7: 売上高(ガトー) | B7: 66 | C7: 66 | D7: 66 | E7: 66 | I7: IM（2026年9月）42ページ 計画値
A8: 売上原価 | B8: 217 | C8: 225 | D8: 232 | E8: 240 | I8: IM（2026年9月）42ページ 計画値
A9: 販売費及び一般管理費 | B9: 269 | C9: 282 | D9: 287 | E9: 291 | I9: IM（2026年9月）42ページ 計画値
A10: 営業利益 | B10: 528 | C10: 556 | D10: 576 | E10: 598 | I10: IM（2026年9月）42ページ 計画値
A11: 売上高 合計 | B11: 1015 | C11: 1062 | D11: 1095 | E11: 1129 | I11: IM（2026年9月）42ページ 計画値（店舗＋ガトーの内訳は端数処理のため合計と1百万円ずれる年あり）
A13: ■ 2030年以降の成長率（2026→2029年の年平均成長率を延長）
A14: 売上高の年平均成長率（2026→2029） | B14: =(E11/B11)^(1/3)-1 -> 0.036118194 | I14: 計算：IM計画の2026→2029年の年平均
A15: 営業利益の年平均成長率（2026→2029） | B15: =(E10/B10)^(1/3)-1 -> 0.04237124 | I15: 計算：IM計画の2026→2029年の年平均
A16: 売上高の成長率（2030〜2032年に適用） | F16: =$B$14 -> 0.036118194 | G16: =$B$14 -> 0.036118194 | H16: =$B$14 -> 0.036118194 | I16: 既定値＝上記の年平均。数値を直接入力して上書きできます
A17: 営業利益の成長率（2030〜2032年に適用） | F17: =$B$15 -> 0.04237124 | G17: =$B$15 -> 0.04237124 | H17: =$B$15 -> 0.04237124 | I17: 既定値＝上記の年平均。数値を直接入力して上書きできます
A19: ■ 当社取得後の調整（IMの営業利益は岸田氏の現行報酬控除後）
A20: 岸田氏の現行報酬（IM計画に含まれる） | B20: 102.6 | I20: 月額60万円×12＋事前確定届出給与95.4百万円（IM計画は現行報酬を前提＝売主QA②）
A21: 岸田氏の役員報酬（取得後） | C21: 20 | D21: 20 | E21: 20 | F21: 0 | G21: 0 | H21: 0 | I21: 条件合意：ロックアップ3年（B案）は年2,000万円、以降は出勤義務なし
A22: 後継料理長の追加人件費 | C22: 0 | D22: 15 | E22: 15 | F22: 15 | G22: 15 | H22: 15 | I22: 仮定：2028年から年15百万円
A23: AM管理報酬 | C23: 61 | D23: 61 | E23: 61 | F23: 61 | G23: 61 | H23: 61 | I23: SPC出資総額30.6億円×2%（AM契約で確定）
A24: 岸田氏法人へのコンサルティング費（アーンアウト） | C24: 0 | D24: 0 | E24: 0 | F24: 400 | G24: 400 | H24: 0 | I24: ユーザー指定：4年目・5年目に三つ星維持で各4億円、対象会社の費用として支払う
A26: ■ 税・投資・資金
A27: 実効税率 | B27: 0.344 | I27: 2025年実績（銀行提出資料と同じ）
A28: 減価償却費（年） | B28: 0 | I28: IM計画に合わせて0（設備投資の償却による節税は保守的に考慮しない）
A29: 設備投資（年） | B29: 30 | I29: 仮定（IMは計画なし。銀行提出資料と同じ保守的な水準）
A30: 決済時の留保現金 | B30: 100 | I30: 銀行提出資料：運転資金として1.0億円を留保
A31: FY2026 未払法人税等（退職金控除前） | B31: 114 | I31: 銀行提出資料：2026年12月期の未払税金1.14億円
A32: 決済時の役員退職金（対象会社が支給） | B32: 225 | I32: 条件合意：前払い2.25億円を退職金に振替（ユーザー指定）
A33: ■ 買収借入（合併後の会社が7年元利均等で返済）
A34: 借入額（ケースA） | B34: 1500 | I34: ユーザー指定：15億円・7年
A35: 金利 | B35: 0.04 | I35: ユーザー指定：金利上昇を含め4%
A36: 返済年数 | B36: 7 | I36: 仮定（みずほ銀行と協議中）
A37: 借入額（ケースB） | B37: 2000 | I37: ユーザー指定：20億円・7年
A39: ■ 子会社 カンテサンスプラス株式会社（プティ・ボノム100%子会社）
A40: 子会社の現預金 | B40: 42.9 | I40: 第10期（2026年6月期）決算書：42,906,344円
A41: 子会社の役員借入金（岸田様への返済） | B41: 5.5 | I41: 第10期（2026年6月期）決算書：5,543,167円。決済までに返済する前提で控除
A42: 決済時に使える子会社の現預金 | B42: =B40-B41 -> 37.4 | I42: 配当（完全子法人からの配当は益金不算入・源泉徴収なし）又は合併で親会社に移す。年間の利益（約4百万円）はCFに含めず保守的に試算

Sheet CF_借入15億
A1: カンテサンス CF計画（2027〜2032年・三つ星維持ケース）｜借入15億円・7年・金利4%
A2: 単位：百万円。2029年まではIM 42ページの計画値、2030年以降はIMの年平均成長率で延長。緑字＝前提条件シートの参照。
A4: 項目 | B4: FY2026（参考） | C4: 2027 | D4: 2028 | E4: 2029 | F4: 2030 | G4: 2031 | H4: 2032
A5: 売上高（IM計画・2030年以降は延長） | B5: =前提条件!B11 -> 1015 | C5: =前提条件!C11 -> 1062 | D5: =前提条件!D11 -> 1095 | E5: =前提条件!E11 -> 1129 | F5: =E5*(1+前提条件!F16) -> 1169.7774 | G5: =F5*(1+前提条件!G16) -> 1212.0277 | H5: =G5*(1+前提条件!H16) -> 1255.8039
A6: 売上高成長率 | C6: =C5/B5-1 -> 0.046305419 | D6: =D5/C5-1 -> 0.031073446 | E6: =E5/D5-1 -> 0.031050228 | F6: =F5/E5-1 -> 0.036118194 | G6: =G5/F5-1 -> 0.036118194 | H6: =H5/G5-1 -> 0.036118194
A7: 営業利益（IM計画・岸田氏の現行報酬控除後） | B7: =前提条件!B10 -> 528 | C7: =前提条件!C10 -> 556 | D7: =前提条件!D10 -> 576 | E7: =前提条件!E10 -> 598 | F7: =E7*(1+前提条件!F17) -> 623.338 | G7: =F7*(1+前提条件!G17) -> 649.74961 | H7: =G7*(1+前提条件!H17) -> 677.2803
A8: 営業利益率 | B8: =B7/B5 -> 0.52019704 | C8: =IF(C5=0,0,C7/C5) -> 0.52354049 | D8: =IF(D5=0,0,D7/D5) -> 0.5260274 | E8: =IF(E5=0,0,E7/E5) -> 0.52967228 | F8: =IF(F5=0,0,F7/F5) -> 0.53286889 | G8: =IF(G5=0,0,G7/G5) -> 0.53608479 | H8: =IF(H5=0,0,H7/H5) -> 0.5393201
A9: ■ 当社取得後の調整
A10: ＋ 岸田氏の現行報酬の戻し | C10: =前提条件!$B$20 -> 102.6 | D10: =前提条件!$B$20 -> 102.6 | E10: =前提条件!$B$20 -> 102.6 | F10: =前提条件!$B$20 -> 102.6 | G10: =前提条件!$B$20 -> 102.6 | H10: =前提条件!$B$20 -> 102.6
A11: − 岸田氏の役員報酬（取得後） | C11: =-前提条件!C21 -> -20 | D11: =-前提条件!D21 -> -20 | E11: =-前提条件!E21 -> -20 | F11: =-前提条件!F21 -> 0 | G11: =-前提条件!G21 -> 0 | H11: =-前提条件!H21 -> 0
A12: − 後継料理長の追加人件費 | C12: =-前提条件!C22 -> 0 | D12: =-前提条件!D22 -> -15 | E12: =-前提条件!E22 -> -15 | F12: =-前提条件!F22 -> -15 | G12: =-前提条件!G22 -> -15 | H12: =-前提条件!H22 -> -15
A13: − AM管理報酬 | C13: =-前提条件!C23 -> -61 | D13: =-前提条件!D23 -> -61 | E13: =-前提条件!E23 -> -61 | F13: =-前提条件!F23 -> -61 | G13: =-前提条件!G23 -> -61 | H13: =-前提条件!H23 -> -61
A14: − 岸田氏法人へのコンサルティング費 | C14: =-前提条件!C24 -> 0 | D14: =-前提条件!D24 -> 0 | E14: =-前提条件!E24 -> 0 | F14: =-前提条件!F24 -> -400 | G14: =-前提条件!G24 -> -400 | H14: =-前提条件!H24 -> 0
A15: 当社想定のEBITDA | C15: =SUM(C7,C10:C14) -> 577.6 | D15: =SUM(D7,D10:D14) -> 582.6 | E15: =SUM(E7,E10:E14) -> 604.6 | F15: =SUM(F7,F10:F14) -> 249.938 | G15: =SUM(G7,G10:G14) -> 276.34961 | H15: =SUM(H7,H10:H14) -> 703.8803
A16: 減価償却費 | C16: =前提条件!$B$28 -> 0 | D16: =前提条件!$B$28 -> 0 | E16: =前提条件!$B$28 -> 0 | F16: =前提条件!$B$28 -> 0 | G16: =前提条件!$B$28 -> 0 | H16: =前提条件!$B$28 -> 0
A17: 営業利益（当社想定） | C17: =C15-C16 -> 577.6 | D17: =D15-D16 -> 582.6 | E17: =E15-E16 -> 604.6 | F17: =F15-F16 -> 249.938 | G17: =G15-G16 -> 276.34961 | H17: =H15-H16 -> 703.8803
A18: 支払利息 | C18: =C35*前提条件!$B$35 -> 60 | D18: =D35*前提条件!$B$35 -> 52.403423 | E18: =E35*前提条件!$B$35 -> 44.502983 | F18: =F35*前提条件!$B$35 -> 36.286526 | G18: =G35*前提条件!$B$35 -> 27.74141 | H18: =H35*前提条件!$B$35 -> 18.85449
A19: 税引前利益 | C19: =C17-C18 -> 517.6 | D19: =D17-D18 -> 530.19658 | E19: =E17-E18 -> 560.09702 | F19: =F17-F18 -> 213.65148 | G19: =G17-G18 -> 248.6082 | H19: =H17-H18 -> 685.02581
A20: 法人税等 | C20: =MAX(0,C19)*前提条件!$B$27 -> 178.0544 | D20: =MAX(0,D19)*前提条件!$B$27 -> 182.38762 | E20: =MAX(0,E19)*前提条件!$B$27 -> 192.67337 | F20: =MAX(0,F19)*前提条件!$B$27 -> 73.496108 | G20: =MAX(0,G19)*前提条件!$B$27 -> 85.521219 | H20: =MAX(0,H19)*前提条件!$B$27 -> 235.64888
A21: 当期純利益 | C21: =C19-C20 -> 339.5456 | D21: =D19-D20 -> 347.80895 | E21: =E19-E20 -> 367.42364 | F21: =F19-F20 -> 140.15537 | G21: =G19-G20 -> 163.08698 | H21: =H19-H20 -> 449.37693
A23: ■ キャッシュフロー
A24: 当期純利益 | C24: =C21 -> 339.5456 | D24: =D21 -> 347.80895 | E24: =E21 -> 367.42364 | F24: =F21 -> 140.15537 | G24: =G21 -> 163.08698 | H24: =H21 -> 449.37693
A25: 減価償却費 | C25: =C16 -> 0 | D25: =D16 -> 0 | E25: =E16 -> 0 | F25: =F16 -> 0 | G25: =G16 -> 0 | H25: =H16 -> 0
A26: 設備投資 | C26: =-前提条件!$B$29 -> -30 | D26: =-前提条件!$B$29 -> -30 | E26: =-前提条件!$B$29 -> -30 | F26: =-前提条件!$B$29 -> -30 | G26: =-前提条件!$B$29 -> -30 | H26: =-前提条件!$B$29 -> -30
A27: FY2026分 法人税の納付（退職金の損金算入後） | C27: =-(前提条件!B31-前提条件!B32*前提条件!B27) -> -36.6 | D27: 0 | E27: 0 | F27: 0 | G27: 0 | H27: 0
A28: 営業CF（借入返済前） | C28: =SUM(C24:C27) -> 272.9456 | D28: =SUM(D24:D27) -> 317.80895 | E28: =SUM(E24:E27) -> 337.42364 | F28: =SUM(F24:F27) -> 110.15537 | G28: =SUM(G24:G27) -> 133.08698 | H28: =SUM(H24:H27) -> 419.37693
A29: 借入元本の返済 | C29: =-C38 -> -189.91442 | D29: =-D38 -> -197.51099 | E29: =-E38 -> -205.41143 | F29: =-F38 -> -213.62789 | G29: =-G38 -> -222.17301 | H29: =-H38 -> -231.05993
A30: 借入返済後のCF | C30: =C28+C29 -> 83.031182 | D30: =D28+D29 -> 120.29796 | E30: =E28+E29 -> 132.01221 | F30: =F28+F29 -> -103.47252 | G30: =G28+G29 -> -89.086031 | H30: =H28+H29 -> 188.31701
A31: 期末現金残高（子会社の現預金を含む） | C31: =前提条件!B30+前提条件!B42+C30 -> 220.43118 | D31: =C31+D30 -> 340.72914 | E31: =D31+E30 -> 472.74135 | F31: =E31+F30 -> 369.26883 | G31: =F31+G30 -> 280.18279 | H31: =G31+H30 -> 468.4998
A34: ■ 買収借入（7年元利均等）
A35: 期首残高 | C35: =前提条件!B34 -> 1500 | D35: =C39 -> 1310.0856 | E35: =D39 -> 1112.5746 | F35: =E39 -> 907.16315 | G35: =F39 -> 693.53526 | H35: =G39 -> 471.36225
A36: 元利返済額 | C36: =IF(C35<=0.001,0,-PMT(前提条件!$B$35,前提条件!$B$36,前提条件!$B$34)) -> 249.91442 | D36: =IF(D35<=0.001,0,-PMT(前提条件!$B$35,前提条件!$B$36,前提条件!$B$34)) -> 249.91442 | E36: =IF(E35<=0.001,0,-PMT(前提条件!$B$35,前提条件!$B$36,前提条件!$B$34)) -> 249.91442 | F36: =IF(F35<=0.001,0,-PMT(前提条件!$B$35,前提条件!$B$36,前提条件!$B$34)) -> 249.91442 | G36: =IF(G35<=0.001,0,-PMT(前提条件!$B$35,前提条件!$B$36,前提条件!$B$34)) -> 249.91442 | H36: =IF(H35<=0.001,0,-PMT(前提条件!$B$35,前提条件!$B$36,前提条件!$B$34)) -> 249.91442
A37: うち利息 | C37: =C18 -> 60 | D37: =D18 -> 52.403423 | E37: =E18 -> 44.502983 | F37: =F18 -> 36.286526 | G37: =G18 -> 27.74141 | H37: =H18 -> 18.85449
A38: うち元本 | C38: =MIN(C35,C36-C37) -> 189.91442 | D38: =MIN(D35,D36-D37) -> 197.51099 | E38: =MIN(E35,E36-E37) -> 205.41143 | F38: =MIN(F35,F36-F37) -> 213.62789 | G38: =MIN(G35,G36-G37) -> 222.17301 | H38: =MIN(H35,H36-H37) -> 231.05993
A39: 期末残高 | C39: =C35-C38 -> 1310.0856 | D39: =D35-D38 -> 1112.5746 | E39: =E35-E38 -> 907.16315 | F39: =F35-F38 -> 693.53526 | G39: =G35-G38 -> 471.36225 | H39: =H35-H38 -> 240.30233
A40: DSCR（返済余力） | C40: =IF(C36=0,0,(C15-C20-前提条件!$B$29)/C36) -> 1.4786886 | D40: =IF(D36=0,0,(D15-D20-前提条件!$B$29)/D36) -> 1.4813566 | E40: =IF(E36=0,0,(E15-E20-前提条件!$B$29)/E36) -> 1.5282297 | F40: =IF(F36=0,0,(F15-F20-前提条件!$B$29)/F36) -> 0.58596817 | G40: =IF(G36=0,0,(G15-G20-前提条件!$B$29)/G36) -> 0.64353385 | H40: =IF(H36=0,0,(H15-H20-前提条件!$B$29)/H36) -> 1.753526
A41: DSCR＝（EBITDA−法人税等−設備投資）÷元利返済額。1.0倍未満の年は、それまでに積み上がった現金で返済します。
A43: ■ 損金算入による節税効果（ご参考）
A44: 決済時の役員退職金（2026年度に損金算入） | C44: =前提条件!B32*前提条件!B27 -> 77.4 | D44: 0 | E44: 0 | F44: 0 | G44: 0 | H44: 0
A45: コンサルティング費（アーンアウト） | C45: =-C14*前提条件!$B$27 -> 0 | D45: =-D14*前提条件!$B$27 -> 0 | E45: =-E14*前提条件!$B$27 -> 0 | F45: =-F14*前提条件!$B$27 -> 137.6 | G45: =-G14*前提条件!$B$27 -> 137.6 | H45: =-H14*前提条件!$B$27 -> 0
...

Sheet CF_借入20億
A1: カンテサンス CF計画（2027〜2032年・三つ星維持ケース）｜借入20億円・7年・金利4%
A2: 単位：百万円。2029年まではIM 42ページの計画値、2030年以降はIMの年平均成長率で延長。緑字＝前提条件シートの参照。
A4: 項目 | B4: FY2026（参考） | C4: 2027 | D4: 2028 | E4: 2029 | F4: 2030 | G4: 2031 | H4: 2032
A5: 売上高（IM計画・2030年以降は延長） | B5: =前提条件!B11 -> 1015 | C5: =前提条件!C11 -> 1062 | D5: =前提条件!D11 -> 1095 | E5: =前提条件!E11 -> 1129 | F5: =E5*(1+前提条件!F16) -> 1169.7774 | G5: =F5*(1+前提条件!G16) -> 1212.0277 | H5: =G5*(1+前提条件!H16) -> 1255.8039
A6: 売上高成長率 | C6: =C5/B5-1 -> 0.046305419 | D6: =D5/C5-1 -> 0.031073446 | E6: =E5/D5-1 -> 0.031050228 | F6: =F5/E5-1 -> 0.036118194 | G6: =G5/F5-1 -> 0.036118194 | H6: =H5/G5-1 -> 0.036118194
A7: 営業利益（IM計画・岸田氏の現行報酬控除後） | B7: =前提条件!B10 -> 528 | C7: =前提条件!C10 -> 556 | D7: =前提条件!D10 -> 576 | E7: =前提条件!E10 -> 598 | F7: =E7*(1+前提条件!F17) -> 623.338 | G7: =F7*(1+前提条件!G17) -> 649.74961 | H7: =G7*(1+前提条件!H17) -> 677.2803
A8: 営業利益率 | B8: =B7/B5 -> 0.52019704 | C8: =IF(C5=0,0,C7/C5) -> 0.52354049 | D8: =IF(D5=0,0,D7/D5) -> 0.5260274 | E8: =IF(E5=0,0,E7/E5) -> 0.52967228 | F8: =IF(F5=0,0,F7/F5) -> 0.53286889 | G8: =IF(G5=0,0,G7/G5) -> 0.53608479 | H8: =IF(H5=0,0,H7/H5) -> 0.5393201
A9: ■ 当社取得後の調整
A10: ＋ 岸田氏の現行報酬の戻し | C10: =前提条件!$B$20 -> 102.6 | D10: =前提条件!$B$20 -> 102.6 | E10: =前提条件!$B$20 -> 102.6 | F10: =前提条件!$B$20 -> 102.6 | G10: =前提条件!$B$20 -> 102.6 | H10: =前提条件!$B$20 -> 102.6
A11: − 岸田氏の役員報酬（取得後） | C11: =-前提条件!C21 -> -20 | D11: =-前提条件!D21 -> -20 | E11: =-前提条件!E21 -> -20 | F11: =-前提条件!F21 -> 0 | G11: =-前提条件!G21 -> 0 | H11: =-前提条件!H21 -> 0
A12: − 後継料理長の追加人件費 | C12: =-前提条件!C22 -> 0 | D12: =-前提条件!D22 -> -15 | E12: =-前提条件!E22 -> -15 | F12: =-前提条件!F22 -> -15 | G12: =-前提条件!G22 -> -15 | H12: =-前提条件!H22 -> -15
A13: − AM管理報酬 | C13: =-前提条件!C23 -> -61 | D13: =-前提条件!D23 -> -61 | E13: =-前提条件!E23 -> -61 | F13: =-前提条件!F23 -> -61 | G13: =-前提条件!G23 -> -61 | H13: =-前提条件!H23 -> -61
A14: − 岸田氏法人へのコンサルティング費 | C14: =-前提条件!C24 -> 0 | D14: =-前提条件!D24 -> 0 | E14: =-前提条件!E24 -> 0 | F14: =-前提条件!F24 -> -400 | G14: =-前提条件!G24 -> -400 | H14: =-前提条件!H24 -> 0
A15: 当社想定のEBITDA | C15: =SUM(C7,C10:C14) -> 577.6 | D15: =SUM(D7,D10:D14) -> 582.6 | E15: =SUM(E7,E10:E14) -> 604.6 | F15: =SUM(F7,F10:F14) -> 249.938 | G15: =SUM(G7,G10:G14) -> 276.34961 | H15: =SUM(H7,H10:H14) -> 703.8803
A16: 減価償却費 | C16: =前提条件!$B$28 -> 0 | D16: =前提条件!$B$28 -> 0 | E16: =前提条件!$B$28 -> 0 | F16: =前提条件!$B$28 -> 0 | G16: =前提条件!$B$28 -> 0 | H16: =前提条件!$B$28 -> 0
A17: 営業利益（当社想定） | C17: =C15-C16 -> 577.6 | D17: =D15-D16 -> 582.6 | E17: =E15-E16 -> 604.6 | F17: =F15-F16 -> 249.938 | G17: =G15-G16 -> 276.34961 | H17: =H15-H16 -> 703.8803
A18: 支払利息 | C18: =C35*前提条件!$B$35 -> 80 | D18: =D35*前提条件!$B$35 -> 69.871231 | E18: =E35*前提条件!$B$35 -> 59.337311 | F18: =F35*前提条件!$B$35 -> 48.382035 | G18: =G35*前提条件!$B$35 -> 36.988547 | H18: =H35*前提条件!$B$35 -> 25.13932
A19: 税引前利益 | C19: =C17-C18 -> 497.6 | D19: =D17-D18 -> 512.72877 | E19: =E17-E18 -> 545.26269 | F19: =F17-F18 -> 201.55597 | G19: =G17-G18 -> 239.36106 | H19: =H17-H18 -> 678.74098
A20: 法人税等 | C20: =MAX(0,C19)*前提条件!$B$27 -> 171.1744 | D20: =MAX(0,D19)*前提条件!$B$27 -> 176.3787 | E20: =MAX(0,E19)*前提条件!$B$27 -> 187.57036 | F20: =MAX(0,F19)*前提条件!$B$27 -> 69.335253 | G20: =MAX(0,G19)*前提条件!$B$27 -> 82.340204 | H20: =MAX(0,H19)*前提条件!$B$27 -> 233.4869
A21: 当期純利益 | C21: =C19-C20 -> 326.4256 | D21: =D19-D20 -> 336.35007 | E21: =E19-E20 -> 357.69232 | F21: =F19-F20 -> 132.22071 | G21: =G19-G20 -> 157.02085 | H21: =H19-H20 -> 445.25408
A23: ■ キャッシュフロー
A24: 当期純利益 | C24: =C21 -> 326.4256 | D24: =D21 -> 336.35007 | E24: =E21 -> 357.69232 | F24: =F21 -> 132.22071 | G24: =G21 -> 157.02085 | H24: =H21 -> 445.25408
A25: 減価償却費 | C25: =C16 -> 0 | D25: =D16 -> 0 | E25: =E16 -> 0 | F25: =F16 -> 0 | G25: =G16 -> 0 | H25: =H16 -> 0
A26: 設備投資 | C26: =-前提条件!$B$29 -> -30 | D26: =-前提条件!$B$29 -> -30 | E26: =-前提条件!$B$29 -> -30 | F26: =-前提条件!$B$29 -> -30 | G26: =-前提条件!$B$29 -> -30 | H26: =-前提条件!$B$29 -> -30
A27: FY2026分 法人税の納付（退職金の損金算入後） | C27: =-(前提条件!B31-前提条件!B32*前提条件!B27) -> -36.6 | D27: 0 | E27: 0 | F27: 0 | G27: 0 | H27: 0
A28: 営業CF（借入返済前） | C28: =SUM(C24:C27) -> 259.8256 | D28: =SUM(D24:D27) -> 306.35007 | E28: =SUM(E24:E27) -> 327.69232 | F28: =SUM(F24:F27) -> 102.22071 | G28: =SUM(G24:G27) -> 127.02085 | H28: =SUM(H24:H27) -> 415.25408
A29: 借入元本の返済 | C29: =-C38 -> -253.21922 | D29: =-D38 -> -263.34799 | E29: =-E38 -> -273.88191 | F29: =-F38 -> -284.83719 | G29: =-G38 -> -296.23068 | H29: =-H38 -> -308.0799
A30: 借入返済後のCF | C30: =C28+C29 -> 6.6063759 | D30: =D28+D29 -> 43.002079 | E30: =E28+E29 -> 53.810411 | F30: =F28+F29 -> -182.61647 | G30: =G28+G29 -> -169.20982 | H30: =H28+H29 -> 107.17418
A31: 期末現金残高（子会社の現預金を含む） | C31: =前提条件!B30+前提条件!B42+C30 -> 144.00638 | D31: =C31+D30 -> 187.00846 | E31: =D31+E30 -> 240.81887 | F31: =E31+F30 -> 58.202391 | G31: =F31+G30 -> -111.00743 | H31: =G31+H30 -> -3.8332499
A34: ■ 買収借入（7年元利均等）
A35: 期首残高 | C35: =前提条件!B37 -> 2000 | D35: =C39 -> 1746.7808 | E35: =D39 -> 1483.4328 | F35: =E39 -> 1209.5509 | G35: =F39 -> 924.71368 | H35: =G39 -> 628.483
A36: 元利返済額 | C36: =IF(C35<=0.001,0,-PMT(前提条件!$B$35,前提条件!$B$36,前提条件!$B$37)) -> 333.21922 | D36: =IF(D35<=0.001,0,-PMT(前提条件!$B$35,前提条件!$B$36,前提条件!$B$37)) -> 333.21922 | E36: =IF(E35<=0.001,0,-PMT(前提条件!$B$35,前提条件!$B$36,前提条件!$B$37)) -> 333.21922 | F36: =IF(F35<=0.001,0,-PMT(前提条件!$B$35,前提条件!$B$36,前提条件!$B$37)) -> 333.21922 | G36: =IF(G35<=0.001,0,-PMT(前提条件!$B$35,前提条件!$B$36,前提条件!$B$37)) -> 333.21922 | H36: =IF(H35<=0.001,0,-PMT(前提条件!$B$35,前提条件!$B$36,前提条件!$B$37)) -> 333.21922
A37: うち利息 | C37: =C18 -> 80 | D37: =D18 -> 69.871231 | E37: =E18 -> 59.337311 | F37: =F18 -> 48.382035 | G37: =G18 -> 36.988547 | H37: =H18 -> 25.13932
A38: うち元本 | C38: =MIN(C35,C36-C37) -> 253.21922 | D38: =MIN(D35,D36-D37) -> 263.34799 | E38: =MIN(E35,E36-E37) -> 273.88191 | F38: =MIN(F35,F36-F37) -> 284.83719 | G38: =MIN(G35,G36-G37) -> 296.23068 | H38: =MIN(H35,H36-H37) -> 308.0799
A39: 期末残高 | C39: =C35-C38 -> 1746.7808 | D39: =D35-D38 -> 1483.4328 | E39: =E35-E38 -> 1209.5509 | F39: =F35-F38 -> 924.71368 | G39: =G35-G38 -> 628.483 | H39: =H35-H38 -> 320.4031
A40: DSCR（返済余力） | C40: =IF(C36=0,0,(C15-C20-前提条件!$B$29)/C36) -> 1.1296635 | D40: =IF(D36=0,0,(D15-D20-前提条件!$B$29)/D36) -> 1.1290504 | E40: =IF(E36=0,0,(E15-E20-前提条件!$B$29)/E36) -> 1.1614865 | F40: =IF(F36=0,0,(F15-F20-前提条件!$B$29)/F36) -> 0.45196297 | G40: =IF(G36=0,0,(G15-G20-前提条件!$B$29)/G36) -> 0.4921967 | H40: =IF(H36=0,0,(H15-H20-前提条件!$B$29)/H36) -> 1.3216326
A41: DSCR＝（EBITDA−法人税等−設備投資）÷元利返済額。1.0倍未満の年は、それまでに積み上がった現金で返済します。
A43: ■ 損金算入による節税効果（ご参考）
A44: 決済時の役員退職金（2026年度に損金算入） | C44: =前提条件!B32*前提条件!B27 -> 77.4 | D44: 0 | E44: 0 | F44: 0 | G44: 0 | H44: 0
A45: コンサルティング費（アーンアウト） | C45: =-C14*前提条件!$B$27 -> 0 | D45: =-D14*前提条件!$B$27 -> 0 | E45: =-E14*前提条件!$B$27 -> 0 | F45: =-F14*前提条件!$B$27 -> 137.6 | G45: =-G14*前提条件!$B$27 -> 137.6 | H45: =-H14*前提条件!$B$27 -> 0
...
