Workbook

Sheet サマリー
A1: BRASSERIE Thierry Marx 5か年事業計画 rev2（FY2027-FY2031）
A2: 単位：百万円／FY＝4月〜翌3月／六本木店 事業収支 rev2（2026年10月改定）の単店economicsに基づく。
A4: ■ 出店ロードマップ
A5: FY2027 | B5: 六本木ミッドタウン 1店（2027年4月開業） | E5: 期末 1店
A6: FY2028 | B6: 札幌・大阪 2店 | E6: 期末 3店
A7: FY2029 | B7: 首都圏・他政令指定都市 2店 | E7: 期末 5店
A8: FY2030 | B8: リゾート含め 年2店 | E8: 期末 7店
A9: FY2031 | B9: リゾート含め 年2店 | E9: 期末 9店
A11: ■ 連結業績サマリー
A12: 項 目 | C12: FY2027 | D12: FY2028 | E12: FY2029 | F12: FY2030 | G12: FY2031 | H12: 5年累計
A13: 期末店舗数（店） | C13: =連結PL!C4 -> 1 | D13: =連結PL!D4 -> 3 | E13: =連結PL!E4 -> 5 | F13: =連結PL!F4 -> 7 | G13: =連結PL!G4 -> 9
A14: 売上高 | C14: =連結PL!C5 -> 385.767 | D14: =連結PL!D5 -> 902.26615 | E14: =連結PL!E5 -> 1750.9535 | F14: =連結PL!F5 -> 2608.2135 | G14: =連結PL!G5 -> 3465.4736 | H14: =連結PL!H5 -> 9112.6738
A15: 店舗EBITDA 計 | C15: =連結PL!C19 -> 46.70771 | D15: =連結PL!D19 -> 115.4309 | E15: =連結PL!E19 -> 236.75871 | F15: =連結PL!F19 -> 365.32179 | G15: =連結PL!G19 -> 493.88487 | H15: =連結PL!H19 -> 1258.104
A16: 本部費 | C16: =連結PL!C20 -> 15 | D16: =連結PL!D20 -> 28 | E16: =連結PL!E20 -> 40 | F16: =連結PL!F20 -> 48 | G16: =連結PL!G20 -> 55 | H16: =連結PL!H20 -> 186
A17: 連結EBITDA | C17: =連結PL!C21 -> 31.70771 | D17: =連結PL!D21 -> 87.430903 | E17: =連結PL!E21 -> 196.75871 | F17: =連結PL!F21 -> 317.32179 | G17: =連結PL!G21 -> 438.88487 | H17: =連結PL!H21 -> 1072.104
A18: EBITDA率 | C18: =連結PL!C22 -> 0.082193941 | D18: =連結PL!D22 -> 0.096901455 | E18: =連結PL!E22 -> 0.11237232 | F18: =連結PL!F22 -> 0.1216625 | G18: =連結PL!G22 -> 0.12664499 | H18: =連結PL!H22 -> 0.11764977
A19: 減価償却費 | C19: =連結PL!C23 -> 20.825 | D19: =連結PL!D23 -> 46.85625 | E19: =連結PL!E23 -> 87.88125 | F19: =連結PL!F23 -> 128.53125 | G19: =連結PL!G23 -> 169.18125 | H19: =連結PL!H23 -> 453.275
A20: 営業利益 | C20: =連結PL!C24 -> 10.88271 | D20: =連結PL!D24 -> 40.574653 | E20: =連結PL!E24 -> 108.87746 | F20: =連結PL!F24 -> 188.79054 | G20: =連結PL!G24 -> 269.70362 | H20: =連結PL!H24 -> 618.82898
A21: 営業利益率 | C21: =連結PL!C25 -> 0.028210578 | D21: =連結PL!D25 -> 0.044969717 | E21: =連結PL!E25 -> 0.062181809 | F21: =連結PL!F25 -> 0.072383083 | G21: =連結PL!G25 -> 0.077825906 | H21: =連結PL!H25 -> 0.067908606
A23: ■ 目標到達時期（自動判定）
A24: 連結EBITDA率 10%超 | B24: =IF(COUNTIF(連結PL!C22:G22,">=0.1")=0,"5年内に未達",INDEX({"FY2027","FY2028","FY2029","FY2030","FY2031"},6-COUNTIF(連結PL!C22:G22,">=0.1"))) -> FY2029 | D24: 旧計画：FY2028
A25: 営業利益率 5%超 | B25: =IF(COUNTIF(連結PL!C25:G25,">=0.05")=0,"5年内に未達",INDEX({"FY2027","FY2028","FY2029","FY2030","FY2031"},6-COUNTIF(連結PL!C25:G25,">=0.05"))) -> FY2029 | D25: 旧計画：FY2029
A27: ■ 投資・資金サマリー
A28: 新規出店数（店） | B28: =投資・キャッシュフロー!H4 -> 9
A29: 初期投資（5年累計） | B29: =投資・キャッシュフロー!H6 -> -2325.25
A30: 開業時 現金支出（5年累計） | B30: =投資・キャッシュフロー!H8 -> -1075.15
A31: 最大資金需要（税引後） | B31: =投資・キャッシュフロー!B18 -> 534.4685
A32: 調達額 計（既存2億＋今回1.5億） | B32: =投資・キャッシュフロー!B21 -> 350
A33: 過不足（マイナスが不足） | B33: =投資・キャッシュフロー!B22 -> -184.4685
A35: ※ 単店の売上460.6→428.6、EBITDA(3年目以降)76.2→64.3となったため、旧計画より各指標が低下しています。

Sheet 前提条件
A1: 前提条件 ／ 六本木店 事業収支 rev2（2026年10月改定）に基づく
A2: 青字＝入力値。標準店の経済性は六本木モデルrev2（115席・店内席効率75%・ディナー回転率0.90）と同一。
A4: ■ 事業前提（標準店モデル）
A5: 標準店 満年度 売上高 | B5: 428.63 | H5: 六本木モデルrev2の満年度年商。旧計画は460.0
A6: 立上り率 1年目 | B6: 0.9
A7: 立上り率 2年目 | B7: 0.98
A8: 立上り率 3年目以降 | B8: 1 | H8: 満年度水準
A9: 新店の開業年度 稼働月数 | B9: 7.5 | H9: 年2店を上期・下期に分散出店する前提の平均値
A10: 東京1号店の稼働月数（FY2027） | B10: 12 | H10: 2027年4月開業＝FY2027は通年稼働
A12: ■ 家賃条件（全店共通）
A13: 地代家賃（固定）年額 | B13: 26.64 | H13: 月222万円×12
A14: 歩合家賃率 | B14: 0.07 | H14: 閾値超過分に対して7%
A15: 歩合家賃 閾値（年商） | B15: 331.4 | H15: 提出P&L時点の水準
A17: ■ 経費率（対売上高）
A18: 費 目 | B18: 1年目 （提出P&L水準） | C18: 2年目 | D18: 3年目以降 | H18: 備考
A19: 売上原価 | B19: 0.3 | C19: 0.3 | D19: 0.3 | H19: 料理30.0%・飲料30.0%（2026年10月改定。原価改善は織り込まず）
A20: 人件費 | B20: 0.345 | C20: 0.335 | D20: 0.325 | H20: 本部集中化・多能工化
A21: 業務委託費・消耗品他 | B21: 0.024 | C21: 0.022 | D21: 0.02 | H21: 本部集中購買・規格統一
A22: 広告宣伝費・販売促進費 | B22: 0.014 | C22: 0.014 | D22: 0.014 | H22: 据置
A23: その他経費 | B23: 0.005 | C23: 0.005 | D23: 0.005 | H23: 据置
A24: 水道光熱費 | B24: 0.04 | C24: 0.038 | D24: 0.036 | H24: 高効率厨房機器・営業時間最適化
A25: ロイヤリティ | B25: 0.04 | C25: 0.04 | D25: 0.04 | H25: 契約条件（ブラッスリー4.0%）
A26: 保険・租税公課 | B26: 0.007 | C26: 0.007 | D26: 0.007 | H26: 据置
A27: 修繕維持費（FFE） | B27: 0.025 | C27: 0.025 | D27: 0.025 | H27: 据置
A28: 変動費 計（対売上） | B28: =SUM(B19:B27) -> 0.8 | C28: =SUM(C19:C27) -> 0.786 | D28: =SUM(D19:D27) -> 0.772
A30: ■ 初期投資（1店舗あたり・百万円）
A31: 項 目 | B31: 1号店 (六本木) | C31: 2〜3号店 (札幌・大阪) | D31: 4号店以降
A32: 契約金 | B32: 10 | C32: 10 | D32: 5 | H32: 契約金 3店舗3,000万円／以下7店舗3,500万円
A33: 事業費（設計・内装施工・OSE/FF&E） | B33: 194.25 | C33: 194.25 | D33: 194.25 | H33: 55.5坪×350万
A34: 開業準備金（広告・採用等） | B34: 4 | C34: 4 | D34: 4
A35: 保証金 | B35: 39 | C35: 39 | D35: 39 | H35: 非償却・退去時返還対象
A36: ワイン・美術品在庫 | B36: 50 | C36: 10 | D36: 10 | H36: 1号店は美術品を含む。2号店以降はワイン1,000万円のみ（非償却）
A37: 初期投資 合計 | B37: =SUM(B32:B36) -> 297.25 | C37: =SUM(C32:C36) -> 257.25 | D37: =SUM(D32:D36) -> 252.25
A38: 償却対象資産（＝合計－保証金－ワイン・美術品在庫） | B38: =B37-B35-B36 -> 208.25 | C38: =C37-C35-C36 -> 208.25 | D38: =D37-D35-D36 -> 203.25 | H38: ワイン在庫は棚卸資産、美術品は取得価額100万円以上なら原則非償却のため除外
A39: 償却年数（年） | B39: 10 | C39: 10 | D39: 10
A40: 年間減価償却費／1店（通年） | B40: =B38/B39 -> 20.825 | C40: =C38/C39 -> 20.825 | D40: =D38/D39 -> 20.325
A42: ■ 分割払いスキーム（百万円）
A43: 分割対象額（内装100＋保証金38.9） | B43: 138.9
A44: 開業時 現金支出／1店 | B44: =B37-$B$43 -> 158.35 | C44: =C37-$B$43 -> 118.35 | D44: =D37-$B$43 -> 113.35
A45: 年間分割弁済額／1店 | B45: 15.6
...

Sheet 店舗群別PL
A1: 店舗群（出店年度コホート）別PL（百万円）
A2: 年次（1/2/3）に応じて前提条件の立上り率・経費率を自動参照。地代家賃と歩合家賃の閾値は稼働月数で按分。
A3: 店舗群 | B3: 店舗数 | C3: FY2027 | D3: FY2028 | E3: FY2029 | F3: FY2030 | G3: FY2031
A5: ① 東京（六本木ミッドタウン）
A6: 店舗数（店） | B6: 1
A7: 開業年度の稼働月数 | B7: =前提条件!$B$10 -> 12
A8: 年次（0=未開業/1/2/3） | C8: 1 | D8: 2 | E8: 3 | F8: 3 | G8: 3
A9: 売上高 | C9: =IF(C8=0,0,前提条件!$B$5*INDEX(前提条件!$B$6:$B$8,C8)*$B$6*IF(C8=1,$B$7/12,1)) -> 385.767 | D9: =IF(D8=0,0,前提条件!$B$5*INDEX(前提条件!$B$6:$B$8,D8)*$B$6*IF(D8=1,$B$7/12,1)) -> 420.0574 | E9: =IF(E8=0,0,前提条件!$B$5*INDEX(前提条件!$B$6:$B$8,E8)*$B$6*IF(E8=1,$B$7/12,1)) -> 428.63 | F9: =IF(F8=0,0,前提条件!$B$5*INDEX(前提条件!$B$6:$B$8,F8)*$B$6*IF(F8=1,$B$7/12,1)) -> 428.63 | G9: =IF(G8=0,0,前提条件!$B$5*INDEX(前提条件!$B$6:$B$8,G8)*$B$6*IF(G8=1,$B$7/12,1)) -> 428.63
A10: 売上原価 | C10: =IF(C$8=0,0,C$9*INDEX(前提条件!$B$19:$D$19,1,C$8)) -> 115.7301 | D10: =IF(D$8=0,0,D$9*INDEX(前提条件!$B$19:$D$19,1,D$8)) -> 126.01722 | E10: =IF(E$8=0,0,E$9*INDEX(前提条件!$B$19:$D$19,1,E$8)) -> 128.589 | F10: =IF(F$8=0,0,F$9*INDEX(前提条件!$B$19:$D$19,1,F$8)) -> 128.589 | G10: =IF(G$8=0,0,G$9*INDEX(前提条件!$B$19:$D$19,1,G$8)) -> 128.589
A11: 人件費 | C11: =IF(C$8=0,0,C$9*INDEX(前提条件!$B$20:$D$20,1,C$8)) -> 133.08962 | D11: =IF(D$8=0,0,D$9*INDEX(前提条件!$B$20:$D$20,1,D$8)) -> 140.71923 | E11: =IF(E$8=0,0,E$9*INDEX(前提条件!$B$20:$D$20,1,E$8)) -> 139.30475 | F11: =IF(F$8=0,0,F$9*INDEX(前提条件!$B$20:$D$20,1,F$8)) -> 139.30475 | G11: =IF(G$8=0,0,G$9*INDEX(前提条件!$B$20:$D$20,1,G$8)) -> 139.30475
A12: 業務委託費・消耗品他 | C12: =IF(C$8=0,0,C$9*INDEX(前提条件!$B$21:$D$21,1,C$8)) -> 9.258408 | D12: =IF(D$8=0,0,D$9*INDEX(前提条件!$B$21:$D$21,1,D$8)) -> 9.2412628 | E12: =IF(E$8=0,0,E$9*INDEX(前提条件!$B$21:$D$21,1,E$8)) -> 8.5726 | F12: =IF(F$8=0,0,F$9*INDEX(前提条件!$B$21:$D$21,1,F$8)) -> 8.5726 | G12: =IF(G$8=0,0,G$9*INDEX(前提条件!$B$21:$D$21,1,G$8)) -> 8.5726
A13: 部門利益 | C13: =C9-SUM(C10:C12) -> 127.68888 | D13: =D9-SUM(D10:D12) -> 144.07969 | E13: =E9-SUM(E10:E12) -> 152.16365 | F13: =F9-SUM(F10:F12) -> 152.16365 | G13: =G9-SUM(G10:G12) -> 152.16365
A14: 広告宣伝費・販売促進費 | C14: =IF(C$8=0,0,C$9*INDEX(前提条件!$B$22:$D$22,1,C$8)) -> 5.400738 | D14: =IF(D$8=0,0,D$9*INDEX(前提条件!$B$22:$D$22,1,D$8)) -> 5.8808036 | E14: =IF(E$8=0,0,E$9*INDEX(前提条件!$B$22:$D$22,1,E$8)) -> 6.00082 | F14: =IF(F$8=0,0,F$9*INDEX(前提条件!$B$22:$D$22,1,F$8)) -> 6.00082 | G14: =IF(G$8=0,0,G$9*INDEX(前提条件!$B$22:$D$22,1,G$8)) -> 6.00082
A15: その他経費 | C15: =IF(C$8=0,0,C$9*INDEX(前提条件!$B$23:$D$23,1,C$8)) -> 1.928835 | D15: =IF(D$8=0,0,D$9*INDEX(前提条件!$B$23:$D$23,1,D$8)) -> 2.100287 | E15: =IF(E$8=0,0,E$9*INDEX(前提条件!$B$23:$D$23,1,E$8)) -> 2.14315 | F15: =IF(F$8=0,0,F$9*INDEX(前提条件!$B$23:$D$23,1,F$8)) -> 2.14315 | G15: =IF(G$8=0,0,G$9*INDEX(前提条件!$B$23:$D$23,1,G$8)) -> 2.14315
A16: 水道光熱費 | C16: =IF(C$8=0,0,C$9*INDEX(前提条件!$B$24:$D$24,1,C$8)) -> 15.43068 | D16: =IF(D$8=0,0,D$9*INDEX(前提条件!$B$24:$D$24,1,D$8)) -> 15.962181 | E16: =IF(E$8=0,0,E$9*INDEX(前提条件!$B$24:$D$24,1,E$8)) -> 15.43068 | F16: =IF(F$8=0,0,F$9*INDEX(前提条件!$B$24:$D$24,1,F$8)) -> 15.43068 | G16: =IF(G$8=0,0,G$9*INDEX(前提条件!$B$24:$D$24,1,G$8)) -> 15.43068
A17: GOP（店舗営業総利益） | C17: =C13-SUM(C14:C16) -> 104.92862 | D17: =D13-SUM(D14:D16) -> 120.13642 | E17: =E13-SUM(E14:E16) -> 128.589 | F17: =F13-SUM(F14:F16) -> 128.589 | G17: =G13-SUM(G14:G16) -> 128.589
A18: ロイヤリティ | C18: =IF(C$8=0,0,C$9*INDEX(前提条件!$B$25:$D$25,1,C$8)) -> 15.43068 | D18: =IF(D$8=0,0,D$9*INDEX(前提条件!$B$25:$D$25,1,D$8)) -> 16.802296 | E18: =IF(E$8=0,0,E$9*INDEX(前提条件!$B$25:$D$25,1,E$8)) -> 17.1452 | F18: =IF(F$8=0,0,F$9*INDEX(前提条件!$B$25:$D$25,1,F$8)) -> 17.1452 | G18: =IF(G$8=0,0,G$9*INDEX(前提条件!$B$25:$D$25,1,G$8)) -> 17.1452
A19: 保険・租税公課 | C19: =IF(C$8=0,0,C$9*INDEX(前提条件!$B$26:$D$26,1,C$8)) -> 2.700369 | D19: =IF(D$8=0,0,D$9*INDEX(前提条件!$B$26:$D$26,1,D$8)) -> 2.9404018 | E19: =IF(E$8=0,0,E$9*INDEX(前提条件!$B$26:$D$26,1,E$8)) -> 3.00041 | F19: =IF(F$8=0,0,F$9*INDEX(前提条件!$B$26:$D$26,1,F$8)) -> 3.00041 | G19: =IF(G$8=0,0,G$9*INDEX(前提条件!$B$26:$D$26,1,G$8)) -> 3.00041
A20: 地代家賃（固定） | C20: =IF(C8=0,0,前提条件!$B$13*$B$6*IF(C8=1,$B$7/12,1)) -> 26.64 | D20: =IF(D8=0,0,前提条件!$B$13*$B$6*IF(D8=1,$B$7/12,1)) -> 26.64 | E20: =IF(E8=0,0,前提条件!$B$13*$B$6*IF(E8=1,$B$7/12,1)) -> 26.64 | F20: =IF(F8=0,0,前提条件!$B$13*$B$6*IF(F8=1,$B$7/12,1)) -> 26.64 | G20: =IF(G8=0,0,前提条件!$B$13*$B$6*IF(G8=1,$B$7/12,1)) -> 26.64
A21: 歩合家賃 | C21: =IF(C8=0,0,MAX(0,C9/$B$6-前提条件!$B$15*IF(C8=1,$B$7/12,1))*前提条件!$B$14*$B$6) -> 3.80569 | D21: =IF(D8=0,0,MAX(0,D9/$B$6-前提条件!$B$15*IF(D8=1,$B$7/12,1))*前提条件!$B$14*$B$6) -> 6.206018 | E21: =IF(E8=0,0,MAX(0,E9/$B$6-前提条件!$B$15*IF(E8=1,$B$7/12,1))*前提条件!$B$14*$B$6) -> 6.8061 | F21: =IF(F8=0,0,MAX(0,F9/$B$6-前提条件!$B$15*IF(F8=1,$B$7/12,1))*前提条件!$B$14*$B$6) -> 6.8061 | G21: =IF(G8=0,0,MAX(0,G9/$B$6-前提条件!$B$15*IF(G8=1,$B$7/12,1))*前提条件!$B$14*$B$6) -> 6.8061
A22: 修繕維持費（FFE） | C22: =IF(C$8=0,0,C$9*INDEX(前提条件!$B$27:$D$27,1,C$8)) -> 9.644175 | D22: =IF(D$8=0,0,D$9*INDEX(前提条件!$B$27:$D$27,1,D$8)) -> 10.501435 | E22: =IF(E$8=0,0,E$9*INDEX(前提条件!$B$27:$D$27,1,E$8)) -> 10.71575 | F22: =IF(F$8=0,0,F$9*INDEX(前提条件!$B$27:$D$27,1,F$8)) -> 10.71575 | G22: =IF(G$8=0,0,G$9*INDEX(前提条件!$B$27:$D$27,1,G$8)) -> 10.71575
A23: 店舗EBITDA | C23: =C17-SUM(C18:C22) -> 46.70771 | D23: =D17-SUM(D18:D22) -> 57.046266 | E23: =E17-SUM(E18:E22) -> 64.28154 | F23: =F17-SUM(F18:F22) -> 64.28154 | G23: =G17-SUM(G18:G22) -> 64.28154
A24: 減価償却費 | C24: =IF(C8=0,0,前提条件!$B$40*$B$6*IF(C8=1,$B$7/12,1)) -> 20.825 | D24: =IF(D8=0,0,前提条件!$B$40*$B$6*IF(D8=1,$B$7/12,1)) -> 20.825 | E24: =IF(E8=0,0,前提条件!$B$40*$B$6*IF(E8=1,$B$7/12,1)) -> 20.825 | F24: =IF(F8=0,0,前提条件!$B$40*$B$6*IF(F8=1,$B$7/12,1)) -> 20.825 | G24: =IF(G8=0,0,前提条件!$B$40*$B$6*IF(G8=1,$B$7/12,1)) -> 20.825
A25: 店舗営業利益 | C25: =C23-C24 -> 25.88271 | D25: =D23-D24 -> 36.221266 | E25: =E23-E24 -> 43.45654 | F25: =F23-F24 -> 43.45654 | G25: =G23-G24 -> 43.45654
A27: ② 札幌・大阪
A28: 店舗数（店） | B28: 2
A29: 開業年度の稼働月数 | B29: =前提条件!$B$9 -> 7.5
A30: 年次（0=未開業/1/2/3） | C30: 0 | D30: 1 | E30: 2 | F30: 3 | G30: 3
A31: 売上高 | C31: =IF(C30=0,0,前提条件!$B$5*INDEX(前提条件!$B$6:$B$8,C30)*$B$28*IF(C30=1,$B$29/12,1)) -> 0 | D31: =IF(D30=0,0,前提条件!$B$5*INDEX(前提条件!$B$6:$B$8,D30)*$B$28*IF(D30=1,$B$29/12,1)) -> 482.20875 | E31: =IF(E30=0,0,前提条件!$B$5*INDEX(前提条件!$B$6:$B$8,E30)*$B$28*IF(E30=1,$B$29/12,1)) -> 840.1148 | F31: =IF(F30=0,0,前提条件!$B$5*INDEX(前提条件!$B$6:$B$8,F30)*$B$28*IF(F30=1,$B$29/12,1)) -> 857.26 | G31: =IF(G30=0,0,前提条件!$B$5*INDEX(前提条件!$B$6:$B$8,G30)*$B$28*IF(G30=1,$B$29/12,1)) -> 857.26
A32: 売上原価 | C32: =IF(C$30=0,0,C$31*INDEX(前提条件!$B$19:$D$19,1,C$30)) -> 0 | D32: =IF(D$30=0,0,D$31*INDEX(前提条件!$B$19:$D$19,1,D$30)) -> 144.66262 | E32: =IF(E$30=0,0,E$31*INDEX(前提条件!$B$19:$D$19,1,E$30)) -> 252.03444 | F32: =IF(F$30=0,0,F$31*INDEX(前提条件!$B$19:$D$19,1,F$30)) -> 257.178 | G32: =IF(G$30=0,0,G$31*INDEX(前提条件!$B$19:$D$19,1,G$30)) -> 257.178
A33: 人件費 | C33: =IF(C$30=0,0,C$31*INDEX(前提条件!$B$20:$D$20,1,C$30)) -> 0 | D33: =IF(D$30=0,0,D$31*INDEX(前提条件!$B$20:$D$20,1,D$30)) -> 166.36202 | E33: =IF(E$30=0,0,E$31*INDEX(前提条件!$B$20:$D$20,1,E$30)) -> 281.43846 | F33: =IF(F$30=0,0,F$31*INDEX(前提条件!$B$20:$D$20,1,F$30)) -> 278.6095 | G33: =IF(G$30=0,0,G$31*INDEX(前提条件!$B$20:$D$20,1,G$30)) -> 278.6095
A34: 業務委託費・消耗品他 | C34: =IF(C$30=0,0,C$31*INDEX(前提条件!$B$21:$D$21,1,C$30)) -> 0 | D34: =IF(D$30=0,0,D$31*INDEX(前提条件!$B$21:$D$21,1,D$30)) -> 11.57301 | E34: =IF(E$30=0,0,E$31*INDEX(前提条件!$B$21:$D$21,1,E$30)) -> 18.482526 | F34: =IF(F$30=0,0,F$31*INDEX(前提条件!$B$21:$D$21,1,F$30)) -> 17.1452 | G34: =IF(G$30=0,0,G$31*INDEX(前提条件!$B$21:$D$21,1,G$30)) -> 17.1452
A35: 部門利益 | C35: =C31-SUM(C32:C34) -> 0 | D35: =D31-SUM(D32:D34) -> 159.6111 | E35: =E31-SUM(E32:E34) -> 288.15938 | F35: =F31-SUM(F32:F34) -> 304.3273 | G35: =G31-SUM(G32:G34) -> 304.3273
A36: 広告宣伝費・販売促進費 | C36: =IF(C$30=0,0,C$31*INDEX(前提条件!$B$22:$D$22,1,C$30)) -> 0 | D36: =IF(D$30=0,0,D$31*INDEX(前提条件!$B$22:$D$22,1,D$30)) -> 6.7509225 | E36: =IF(E$30=0,0,E$31*INDEX(前提条件!$B$22:$D$22,1,E$30)) -> 11.761607 | F36: =IF(F$30=0,0,F$31*INDEX(前提条件!$B$22:$D$22,1,F$30)) -> 12.00164 | G36: =IF(G$30=0,0,G$31*INDEX(前提条件!$B$22:$D$22,1,G$30)) -> 12.00164
A37: その他経費 | C37: =IF(C$30=0,0,C$31*INDEX(前提条件!$B$23:$D$23,1,C$30)) -> 0 | D37: =IF(D$30=0,0,D$31*INDEX(前提条件!$B$23:$D$23,1,D$30)) -> 2.4110438 | E37: =IF(E$30=0,0,E$31*INDEX(前提条件!$B$23:$D$23,1,E$30)) -> 4.200574 | F37: =IF(F$30=0,0,F$31*INDEX(前提条件!$B$23:$D$23,1,F$30)) -> 4.2863 | G37: =IF(G$30=0,0,G$31*INDEX(前提条件!$B$23:$D$23,1,G$30)) -> 4.2863
A38: 水道光熱費 | C38: =IF(C$30=0,0,C$31*INDEX(前提条件!$B$24:$D$24,1,C$30)) -> 0 | D38: =IF(D$30=0,0,D$31*INDEX(前提条件!$B$24:$D$24,1,D$30)) -> 19.28835 | E38: =IF(E$30=0,0,E$31*INDEX(前提条件!$B$24:$D$24,1,E$30)) -> 31.924362 | F38: =IF(F$30=0,0,F$31*INDEX(前提条件!$B$24:$D$24,1,F$30)) -> 30.86136 | G38: =IF(G$30=0,0,G$31*INDEX(前提条件!$B$24:$D$24,1,G$30)) -> 30.86136
A39: GOP（店舗営業総利益） | C39: =C35-SUM(C36:C38) -> 0 | D39: =D35-SUM(D36:D38) -> 131.16078 | E39: =E35-SUM(E36:E38) -> 240.27283 | F39: =F35-SUM(F36:F38) -> 257.178 | G39: =G35-SUM(G36:G38) -> 257.178
A40: ロイヤリティ | C40: =IF(C$30=0,0,C$31*INDEX(前提条件!$B$25:$D$25,1,C$30)) -> 0 | D40: =IF(D$30=0,0,D$31*INDEX(前提条件!$B$25:$D$25,1,D$30)) -> 19.28835 | E40: =IF(E$30=0,0,E$31*INDEX(前提条件!$B$25:$D$25,1,E$30)) -> 33.604592 | F40: =IF(F$30=0,0,F$31*INDEX(前提条件!$B$25:$D$25,1,F$30)) -> 34.2904 | G40: =IF(G$30=0,0,G$31*INDEX(前提条件!$B$25:$D$25,1,G$30)) -> 34.2904
A41: 保険・租税公課 | C41: =IF(C$30=0,0,C$31*INDEX(前提条件!$B$26:$D$26,1,C$30)) -> 0 | D41: =IF(D$30=0,0,D$31*INDEX(前提条件!$B$26:$D$26,1,D$30)) -> 3.3754612 | E41: =IF(E$30=0,0,E$31*INDEX(前提条件!$B$26:$D$26,1,E$30)) -> 5.8808036 | F41: =IF(F$30=0,0,F$31*INDEX(前提条件!$B$26:$D$26,1,F$30)) -> 6.00082 | G41: =IF(G$30=0,0,G$31*INDEX(前提条件!$B$26:$D$26,1,G$30)) -> 6.00082
A42: 地代家賃（固定） | C42: =IF(C30=0,0,前提条件!$B$13*$B$28*IF(C30=1,$B$29/12,1)) -> 0 | D42: =IF(D30=0,0,前提条件!$B$13*$B$28*IF(D30=1,$B$29/12,1)) -> 33.3 | E42: =IF(E30=0,0,前提条件!$B$13*$B$28*IF(E30=1,$B$29/12,1)) -> 53.28 | F42: =IF(F30=0,0,前提条件!$B$13*$B$28*IF(F30=1,$B$29/12,1)) -> 53.28 | G42: =IF(G30=0,0,前提条件!$B$13*$B$28*IF(G30=1,$B$29/12,1)) -> 53.28
...

Sheet 連結PL
A1: 5か年事業計画 連結損益計画（FY2027-FY2031・百万円）
A2: 2027年4月 六本木開業 → 2028年 札幌・大阪 → 2029年 首都圏・政令指定都市 → 2030年以降 リゾート含め年2店舗
A3: 科 目 | B3: 対売上比 (FY2031) | C3: FY2027 | D3: FY2028 | E3: FY2029 | F3: FY2030 | G3: FY2031 | H3: 5年累計
A4: 期末店舗数（店） | C4: =前提条件!B50 -> 1 | D4: =前提条件!C50 -> 3 | E4: =前提条件!D50 -> 5 | F4: =前提条件!E50 -> 7 | G4: =前提条件!F50 -> 9
A5: 売上高 | B5: =IF($G$5=0,0,G5/$G$5) -> 1 | C5: =店舗群別PL!C9+店舗群別PL!C31+店舗群別PL!C53+店舗群別PL!C75+店舗群別PL!C97 -> 385.767 | D5: =店舗群別PL!D9+店舗群別PL!D31+店舗群別PL!D53+店舗群別PL!D75+店舗群別PL!D97 -> 902.26615 | E5: =店舗群別PL!E9+店舗群別PL!E31+店舗群別PL!E53+店舗群別PL!E75+店舗群別PL!E97 -> 1750.9535 | F5: =店舗群別PL!F9+店舗群別PL!F31+店舗群別PL!F53+店舗群別PL!F75+店舗群別PL!F97 -> 2608.2135 | G5: =店舗群別PL!G9+店舗群別PL!G31+店舗群別PL!G53+店舗群別PL!G75+店舗群別PL!G97 -> 3465.4736 | H5: =SUM(C5:G5) -> 9112.6738
A6: 売上原価 | B6: =IF($G$5=0,0,G6/$G$5) -> 0.3 | C6: =店舗群別PL!C10+店舗群別PL!C32+店舗群別PL!C54+店舗群別PL!C76+店舗群別PL!C98 -> 115.7301 | D6: =店舗群別PL!D10+店舗群別PL!D32+店舗群別PL!D54+店舗群別PL!D76+店舗群別PL!D98 -> 270.67985 | E6: =店舗群別PL!E10+店舗群別PL!E32+店舗群別PL!E54+店舗群別PL!E76+店舗群別PL!E98 -> 525.28607 | F6: =店舗群別PL!F10+店舗群別PL!F32+店舗群別PL!F54+店舗群別PL!F76+店舗群別PL!F98 -> 782.46407 | G6: =店舗群別PL!G10+店舗群別PL!G32+店舗群別PL!G54+店舗群別PL!G76+店舗群別PL!G98 -> 1039.6421 | H6: =SUM(C6:G6) -> 2733.8021
A7: 人件費 | B7: =IF($G$5=0,0,G7/$G$5) -> 0.33020717 | C7: =店舗群別PL!C11+店舗群別PL!C33+店舗群別PL!C55+店舗群別PL!C77+店舗群別PL!C99 -> 133.08962 | D7: =店舗群別PL!D11+店舗群別PL!D33+店舗群別PL!D55+店舗群別PL!D77+店舗群別PL!D99 -> 307.08125 | E7: =店舗群別PL!E11+店舗群別PL!E33+店舗群別PL!E55+店舗群別PL!E77+店舗群別PL!E99 -> 587.10523 | F7: =店舗群別PL!F11+店舗群別PL!F33+店舗群別PL!F55+店舗群別PL!F77+店舗群別PL!F99 -> 865.71473 | G7: =店舗群別PL!G11+店舗群別PL!G33+店舗群別PL!G55+店舗群別PL!G77+店舗群別PL!G99 -> 1144.3242 | H7: =SUM(C7:G7) -> 3037.315
A8: 業務委託費・消耗品他 | B8: =IF($G$5=0,0,G8/$G$5) -> 0.021041435 | C8: =店舗群別PL!C12+店舗群別PL!C34+店舗群別PL!C56+店舗群別PL!C78+店舗群別PL!C100 -> 9.258408 | D8: =店舗群別PL!D12+店舗群別PL!D34+店舗群別PL!D56+店舗群別PL!D78+店舗群別PL!D100 -> 20.814273 | E8: =店舗群別PL!E12+店舗群別PL!E34+店舗群別PL!E56+店舗群別PL!E78+店舗群別PL!E100 -> 38.628136 | F8: =店舗群別PL!F12+店舗群別PL!F34+店舗群別PL!F56+店舗群別PL!F78+店舗群別PL!F100 -> 55.773336 | G8: =店舗群別PL!G12+店舗群別PL!G34+店舗群別PL!G56+店舗群別PL!G78+店舗群別PL!G100 -> 72.918536 | H8: =SUM(C8:G8) -> 197.39269
A9: 部門利益 | B9: =IF($G$5=0,0,G9/$G$5) -> 0.34875139 | C9: =店舗群別PL!C13+店舗群別PL!C35+店舗群別PL!C57+店舗群別PL!C79+店舗群別PL!C101 -> 127.68888 | D9: =店舗群別PL!D13+店舗群別PL!D35+店舗群別PL!D57+店舗群別PL!D79+店舗群別PL!D101 -> 303.69078 | E9: =店舗群別PL!E13+店舗群別PL!E35+店舗群別PL!E57+店舗群別PL!E79+店舗群別PL!E101 -> 599.93412 | F9: =店舗群別PL!F13+店舗群別PL!F35+店舗群別PL!F57+店舗群別PL!F79+店舗群別PL!F101 -> 904.26142 | G9: =店舗群別PL!G13+店舗群別PL!G35+店舗群別PL!G57+店舗群別PL!G79+店舗群別PL!G101 -> 1208.5887 | H9: =SUM(C9:G9) -> 3144.1639
A10: 広告宣伝費・販売促進費 | B10: =IF($G$5=0,0,G10/$G$5) -> 0.014 | C10: =店舗群別PL!C14+店舗群別PL!C36+店舗群別PL!C58+店舗群別PL!C80+店舗群別PL!C102 -> 5.400738 | D10: =店舗群別PL!D14+店舗群別PL!D36+店舗群別PL!D58+店舗群別PL!D80+店舗群別PL!D102 -> 12.631726 | E10: =店舗群別PL!E14+店舗群別PL!E36+店舗群別PL!E58+店舗群別PL!E80+店舗群別PL!E102 -> 24.51335 | F10: =店舗群別PL!F14+店舗群別PL!F36+店舗群別PL!F58+店舗群別PL!F80+店舗群別PL!F102 -> 36.51499 | G10: =店舗群別PL!G14+店舗群別PL!G36+店舗群別PL!G58+店舗群別PL!G80+店舗群別PL!G102 -> 48.51663 | H10: =SUM(C10:G10) -> 127.57743
A11: その他経費 | B11: =IF($G$5=0,0,G11/$G$5) -> 0.005 | C11: =店舗群別PL!C15+店舗群別PL!C37+店舗群別PL!C59+店舗群別PL!C81+店舗群別PL!C103 -> 1.928835 | D11: =店舗群別PL!D15+店舗群別PL!D37+店舗群別PL!D59+店舗群別PL!D81+店舗群別PL!D103 -> 4.5113307 | E11: =店舗群別PL!E15+店舗群別PL!E37+店舗群別PL!E59+店舗群別PL!E81+店舗群別PL!E103 -> 8.7547677 | F11: =店舗群別PL!F15+店舗群別PL!F37+店舗群別PL!F59+店舗群別PL!F81+店舗群別PL!F103 -> 13.041068 | G11: =店舗群別PL!G15+店舗群別PL!G37+店舗群別PL!G59+店舗群別PL!G81+店舗群別PL!G103 -> 17.327368 | H11: =SUM(C11:G11) -> 45.563369
A12: 水道光熱費 | B12: =IF($G$5=0,0,G12/$G$5) -> 0.037041435 | C12: =店舗群別PL!C16+店舗群別PL!C38+店舗群別PL!C60+店舗群別PL!C82+店舗群別PL!C104 -> 15.43068 | D12: =店舗群別PL!D16+店舗群別PL!D38+店舗群別PL!D60+店舗群別PL!D82+店舗群別PL!D104 -> 35.250531 | E12: =店舗群別PL!E16+店舗群別PL!E38+店舗群別PL!E60+店舗群別PL!E82+店舗群別PL!E104 -> 66.643392 | F12: =店舗群別PL!F16+店舗群別PL!F38+店舗群別PL!F60+店舗群別PL!F82+店舗群別PL!F104 -> 97.504752 | G12: =店舗群別PL!G16+店舗群別PL!G38+店舗群別PL!G60+店舗群別PL!G82+店舗群別PL!G104 -> 128.36611 | H12: =SUM(C12:G12) -> 343.19547
A13: GOP（店舗営業総利益） | B13: =IF($G$5=0,0,G13/$G$5) -> 0.29270996 | C13: =店舗群別PL!C17+店舗群別PL!C39+店舗群別PL!C61+店舗群別PL!C83+店舗群別PL!C105 -> 104.92862 | D13: =店舗群別PL!D17+店舗群別PL!D39+店舗群別PL!D61+店舗群別PL!D83+店舗群別PL!D105 -> 251.2972 | E13: =店舗群別PL!E17+店舗群別PL!E39+店舗群別PL!E61+店舗群別PL!E83+店舗群別PL!E105 -> 500.02261 | F13: =店舗群別PL!F17+店舗群別PL!F39+店舗群別PL!F61+店舗群別PL!F83+店舗群別PL!F105 -> 757.20061 | G13: =店舗群別PL!G17+店舗群別PL!G39+店舗群別PL!G61+店舗群別PL!G83+店舗群別PL!G105 -> 1014.3786 | H13: =SUM(C13:G13) -> 2627.8277
A14: ロイヤリティ | B14: =IF($G$5=0,0,G14/$G$5) -> 0.04 | C14: =店舗群別PL!C18+店舗群別PL!C40+店舗群別PL!C62+店舗群別PL!C84+店舗群別PL!C106 -> 15.43068 | D14: =店舗群別PL!D18+店舗群別PL!D40+店舗群別PL!D62+店舗群別PL!D84+店舗群別PL!D106 -> 36.090646 | E14: =店舗群別PL!E18+店舗群別PL!E40+店舗群別PL!E62+店舗群別PL!E84+店舗群別PL!E106 -> 70.038142 | F14: =店舗群別PL!F18+店舗群別PL!F40+店舗群別PL!F62+店舗群別PL!F84+店舗群別PL!F106 -> 104.32854 | G14: =店舗群別PL!G18+店舗群別PL!G40+店舗群別PL!G62+店舗群別PL!G84+店舗群別PL!G106 -> 138.61894 | H14: =SUM(C14:G14) -> 364.50695
A15: 保険・租税公課 | B15: =IF($G$5=0,0,G15/$G$5) -> 0.007 | C15: =店舗群別PL!C19+店舗群別PL!C41+店舗群別PL!C63+店舗群別PL!C85+店舗群別PL!C107 -> 2.700369 | D15: =店舗群別PL!D19+店舗群別PL!D41+店舗群別PL!D63+店舗群別PL!D85+店舗群別PL!D107 -> 6.315863 | E15: =店舗群別PL!E19+店舗群別PL!E41+店舗群別PL!E63+店舗群別PL!E85+店舗群別PL!E107 -> 12.256675 | F15: =店舗群別PL!F19+店舗群別PL!F41+店舗群別PL!F63+店舗群別PL!F85+店舗群別PL!F107 -> 18.257495 | G15: =店舗群別PL!G19+店舗群別PL!G41+店舗群別PL!G63+店舗群別PL!G85+店舗群別PL!G107 -> 24.258315 | H15: =SUM(C15:G15) -> 63.788717
A16: 地代家賃（固定） | B16: =IF($G$5=0,0,G16/$G$5) -> 0.063419904 | C16: =店舗群別PL!C20+店舗群別PL!C42+店舗群別PL!C64+店舗群別PL!C86+店舗群別PL!C108 -> 26.64 | D16: =店舗群別PL!D20+店舗群別PL!D42+店舗群別PL!D64+店舗群別PL!D86+店舗群別PL!D108 -> 59.94 | E16: =店舗群別PL!E20+店舗群別PL!E42+店舗群別PL!E64+店舗群別PL!E86+店舗群別PL!E108 -> 113.22 | F16: =店舗群別PL!F20+店舗群別PL!F42+店舗群別PL!F64+店舗群別PL!F86+店舗群別PL!F108 -> 166.5 | G16: =店舗群別PL!G20+店舗群別PL!G42+店舗群別PL!G64+店舗群別PL!G86+店舗群別PL!G108 -> 219.78 | H16: =SUM(C16:G16) -> 586.08
... A19: 店舗EBITDA 計 | B19: =IF($G$5=0,0,G19/$G$5) -> 0.14251584 | C19: =店舗群別PL!C23+店舗群別PL!C45+店舗群別PL!C67+店舗群別PL!C89+店舗群別PL!C111 -> 46.70771 | D19: =店舗群別PL!D23+店舗群別PL!D45+店舗群別PL!D67+店舗群別PL!D89+店舗群別PL!D111 -> 115.4309 | E19: =店舗群別PL!E23+店舗群別PL!E45+店舗群別PL!E67+店舗群別PL!E89+店舗群別PL!E111 -> 236.75871 | F19: =店舗群別PL!F23+店舗群別PL!F45+店舗群別PL!F67+店舗群別PL!F89+店舗群別PL!F111 -> 365.32179 | G19: =店舗群別PL!G23+店舗群別PL!G45+店舗群別PL!G67+店舗群別PL!G89+店舗群別PL!G111 -> 493.88487 | H19: =SUM(C19:G19) -> 1258.104
A20: 本部費 | B20: =IF($G$5=0,0,G20/$G$5) -> 0.015870847 | C20: =前提条件!B51 -> 15 | D20: =前提条件!C51 -> 28 | E20: =前提条件!D51 -> 40 | F20: =前提条件!E51 -> 48 | G20: =前提条件!F51 -> 55 | H20: =SUM(C20:G20) -> 186
A21: 連結EBITDA | B21: =IF($G$5=0,0,G21/$G$5) -> 0.12664499 | C21: =C19-C20 -> 31.70771 | D21: =D19-D20 -> 87.430903 | E21: =E19-E20 -> 196.75871 | F21: =F19-F20 -> 317.32179 | G21: =G19-G20 -> 438.88487 | H21: =SUM(C21:G21) -> 1072.104
A22: EBITDA率 | C22: =IF(C5=0,0,C21/C5) -> 0.082193941 | D22: =IF(D5=0,0,D21/D5) -> 0.096901455 | E22: =IF(E5=0,0,E21/E5) -> 0.11237232 | F22: =IF(F5=0,0,F21/F5) -> 0.1216625 | G22: =IF(G5=0,0,G21/G5) -> 0.12664499 | H22: =H21/H5 -> 0.11764977
A23: 減価償却費 | B23: =IF($G$5=0,0,G23/$G$5) -> 0.048819086 | C23: =店舗群別PL!C24+店舗群別PL!C46+店舗群別PL!C68+店舗群別PL!C90+店舗群別PL!C112 -> 20.825 | D23: =店舗群別PL!D24+店舗群別PL!D46+店舗群別PL!D68+店舗群別PL!D90+店舗群別PL!D112 -> 46.85625 | E23: =店舗群別PL!E24+店舗群別PL!E46+店舗群別PL!E68+店舗群別PL!E90+店舗群別PL!E112 -> 87.88125 | F23: =店舗群別PL!F24+店舗群別PL!F46+店舗群別PL!F68+店舗群別PL!F90+店舗群別PL!F112 -> 128.53125 | G23: =店舗群別PL!G24+店舗群別PL!G46+店舗群別PL!G68+店舗群別PL!G90+店舗群別PL!G112 -> 169.18125 | H23: =SUM(C23:G23) -> 453.275
A24: 営業利益 | B24: =IF($G$5=0,0,G24/$G$5) -> 0.077825906 | C24: =C21-C23 -> 10.88271 | D24: =D21-D23 -> 40.574653 | E24: =E21-E23 -> 108.87746 | F24: =F21-F23 -> 188.79054 | G24: =G21-G23 -> 269.70362 | H24: =SUM(C24:G24) -> 618.82898
A25: 営業利益率 | C25: =IF(C5=0,0,C24/C5) -> 0.028210578 | D25: =IF(D5=0,0,D24/D5) -> 0.044969717 | E25: =IF(E5=0,0,E24/E5) -> 0.062181809 | F25: =IF(F5=0,0,F24/F5) -> 0.072383083 | G25: =IF(G5=0,0,G24/G5) -> 0.077825906 | H25: =H24/H5 -> 0.067908606
A27: ※ 到達時期は下表参照。FY＝4月〜3月。新店初年度は売上90%・開業7.5か月で計上。金利・税金は含まない。
A28: ※ 売上原価は料理30.0%・飲料30.0%（2026年10月改定）。原価改善を織り込んでいないため、EBITDA率の伸びは旧計画より緩やかです。

Sheet 投資・キャッシュフロー
A1: 5か年事業計画 連結キャッシュフロー（百万円）
A2: 分割払いスキーム反映。初期投資は1号店297.25／2〜3号店257.25／4号店以降252.25百万円。うち138.9百万円を分割。
A3: 項 目 | C3: FY2027 | D3: FY2028 | E3: FY2029 | F3: FY2030 | G3: FY2031 | H3: 5年累計
A4: 新規出店数（店） | C4: =前提条件!B49 -> 1 | D4: =前提条件!C49 -> 2 | E4: =前提条件!D49 -> 2 | F4: =前提条件!E49 -> 2 | G4: =前提条件!F49 -> 2 | H4: =SUM(C4:G4) -> 9
A5: 期末店舗数（店） | C5: =前提条件!B50 -> 1 | D5: =前提条件!C50 -> 3 | E5: =前提条件!D50 -> 5 | F5: =前提条件!E50 -> 7 | G5: =前提条件!F50 -> 9
A6: 初期投資（総額） | C6: =-C4*前提条件!$B$37 -> -297.25 | D6: =-D4*前提条件!$C$37 -> -514.5 | E6: =-E4*前提条件!$D$37 -> -504.5 | F6: =-F4*前提条件!$D$37 -> -504.5 | G6: =-G4*前提条件!$D$37 -> -504.5 | H6: =SUM(C6:G6) -> -2325.25
A7: うち 分割対象額 | C7: =C4*前提条件!$B$43 -> 138.9 | D7: =D4*前提条件!$B$43 -> 277.8 | E7: =E4*前提条件!$B$43 -> 277.8 | F7: =F4*前提条件!$B$43 -> 277.8 | G7: =G4*前提条件!$B$43 -> 277.8 | H7: =SUM(C7:G7) -> 1250.1
A8: 開業時 現金支出 | C8: =C6+C7 -> -158.35 | D8: =D6+D7 -> -236.7 | E8: =E6+E7 -> -226.7 | F8: =F6+F7 -> -226.7 | G8: =G6+G7 -> -226.7 | H8: =SUM(C8:G8) -> -1075.15
A9: 分割弁済額 | C9: =-(IF(店舗群別PL!C8=0,0,前提条件!$B$45*店舗群別PL!$B$6*IF(店舗群別PL!C8=1,店舗群別PL!$B$7/12,1))+IF(店舗群別PL!C30=0,0,前提条件!$B$45*店舗群別PL!$B$28*IF(店舗群別PL!C30=1,店舗群別PL!$B$29/12,1))+IF(店舗群別PL!C52=0,0,前提条件!$B$45*店舗群別PL!$B$50*IF(店舗群別PL!C52=1,店舗群別PL!$B$51/12,1))+IF(店舗群別PL!C74=0,0,前提条件!$B$45*店舗群別PL!$B$72*IF(店舗群別PL!C74=1,店舗群別PL!$B$73/12,1))+IF(店舗群別PL!C96=0,0,前提条件!$B$45*店舗群別PL!$B$94*IF(店舗群別PL!C96=1,店舗群別PL!$B$95/12,1))) -> -15.6 | D9: =-(IF(店舗群別PL!D8=0,0,前提条件!$B$45*店舗群別PL!$B$6*IF(店舗群別PL!D8=1,店舗群別PL!$B$7/12,1))+IF(店舗群別PL!D30=0,0,前提条件!$B$45*店舗群別PL!$B$28*IF(店舗群別PL!D30=1,店舗群別PL!$B$29/12,1))+IF(店舗群別PL!D52=0,0,前提条件!$B$45*店舗群別PL!$B$50*IF(店舗群別PL!D52=1,店舗群別PL!$B$51/12,1))+IF(店舗群別PL!D74=0,0,前提条件!$B$45*店舗群別PL!$B$72*IF(店舗群別PL!D74=1,店舗群別PL!$B$73/12,1))+IF(店舗群別PL!D96=0,0,前提条件!$B$45*店舗群別PL!$B$94*IF(店舗群別PL!D96=1,店舗群別PL!$B$95/12,1))) -> -35.1 | E9: =-(IF(店舗群別PL!E8=0,0,前提条件!$B$45*店舗群別PL!$B$6*IF(店舗群別PL!E8=1,店舗群別PL!$B$7/12,1))+IF(店舗群別PL!E30=0,0,前提条件!$B$45*店舗群別PL!$B$28*IF(店舗群別PL!E30=1,店舗群別PL!$B$29/12,1))+IF(店舗群別PL!E52=0,0,前提条件!$B$45*店舗群別PL!$B$50*IF(店舗群別PL!E52=1,店舗群別PL!$B$51/12,1))+IF(店舗群別PL!E74=0,0,前提条件!$B$45*店舗群別PL!$B$72*IF(店舗群別PL!E74=1,店舗群別PL!$B$73/12,1))+IF(店舗群別PL!E96=0,0,前提条件!$B$45*店舗群別PL!$B$94*IF(店舗群別PL!E96=1,店舗群別PL!$B$95/12,1))) -> -66.3 | F9: =-(IF(店舗群別PL!F8=0,0,前提条件!$B$45*店舗群別PL!$B$6*IF(店舗群別PL!F8=1,店舗群別PL!$B$7/12,1))+IF(店舗群別PL!F30=0,0,前提条件!$B$45*店舗群別PL!$B$28*IF(店舗群別PL!F30=1,店舗群別PL!$B$29/12,1))+IF(店舗群別PL!F52=0,0,前提条件!$B$45*店舗群別PL!$B$50*IF(店舗群別PL!F52=1,店舗群別PL!$B$51/12,1))+IF(店舗群別PL!F74=0,0,前提条件!$B$45*店舗群別PL!$B$72*IF(店舗群別PL!F74=1,店舗群別PL!$B$73/12,1))+IF(店舗群別PL!F96=0,0,前提条件!$B$45*店舗群別PL!$B$94*IF(店舗群別PL!F96=1,店舗群別PL!$B$95/12,1))) -> -97.5 | G9: =-(IF(店舗群別PL!G8=0,0,前提条件!$B$45*店舗群別PL!$B$6*IF(店舗群別PL!G8=1,店舗群別PL!$B$7/12,1))+IF(店舗群別PL!G30=0,0,前提条件!$B$45*店舗群別PL!$B$28*IF(店舗群別PL!G30=1,店舗群別PL!$B$29/12,1))+IF(店舗群別PL!G52=0,0,前提条件!$B$45*店舗群別PL!$B$50*IF(店舗群別PL!G52=1,店舗群別PL!$B$51/12,1))+IF(店舗群別PL!G74=0,0,前提条件!$B$45*店舗群別PL!$B$72*IF(店舗群別PL!G74=1,店舗群別PL!$B$73/12,1))+IF(店舗群別PL!G96=0,0,前提条件!$B$45*店舗群別PL!$B$94*IF(店舗群別PL!G96=1,店舗群別PL!$B$95/12,1))) -> -128.7 | H9: =SUM(C9:G9) -> -343.2
A10: 投資キャッシュアウト 計 | C10: =C8+C9 -> -173.95 | D10: =D8+D9 -> -271.8 | E10: =E8+E9 -> -293 | F10: =F8+F9 -> -324.2 | G10: =G8+G9 -> -355.4 | H10: =SUM(C10:G10) -> -1418.35
A11: 連結EBITDA | C11: =連結PL!C21 -> 31.70771 | D11: =連結PL!D21 -> 87.430903 | E11: =連結PL!E21 -> 196.75871 | F11: =連結PL!F21 -> 317.32179 | G11: =連結PL!G21 -> 438.88487 | H11: =SUM(C11:G11) -> 1072.104
A12: 法人税等（推計） | C12: =-MAX(0,連結PL!C24)*$B$17 -> -3.264813 | D12: =-MAX(0,連結PL!D24)*$B$17 -> -12.172396 | E12: =-MAX(0,連結PL!E24)*$B$17 -> -32.663238 | F12: =-MAX(0,連結PL!F24)*$B$17 -> -56.637162 | G12: =-MAX(0,連結PL!G24)*$B$17 -> -80.911086 | H12: =SUM(C12:G12) -> -185.64869
A13: 簡易フリーキャッシュフロー | C13: =C11+C12+C10 -> -145.5071 | D13: =D11+D12+D10 -> -196.54149 | E13: =E11+E12+E10 -> -128.90453 | F13: =F11+F12+F10 -> -63.515373 | G13: =G11+G12+G10 -> 2.5737831 | H13: =SUM(C13:G13) -> -531.89471
A14: 累計フリーキャッシュフロー | C14: =C13 -> -145.5071 | D14: =C14+D13 -> -342.0486 | E14: =D14+E13 -> -470.95312 | F14: =E14+F13 -> -534.4685 | G14: =F14+G13 -> -531.89471
A16: ■ 必要資金と調達
A17: 法人税 実効税率 | B17: 0.3 | J17: 簡易。繰越欠損金の控除は考慮せず
A18: 最大資金需要（累計FCFの最小値） | B18: =-MIN(C14:G14) -> 534.4685 | J18: 税引後ベース
A19: 既存調達額（エクイティ＋デット） | B19: 200 | J19: 事業収支資料p11「2億調達済み」。内訳未確認
A20: 第三者割当①（2026年10月） | B20: 150 | J20: Pre3億・Post4.5億
A21: 調達額 計 | B21: =B19+B20 -> 350
A22: 過不足（マイナスが不足） | B22: =B21-B18 -> -184.4685 | J22: デット元本返済・分割払い金利は未考慮
A24: ※ 簡易FCF＝連結EBITDA－法人税等－投資キャッシュアウト。運転資本増減・借入返済は含まない。
A25: ※ ワイン・美術品在庫は1号店50百万円（美術品含む）、2号店以降はワインのみ10百万円。9店舗累計の初期投資は23.3億円。
