Workbook

Sheet サマリー
A1: BRASSERIE Thierry Marx（仮称） 5か年事業計画 FY2027-FY2031
A2: 単位：百万円 ／ FY＝4月〜翌3月 ／ 六本木ミッドタウン店 2026年8月3日提出P&L 準拠
A4: ■ 出店ロードマップ
A5: FY2027 | B5: 六本木ミッドタウン 1店（2027年4月開業） | E5: 期末 1店
A6: FY2028 | B6: 札幌・大阪 2店 | E6: 期末 3店
A7: FY2029 | B7: 首都圏・他政令指定都市 2店 | E7: 期末 5店
A8: FY2030 | B8: リゾート含め 年2店 | E8: 期末 7店
A9: FY2031 | B9: リゾート含め 年2店 | E9: 期末 9店
A11: ■ 連結業績サマリー
A12: 項 目 | C12: FY2027 | D12: FY2028 | E12: FY2029 | F12: FY2030 | G12: FY2031 | H12: 5年累計
A13: 期末店舗数（店） | C13: ='5カ年連結PL'!C4 -> 1 | D13: ='5カ年連結PL'!D4 -> 3 | E13: ='5カ年連結PL'!E4 -> 5 | F13: ='5カ年連結PL'!F4 -> 7 | G13: ='5カ年連結PL'!G4 -> 9
A14: 売上高 | C14: ='5カ年連結PL'!C5 -> 414 | D14: ='5カ年連結PL'!D5 -> 968.3 | E14: ='5カ年連結PL'!E5 -> 1879.1 | F14: ='5カ年連結PL'!F5 -> 2799.1 | G14: ='5カ年連結PL'!G5 -> 3719.1 | H14: ='5カ年連結PL'!H5 -> 9779.6
A15: 店舗EBITDA 計 | C15: ='5カ年連結PL'!C19 -> 52.448 | D15: ='5カ年連結PL'!D19 -> 131.5412 | E15: ='5カ年連結PL'!E19 -> 273.6604 | F15: ='5カ年連結PL'!F19 -> 425.9364 | G15: ='5カ年連結PL'!G19 -> 578.2124 | H15: ='5カ年連結PL'!H19 -> 1461.7984
A16: 本部費 | C16: ='5カ年連結PL'!C20 -> 15 | D16: ='5カ年連結PL'!D20 -> 28 | E16: ='5カ年連結PL'!E20 -> 40 | F16: ='5カ年連結PL'!F20 -> 48 | G16: ='5カ年連結PL'!G20 -> 55 | H16: ='5カ年連結PL'!H20 -> 186
A17: 連結EBITDA | C17: ='5カ年連結PL'!C21 -> 37.448 | D17: ='5カ年連結PL'!D21 -> 103.5412 | E17: ='5カ年連結PL'!E21 -> 233.6604 | F17: ='5カ年連結PL'!F21 -> 377.9364 | G17: ='5カ年連結PL'!G21 -> 523.2124 | H17: ='5カ年連結PL'!H21 -> 1275.7984
A18: EBITDA率 | C18: ='5カ年連結PL'!C22 -> 0.090454106 | D18: ='5カ年連結PL'!D22 -> 0.10693091 | E18: ='5カ年連結PL'!E22 -> 0.12434697 | F18: ='5カ年連結PL'!F22 -> 0.13502069 | G18: ='5カ年連結PL'!G22 -> 0.14068253 | H18: ='5カ年連結PL'!H22 -> 0.13045507
A19: 減価償却費 | C19: ='5カ年連結PL'!C23 -> 20.8 | D19: ='5カ年連結PL'!D23 -> 46.8 | E19: ='5カ年連結PL'!E23 -> 87.775 | F19: ='5カ年連結PL'!F23 -> 128.375 | G19: ='5カ年連結PL'!G23 -> 168.975 | H19: ='5カ年連結PL'!H23 -> 452.725
A20: 営業利益 | C20: ='5カ年連結PL'!C24 -> 16.648 | D20: ='5カ年連結PL'!D24 -> 56.7412 | E20: ='5カ年連結PL'!E24 -> 145.8854 | F20: ='5カ年連結PL'!F24 -> 249.5614 | G20: ='5カ年連結PL'!G24 -> 354.2374 | H20: ='5カ年連結PL'!H24 -> 823.0734
A21: 営業利益率 | C21: ='5カ年連結PL'!C25 -> 0.04021256 | D21: ='5カ年連結PL'!D25 -> 0.058598781 | E21: ='5カ年連結PL'!E25 -> 0.077635783 | F21: ='5カ年連結PL'!F25 -> 0.089157729 | G21: ='5カ年連結PL'!G25 -> 0.095248151 | H21: ='5カ年連結PL'!H25 -> 0.084162277
A23: 【目標達成】FY2028に連結EBITDA率10%超 ／ FY2029に営業利益率5%超 → 以降も継続的に改善
A25: ■ 単店モデル（六本木ミッドタウン）
A26: 項 目 | C26: 1年目 | D26: 2年目 | E26: 3年目以降
A27: 売上高 | C27: ='単店モデルPL'!C5 -> 414 | D27: ='単店モデルPL'!D5 -> 450.8 | E27: ='単店モデルPL'!E5 -> 460
A28: EBITDA | C28: ='単店モデルPL'!C19 -> 52.448 | D28: ='単店モデルPL'!D19 -> 65.9812 | E28: ='単店モデルPL'!E19 -> 76.138
A29: EBITDA率 | C29: ='単店モデルPL'!C22 -> 0.12668599 | D29: ='単店モデルPL'!D22 -> 0.14636469 | E29: ='単店モデルPL'!E22 -> 0.16551739
A30: 営業利益 | C30: ='単店モデルPL'!C21 -> 31.648 | D30: ='単店モデルPL'!D21 -> 45.1812 | E30: ='単店モデルPL'!E21 -> 55.338
A31: 営業利益率 | C31: ='単店モデルPL'!C23 -> 0.076444444 | D31: ='単店モデルPL'!D23 -> 0.10022449 | E31: ='単店モデルPL'!E23 -> 0.1203
A33: ■ 投資・キャッシュフロー サマリー
A34: 項 目 | C34: FY2027 | D34: FY2028 | E34: FY2029 | F34: FY2030 | G34: FY2031 | H34: 5年累計
A35: 新規出店数（店） | C35: ='投資・キャッシュフロー'!C4 -> 1 | D35: ='投資・キャッシュフロー'!D4 -> 2 | E35: ='投資・キャッシュフロー'!E4 -> 2 | F35: ='投資・キャッシュフロー'!F4 -> 2 | G35: ='投資・キャッシュフロー'!G4 -> 2 | H35: ='投資・キャッシュフロー'!H4 -> 9
A36: 初期投資（総額） | C36: ='投資・キャッシュフロー'!C6 -> -247 | D36: ='投資・キャッシュフロー'!D6 -> -494 | E36: ='投資・キャッシュフロー'!E6 -> -484 | F36: ='投資・キャッシュフロー'!F6 -> -484 | G36: ='投資・キャッシュフロー'!G6 -> -484 | H36: ='投資・キャッシュフロー'!H6 -> -2193
A37: 開業時 現金支出 | C37: ='投資・キャッシュフロー'!C8 -> -108.1 | D37: ='投資・キャッシュフロー'!D8 -> -216.2 | E37: ='投資・キャッシュフロー'!E8 -> -206.2 | F37: ='投資・キャッシュフロー'!F8 -> -206.2 | G37: ='投資・キャッシュフロー'!G8 -> -206.2 | H37: ='投資・キャッシュフロー'!H8 -> -942.9
A38: 投資キャッシュアウト 計 | C38: ='投資・キャッシュフロー'!C10 -> -123.7 | D38: ='投資・キャッシュフロー'!D10 -> -251.3 | E38: ='投資・キャッシュフロー'!E10 -> -272.5 | F38: ='投資・キャッシュフロー'!F10 -> -303.7 | G38: ='投資・キャッシュフロー'!G10 -> -334.9 | H38: ='投資・キャッシュフロー'!H10 -> -1286.1
A39: 簡易フリーキャッシュフロー | C39: ='投資・キャッシュフロー'!C12 -> -86.252 | D39: ='投資・キャッシュフロー'!D12 -> -147.7588 | E39: ='投資・キャッシュフロー'!E12 -> -38.8396 | F39: ='投資・キャッシュフロー'!F12 -> 74.2364 | G39: ='投資・キャッシュフロー'!G12 -> 188.3124 | H39: ='投資・キャッシュフロー'!H12 -> -10.3016
A40: 累計フリーキャッシュフロー | C40: ='投資・キャッシュフロー'!C13 -> -86.252 | D40: ='投資・キャッシュフロー'!D13 -> -234.0108 | E40: ='投資・キャッシュフロー'!E13 -> -272.8504 | F40: ='投資・キャッシュフロー'!F13 -> -198.614 | G40: ='投資・キャッシュフロー'!G13 -> -10.3016
A42: ※ 分割払いスキームにより5年間の現金投資額を21.9億円 → 12.9億円に圧縮。FY2030に単年FCF黒字化、5年累計FCFはほぼ均衡。
A43: ※ 保証金（9店合計350百万円）は退去時返還対象。
A45: ■ 経費改善レバー（提出P&L → 3年目以降）
A46: 売上原価 | B46: 29.5% → 28.5% | C46: 直輸入ワイン活用・複数店一括仕入
A47: 人件費 | B47: 34.5% → 32.5% | C47: 本部集中化・多能工化
...

Sheet 前提条件
A1: 前提条件 ／ 六本木ミッドタウン店 2026年8月3日提出P&L 準拠
A2: 青字＝入力値（前提）。変更すると全シートが自動再計算されます。黒字＝計算式、緑字＝他シート参照。単位：百万円
A4: ■ 売上前提（六本木ミッドタウン店＝標準店モデル）
A5: 満年度 売上高 | B5: 460 | H5: 183.59㎡(55.5坪)・123席・年363日営業・稼働率80%。日商約127万円／月商約3,829万円
A6: 立上り率 1年目 | B6: 0.9 | H6: 新店初年度は保守的に90%で計画
A7: 立上り率 2年目 | B7: 0.98
A8: 立上り率 3年目以降 | B8: 1 | H8: 満年度水準
A9: 新店の開業年度 稼働月数 | B9: 7.5 | H9: 年2店を上期・下期に分散出店する前提の平均値
A10: 東京1号店の稼働月数（FY2027） | B10: 12 | H10: 2027年4月開業＝FY2027は通年稼働
A12: ■ 家賃条件（契約条件どおり全店適用）
A13: 地代家賃（固定）月額 | B13: 2.22 | H13: 月222万円。売上非連動の固定費
A14: 地代家賃（固定）年額 | B14: =B13*12 -> 26.64 | H14: ＝月額×12
A15: 歩合家賃率 | B15: 0.07 | H15: 閾値超過分に対して7%
A16: 歩合家賃 閾値（年額売上） | B16: 331.4 | H16: 満年度歩合家賃9百万円（対売上1.9%）から逆算
A18: ■ 変動費率（対売上高） ※提出P&L水準 → 改善後
A21: 費 目 | B21: 1年目 （提出P&L） | C21: 2年目 （改善途上） | D21: 3年目以降 （改善後） | H21: 改善レバー
A22: 売上原価 | B22: 0.295 | C22: 0.29 | D22: 0.285 | H22: 直輸入ワイン活用・複数店一括仕入（▲1.0pt）
A23: 人件費 | B23: 0.345 | C23: 0.335 | D23: 0.325 | H23: 本部集中化・多能工化。26名体制の最適化（▲2.0pt）
A24: 業務委託費・消耗品他 | B24: 0.024 | C24: 0.022 | D24: 0.02 | H24: 本部集中購買・規格統一（▲0.4pt）
A25: 広告宣伝費・販売促進費 | B25: 0.014 | C25: 0.014 | D25: 0.014 | H25: 1号店の話題性を活用（据置）
A26: その他経費 | B26: 0.005 | C26: 0.005 | D26: 0.005 | H26: 据置
A27: 水道光熱費 | B27: 0.04 | C27: 0.038 | D27: 0.036 | H27: 高効率厨房機器・営業時間最適化（▲0.4pt）
A28: ロイヤリティ | B28: 0.04 | C28: 0.04 | D28: 0.04 | H28: 契約条件（ブラッスリー4.0%）
A29: 保険・租税公課 | B29: 0.007 | C29: 0.007 | D29: 0.007 | H29: 据置
A30: 修繕維持費（FFE） | B30: 0.025 | C30: 0.025 | D30: 0.025 | H30: 据置
A31: 変動費 計（対売上） | B31: =SUM(B22:B30) -> 0.795 | C31: =SUM(C22:C30) -> 0.776 | D31: =SUM(D22:D30) -> 0.757
A33: ■ 初期投資（1店舗あたり） ※六本木ミッドタウン実額準拠
A34: 項 目 | B34: 1〜3号店 (東京・札幌・大阪) | C34: 4号店以降
A35: 契約金 | B35: 10 | C35: 5 | H35: 契約金 3店舗3,000万円／以下7店舗3,500万円
A36: 事業費（設計・内装施工・OSE/FF&E） | B36: 194 | C36: 194
A37: 開業準備金（広告・採用等） | B37: 4 | C37: 4
A38: 保証金（賃料70か月相当） | B38: 39 | C38: 39 | H38: 非償却・退去時返還対象
A39: 初期投資 合計 | B39: =SUM(B35:B38) -> 247 | C39: =SUM(C35:C38) -> 242 | H39: 1〜3号店 247百万円／4号店以降 242百万円
A40: 償却対象資産（＝合計－保証金） | B40: =B39-B38 -> 208 | C40: =C39-C38 -> 203
A41: 平均償却年数（年） | B41: 10 | C41: 10
A42: 年間減価償却費／1店（通年） | B42: =B40/B41 -> 20.8 | C42: =C40/C41 -> 20.3
A44: ■ 分割払いスキーム（ミッドタウン契約と同条件・全店適用）
A45: 分割対象：内装工事費 | B45: 100 | H45: 月833千円 × 120回（10年）
A46: 分割対象：保証金 | B46: 38.9 | H46: 月463千円 × 84回（7年）
A47: 分割対象額 計／1店 | B47: =B45+B46 -> 138.9 | H47: 開業時現金支出＝初期投資－分割対象額
...

Sheet 単店モデルPL
A1: 単店モデルPL（六本木ミッドタウン店・百万円）
A2: 満年度＝2026年8月3日提出P&Lどおり。1年目/2年目/3年目以降は立上り率と経費改善を反映。
A4: 科 目 | B4: 満年度 （提出P&L） | C4: 1年目 | D4: 2年目 | E4: 3年目以降
A5: 売上高 | B5: ='前提条件'!$B$5*'前提条件'!$B$8 -> 460 | C5: ='前提条件'!$B$5*'前提条件'!$B$6 -> 414 | D5: ='前提条件'!$B$5*'前提条件'!$B$7 -> 450.8 | E5: ='前提条件'!$B$5*'前提条件'!$B$8 -> 460
A6: 売上原価 | B6: =B$5*'前提条件'!$B$22 -> 135.7 | C6: =C$5*'前提条件'!$B$22 -> 122.13 | D6: =D$5*'前提条件'!$C$22 -> 130.732 | E6: =E$5*'前提条件'!$D$22 -> 131.1
A7: 人件費 | B7: =B$5*'前提条件'!$B$23 -> 158.7 | C7: =C$5*'前提条件'!$B$23 -> 142.83 | D7: =D$5*'前提条件'!$C$23 -> 151.018 | E7: =E$5*'前提条件'!$D$23 -> 149.5
A8: 業務委託費・消耗品他 | B8: =B$5*'前提条件'!$B$24 -> 11.04 | C8: =C$5*'前提条件'!$B$24 -> 9.936 | D8: =D$5*'前提条件'!$C$24 -> 9.9176 | E8: =E$5*'前提条件'!$D$24 -> 9.2
A9: 部門利益 | B9: =B5-SUM(B6:B8) -> 154.56 | C9: =C5-SUM(C6:C8) -> 139.104 | D9: =D5-SUM(D6:D8) -> 159.1324 | E9: =E5-SUM(E6:E8) -> 170.2
A10: 広告宣伝費・販売促進費 | B10: =B$5*'前提条件'!$B$25 -> 6.44 | C10: =C$5*'前提条件'!$B$25 -> 5.796 | D10: =D$5*'前提条件'!$C$25 -> 6.3112 | E10: =E$5*'前提条件'!$D$25 -> 6.44
A11: その他経費 | B11: =B$5*'前提条件'!$B$26 -> 2.3 | C11: =C$5*'前提条件'!$B$26 -> 2.07 | D11: =D$5*'前提条件'!$C$26 -> 2.254 | E11: =E$5*'前提条件'!$D$26 -> 2.3
A12: 水道光熱費 | B12: =B$5*'前提条件'!$B$27 -> 18.4 | C12: =C$5*'前提条件'!$B$27 -> 16.56 | D12: =D$5*'前提条件'!$C$27 -> 17.1304 | E12: =E$5*'前提条件'!$D$27 -> 16.56
A13: GOP（店舗営業総利益） | B13: =B9-SUM(B10:B12) -> 127.42 | C13: =C9-SUM(C10:C12) -> 114.678 | D13: =D9-SUM(D10:D12) -> 133.4368 | E13: =E9-SUM(E10:E12) -> 144.9
A14: ロイヤリティ | B14: =B$5*'前提条件'!$B$28 -> 18.4 | C14: =C$5*'前提条件'!$B$28 -> 16.56 | D14: =D$5*'前提条件'!$C$28 -> 18.032 | E14: =E$5*'前提条件'!$D$28 -> 18.4
A15: 保険・租税公課 | B15: =B$5*'前提条件'!$B$29 -> 3.22 | C15: =C$5*'前提条件'!$B$29 -> 2.898 | D15: =D$5*'前提条件'!$C$29 -> 3.1556 | E15: =E$5*'前提条件'!$D$29 -> 3.22
A16: 地代家賃（固定） | B16: ='前提条件'!$B$14 -> 26.64 | C16: ='前提条件'!$B$14 -> 26.64 | D16: ='前提条件'!$B$14 -> 26.64 | E16: ='前提条件'!$B$14 -> 26.64
A17: 歩合家賃 | B17: =MAX(0,B5-'前提条件'!$B$16)*'前提条件'!$B$15 -> 9.002 | C17: =MAX(0,C5-'前提条件'!$B$16)*'前提条件'!$B$15 -> 5.782 | D17: =MAX(0,D5-'前提条件'!$B$16)*'前提条件'!$B$15 -> 8.358 | E17: =MAX(0,E5-'前提条件'!$B$16)*'前提条件'!$B$15 -> 9.002
A18: 修繕維持費（FFE） | B18: =B$5*'前提条件'!$B$30 -> 11.5 | C18: =C$5*'前提条件'!$B$30 -> 10.35 | D18: =D$5*'前提条件'!$C$30 -> 11.27 | E18: =E$5*'前提条件'!$D$30 -> 11.5
A19: EBITDA | B19: =B13-SUM(B14:B18) -> 58.658 | C19: =C13-SUM(C14:C18) -> 52.448 | D19: =D13-SUM(D14:D18) -> 65.9812 | E19: =E13-SUM(E14:E18) -> 76.138 | G19: 成熟店：EBITDA率16.5%／営業利益率12.1%
A20: 減価償却費 | B20: ='前提条件'!$B$42 -> 20.8 | C20: ='前提条件'!$B$42 -> 20.8 | D20: ='前提条件'!$B$42 -> 20.8 | E20: ='前提条件'!$B$42 -> 20.8
A21: 営業利益 | B21: =B19-B20 -> 37.858 | C21: =C19-C20 -> 31.648 | D21: =D19-D20 -> 45.1812 | E21: =E19-E20 -> 55.338
A22: EBITDA率 | B22: =B19/B5 -> 0.12751739 | C22: =C19/C5 -> 0.12668599 | D22: =D19/D5 -> 0.14636469 | E22: =E19/E5 -> 0.16551739
A23: 営業利益率 | B23: =B21/B5 -> 0.0823 | C23: =C21/C5 -> 0.076444444 | D23: =D21/D5 -> 0.10022449 | E23: =E21/E5 -> 0.1203
A25: ※ 減価償却費は1〜3号店ベース（償却対象208百万円÷10年）。金利・税金は含まない。

Sheet 店舗群別PL
A1: 店舗群（出店年度コホート）別PL（百万円）
A2: 年次（1/2/3）に応じて「前提条件」の立上り率・変動費率を自動参照。地代家賃と歩合家賃の閾値は稼働月数で按分。
A3: 店舗群 | B3: 店舗数 | C3: FY2027 | D3: FY2028 | E3: FY2029 | F3: FY2030 | G3: FY2031
A5: ① 東京（六本木ミッドタウン）
A6: 店舗数（店） | B6: 1
A7: 開業年度の稼働月数 | B7: ='前提条件'!$B$10 -> 12
A8: 年次（0=未開業/1/2/3） | C8: 1 | D8: 2 | E8: 3 | F8: 3 | G8: 3
A9: 売上高 | C9: =IF(C8=0,0,'前提条件'!$B$5*INDEX('前提条件'!$B$6:$B$8,C8)*$B$6*IF(C8=1,$B$7/12,1)) -> 414 | D9: =IF(D8=0,0,'前提条件'!$B$5*INDEX('前提条件'!$B$6:$B$8,D8)*$B$6*IF(D8=1,$B$7/12,1)) -> 450.8 | E9: =IF(E8=0,0,'前提条件'!$B$5*INDEX('前提条件'!$B$6:$B$8,E8)*$B$6*IF(E8=1,$B$7/12,1)) -> 460 | F9: =IF(F8=0,0,'前提条件'!$B$5*INDEX('前提条件'!$B$6:$B$8,F8)*$B$6*IF(F8=1,$B$7/12,1)) -> 460 | G9: =IF(G8=0,0,'前提条件'!$B$5*INDEX('前提条件'!$B$6:$B$8,G8)*$B$6*IF(G8=1,$B$7/12,1)) -> 460
A10: 売上原価 | C10: =IF(C$8=0,0,C$9*INDEX('前提条件'!$B$22:$D$22,1,C$8)) -> 122.13 | D10: =IF(D$8=0,0,D$9*INDEX('前提条件'!$B$22:$D$22,1,D$8)) -> 130.732 | E10: =IF(E$8=0,0,E$9*INDEX('前提条件'!$B$22:$D$22,1,E$8)) -> 131.1 | F10: =IF(F$8=0,0,F$9*INDEX('前提条件'!$B$22:$D$22,1,F$8)) -> 131.1 | G10: =IF(G$8=0,0,G$9*INDEX('前提条件'!$B$22:$D$22,1,G$8)) -> 131.1
A11: 人件費 | C11: =IF(C$8=0,0,C$9*INDEX('前提条件'!$B$23:$D$23,1,C$8)) -> 142.83 | D11: =IF(D$8=0,0,D$9*INDEX('前提条件'!$B$23:$D$23,1,D$8)) -> 151.018 | E11: =IF(E$8=0,0,E$9*INDEX('前提条件'!$B$23:$D$23,1,E$8)) -> 149.5 | F11: =IF(F$8=0,0,F$9*INDEX('前提条件'!$B$23:$D$23,1,F$8)) -> 149.5 | G11: =IF(G$8=0,0,G$9*INDEX('前提条件'!$B$23:$D$23,1,G$8)) -> 149.5
A12: 業務委託費・消耗品他 | C12: =IF(C$8=0,0,C$9*INDEX('前提条件'!$B$24:$D$24,1,C$8)) -> 9.936 | D12: =IF(D$8=0,0,D$9*INDEX('前提条件'!$B$24:$D$24,1,D$8)) -> 9.9176 | E12: =IF(E$8=0,0,E$9*INDEX('前提条件'!$B$24:$D$24,1,E$8)) -> 9.2 | F12: =IF(F$8=0,0,F$9*INDEX('前提条件'!$B$24:$D$24,1,F$8)) -> 9.2 | G12: =IF(G$8=0,0,G$9*INDEX('前提条件'!$B$24:$D$24,1,G$8)) -> 9.2
A13: 部門利益 | C13: =C9-SUM(C10:C12) -> 139.104 | D13: =D9-SUM(D10:D12) -> 159.1324 | E13: =E9-SUM(E10:E12) -> 170.2 | F13: =F9-SUM(F10:F12) -> 170.2 | G13: =G9-SUM(G10:G12) -> 170.2
A14: 広告宣伝費・販売促進費 | C14: =IF(C$8=0,0,C$9*INDEX('前提条件'!$B$25:$D$25,1,C$8)) -> 5.796 | D14: =IF(D$8=0,0,D$9*INDEX('前提条件'!$B$25:$D$25,1,D$8)) -> 6.3112 | E14: =IF(E$8=0,0,E$9*INDEX('前提条件'!$B$25:$D$25,1,E$8)) -> 6.44 | F14: =IF(F$8=0,0,F$9*INDEX('前提条件'!$B$25:$D$25,1,F$8)) -> 6.44 | G14: =IF(G$8=0,0,G$9*INDEX('前提条件'!$B$25:$D$25,1,G$8)) -> 6.44
A15: その他経費 | C15: =IF(C$8=0,0,C$9*INDEX('前提条件'!$B$26:$D$26,1,C$8)) -> 2.07 | D15: =IF(D$8=0,0,D$9*INDEX('前提条件'!$B$26:$D$26,1,D$8)) -> 2.254 | E15: =IF(E$8=0,0,E$9*INDEX('前提条件'!$B$26:$D$26,1,E$8)) -> 2.3 | F15: =IF(F$8=0,0,F$9*INDEX('前提条件'!$B$26:$D$26,1,F$8)) -> 2.3 | G15: =IF(G$8=0,0,G$9*INDEX('前提条件'!$B$26:$D$26,1,G$8)) -> 2.3
A16: 水道光熱費 | C16: =IF(C$8=0,0,C$9*INDEX('前提条件'!$B$27:$D$27,1,C$8)) -> 16.56 | D16: =IF(D$8=0,0,D$9*INDEX('前提条件'!$B$27:$D$27,1,D$8)) -> 17.1304 | E16: =IF(E$8=0,0,E$9*INDEX('前提条件'!$B$27:$D$27,1,E$8)) -> 16.56 | F16: =IF(F$8=0,0,F$9*INDEX('前提条件'!$B$27:$D$27,1,F$8)) -> 16.56 | G16: =IF(G$8=0,0,G$9*INDEX('前提条件'!$B$27:$D$27,1,G$8)) -> 16.56
A17: GOP（店舗営業総利益） | C17: =C13-SUM(C14:C16) -> 114.678 | D17: =D13-SUM(D14:D16) -> 133.4368 | E17: =E13-SUM(E14:E16) -> 144.9 | F17: =F13-SUM(F14:F16) -> 144.9 | G17: =G13-SUM(G14:G16) -> 144.9
A18: ロイヤリティ | C18: =IF(C$8=0,0,C$9*INDEX('前提条件'!$B$28:$D$28,1,C$8)) -> 16.56 | D18: =IF(D$8=0,0,D$9*INDEX('前提条件'!$B$28:$D$28,1,D$8)) -> 18.032 | E18: =IF(E$8=0,0,E$9*INDEX('前提条件'!$B$28:$D$28,1,E$8)) -> 18.4 | F18: =IF(F$8=0,0,F$9*INDEX('前提条件'!$B$28:$D$28,1,F$8)) -> 18.4 | G18: =IF(G$8=0,0,G$9*INDEX('前提条件'!$B$28:$D$28,1,G$8)) -> 18.4
A19: 保険・租税公課 | C19: =IF(C$8=0,0,C$9*INDEX('前提条件'!$B$29:$D$29,1,C$8)) -> 2.898 | D19: =IF(D$8=0,0,D$9*INDEX('前提条件'!$B$29:$D$29,1,D$8)) -> 3.1556 | E19: =IF(E$8=0,0,E$9*INDEX('前提条件'!$B$29:$D$29,1,E$8)) -> 3.22 | F19: =IF(F$8=0,0,F$9*INDEX('前提条件'!$B$29:$D$29,1,F$8)) -> 3.22 | G19: =IF(G$8=0,0,G$9*INDEX('前提条件'!$B$29:$D$29,1,G$8)) -> 3.22
A20: 地代家賃（固定） | C20: =IF(C8=0,0,'前提条件'!$B$14*$B$6*IF(C8=1,$B$7/12,1)) -> 26.64 | D20: =IF(D8=0,0,'前提条件'!$B$14*$B$6*IF(D8=1,$B$7/12,1)) -> 26.64 | E20: =IF(E8=0,0,'前提条件'!$B$14*$B$6*IF(E8=1,$B$7/12,1)) -> 26.64 | F20: =IF(F8=0,0,'前提条件'!$B$14*$B$6*IF(F8=1,$B$7/12,1)) -> 26.64 | G20: =IF(G8=0,0,'前提条件'!$B$14*$B$6*IF(G8=1,$B$7/12,1)) -> 26.64
A21: 歩合家賃 | C21: =IF(C8=0,0,MAX(0,C9/$B$6-'前提条件'!$B$16*IF(C8=1,$B$7/12,1))*'前提条件'!$B$15*$B$6) -> 5.782 | D21: =IF(D8=0,0,MAX(0,D9/$B$6-'前提条件'!$B$16*IF(D8=1,$B$7/12,1))*'前提条件'!$B$15*$B$6) -> 8.358 | E21: =IF(E8=0,0,MAX(0,E9/$B$6-'前提条件'!$B$16*IF(E8=1,$B$7/12,1))*'前提条件'!$B$15*$B$6) -> 9.002 | F21: =IF(F8=0,0,MAX(0,F9/$B$6-'前提条件'!$B$16*IF(F8=1,$B$7/12,1))*'前提条件'!$B$15*$B$6) -> 9.002 | G21: =IF(G8=0,0,MAX(0,G9/$B$6-'前提条件'!$B$16*IF(G8=1,$B$7/12,1))*'前提条件'!$B$15*$B$6) -> 9.002
A22: 修繕維持費（FFE） | C22: =IF(C$8=0,0,C$9*INDEX('前提条件'!$B$30:$D$30,1,C$8)) -> 10.35 | D22: =IF(D$8=0,0,D$9*INDEX('前提条件'!$B$30:$D$30,1,D$8)) -> 11.27 | E22: =IF(E$8=0,0,E$9*INDEX('前提条件'!$B$30:$D$30,1,E$8)) -> 11.5 | F22: =IF(F$8=0,0,F$9*INDEX('前提条件'!$B$30:$D$30,1,F$8)) -> 11.5 | G22: =IF(G$8=0,0,G$9*INDEX('前提条件'!$B$30:$D$30,1,G$8)) -> 11.5
A23: 店舗EBITDA | C23: =C17-SUM(C18:C22) -> 52.448 | D23: =D17-SUM(D18:D22) -> 65.9812 | E23: =E17-SUM(E18:E22) -> 76.138 | F23: =F17-SUM(F18:F22) -> 76.138 | G23: =G17-SUM(G18:G22) -> 76.138
A24: 減価償却費 | C24: =IF(C8=0,0,'前提条件'!$B$42*$B$6*IF(C8=1,$B$7/12,1)) -> 20.8 | D24: =IF(D8=0,0,'前提条件'!$B$42*$B$6*IF(D8=1,$B$7/12,1)) -> 20.8 | E24: =IF(E8=0,0,'前提条件'!$B$42*$B$6*IF(E8=1,$B$7/12,1)) -> 20.8 | F24: =IF(F8=0,0,'前提条件'!$B$42*$B$6*IF(F8=1,$B$7/12,1)) -> 20.8 | G24: =IF(G8=0,0,'前提条件'!$B$42*$B$6*IF(G8=1,$B$7/12,1)) -> 20.8
A25: 店舗営業利益 | C25: =C23-C24 -> 31.648 | D25: =D23-D24 -> 45.1812 | E25: =E23-E24 -> 55.338 | F25: =F23-F24 -> 55.338 | G25: =G23-G24 -> 55.338
A27: ② 札幌・大阪
A28: 店舗数（店） | B28: 2
A29: 開業年度の稼働月数 | B29: ='前提条件'!$B$9 -> 7.5
A30: 年次（0=未開業/1/2/3） | C30: 0 | D30: 1 | E30: 2 | F30: 3 | G30: 3
A31: 売上高 | C31: =IF(C30=0,0,'前提条件'!$B$5*INDEX('前提条件'!$B$6:$B$8,C30)*$B$28*IF(C30=1,$B$29/12,1)) -> 0 | D31: =IF(D30=0,0,'前提条件'!$B$5*INDEX('前提条件'!$B$6:$B$8,D30)*$B$28*IF(D30=1,$B$29/12,1)) -> 517.5 | E31: =IF(E30=0,0,'前提条件'!$B$5*INDEX('前提条件'!$B$6:$B$8,E30)*$B$28*IF(E30=1,$B$29/12,1)) -> 901.6 | F31: =IF(F30=0,0,'前提条件'!$B$5*INDEX('前提条件'!$B$6:$B$8,F30)*$B$28*IF(F30=1,$B$29/12,1)) -> 920 | G31: =IF(G30=0,0,'前提条件'!$B$5*INDEX('前提条件'!$B$6:$B$8,G30)*$B$28*IF(G30=1,$B$29/12,1)) -> 920
A32: 売上原価 | C32: =IF(C$30=0,0,C$31*INDEX('前提条件'!$B$22:$D$22,1,C$30)) -> 0 | D32: =IF(D$30=0,0,D$31*INDEX('前提条件'!$B$22:$D$22,1,D$30)) -> 152.6625 | E32: =IF(E$30=0,0,E$31*INDEX('前提条件'!$B$22:$D$22,1,E$30)) -> 261.464 | F32: =IF(F$30=0,0,F$31*INDEX('前提条件'!$B$22:$D$22,1,F$30)) -> 262.2 | G32: =IF(G$30=0,0,G$31*INDEX('前提条件'!$B$22:$D$22,1,G$30)) -> 262.2
A33: 人件費 | C33: =IF(C$30=0,0,C$31*INDEX('前提条件'!$B$23:$D$23,1,C$30)) -> 0 | D33: =IF(D$30=0,0,D$31*INDEX('前提条件'!$B$23:$D$23,1,D$30)) -> 178.5375 | E33: =IF(E$30=0,0,E$31*INDEX('前提条件'!$B$23:$D$23,1,E$30)) -> 302.036 | F33: =IF(F$30=0,0,F$31*INDEX('前提条件'!$B$23:$D$23,1,F$30)) -> 299 | G33: =IF(G$30=0,0,G$31*INDEX('前提条件'!$B$23:$D$23,1,G$30)) -> 299
A34: 業務委託費・消耗品他 | C34: =IF(C$30=0,0,C$31*INDEX('前提条件'!$B$24:$D$24,1,C$30)) -> 0 | D34: =IF(D$30=0,0,D$31*INDEX('前提条件'!$B$24:$D$24,1,D$30)) -> 12.42 | E34: =IF(E$30=0,0,E$31*INDEX('前提条件'!$B$24:$D$24,1,E$30)) -> 19.8352 | F34: =IF(F$30=0,0,F$31*INDEX('前提条件'!$B$24:$D$24,1,F$30)) -> 18.4 | G34: =IF(G$30=0,0,G$31*INDEX('前提条件'!$B$24:$D$24,1,G$30)) -> 18.4
A35: 部門利益 | C35: =C31-SUM(C32:C34) -> 0 | D35: =D31-SUM(D32:D34) -> 173.88 | E35: =E31-SUM(E32:E34) -> 318.2648 | F35: =F31-SUM(F32:F34) -> 340.4 | G35: =G31-SUM(G32:G34) -> 340.4
A36: 広告宣伝費・販売促進費 | C36: =IF(C$30=0,0,C$31*INDEX('前提条件'!$B$25:$D$25,1,C$30)) -> 0 | D36: =IF(D$30=0,0,D$31*INDEX('前提条件'!$B$25:$D$25,1,D$30)) -> 7.245 | E36: =IF(E$30=0,0,E$31*INDEX('前提条件'!$B$25:$D$25,1,E$30)) -> 12.6224 | F36: =IF(F$30=0,0,F$31*INDEX('前提条件'!$B$25:$D$25,1,F$30)) -> 12.88 | G36: =IF(G$30=0,0,G$31*INDEX('前提条件'!$B$25:$D$25,1,G$30)) -> 12.88
A37: その他経費 | C37: =IF(C$30=0,0,C$31*INDEX('前提条件'!$B$26:$D$26,1,C$30)) -> 0 | D37: =IF(D$30=0,0,D$31*INDEX('前提条件'!$B$26:$D$26,1,D$30)) -> 2.5875 | E37: =IF(E$30=0,0,E$31*INDEX('前提条件'!$B$26:$D$26,1,E$30)) -> 4.508 | F37: =IF(F$30=0,0,F$31*INDEX('前提条件'!$B$26:$D$26,1,F$30)) -> 4.6 | G37: =IF(G$30=0,0,G$31*INDEX('前提条件'!$B$26:$D$26,1,G$30)) -> 4.6
A38: 水道光熱費 | C38: =IF(C$30=0,0,C$31*INDEX('前提条件'!$B$27:$D$27,1,C$30)) -> 0 | D38: =IF(D$30=0,0,D$31*INDEX('前提条件'!$B$27:$D$27,1,D$30)) -> 20.7 | E38: =IF(E$30=0,0,E$31*INDEX('前提条件'!$B$27:$D$27,1,E$30)) -> 34.2608 | F38: =IF(F$30=0,0,F$31*INDEX('前提条件'!$B$27:$D$27,1,F$30)) -> 33.12 | G38: =IF(G$30=0,0,G$31*INDEX('前提条件'!$B$27:$D$27,1,G$30)) -> 33.12
A39: GOP（店舗営業総利益） | C39: =C35-SUM(C36:C38) -> 0 | D39: =D35-SUM(D36:D38) -> 143.3475 | E39: =E35-SUM(E36:E38) -> 266.8736 | F39: =F35-SUM(F36:F38) -> 289.8 | G39: =G35-SUM(G36:G38) -> 289.8
A40: ロイヤリティ | C40: =IF(C$30=0,0,C$31*INDEX('前提条件'!$B$28:$D$28,1,C$30)) -> 0 | D40: =IF(D$30=0,0,D$31*INDEX('前提条件'!$B$28:$D$28,1,D$30)) -> 20.7 | E40: =IF(E$30=0,0,E$31*INDEX('前提条件'!$B$28:$D$28,1,E$30)) -> 36.064 | F40: =IF(F$30=0,0,F$31*INDEX('前提条件'!$B$28:$D$28,1,F$30)) -> 36.8 | G40: =IF(G$30=0,0,G$31*INDEX('前提条件'!$B$28:$D$28,1,G$30)) -> 36.8
A41: 保険・租税公課 | C41: =IF(C$30=0,0,C$31*INDEX('前提条件'!$B$29:$D$29,1,C$30)) -> 0 | D41: =IF(D$30=0,0,D$31*INDEX('前提条件'!$B$29:$D$29,1,D$30)) -> 3.6225 | E41: =IF(E$30=0,0,E$31*INDEX('前提条件'!$B$29:$D$29,1,E$30)) -> 6.3112 | F41: =IF(F$30=0,0,F$31*INDEX('前提条件'!$B$29:$D$29,1,F$30)) -> 6.44 | G41: =IF(G$30=0,0,G$31*INDEX('前提条件'!$B$29:$D$29,1,G$30)) -> 6.44
A42: 地代家賃（固定） | C42: =IF(C30=0,0,'前提条件'!$B$14*$B$28*IF(C30=1,$B$29/12,1)) -> 0 | D42: =IF(D30=0,0,'前提条件'!$B$14*$B$28*IF(D30=1,$B$29/12,1)) -> 33.3 | E42: =IF(E30=0,0,'前提条件'!$B$14*$B$28*IF(E30=1,$B$29/12,1)) -> 53.28 | F42: =IF(F30=0,0,'前提条件'!$B$14*$B$28*IF(F30=1,$B$29/12,1)) -> 53.28 | G42: =IF(G30=0,0,'前提条件'!$B$14*$B$28*IF(G30=1,$B$29/12,1)) -> 53.28
...

Sheet 5カ年連結PL
A1: 5か年事業計画 連結損益計画（FY2027-FY2031・百万円）
A2: FY＝4月〜翌3月。2027年4月 六本木開業 → 2028年 札幌・大阪 → 2029年 首都圏・政令指定都市 → 2030年以降 リゾート含め年2店舗
A3: 科 目 | B3: 対売上比 (FY2031) | C3: FY2027 | D3: FY2028 | E3: FY2029 | F3: FY2030 | G3: FY2031 | H3: 5年累計
A4: 期末店舗数（店） | C4: ='前提条件'!B55 -> 1 | D4: ='前提条件'!C55 -> 3 | E4: ='前提条件'!D55 -> 5 | F4: ='前提条件'!E55 -> 7 | G4: ='前提条件'!F55 -> 9
A5: 売上高 | B5: =IF($G$5=0,0,G5/$G$5) -> 1 | C5: ='店舗群別PL'!C9+'店舗群別PL'!C31+'店舗群別PL'!C53+'店舗群別PL'!C75+'店舗群別PL'!C97 -> 414 | D5: ='店舗群別PL'!D9+'店舗群別PL'!D31+'店舗群別PL'!D53+'店舗群別PL'!D75+'店舗群別PL'!D97 -> 968.3 | E5: ='店舗群別PL'!E9+'店舗群別PL'!E31+'店舗群別PL'!E53+'店舗群別PL'!E75+'店舗群別PL'!E97 -> 1879.1 | F5: ='店舗群別PL'!F9+'店舗群別PL'!F31+'店舗群別PL'!F53+'店舗群別PL'!F75+'店舗群別PL'!F97 -> 2799.1 | G5: ='店舗群別PL'!G9+'店舗群別PL'!G31+'店舗群別PL'!G53+'店舗群別PL'!G75+'店舗群別PL'!G97 -> 3719.1 | H5: =SUM(C5:G5) -> 9779.6
A6: 売上原価 | B6: =IF($G$5=0,0,G6/$G$5) -> 0.28760359 | C6: ='店舗群別PL'!C10+'店舗群別PL'!C32+'店舗群別PL'!C54+'店舗群別PL'!C76+'店舗群別PL'!C98 -> 122.13 | D6: ='店舗群別PL'!D10+'店舗群別PL'!D32+'店舗群別PL'!D54+'店舗群別PL'!D76+'店舗群別PL'!D98 -> 283.3945 | E6: ='店舗群別PL'!E10+'店舗群別PL'!E32+'店舗群別PL'!E54+'店舗群別PL'!E76+'店舗群別PL'!E98 -> 545.2265 | F6: ='店舗群別PL'!F10+'店舗群別PL'!F32+'店舗群別PL'!F54+'店舗群別PL'!F76+'店舗群別PL'!F98 -> 807.4265 | G6: ='店舗群別PL'!G10+'店舗群別PL'!G32+'店舗群別PL'!G54+'店舗群別PL'!G76+'店舗群別PL'!G98 -> 1069.6265 | H6: =SUM(C6:G6) -> 2827.804
A7: 人件費 | B7: =IF($G$5=0,0,G7/$G$5) -> 0.33020717 | C7: ='店舗群別PL'!C11+'店舗群別PL'!C33+'店舗群別PL'!C55+'店舗群別PL'!C77+'店舗群別PL'!C99 -> 142.83 | D7: ='店舗群別PL'!D11+'店舗群別PL'!D33+'店舗群別PL'!D55+'店舗群別PL'!D77+'店舗群別PL'!D99 -> 329.5555 | E7: ='店舗群別PL'!E11+'店舗群別PL'!E33+'店舗群別PL'!E55+'店舗群別PL'!E77+'店舗群別PL'!E99 -> 630.0735 | F7: ='店舗群別PL'!F11+'店舗群別PL'!F33+'店舗群別PL'!F55+'店舗群別PL'!F77+'店舗群別PL'!F99 -> 929.0735 | G7: ='店舗群別PL'!G11+'店舗群別PL'!G33+'店舗群別PL'!G55+'店舗群別PL'!G77+'店舗群別PL'!G99 -> 1228.0735 | H7: =SUM(C7:G7) -> 3259.606
A8: 業務委託費・消耗品他 | B8: =IF($G$5=0,0,G8/$G$5) -> 0.021041435 | C8: ='店舗群別PL'!C12+'店舗群別PL'!C34+'店舗群別PL'!C56+'店舗群別PL'!C78+'店舗群別PL'!C100 -> 9.936 | D8: ='店舗群別PL'!D12+'店舗群別PL'!D34+'店舗群別PL'!D56+'店舗群別PL'!D78+'店舗群別PL'!D100 -> 22.3376 | E8: ='店舗群別PL'!E12+'店舗群別PL'!E34+'店舗群別PL'!E56+'店舗群別PL'!E78+'店舗群別PL'!E100 -> 41.4552 | F8: ='店舗群別PL'!F12+'店舗群別PL'!F34+'店舗群別PL'!F56+'店舗群別PL'!F78+'店舗群別PL'!F100 -> 59.8552 | G8: ='店舗群別PL'!G12+'店舗群別PL'!G34+'店舗群別PL'!G56+'店舗群別PL'!G78+'店舗群別PL'!G100 -> 78.2552 | H8: =SUM(C8:G8) -> 211.8392
A9: 部門利益 | B9: =IF($G$5=0,0,G9/$G$5) -> 0.3611478 | C9: ='店舗群別PL'!C13+'店舗群別PL'!C35+'店舗群別PL'!C57+'店舗群別PL'!C79+'店舗群別PL'!C101 -> 139.104 | D9: ='店舗群別PL'!D13+'店舗群別PL'!D35+'店舗群別PL'!D57+'店舗群別PL'!D79+'店舗群別PL'!D101 -> 333.0124 | E9: ='店舗群別PL'!E13+'店舗群別PL'!E35+'店舗群別PL'!E57+'店舗群別PL'!E79+'店舗群別PL'!E101 -> 662.3448 | F9: ='店舗群別PL'!F13+'店舗群別PL'!F35+'店舗群別PL'!F57+'店舗群別PL'!F79+'店舗群別PL'!F101 -> 1002.7448 | G9: ='店舗群別PL'!G13+'店舗群別PL'!G35+'店舗群別PL'!G57+'店舗群別PL'!G79+'店舗群別PL'!G101 -> 1343.1448 | H9: =SUM(C9:G9) -> 3480.3508
A10: 広告宣伝費・販売促進費 | B10: =IF($G$5=0,0,G10/$G$5) -> 0.014 | C10: ='店舗群別PL'!C14+'店舗群別PL'!C36+'店舗群別PL'!C58+'店舗群別PL'!C80+'店舗群別PL'!C102 -> 5.796 | D10: ='店舗群別PL'!D14+'店舗群別PL'!D36+'店舗群別PL'!D58+'店舗群別PL'!D80+'店舗群別PL'!D102 -> 13.5562 | E10: ='店舗群別PL'!E14+'店舗群別PL'!E36+'店舗群別PL'!E58+'店舗群別PL'!E80+'店舗群別PL'!E102 -> 26.3074 | F10: ='店舗群別PL'!F14+'店舗群別PL'!F36+'店舗群別PL'!F58+'店舗群別PL'!F80+'店舗群別PL'!F102 -> 39.1874 | G10: ='店舗群別PL'!G14+'店舗群別PL'!G36+'店舗群別PL'!G58+'店舗群別PL'!G80+'店舗群別PL'!G102 -> 52.0674 | H10: =SUM(C10:G10) -> 136.9144
A11: その他経費 | B11: =IF($G$5=0,0,G11/$G$5) -> 0.005 | C11: ='店舗群別PL'!C15+'店舗群別PL'!C37+'店舗群別PL'!C59+'店舗群別PL'!C81+'店舗群別PL'!C103 -> 2.07 | D11: ='店舗群別PL'!D15+'店舗群別PL'!D37+'店舗群別PL'!D59+'店舗群別PL'!D81+'店舗群別PL'!D103 -> 4.8415 | E11: ='店舗群別PL'!E15+'店舗群別PL'!E37+'店舗群別PL'!E59+'店舗群別PL'!E81+'店舗群別PL'!E103 -> 9.3955 | F11: ='店舗群別PL'!F15+'店舗群別PL'!F37+'店舗群別PL'!F59+'店舗群別PL'!F81+'店舗群別PL'!F103 -> 13.9955 | G11: ='店舗群別PL'!G15+'店舗群別PL'!G37+'店舗群別PL'!G59+'店舗群別PL'!G81+'店舗群別PL'!G103 -> 18.5955 | H11: =SUM(C11:G11) -> 48.898
A12: 水道光熱費 | B12: =IF($G$5=0,0,G12/$G$5) -> 0.037041435 | C12: ='店舗群別PL'!C16+'店舗群別PL'!C38+'店舗群別PL'!C60+'店舗群別PL'!C82+'店舗群別PL'!C104 -> 16.56 | D12: ='店舗群別PL'!D16+'店舗群別PL'!D38+'店舗群別PL'!D60+'店舗群別PL'!D82+'店舗群別PL'!D104 -> 37.8304 | E12: ='店舗群別PL'!E16+'店舗群別PL'!E38+'店舗群別PL'!E60+'店舗群別PL'!E82+'店舗群別PL'!E104 -> 71.5208 | F12: ='店舗群別PL'!F16+'店舗群別PL'!F38+'店舗群別PL'!F60+'店舗群別PL'!F82+'店舗群別PL'!F104 -> 104.6408 | G12: ='店舗群別PL'!G16+'店舗群別PL'!G38+'店舗群別PL'!G60+'店舗群別PL'!G82+'店舗群別PL'!G104 -> 137.7608 | H12: =SUM(C12:G12) -> 368.3128
A13: GOP（店舗営業総利益） | B13: =IF($G$5=0,0,G13/$G$5) -> 0.30510637 | C13: ='店舗群別PL'!C17+'店舗群別PL'!C39+'店舗群別PL'!C61+'店舗群別PL'!C83+'店舗群別PL'!C105 -> 114.678 | D13: ='店舗群別PL'!D17+'店舗群別PL'!D39+'店舗群別PL'!D61+'店舗群別PL'!D83+'店舗群別PL'!D105 -> 276.7843 | E13: ='店舗群別PL'!E17+'店舗群別PL'!E39+'店舗群別PL'!E61+'店舗群別PL'!E83+'店舗群別PL'!E105 -> 555.1211 | F13: ='店舗群別PL'!F17+'店舗群別PL'!F39+'店舗群別PL'!F61+'店舗群別PL'!F83+'店舗群別PL'!F105 -> 844.9211 | G13: ='店舗群別PL'!G17+'店舗群別PL'!G39+'店舗群別PL'!G61+'店舗群別PL'!G83+'店舗群別PL'!G105 -> 1134.7211 | H13: =SUM(C13:G13) -> 2926.2256
A14: ロイヤリティ | B14: =IF($G$5=0,0,G14/$G$5) -> 0.04 | C14: ='店舗群別PL'!C18+'店舗群別PL'!C40+'店舗群別PL'!C62+'店舗群別PL'!C84+'店舗群別PL'!C106 -> 16.56 | D14: ='店舗群別PL'!D18+'店舗群別PL'!D40+'店舗群別PL'!D62+'店舗群別PL'!D84+'店舗群別PL'!D106 -> 38.732 | E14: ='店舗群別PL'!E18+'店舗群別PL'!E40+'店舗群別PL'!E62+'店舗群別PL'!E84+'店舗群別PL'!E106 -> 75.164 | F14: ='店舗群別PL'!F18+'店舗群別PL'!F40+'店舗群別PL'!F62+'店舗群別PL'!F84+'店舗群別PL'!F106 -> 111.964 | G14: ='店舗群別PL'!G18+'店舗群別PL'!G40+'店舗群別PL'!G62+'店舗群別PL'!G84+'店舗群別PL'!G106 -> 148.764 | H14: =SUM(C14:G14) -> 391.184
A15: 保険・租税公課 | B15: =IF($G$5=0,0,G15/$G$5) -> 0.007 | C15: ='店舗群別PL'!C19+'店舗群別PL'!C41+'店舗群別PL'!C63+'店舗群別PL'!C85+'店舗群別PL'!C107 -> 2.898 | D15: ='店舗群別PL'!D19+'店舗群別PL'!D41+'店舗群別PL'!D63+'店舗群別PL'!D85+'店舗群別PL'!D107 -> 6.7781 | E15: ='店舗群別PL'!E19+'店舗群別PL'!E41+'店舗群別PL'!E63+'店舗群別PL'!E85+'店舗群別PL'!E107 -> 13.1537 | F15: ='店舗群別PL'!F19+'店舗群別PL'!F41+'店舗群別PL'!F63+'店舗群別PL'!F85+'店舗群別PL'!F107 -> 19.5937 | G15: ='店舗群別PL'!G19+'店舗群別PL'!G41+'店舗群別PL'!G63+'店舗群別PL'!G85+'店舗群別PL'!G107 -> 26.0337 | H15: =SUM(C15:G15) -> 68.4572
A16: 地代家賃（固定） | B16: =IF($G$5=0,0,G16/$G$5) -> 0.059094942 | C16: ='店舗群別PL'!C20+'店舗群別PL'!C42+'店舗群別PL'!C64+'店舗群別PL'!C86+'店舗群別PL'!C108 -> 26.64 | D16: ='店舗群別PL'!D20+'店舗群別PL'!D42+'店舗群別PL'!D64+'店舗群別PL'!D86+'店舗群別PL'!D108 -> 59.94 | E16: ='店舗群別PL'!E20+'店舗群別PL'!E42+'店舗群別PL'!E64+'店舗群別PL'!E86+'店舗群別PL'!E108 -> 113.22 | F16: ='店舗群別PL'!F20+'店舗群別PL'!F42+'店舗群別PL'!F64+'店舗群別PL'!F86+'店舗群別PL'!F108 -> 166.5 | G16: ='店舗群別PL'!G20+'店舗群別PL'!G42+'店舗群別PL'!G64+'店舗群別PL'!G86+'店舗群別PL'!G108 -> 219.78 | H16: =SUM(C16:G16) -> 586.08
... A19: 店舗EBITDA 計 | B19: =IF($G$5=0,0,G19/$G$5) -> 0.15547105 | C19: ='店舗群別PL'!C23+'店舗群別PL'!C45+'店舗群別PL'!C67+'店舗群別PL'!C89+'店舗群別PL'!C111 -> 52.448 | D19: ='店舗群別PL'!D23+'店舗群別PL'!D45+'店舗群別PL'!D67+'店舗群別PL'!D89+'店舗群別PL'!D111 -> 131.5412 | E19: ='店舗群別PL'!E23+'店舗群別PL'!E45+'店舗群別PL'!E67+'店舗群別PL'!E89+'店舗群別PL'!E111 -> 273.6604 | F19: ='店舗群別PL'!F23+'店舗群別PL'!F45+'店舗群別PL'!F67+'店舗群別PL'!F89+'店舗群別PL'!F111 -> 425.9364 | G19: ='店舗群別PL'!G23+'店舗群別PL'!G45+'店舗群別PL'!G67+'店舗群別PL'!G89+'店舗群別PL'!G111 -> 578.2124 | H19: =SUM(C19:G19) -> 1461.7984
A20: 本部費 | B20: =IF($G$5=0,0,G20/$G$5) -> 0.014788524 | C20: ='前提条件'!B56 -> 15 | D20: ='前提条件'!C56 -> 28 | E20: ='前提条件'!D56 -> 40 | F20: ='前提条件'!E56 -> 48 | G20: ='前提条件'!F56 -> 55 | H20: =SUM(C20:G20) -> 186
A21: 連結EBITDA | B21: =IF($G$5=0,0,G21/$G$5) -> 0.14068253 | C21: =C19-C20 -> 37.448 | D21: =D19-D20 -> 103.5412 | E21: =E19-E20 -> 233.6604 | F21: =F19-F20 -> 377.9364 | G21: =G19-G20 -> 523.2124 | H21: =SUM(C21:G21) -> 1275.7984
A22: EBITDA率 | C22: =IF(C5=0,0,C21/C5) -> 0.090454106 | D22: =IF(D5=0,0,D21/D5) -> 0.10693091 | E22: =IF(E5=0,0,E21/E5) -> 0.12434697 | F22: =IF(F5=0,0,F21/F5) -> 0.13502069 | G22: =IF(G5=0,0,G21/G5) -> 0.14068253 | H22: =H21/H5 -> 0.13045507
A23: 減価償却費 | B23: =IF($G$5=0,0,G23/$G$5) -> 0.045434379 | C23: ='店舗群別PL'!C24+'店舗群別PL'!C46+'店舗群別PL'!C68+'店舗群別PL'!C90+'店舗群別PL'!C112 -> 20.8 | D23: ='店舗群別PL'!D24+'店舗群別PL'!D46+'店舗群別PL'!D68+'店舗群別PL'!D90+'店舗群別PL'!D112 -> 46.8 | E23: ='店舗群別PL'!E24+'店舗群別PL'!E46+'店舗群別PL'!E68+'店舗群別PL'!E90+'店舗群別PL'!E112 -> 87.775 | F23: ='店舗群別PL'!F24+'店舗群別PL'!F46+'店舗群別PL'!F68+'店舗群別PL'!F90+'店舗群別PL'!F112 -> 128.375 | G23: ='店舗群別PL'!G24+'店舗群別PL'!G46+'店舗群別PL'!G68+'店舗群別PL'!G90+'店舗群別PL'!G112 -> 168.975 | H23: =SUM(C23:G23) -> 452.725
A24: 営業利益 | B24: =IF($G$5=0,0,G24/$G$5) -> 0.095248151 | C24: =C21-C23 -> 16.648 | D24: =D21-D23 -> 56.7412 | E24: =E21-E23 -> 145.8854 | F24: =F21-F23 -> 249.5614 | G24: =G21-G23 -> 354.2374 | H24: =SUM(C24:G24) -> 823.0734
A25: 営業利益率 | C25: =IF(C5=0,0,C24/C5) -> 0.04021256 | D25: =IF(D5=0,0,D24/D5) -> 0.058598781 | E25: =IF(E5=0,0,E24/E5) -> 0.077635783 | F25: =IF(F5=0,0,F24/F5) -> 0.089157729 | G25: =IF(G5=0,0,G24/G5) -> 0.095248151 | H25: =H24/H5 -> 0.084162277
A27: 【計画のポイント】FY2028に連結EBITDA率10%超、FY2029に営業利益率5%超。FY2031はEBITDA率14.0%・営業利益率9.5%。
A28: ※ 1号店の初年度は2026年8月3日提出P&Lをそのまま採用。新店初年度は売上90%・開業7.5か月で保守的に計上。
A29: ※ ロイヤリティ4%・歩合家賃7%・地代家賃は契約条件どおり全店適用。金利・税金は含まない。

Sheet 投資・キャッシュフロー
A1: 5か年事業計画 連結キャッシュフロー（百万円）
A2: 分割払いスキーム活用により、1店あたり開業時現金支出を247百万円 → 108百万円に圧縮。
A3: 項 目 | C3: FY2027 | D3: FY2028 | E3: FY2029 | F3: FY2030 | G3: FY2031 | H3: 5年累計
A4: 新規出店数（店） | C4: ='前提条件'!B54 -> 1 | D4: ='前提条件'!C54 -> 2 | E4: ='前提条件'!D54 -> 2 | F4: ='前提条件'!E54 -> 2 | G4: ='前提条件'!F54 -> 2 | H4: =SUM(C4:G4) -> 9
A5: 期末店舗数（店） | C5: ='前提条件'!B55 -> 1 | D5: ='前提条件'!C55 -> 3 | E5: ='前提条件'!D55 -> 5 | F5: ='前提条件'!E55 -> 7 | G5: ='前提条件'!F55 -> 9
A6: 初期投資（総額） | C6: =-C4*'前提条件'!$B$39 -> -247 | D6: =-D4*'前提条件'!$B$39 -> -494 | E6: =-E4*'前提条件'!$C$39 -> -484 | F6: =-F4*'前提条件'!$C$39 -> -484 | G6: =-G4*'前提条件'!$C$39 -> -484 | H6: =SUM(C6:G6) -> -2193
A7: うち分割対象額 | C7: =C4*'前提条件'!$B$47 -> 138.9 | D7: =D4*'前提条件'!$B$47 -> 277.8 | E7: =E4*'前提条件'!$B$47 -> 277.8 | F7: =F4*'前提条件'!$B$47 -> 277.8 | G7: =G4*'前提条件'!$B$47 -> 277.8 | H7: =SUM(C7:G7) -> 1250.1
A8: 開業時 現金支出 | C8: =C6+C7 -> -108.1 | D8: =D6+D7 -> -216.2 | E8: =E6+E7 -> -206.2 | F8: =F6+F7 -> -206.2 | G8: =G6+G7 -> -206.2 | H8: =SUM(C8:G8) -> -942.9
A9: 分割弁済額 | C9: =-(IF('店舗群別PL'!C8=0,0,'前提条件'!$B$48*'店舗群別PL'!$B$6*IF('店舗群別PL'!C8=1,'店舗群別PL'!$B$7/12,1))+IF('店舗群別PL'!C30=0,0,'前提条件'!$B$48*'店舗群別PL'!$B$28*IF('店舗群別PL'!C30=1,'店舗群別PL'!$B$29/12,1))+IF('店舗群別PL'!C52=0,0,'前提条件'!$B$48*'店舗群別PL'!$B$50*IF('店舗群別PL'!C52=1,'店舗群別PL'!$B$51/12,1))+IF('店舗群別PL'!C74=0,0,'前提条件'!$B$48*'店舗群別PL'!$B$72*IF('店舗群別PL'!C74=1,'店舗群別PL'!$B$73/12,1))+IF('店舗群別PL'!C96=0,0,'前提条件'!$B$48*'店舗群別PL'!$B$94*IF('店舗群別PL'!C96=1,'店舗群別PL'!$B$95/12,1))) -> -15.6 | D9: =-(IF('店舗群別PL'!D8=0,0,'前提条件'!$B$48*'店舗群別PL'!$B$6*IF('店舗群別PL'!D8=1,'店舗群別PL'!$B$7/12,1))+IF('店舗群別PL'!D30=0,0,'前提条件'!$B$48*'店舗群別PL'!$B$28*IF('店舗群別PL'!D30=1,'店舗群別PL'!$B$29/12,1))+IF('店舗群別PL'!D52=0,0,'前提条件'!$B$48*'店舗群別PL'!$B$50*IF('店舗群別PL'!D52=1,'店舗群別PL'!$B$51/12,1))+IF('店舗群別PL'!D74=0,0,'前提条件'!$B$48*'店舗群別PL'!$B$72*IF('店舗群別PL'!D74=1,'店舗群別PL'!$B$73/12,1))+IF('店舗群別PL'!D96=0,0,'前提条件'!$B$48*'店舗群別PL'!$B$94*IF('店舗群別PL'!D96=1,'店舗群別PL'!$B$95/12,1))) -> -35.1 | E9: =-(IF('店舗群別PL'!E8=0,0,'前提条件'!$B$48*'店舗群別PL'!$B$6*IF('店舗群別PL'!E8=1,'店舗群別PL'!$B$7/12,1))+IF('店舗群別PL'!E30=0,0,'前提条件'!$B$48*'店舗群別PL'!$B$28*IF('店舗群別PL'!E30=1,'店舗群別PL'!$B$29/12,1))+IF('店舗群別PL'!E52=0,0,'前提条件'!$B$48*'店舗群別PL'!$B$50*IF('店舗群別PL'!E52=1,'店舗群別PL'!$B$51/12,1))+IF('店舗群別PL'!E74=0,0,'前提条件'!$B$48*'店舗群別PL'!$B$72*IF('店舗群別PL'!E74=1,'店舗群別PL'!$B$73/12,1))+IF('店舗群別PL'!E96=0,0,'前提条件'!$B$48*'店舗群別PL'!$B$94*IF('店舗群別PL'!E96=1,'店舗群別PL'!$B$95/12,1))) -> -66.3 | F9: =-(IF('店舗群別PL'!F8=0,0,'前提条件'!$B$48*'店舗群別PL'!$B$6*IF('店舗群別PL'!F8=1,'店舗群別PL'!$B$7/12,1))+IF('店舗群別PL'!F30=0,0,'前提条件'!$B$48*'店舗群別PL'!$B$28*IF('店舗群別PL'!F30=1,'店舗群別PL'!$B$29/12,1))+IF('店舗群別PL'!F52=0,0,'前提条件'!$B$48*'店舗群別PL'!$B$50*IF('店舗群別PL'!F52=1,'店舗群別PL'!$B$51/12,1))+IF('店舗群別PL'!F74=0,0,'前提条件'!$B$48*'店舗群別PL'!$B$72*IF('店舗群別PL'!F74=1,'店舗群別PL'!$B$73/12,1))+IF('店舗群別PL'!F96=0,0,'前提条件'!$B$48*'店舗群別PL'!$B$94*IF('店舗群別PL'!F96=1,'店舗群別PL'!$B$95/12,1))) -> -97.5 | G9: =-(IF('店舗群別PL'!G8=0,0,'前提条件'!$B$48*'店舗群別PL'!$B$6*IF('店舗群別PL'!G8=1,'店舗群別PL'!$B$7/12,1))+IF('店舗群別PL'!G30=0,0,'前提条件'!$B$48*'店舗群別PL'!$B$28*IF('店舗群別PL'!G30=1,'店舗群別PL'!$B$29/12,1))+IF('店舗群別PL'!G52=0,0,'前提条件'!$B$48*'店舗群別PL'!$B$50*IF('店舗群別PL'!G52=1,'店舗群別PL'!$B$51/12,1))+IF('店舗群別PL'!G74=0,0,'前提条件'!$B$48*'店舗群別PL'!$B$72*IF('店舗群別PL'!G74=1,'店舗群別PL'!$B$73/12,1))+IF('店舗群別PL'!G96=0,0,'前提条件'!$B$48*'店舗群別PL'!$B$94*IF('店舗群別PL'!G96=1,'店舗群別PL'!$B$95/12,1))) -> -128.7 | H9: =SUM(C9:G9) -> -343.2
A10: 投資キャッシュアウト 計 | C10: =C8+C9 -> -123.7 | D10: =D8+D9 -> -251.3 | E10: =E8+E9 -> -272.5 | F10: =F8+F9 -> -303.7 | G10: =G8+G9 -> -334.9 | H10: =SUM(C10:G10) -> -1286.1
A11: 連結EBITDA | C11: ='5カ年連結PL'!C21 -> 37.448 | D11: ='5カ年連結PL'!D21 -> 103.5412 | E11: ='5カ年連結PL'!E21 -> 233.6604 | F11: ='5カ年連結PL'!F21 -> 377.9364 | G11: ='5カ年連結PL'!G21 -> 523.2124 | H11: =SUM(C11:G11) -> 1275.7984
A12: 簡易フリーキャッシュフロー | C12: =C11+C10 -> -86.252 | D12: =D11+D10 -> -147.7588 | E12: =E11+E10 -> -38.8396 | F12: =F11+F10 -> 74.2364 | G12: =G11+G10 -> 188.3124 | H12: =SUM(C12:G12) -> -10.3016
A13: 累計フリーキャッシュフロー | C13: =C12 -> -86.252 | D13: =C13+D12 -> -234.0108 | E13: =D13+E12 -> -272.8504 | F13: =E13+F12 -> -198.614 | G13: =F13+G12 -> -10.3016
A15: ■ 分割払いスキーム
A16: 内装工事費100百万円（月833千円×120回・10年）／保証金38.9百万円（月463千円×84回・7年）。1店あたり開業時現金支出 247→108百万円。
A17: 分割弁済は資産計上済みの繰延支払（損益は減価償却で費用化済み）のため、P/Lには影響させずCF上のみ計上。
A18: ※ 簡易FCF＝連結EBITDA－投資キャッシュアウト。法人税・運転資本増減・借入/返済・分割払い金利相当は含まない。
A20: ■ 単店の投資回収（1〜3号店・分割払い活用ベース）
A21: 項 目 | C21: 1年目 | D21: 2年目 | E21: 3年目 | F21: 4年目 | G21: 5年目
A22: EBITDA | C22: ='単店モデルPL'!C19 -> 52.448 | D22: ='単店モデルPL'!D19 -> 65.9812 | E22: ='単店モデルPL'!E19 -> 76.138 | F22: ='単店モデルPL'!E19 -> 76.138 | G22: ='単店モデルPL'!E19 -> 76.138
A23: 分割弁済 | C23: =-'前提条件'!$B$48 -> -15.6 | D23: =-'前提条件'!$B$48 -> -15.6 | E23: =-'前提条件'!$B$48 -> -15.6 | F23: =-'前提条件'!$B$48 -> -15.6 | G23: =-'前提条件'!$B$48 -> -15.6
A24: 単店FCF | C24: =C22+C23 -> 36.848 | D24: =D22+D23 -> 50.3812 | E24: =E22+E23 -> 60.538 | F24: =F22+F23 -> 60.538 | G24: =G22+G23 -> 60.538
A25: 累計FCF（開業時支出△108含む） | C25: =-('前提条件'!$B$39-'前提条件'!$B$47)+C24 -> -71.252 | D25: =C25+D24 -> -20.8708 | E25: =D25+E24 -> 39.6672 | F25: =E25+F24 -> 100.2052 | G25: =F25+G24 -> 160.7432
A27: → 開業3年目に累計FCFが黒字転換（投資回収 約2.8年）。保証金39百万円は退去時返還対象のため実質回収はさらに短期。
A28: ※ 分割払いを使わない場合は開業時支出247百万円・回収約3.3年。定常期の年間FCFは60百万円で2号店以降の出店原資となる。
