Workbook

Sheet サマリー
A1: BRASSERIE Thierry Marx 事業収支 統合モデル（2026年10月）
A2: 単位：百万円。「売上前提」の席数・席効率・回転率・客単価を変えると、単店PLから5か年連結・資金計画まで一気に再計算されます。
A4: ■ よく変える前提（編集は「売上前提」シートで）
A5: 総席数（店内＋テラス） | B5: =売上前提!$B$18 -> 114
A6: 店内 | B6: =売上前提!$B$16 -> 62
A7: テラス | B7: =売上前提!$B$17 -> 52
A8: 店内 席効率 | B8: =売上前提!$D$22 -> 0.75
A9: ディナー 回転率（店内） | B9: =売上前提!$E$26 -> 0.9
A10: 客単価 ランチ | B10: =売上前提!$H$22 -> 4000
A11: 客単価 カフェ | B11: =売上前提!$H$24 -> 2500
A12: 客単価 ディナー（店内） | B12: =売上前提!$H$26 -> 15000
A13: 客単価 ディナー（テラス） | B13: =売上前提!$H$27 -> 10000
A14: 営業日数（日／年） | B14: =売上前提!$B$5 -> 363
A15: 標準店 満年度 年商 | B15: =売上前提!$K$28 -> 423.35782
A17: ■ 単店PL（1号店）
A18: 項 目 | B18: 満年度 | C18: 1年目 | D18: 2年目 | E18: 3年目以降
A19: 売上高 | B19: =単店PL!B6 -> 423.35782 | C19: =単店PL!C6 -> 381.02204 | D19: =単店PL!D6 -> 414.89067 | E19: =単店PL!E6 -> 423.35782
A20: GOP（店舗営業総利益） | B20: =単店PL!B16 -> 115.15333 | C20: =単店PL!C16 -> 103.638 | D20: =単店PL!D16 -> 118.65873 | E20: =単店PL!E16 -> 127.00735
A21: EBITDA | B21: =単店PL!B22 -> 51.594517 | C21: =単店PL!C22 -> 46.090866 | D21: =単店PL!D22 -> 56.302256 | E21: =単店PL!E22 -> 63.448536
A22: 減価償却費 | B22: =単店PL!B23 -> 20.825 | C22: =単店PL!C23 -> 20.825 | D22: =単店PL!D23 -> 20.825 | E22: =単店PL!E23 -> 20.825
A23: 営業利益 | B23: =単店PL!B24 -> 30.769517 | C23: =単店PL!C24 -> 25.265866 | D23: =単店PL!D24 -> 35.477256 | E23: =単店PL!E24 -> 42.623536
A24: EBITDA率 | B24: =IF(単店PL!B6=0,0,単店PL!B22/単店PL!B6) -> 0.12186976 | C24: =IF(単店PL!C6=0,0,単店PL!C22/単店PL!C6) -> 0.1209664 | D24: =IF(単店PL!D6=0,0,単店PL!D22/単店PL!D6) -> 0.13570384 | E24: =IF(単店PL!E6=0,0,単店PL!E22/単店PL!E6) -> 0.14986976
A25: 営業利益率 | B25: =IF(単店PL!B6=0,0,単店PL!B24/単店PL!B6) -> 0.072679694 | C25: =IF(単店PL!C6=0,0,単店PL!C24/単店PL!C6) -> 0.066310771 | D25: =IF(単店PL!D6=0,0,単店PL!D24/単店PL!D6) -> 0.085509892 | E25: =IF(単店PL!E6=0,0,単店PL!E24/単店PL!E6) -> 0.10067969
A27: ■ 5か年連結
A28: 項 目 | C28: FY2027 | D28: FY2028 | E28: FY2029 | F28: FY2030 | G28: FY2031 | H28: 5年累計
A29: 期末店舗数（店） | C29: =連結PL!C4 -> 1 | D29: =連結PL!D4 -> 3 | E29: =連結PL!E4 -> 5 | F29: =連結PL!F4 -> 7 | G29: =連結PL!G4 -> 9
A30: 売上高 | C30: =連結PL!C5 -> 381.02204 | D30: =連結PL!D5 -> 891.16822 | E30: =連結PL!E5 -> 1729.4167 | F30: =連結PL!F5 -> 2576.1324 | G30: =連結PL!G5 -> 3422.848 | H30: =連結PL!H5 -> 9000.5874
A31: 連結EBITDA | C31: =連結PL!C21 -> 31.090866 | D31: =連結PL!D21 -> 85.915838 | E31: =連結PL!E21 -> 193.66663 | F31: =連結PL!F21 -> 312.5637 | G31: =連結PL!G21 -> 432.46078 | H31: =連結PL!H21 -> 1055.6978
A32: EBITDA率 | C32: =連結PL!C22 -> 0.081598601 | D32: =連結PL!D22 -> 0.096408104 | E32: =連結PL!E22 -> 0.11198379 | F32: =連結PL!F22 -> 0.12133061 | G32: =連結PL!G22 -> 0.1263453 | H32: =連結PL!H22 -> 0.1172921
A33: 営業利益 | C33: =連結PL!C24 -> 10.265866 | D33: =連結PL!D24 -> 39.059588 | E33: =連結PL!E24 -> 105.78538 | F33: =連結PL!F24 -> 184.03245 | G33: =連結PL!G24 -> 263.27953 | H33: =連結PL!H24 -> 602.42281
A34: 営業利益率 | C34: =連結PL!C25 -> 0.02694297 | D34: =連結PL!D25 -> 0.043829647 | E34: =連結PL!E25 -> 0.061168242 | F34: =連結PL!F25 -> 0.071437499 | G34: =連結PL!G25 -> 0.076918264 | H34: =連結PL!H25 -> 0.0669315
A36: ■ 目標到達時期（自動判定）
A37: 連結EBITDA率 10%超 | B37: =IF(COUNTIF(連結PL!C22:G22,">=0.1")=0,"5年内に未達",INDEX({"FY2027","FY2028","FY2029","FY2030","FY2031"},6-COUNTIF(連結PL!C22:G22,">=0.1"))) -> FY2029 | D37: 旧計画：FY2028
A38: 営業利益率 5%超 | B38: =IF(COUNTIF(連結PL!C25:G25,">=0.05")=0,"5年内に未達",INDEX({"FY2027","FY2028","FY2029","FY2030","FY2031"},6-COUNTIF(連結PL!C25:G25,">=0.05"))) -> FY2029 | D38: 旧計画：FY2029
A40: ■ 投資回収・資金
A41: 1号店 初期投資 合計 | B41: =経費前提!$B$39 -> 297.25
A42: うち 開業時に支払う現金 | B42: =経費前提!$B$48 -> 158.35
A43: うち 分割払い（内装100＋保証金38.9） | B43: =経費前提!$B$47 -> 138.9
A44: 1号店 投資回収 | B44: =投資・CF!B13 -> 4年目
A45: 1号店 投資回収年数（年） | B45: =投資・CF!B14 -> 3.8180963
...

Sheet 売上前提
A1: 売上前提 ／ 席数 × 席効率 × 回転率 × 客単価 からの積上げ
A2: 水色セル＝入力値。ここを変えると単店PLだけでなく5か年連結・資金計画まで全て再計算されます。
A4: ■ 基本条件
A5: 営業日数（日／年） | B5: 363 | N5: 年363日営業
A6: 立上り率 1年目 | B6: 0.9 | N6: 新店初年度は保守的に90%
A7: 立上り率 2年目 | B7: 0.98
A8: 立上り率 3年目以降（成熟） | B8: 1 | N8: 満年度＝この水準
A9: 新店の開業年度 稼働月数 | B9: 7.5 | N9: 2号店以降。年2店を上期・下期に分散する前提の平均
A10: 1号店の稼働月数（FY2027） | B10: 12 | N10: 2027年4月開業＝FY2027は通年稼働
A12: ■ 席数（席）
A13: カウンター | B13: 14 | N13: 2026年10月時点：店内62席＋テラス52席＝114席。面積55.5坪
A14: ダイニング | B14: 23
A15: 個室 | B15: 25
A16: 店内 小計 | B16: =SUM(B13:B15) -> 62
A17: テラス | B17: 52
A18: 合 計 | B18: =B16+B17 -> 114
A20: ■ 時間帯 × エリア 別の売上前提
A21: 時間帯 | B21: エリア | C21: 席数 | D21: 席効率 | E21: 回転率 (回/日) | F21: 客単価 料理(円) | G21: 客単価 飲料(円) | H21: 客単価 計(円) | I21: 1日 客数(人) | J21: 日商(円) | K21: 年間売上 (百万円) | L21: 構成比
A22: ランチ | B22: 店内 | C22: =$B$16 -> 62 | D22: 0.75 | E22: 1.15 | F22: 3000 | G22: 1000 | H22: =F22+G22 -> 4000 | I22: =C22*D22*E22 -> 53.475 | J22: =I22*H22 -> 213900 | K22: =J22*$B$5/1000000 -> 77.6457 | L22: =IF($K$28=0,0,K22/$K$28) -> 0.18340443 | N22: ★ この表の年間売上合計が、5か年計画の『標準店 満年度売上』になります
A23: ランチ | B23: テラス | C23: =$B$17 -> 52 | D23: 0.5 | E23: 1 | F23: 3000 | G23: 1000 | H23: =F23+G23 -> 4000 | I23: =C23*D23*E23 -> 26 | J23: =I23*H23 -> 104000 | K23: =J23*$B$5/1000000 -> 37.752 | L23: =IF($K$28=0,0,K23/$K$28) -> 0.089172794
A24: カフェ（アイドルタイム） | B24: 店内 | C24: =$B$16 -> 62 | D24: 0.75 | E24: 0.5 | F24: 1500 | G24: 1000 | H24: =F24+G24 -> 2500 | I24: =C24*D24*E24 -> 23.25 | J24: =I24*H24 -> 58125 | K24: =J24*$B$5/1000000 -> 21.099375 | L24: =IF($K$28=0,0,K24/$K$28) -> 0.04983816
A25: カフェ（アイドルタイム） | B25: テラス | C25: =$B$17 -> 52 | D25: 0.5 | E25: 0.5 | F25: 1500 | G25: 1000 | H25: =F25+G25 -> 2500 | I25: =C25*D25*E25 -> 13 | J25: =I25*H25 -> 32500 | K25: =J25*$B$5/1000000 -> 11.7975 | L25: =IF($K$28=0,0,K25/$K$28) -> 0.027866498
A26: ディナー | B26: 店内 | C26: =$B$16 -> 62 | D26: 0.75 | E26: 0.9 | F26: 9000 | G26: 6000 | H26: =F26+G26 -> 15000 | I26: =C26*D26*E26 -> 41.85 | J26: =I26*H26 -> 627750 | K26: =J26*$B$5/1000000 -> 227.87325 | L26: =IF($K$28=0,0,K26/$K$28) -> 0.53825213
A27: ディナー | B27: テラス | C27: =$B$17 -> 52 | D27: 0.5 | E27: 0.5 | F27: 5000 | G27: 5000 | H27: =F27+G27 -> 10000 | I27: =C27*D27*E27 -> 13 | J27: =I27*H27 -> 130000 | K27: =J27*$B$5/1000000 -> 47.19 | L27: =IF($K$28=0,0,K27/$K$28) -> 0.11146599
A28: 合 計 | I28: =SUM(I22:I27) -> 170.575 | J28: =SUM(J22:J27) -> 1166275 | K28: =SUM(K22:K27) -> 423.35782 | L28: =SUM(L22:L27) -> 1
A29: ■ 料理・飲料別の年間売上（原価計算用）
A30: 料理売上 | B30: =SUMPRODUCT(I22:I27,F22:F27)*$B$5/1000000 -> 266.60535
A31: 飲料売上 | B31: =SUMPRODUCT(I22:I27,G22:G27)*$B$5/1000000 -> 156.75248
A32: 合 計 | B32: =B30+B31 -> 423.35782
A33: 料理 構成比 | B33: =IF($B$32=0,0,B30/$B$32) -> 0.62973998
A34: 飲料 構成比 | B34: =IF($B$32=0,0,B31/$B$32) -> 0.37026002
A35: ■ 参考指標
A36: 日商（円） | B36: =J28 -> 1166275
A37: 月商（百万円） | B37: =K28/12 -> 35.279819
A38: 年商（百万円・満年度） | B38: =K28 -> 423.35782 | N38: ＝標準店 満年度売上
A39: 1日あたり総客数（人） | B39: =I28 -> 170.575
A40: 平均客単価（円） | B40: =IF(I28=0,0,J28/I28) -> 6837.315
A41: 延べ席回転率（回/日） | B41: =IF($B$18=0,0,I28/$B$18) -> 1.4962719
A42: 坪数（坪） | B42: 55.5 | N42: 183.59㎡
A43: 坪売上（百万円/坪・年） | B43: =IF(B42=0,0,K28/B42) -> 7.6280689
...

Sheet 経費前提
A1: 経費前提・投資前提（水色セル＝入力値）
A2: 単店PLと5か年連結の両方がこのシートを参照します。経費率は2026年8月3日提出P&L準拠。
A4: ■ 売上原価の計算方法
A5: 計算方法（1＝売上比一括／2＝料理・飲料別） | B5: 2 | H5: 2を選ぶと料理・飲料それぞれの原価率で計算（直輸入ワインの効果を分けて見る場合）
A7: ■ 経費率（対売上高）
A8: 費 目 | B8: 提出P&L水準 （満年度・1年目） | C8: 2年目 | D8: 3年目以降
A9: 売上原価（方法1：売上比一括） | B9: 0.295 | C9: 0.29 | D9: 0.285 | H9: 方法1のときに使用
A10: 料理原価率（方法2） | B10: 0.3 | C10: 0.3 | D10: 0.3 | H10: 方法2のときに使用
A11: 飲料原価率（方法2） | B11: 0.3 | C11: 0.3 | D11: 0.3 | H11: 同上。直輸入ワインで下げる余地あり
A12: 実効売上原価率（方法に連動） | B12: =IF($B$5=1,B9,売上前提!$B$33*B10+売上前提!$B$34*B11) -> 0.3 | C12: =IF($B$5=1,C9,売上前提!$B$33*C10+売上前提!$B$34*C11) -> 0.3 | D12: =IF($B$5=1,D9,売上前提!$B$33*D10+売上前提!$B$34*D11) -> 0.3 | H12: 計算結果。以降のPLはこの率を使用
A13: 人件費 | B13: 0.345 | C13: 0.335 | D13: 0.325 | H13: 本部集中化・多能工化。人員26名
A14: 業務委託費・消耗品他 | B14: 0.024 | C14: 0.022 | D14: 0.02 | H14: 本部集中購買・規格統一
A15: 広告宣伝費・販売促進費 | B15: 0.014 | C15: 0.014 | D15: 0.014 | H15: 据置
A16: その他経費 | B16: 0.005 | C16: 0.005 | D16: 0.005 | H16: 据置
A17: 水道光熱費 | B17: 0.04 | C17: 0.038 | D17: 0.036 | H17: 高効率厨房機器・営業時間最適化
A18: ロイヤリティ | B18: 0.04 | C18: 0.04 | D18: 0.04 | H18: 契約条件（ブラッスリー4.0%）
A19: 保険・租税公課 | B19: 0.007 | C19: 0.007 | D19: 0.007 | H19: 据置
A20: 修繕維持費（FFE） | B20: 0.025 | C20: 0.025 | D20: 0.025 | H20: 据置
A21: 変動費 計（対売上） | B21: =B12+SUM(B13:B20) -> 0.8 | C21: =C12+SUM(C13:C20) -> 0.786 | D21: =D12+SUM(D13:D20) -> 0.772
A23: ■ 固定費・家賃条件（全店共通）
A24: 地代家賃（固定）月額 | B24: 2.22 | H24: 月222万円。席数を変えても面積は同じため不変
A25: 地代家賃（固定）年額 | B25: =B24*12 -> 26.64 | H25: ＝月額×12
A26: 歩合家賃率 | B26: 0.07 | H26: 閾値超過分に対して7%
A27: 歩合家賃 閾値（年商） | B27: 331.4 | H27: 提出P&L時点の水準から逆算
A28: 人員数（名・参考） | B28: 26 | H28: 人件費は売上比で計算
A30: ■ 初期投資（1店舗あたり・百万円）
A31: 項 目 | B31: 1号店 (六本木) | C31: 2〜3号店 (札幌・大阪) | D31: 4号店以降
A32: 契約金 | B32: 10 | C32: 10 | D32: 5 | H32: 契約金 3店舗3,000万円／以下7店舗3,500万円
A33: 事業費（設計・内装施工・OSE/FF&E） | B33: 194.25 | C33: 194.25 | D33: 194.25 | H33: 55.5坪×350万
A34: うち 資産計上対象外（補助金等） | B34: 0 | C34: 0 | D34: 0 | H34: 家主立替分は自社資産として計上するため0。ここは純粋な資産控除がある場合のみ使用
A35: 資産計上額 | B35: =B33-B34 -> 194.25 | C35: =C33-C34 -> 194.25 | D35: =D33-D34 -> 194.25 | H35: ＝事業費 － 資産計上対象外
A36: 開業準備金（広告・採用等） | B36: 4 | C36: 4 | D36: 4
A37: 保証金 | B37: 39 | C37: 39 | D37: 39 | H37: 非償却・退去時返還対象
A38: ワイン・美術品在庫 | B38: 50 | C38: 10 | D38: 10 | H38: 1号店は美術品含む。2号店以降はワイン1,000万円のみ（非償却）
A39: 初期投資 合計 | B39: =B32+B35+B36+B37+B38 -> 297.25 | C39: =C32+C35+C36+C37+C38 -> 257.25 | D39: =D32+D35+D36+D37+D38 -> 252.25
A40: 償却対象資産（＝合計－保証金－ワイン・美術品） | B40: =B39-B37-B38 -> 208.25 | C40: =C39-C37-C38 -> 208.25 | D40: =D39-D37-D38 -> 203.25 | H40: ワイン在庫は棚卸資産、美術品は取得価額100万円以上なら原則非償却のため除外
A41: 償却年数（年） | B41: 10 | C41: 10 | D41: 10
A42: 年間減価償却費／1店（通年） | B42: =B40/B41 -> 20.825 | C42: =C40/C41 -> 20.825 | D42: =D40/D41 -> 20.325
A44: ■ 分割払いスキーム（百万円）
A45: 分割対象：内装工事費（家主立替） | B45: 100 | C45: 100 | D45: 100 | H45: 家主が立替え、月833千円×120回（10年）で返済。資産計上・減価償却は自社で継続
...

Sheet 単店PL
A1: 六本木ミッドタウン店（1号店） 単店PL（百万円）
A2: 売上は「売上前提」、経費率・減価償却は「経費前提」に連動。科目は2026年8月3日提出P&Lのまま。
A4: 科 目 | B4: 満年度 （提出P&L水準） | C4: 1年目 | D4: 2年目 | E4: 3年目以降
A5: 立上り率 | B5: =売上前提!B47 -> 1 | C5: =売上前提!C47 -> 0.9 | D5: =売上前提!D47 -> 0.98 | E5: =売上前提!E47 -> 1
A6: 売上高 | B6: =売上前提!B$48 -> 423.35782 | C6: =売上前提!C$48 -> 381.02204 | D6: =売上前提!D$48 -> 414.89067 | E6: =売上前提!E$48 -> 423.35782
A7: うち 料理売上 | B7: =B$6*売上前提!$B$33 -> 266.60535 | C7: =C$6*売上前提!$B$33 -> 239.94482 | D7: =D$6*売上前提!$B$33 -> 261.27324 | E7: =E$6*売上前提!$B$33 -> 266.60535
A8: うち 飲料売上 | B8: =B$6*売上前提!$B$34 -> 156.75248 | C8: =C$6*売上前提!$B$34 -> 141.07723 | D8: =D$6*売上前提!$B$34 -> 153.61743 | E8: =E$6*売上前提!$B$34 -> 156.75248
A9: 売上原価 | B9: =B$6*経費前提!$B$12 -> 127.00735 | C9: =C$6*経費前提!$B$12 -> 114.30661 | D9: =D$6*経費前提!$C$12 -> 124.4672 | E9: =E$6*経費前提!$D$12 -> 127.00735
A10: 人件費 | B10: =B$6*経費前提!$B$13 -> 146.05845 | C10: =C$6*経費前提!$B$13 -> 131.4526 | D10: =D$6*経費前提!$C$13 -> 138.98837 | E10: =E$6*経費前提!$D$13 -> 137.59129
A11: 業務委託費・消耗品他 | B11: =B$6*経費前提!$B$14 -> 10.160588 | C11: =C$6*経費前提!$B$14 -> 9.144529 | D11: =D$6*経費前提!$C$14 -> 9.1275947 | E11: =E$6*経費前提!$D$14 -> 8.4671565
A12: 部門利益 | B12: =B6-B9-B10-B11 -> 140.13144 | C12: =C6-C9-C10-C11 -> 126.1183 | D12: =D6-D9-D10-D11 -> 142.3075 | E12: =E6-E9-E10-E11 -> 150.29203
A13: 広告宣伝費・販売促進費 | B13: =B$6*経費前提!$B$15 -> 5.9270096 | C13: =C$6*経費前提!$B$15 -> 5.3343086 | D13: =D$6*経費前提!$C$15 -> 5.8084694 | E13: =E$6*経費前提!$D$15 -> 5.9270096
A14: その他経費 | B14: =B$6*経費前提!$B$16 -> 2.1167891 | C14: =C$6*経費前提!$B$16 -> 1.9051102 | D14: =D$6*経費前提!$C$16 -> 2.0744533 | E14: =E$6*経費前提!$D$16 -> 2.1167891
A15: 水道光熱費 | B15: =B$6*経費前提!$B$17 -> 16.934313 | C15: =C$6*経費前提!$B$17 -> 15.240882 | D15: =D$6*経費前提!$C$17 -> 15.765845 | E15: =E$6*経費前提!$D$17 -> 15.240882
A16: GOP（店舗営業総利益） | B16: =B12-B13-B14-B15 -> 115.15333 | C16: =C12-C13-C14-C15 -> 103.638 | D16: =D12-D13-D14-D15 -> 118.65873 | E16: =E12-E13-E14-E15 -> 127.00735
A17: ロイヤリティ | B17: =B$6*経費前提!$B$18 -> 16.934313 | C17: =C$6*経費前提!$B$18 -> 15.240882 | D17: =D$6*経費前提!$C$18 -> 16.595627 | E17: =E$6*経費前提!$D$18 -> 16.934313
A18: 保険・租税公課 | B18: =B$6*経費前提!$B$19 -> 2.9635048 | C18: =C$6*経費前提!$B$19 -> 2.6671543 | D18: =D$6*経費前提!$C$19 -> 2.9042347 | E18: =E$6*経費前提!$D$19 -> 2.9635048
A19: 地代家賃（固定） | B19: =経費前提!$B$25 -> 26.64 | C19: =経費前提!$B$25 -> 26.64 | D19: =経費前提!$B$25 -> 26.64 | E19: =経費前提!$B$25 -> 26.64
A20: 歩合家賃 | B20: =MAX(0,B6-経費前提!$B$27)*経費前提!$B$26 -> 6.4370477 | C20: =MAX(0,C6-経費前提!$B$27)*経費前提!$B$26 -> 3.473543 | D20: =MAX(0,D6-経費前提!$B$27)*経費前提!$B$26 -> 5.8443468 | E20: =MAX(0,E6-経費前提!$B$27)*経費前提!$B$26 -> 6.4370477
A21: 修繕維持費（FFE） | B21: =B$6*経費前提!$B$20 -> 10.583946 | C21: =C$6*経費前提!$B$20 -> 9.5255511 | D21: =D$6*経費前提!$C$20 -> 10.372267 | E21: =E$6*経費前提!$D$20 -> 10.583946
A22: EBITDA | B22: =B16-B17-B18-B19-B20-B21 -> 51.594517 | C22: =C16-C17-C18-C19-C20-C21 -> 46.090866 | D22: =D16-D17-D18-D19-D20-D21 -> 56.302256 | E22: =E16-E17-E18-E19-E20-E21 -> 63.448536
A23: 減価償却費 | B23: =経費前提!$B$42 -> 20.825 | C23: =経費前提!$B$42 -> 20.825 | D23: =経費前提!$B$42 -> 20.825 | E23: =経費前提!$B$42 -> 20.825
A24: 営業利益 | B24: =B22-B23 -> 30.769517 | C24: =C22-C23 -> 25.265866 | D24: =D22-D23 -> 35.477256 | E24: =E22-E23 -> 42.623536
A26: ■ 対売上比
A27: 科 目 | B27: 満年度 | C27: 1年目 | D27: 2年目 | E27: 3年目以降
A28: 売上高 | B28: =IF(B$6=0,0,B6/B$6) -> 1 | C28: =IF(C$6=0,0,C6/C$6) -> 1 | D28: =IF(D$6=0,0,D6/D$6) -> 1 | E28: =IF(E$6=0,0,E6/E$6) -> 1
A29: 売上原価 | B29: =IF(B$6=0,0,B9/B$6) -> 0.3 | C29: =IF(C$6=0,0,C9/C$6) -> 0.3 | D29: =IF(D$6=0,0,D9/D$6) -> 0.3 | E29: =IF(E$6=0,0,E9/E$6) -> 0.3
A30: 人件費 | B30: =IF(B$6=0,0,B10/B$6) -> 0.345 | C30: =IF(C$6=0,0,C10/C$6) -> 0.345 | D30: =IF(D$6=0,0,D10/D$6) -> 0.335 | E30: =IF(E$6=0,0,E10/E$6) -> 0.325
A31: 業務委託費・消耗品他 | B31: =IF(B$6=0,0,B11/B$6) -> 0.024 | C31: =IF(C$6=0,0,C11/C$6) -> 0.024 | D31: =IF(D$6=0,0,D11/D$6) -> 0.022 | E31: =IF(E$6=0,0,E11/E$6) -> 0.02
A32: 部門利益 | B32: =IF(B$6=0,0,B12/B$6) -> 0.331 | C32: =IF(C$6=0,0,C12/C$6) -> 0.331 | D32: =IF(D$6=0,0,D12/D$6) -> 0.343 | E32: =IF(E$6=0,0,E12/E$6) -> 0.355
A33: 広告宣伝費・販売促進費 | B33: =IF(B$6=0,0,B13/B$6) -> 0.014 | C33: =IF(C$6=0,0,C13/C$6) -> 0.014 | D33: =IF(D$6=0,0,D13/D$6) -> 0.014 | E33: =IF(E$6=0,0,E13/E$6) -> 0.014
A34: その他経費 | B34: =IF(B$6=0,0,B14/B$6) -> 0.005 | C34: =IF(C$6=0,0,C14/C$6) -> 0.005 | D34: =IF(D$6=0,0,D14/D$6) -> 0.005 | E34: =IF(E$6=0,0,E14/E$6) -> 0.005
A35: 水道光熱費 | B35: =IF(B$6=0,0,B15/B$6) -> 0.04 | C35: =IF(C$6=0,0,C15/C$6) -> 0.04 | D35: =IF(D$6=0,0,D15/D$6) -> 0.038 | E35: =IF(E$6=0,0,E15/E$6) -> 0.036
A36: GOP（店舗営業総利益） | B36: =IF(B$6=0,0,B16/B$6) -> 0.272 | C36: =IF(C$6=0,0,C16/C$6) -> 0.272 | D36: =IF(D$6=0,0,D16/D$6) -> 0.286 | E36: =IF(E$6=0,0,E16/E$6) -> 0.3
A37: ロイヤリティ | B37: =IF(B$6=0,0,B17/B$6) -> 0.04 | C37: =IF(C$6=0,0,C17/C$6) -> 0.04 | D37: =IF(D$6=0,0,D17/D$6) -> 0.04 | E37: =IF(E$6=0,0,E17/E$6) -> 0.04
A38: 保険・租税公課 | B38: =IF(B$6=0,0,B18/B$6) -> 0.007 | C38: =IF(C$6=0,0,C18/C$6) -> 0.007 | D38: =IF(D$6=0,0,D18/D$6) -> 0.007 | E38: =IF(E$6=0,0,E18/E$6) -> 0.007
A39: 地代家賃（固定） | B39: =IF(B$6=0,0,B19/B$6) -> 0.062925493 | C39: =IF(C$6=0,0,C19/C$6) -> 0.069917215 | D39: =IF(D$6=0,0,D19/D$6) -> 0.064209687 | E39: =IF(E$6=0,0,E19/E$6) -> 0.062925493
A40: 歩合家賃 | B40: =IF(B$6=0,0,B20/B$6) -> 0.015204745 | C40: =IF(C$6=0,0,C20/C$6) -> 0.0091163833 | D40: =IF(D$6=0,0,D20/D$6) -> 0.014086474 | E40: =IF(E$6=0,0,E20/E$6) -> 0.015204745
... A44: 営業利益 | B44: =IF(B$6=0,0,B24/B$6) -> 0.072679694 | C44: =IF(C$6=0,0,C24/C$6) -> 0.066310771 | D44: =IF(D$6=0,0,D24/D$6) -> 0.085509892 | E44: =IF(E$6=0,0,E24/E$6) -> 0.10067969

Sheet 店舗群別PL
A1: 店舗群（出店年度コホート）別PL（百万円）
A2: 各群の売上は「売上前提」の標準店年商に立上り率・店舗数・稼働月数を掛けたもの。経費率は年次に応じて自動参照。
A3: 店舗群 | B3: 店舗数 | C3: FY2027 | D3: FY2028 | E3: FY2029 | F3: FY2030 | G3: FY2031
A5: ① 東京（六本木ミッドタウン）
A6: 店舗数（店） | B6: 1
A7: 開業年度の稼働月数 | B7: =売上前提!$B$10 -> 12
A8: 年次（0=未開業/1/2/3） | C8: 1 | D8: 2 | E8: 3 | F8: 3 | G8: 3
A9: 売上高 | C9: =IF(C8=0,0,売上前提!$K$28*INDEX(売上前提!$B$6:$B$8,C8)*$B$6*IF(C8=1,$B$7/12,1)) -> 381.02204 | D9: =IF(D8=0,0,売上前提!$K$28*INDEX(売上前提!$B$6:$B$8,D8)*$B$6*IF(D8=1,$B$7/12,1)) -> 414.89067 | E9: =IF(E8=0,0,売上前提!$K$28*INDEX(売上前提!$B$6:$B$8,E8)*$B$6*IF(E8=1,$B$7/12,1)) -> 423.35782 | F9: =IF(F8=0,0,売上前提!$K$28*INDEX(売上前提!$B$6:$B$8,F8)*$B$6*IF(F8=1,$B$7/12,1)) -> 423.35782 | G9: =IF(G8=0,0,売上前提!$K$28*INDEX(売上前提!$B$6:$B$8,G8)*$B$6*IF(G8=1,$B$7/12,1)) -> 423.35782
A10: 売上原価 | C10: =IF(C$8=0,0,C$9*INDEX(経費前提!$B$12:$D$12,1,C$8)) -> 114.30661 | D10: =IF(D$8=0,0,D$9*INDEX(経費前提!$B$12:$D$12,1,D$8)) -> 124.4672 | E10: =IF(E$8=0,0,E$9*INDEX(経費前提!$B$12:$D$12,1,E$8)) -> 127.00735 | F10: =IF(F$8=0,0,F$9*INDEX(経費前提!$B$12:$D$12,1,F$8)) -> 127.00735 | G10: =IF(G$8=0,0,G$9*INDEX(経費前提!$B$12:$D$12,1,G$8)) -> 127.00735
A11: 人件費 | C11: =IF(C$8=0,0,C$9*INDEX(経費前提!$B$13:$D$13,1,C$8)) -> 131.4526 | D11: =IF(D$8=0,0,D$9*INDEX(経費前提!$B$13:$D$13,1,D$8)) -> 138.98837 | E11: =IF(E$8=0,0,E$9*INDEX(経費前提!$B$13:$D$13,1,E$8)) -> 137.59129 | F11: =IF(F$8=0,0,F$9*INDEX(経費前提!$B$13:$D$13,1,F$8)) -> 137.59129 | G11: =IF(G$8=0,0,G$9*INDEX(経費前提!$B$13:$D$13,1,G$8)) -> 137.59129
A12: 業務委託費・消耗品他 | C12: =IF(C$8=0,0,C$9*INDEX(経費前提!$B$14:$D$14,1,C$8)) -> 9.144529 | D12: =IF(D$8=0,0,D$9*INDEX(経費前提!$B$14:$D$14,1,D$8)) -> 9.1275947 | E12: =IF(E$8=0,0,E$9*INDEX(経費前提!$B$14:$D$14,1,E$8)) -> 8.4671565 | F12: =IF(F$8=0,0,F$9*INDEX(経費前提!$B$14:$D$14,1,F$8)) -> 8.4671565 | G12: =IF(G$8=0,0,G$9*INDEX(経費前提!$B$14:$D$14,1,G$8)) -> 8.4671565
A13: 部門利益 | C13: =C9-SUM(C10:C12) -> 126.1183 | D13: =D9-SUM(D10:D12) -> 142.3075 | E13: =E9-SUM(E10:E12) -> 150.29203 | F13: =F9-SUM(F10:F12) -> 150.29203 | G13: =G9-SUM(G10:G12) -> 150.29203
A14: 広告宣伝費・販売促進費 | C14: =IF(C$8=0,0,C$9*INDEX(経費前提!$B$15:$D$15,1,C$8)) -> 5.3343086 | D14: =IF(D$8=0,0,D$9*INDEX(経費前提!$B$15:$D$15,1,D$8)) -> 5.8084694 | E14: =IF(E$8=0,0,E$9*INDEX(経費前提!$B$15:$D$15,1,E$8)) -> 5.9270096 | F14: =IF(F$8=0,0,F$9*INDEX(経費前提!$B$15:$D$15,1,F$8)) -> 5.9270096 | G14: =IF(G$8=0,0,G$9*INDEX(経費前提!$B$15:$D$15,1,G$8)) -> 5.9270096
A15: その他経費 | C15: =IF(C$8=0,0,C$9*INDEX(経費前提!$B$16:$D$16,1,C$8)) -> 1.9051102 | D15: =IF(D$8=0,0,D$9*INDEX(経費前提!$B$16:$D$16,1,D$8)) -> 2.0744533 | E15: =IF(E$8=0,0,E$9*INDEX(経費前提!$B$16:$D$16,1,E$8)) -> 2.1167891 | F15: =IF(F$8=0,0,F$9*INDEX(経費前提!$B$16:$D$16,1,F$8)) -> 2.1167891 | G15: =IF(G$8=0,0,G$9*INDEX(経費前提!$B$16:$D$16,1,G$8)) -> 2.1167891
A16: 水道光熱費 | C16: =IF(C$8=0,0,C$9*INDEX(経費前提!$B$17:$D$17,1,C$8)) -> 15.240882 | D16: =IF(D$8=0,0,D$9*INDEX(経費前提!$B$17:$D$17,1,D$8)) -> 15.765845 | E16: =IF(E$8=0,0,E$9*INDEX(経費前提!$B$17:$D$17,1,E$8)) -> 15.240882 | F16: =IF(F$8=0,0,F$9*INDEX(経費前提!$B$17:$D$17,1,F$8)) -> 15.240882 | G16: =IF(G$8=0,0,G$9*INDEX(経費前提!$B$17:$D$17,1,G$8)) -> 15.240882
A17: GOP（店舗営業総利益） | C17: =C13-SUM(C14:C16) -> 103.638 | D17: =D13-SUM(D14:D16) -> 118.65873 | E17: =E13-SUM(E14:E16) -> 127.00735 | F17: =F13-SUM(F14:F16) -> 127.00735 | G17: =G13-SUM(G14:G16) -> 127.00735
A18: ロイヤリティ | C18: =IF(C$8=0,0,C$9*INDEX(経費前提!$B$18:$D$18,1,C$8)) -> 15.240882 | D18: =IF(D$8=0,0,D$9*INDEX(経費前提!$B$18:$D$18,1,D$8)) -> 16.595627 | E18: =IF(E$8=0,0,E$9*INDEX(経費前提!$B$18:$D$18,1,E$8)) -> 16.934313 | F18: =IF(F$8=0,0,F$9*INDEX(経費前提!$B$18:$D$18,1,F$8)) -> 16.934313 | G18: =IF(G$8=0,0,G$9*INDEX(経費前提!$B$18:$D$18,1,G$8)) -> 16.934313
A19: 保険・租税公課 | C19: =IF(C$8=0,0,C$9*INDEX(経費前提!$B$19:$D$19,1,C$8)) -> 2.6671543 | D19: =IF(D$8=0,0,D$9*INDEX(経費前提!$B$19:$D$19,1,D$8)) -> 2.9042347 | E19: =IF(E$8=0,0,E$9*INDEX(経費前提!$B$19:$D$19,1,E$8)) -> 2.9635048 | F19: =IF(F$8=0,0,F$9*INDEX(経費前提!$B$19:$D$19,1,F$8)) -> 2.9635048 | G19: =IF(G$8=0,0,G$9*INDEX(経費前提!$B$19:$D$19,1,G$8)) -> 2.9635048
A20: 地代家賃（固定） | C20: =IF(C8=0,0,経費前提!$B$25*$B$6*IF(C8=1,$B$7/12,1)) -> 26.64 | D20: =IF(D8=0,0,経費前提!$B$25*$B$6*IF(D8=1,$B$7/12,1)) -> 26.64 | E20: =IF(E8=0,0,経費前提!$B$25*$B$6*IF(E8=1,$B$7/12,1)) -> 26.64 | F20: =IF(F8=0,0,経費前提!$B$25*$B$6*IF(F8=1,$B$7/12,1)) -> 26.64 | G20: =IF(G8=0,0,経費前提!$B$25*$B$6*IF(G8=1,$B$7/12,1)) -> 26.64
A21: 歩合家賃 | C21: =IF(C8=0,0,MAX(0,C9/$B$6-経費前提!$B$27*IF(C8=1,$B$7/12,1))*経費前提!$B$26*$B$6) -> 3.473543 | D21: =IF(D8=0,0,MAX(0,D9/$B$6-経費前提!$B$27*IF(D8=1,$B$7/12,1))*経費前提!$B$26*$B$6) -> 5.8443468 | E21: =IF(E8=0,0,MAX(0,E9/$B$6-経費前提!$B$27*IF(E8=1,$B$7/12,1))*経費前提!$B$26*$B$6) -> 6.4370477 | F21: =IF(F8=0,0,MAX(0,F9/$B$6-経費前提!$B$27*IF(F8=1,$B$7/12,1))*経費前提!$B$26*$B$6) -> 6.4370477 | G21: =IF(G8=0,0,MAX(0,G9/$B$6-経費前提!$B$27*IF(G8=1,$B$7/12,1))*経費前提!$B$26*$B$6) -> 6.4370477
A22: 修繕維持費（FFE） | C22: =IF(C$8=0,0,C$9*INDEX(経費前提!$B$20:$D$20,1,C$8)) -> 9.5255511 | D22: =IF(D$8=0,0,D$9*INDEX(経費前提!$B$20:$D$20,1,D$8)) -> 10.372267 | E22: =IF(E$8=0,0,E$9*INDEX(経費前提!$B$20:$D$20,1,E$8)) -> 10.583946 | F22: =IF(F$8=0,0,F$9*INDEX(経費前提!$B$20:$D$20,1,F$8)) -> 10.583946 | G22: =IF(G$8=0,0,G$9*INDEX(経費前提!$B$20:$D$20,1,G$8)) -> 10.583946
A23: 店舗EBITDA | C23: =C17-SUM(C18:C22) -> 46.090866 | D23: =D17-SUM(D18:D22) -> 56.302256 | E23: =E17-SUM(E18:E22) -> 63.448536 | F23: =F17-SUM(F18:F22) -> 63.448536 | G23: =G17-SUM(G18:G22) -> 63.448536
A24: 減価償却費 | C24: =IF(C8=0,0,経費前提!$B$42*$B$6*IF(C8=1,$B$7/12,1)) -> 20.825 | D24: =IF(D8=0,0,経費前提!$B$42*$B$6*IF(D8=1,$B$7/12,1)) -> 20.825 | E24: =IF(E8=0,0,経費前提!$B$42*$B$6*IF(E8=1,$B$7/12,1)) -> 20.825 | F24: =IF(F8=0,0,経費前提!$B$42*$B$6*IF(F8=1,$B$7/12,1)) -> 20.825 | G24: =IF(G8=0,0,経費前提!$B$42*$B$6*IF(G8=1,$B$7/12,1)) -> 20.825
A25: 店舗営業利益 | C25: =C23-C24 -> 25.265866 | D25: =D23-D24 -> 35.477256 | E25: =E23-E24 -> 42.623536 | F25: =F23-F24 -> 42.623536 | G25: =G23-G24 -> 42.623536
A27: ② 札幌・大阪
A28: 店舗数（店） | B28: 2
A29: 開業年度の稼働月数 | B29: =売上前提!$B$9 -> 7.5
A30: 年次（0=未開業/1/2/3） | C30: 0 | D30: 1 | E30: 2 | F30: 3 | G30: 3
A31: 売上高 | C31: =IF(C30=0,0,売上前提!$K$28*INDEX(売上前提!$B$6:$B$8,C30)*$B$28*IF(C30=1,$B$29/12,1)) -> 0 | D31: =IF(D30=0,0,売上前提!$K$28*INDEX(売上前提!$B$6:$B$8,D30)*$B$28*IF(D30=1,$B$29/12,1)) -> 476.27755 | E31: =IF(E30=0,0,売上前提!$K$28*INDEX(売上前提!$B$6:$B$8,E30)*$B$28*IF(E30=1,$B$29/12,1)) -> 829.78134 | F31: =IF(F30=0,0,売上前提!$K$28*INDEX(売上前提!$B$6:$B$8,F30)*$B$28*IF(F30=1,$B$29/12,1)) -> 846.71565 | G31: =IF(G30=0,0,売上前提!$K$28*INDEX(売上前提!$B$6:$B$8,G30)*$B$28*IF(G30=1,$B$29/12,1)) -> 846.71565
A32: 売上原価 | C32: =IF(C$30=0,0,C$31*INDEX(経費前提!$B$12:$D$12,1,C$30)) -> 0 | D32: =IF(D$30=0,0,D$31*INDEX(経費前提!$B$12:$D$12,1,D$30)) -> 142.88327 | E32: =IF(E$30=0,0,E$31*INDEX(経費前提!$B$12:$D$12,1,E$30)) -> 248.9344 | F32: =IF(F$30=0,0,F$31*INDEX(経費前提!$B$12:$D$12,1,F$30)) -> 254.01469 | G32: =IF(G$30=0,0,G$31*INDEX(経費前提!$B$12:$D$12,1,G$30)) -> 254.01469
A33: 人件費 | C33: =IF(C$30=0,0,C$31*INDEX(経費前提!$B$13:$D$13,1,C$30)) -> 0 | D33: =IF(D$30=0,0,D$31*INDEX(経費前提!$B$13:$D$13,1,D$30)) -> 164.31576 | E33: =IF(E$30=0,0,E$31*INDEX(経費前提!$B$13:$D$13,1,E$30)) -> 277.97675 | F33: =IF(F$30=0,0,F$31*INDEX(経費前提!$B$13:$D$13,1,F$30)) -> 275.18259 | G33: =IF(G$30=0,0,G$31*INDEX(経費前提!$B$13:$D$13,1,G$30)) -> 275.18259
A34: 業務委託費・消耗品他 | C34: =IF(C$30=0,0,C$31*INDEX(経費前提!$B$14:$D$14,1,C$30)) -> 0 | D34: =IF(D$30=0,0,D$31*INDEX(経費前提!$B$14:$D$14,1,D$30)) -> 11.430661 | E34: =IF(E$30=0,0,E$31*INDEX(経費前提!$B$14:$D$14,1,E$30)) -> 18.255189 | F34: =IF(F$30=0,0,F$31*INDEX(経費前提!$B$14:$D$14,1,F$30)) -> 16.934313 | G34: =IF(G$30=0,0,G$31*INDEX(経費前提!$B$14:$D$14,1,G$30)) -> 16.934313
A35: 部門利益 | C35: =C31-SUM(C32:C34) -> 0 | D35: =D31-SUM(D32:D34) -> 157.64787 | E35: =E31-SUM(E32:E34) -> 284.615 | F35: =F31-SUM(F32:F34) -> 300.58406 | G35: =G31-SUM(G32:G34) -> 300.58406
A36: 広告宣伝費・販売促進費 | C36: =IF(C$30=0,0,C$31*INDEX(経費前提!$B$15:$D$15,1,C$30)) -> 0 | D36: =IF(D$30=0,0,D$31*INDEX(経費前提!$B$15:$D$15,1,D$30)) -> 6.6678857 | E36: =IF(E$30=0,0,E$31*INDEX(経費前提!$B$15:$D$15,1,E$30)) -> 11.616939 | F36: =IF(F$30=0,0,F$31*INDEX(経費前提!$B$15:$D$15,1,F$30)) -> 11.854019 | G36: =IF(G$30=0,0,G$31*INDEX(経費前提!$B$15:$D$15,1,G$30)) -> 11.854019
A37: その他経費 | C37: =IF(C$30=0,0,C$31*INDEX(経費前提!$B$16:$D$16,1,C$30)) -> 0 | D37: =IF(D$30=0,0,D$31*INDEX(経費前提!$B$16:$D$16,1,D$30)) -> 2.3813878 | E37: =IF(E$30=0,0,E$31*INDEX(経費前提!$B$16:$D$16,1,E$30)) -> 4.1489067 | F37: =IF(F$30=0,0,F$31*INDEX(経費前提!$B$16:$D$16,1,F$30)) -> 4.2335782 | G37: =IF(G$30=0,0,G$31*INDEX(経費前提!$B$16:$D$16,1,G$30)) -> 4.2335782
A38: 水道光熱費 | C38: =IF(C$30=0,0,C$31*INDEX(経費前提!$B$17:$D$17,1,C$30)) -> 0 | D38: =IF(D$30=0,0,D$31*INDEX(経費前提!$B$17:$D$17,1,D$30)) -> 19.051102 | E38: =IF(E$30=0,0,E$31*INDEX(経費前提!$B$17:$D$17,1,E$30)) -> 31.531691 | F38: =IF(F$30=0,0,F$31*INDEX(経費前提!$B$17:$D$17,1,F$30)) -> 30.481763 | G38: =IF(G$30=0,0,G$31*INDEX(経費前提!$B$17:$D$17,1,G$30)) -> 30.481763
A39: GOP（店舗営業総利益） | C39: =C35-SUM(C36:C38) -> 0 | D39: =D35-SUM(D36:D38) -> 129.54749 | E39: =E35-SUM(E36:E38) -> 237.31746 | F39: =F35-SUM(F36:F38) -> 254.01469 | G39: =G35-SUM(G36:G38) -> 254.01469
A40: ロイヤリティ | C40: =IF(C$30=0,0,C$31*INDEX(経費前提!$B$18:$D$18,1,C$30)) -> 0 | D40: =IF(D$30=0,0,D$31*INDEX(経費前提!$B$18:$D$18,1,D$30)) -> 19.051102 | E40: =IF(E$30=0,0,E$31*INDEX(経費前提!$B$18:$D$18,1,E$30)) -> 33.191253 | F40: =IF(F$30=0,0,F$31*INDEX(経費前提!$B$18:$D$18,1,F$30)) -> 33.868626 | G40: =IF(G$30=0,0,G$31*INDEX(経費前提!$B$18:$D$18,1,G$30)) -> 33.868626
A41: 保険・租税公課 | C41: =IF(C$30=0,0,C$31*INDEX(経費前提!$B$19:$D$19,1,C$30)) -> 0 | D41: =IF(D$30=0,0,D$31*INDEX(経費前提!$B$19:$D$19,1,D$30)) -> 3.3339429 | E41: =IF(E$30=0,0,E$31*INDEX(経費前提!$B$19:$D$19,1,E$30)) -> 5.8084694 | F41: =IF(F$30=0,0,F$31*INDEX(経費前提!$B$19:$D$19,1,F$30)) -> 5.9270096 | G41: =IF(G$30=0,0,G$31*INDEX(経費前提!$B$19:$D$19,1,G$30)) -> 5.9270096
A42: 地代家賃（固定） | C42: =IF(C30=0,0,経費前提!$B$25*$B$28*IF(C30=1,$B$29/12,1)) -> 0 | D42: =IF(D30=0,0,経費前提!$B$25*$B$28*IF(D30=1,$B$29/12,1)) -> 33.3 | E42: =IF(E30=0,0,経費前提!$B$25*$B$28*IF(E30=1,$B$29/12,1)) -> 53.28 | F42: =IF(F30=0,0,経費前提!$B$25*$B$28*IF(F30=1,$B$29/12,1)) -> 53.28 | G42: =IF(G30=0,0,経費前提!$B$25*$B$28*IF(G30=1,$B$29/12,1)) -> 53.28
...

Sheet 連結PL
A1: 5か年事業計画 連結損益計画（FY2027-FY2031・百万円）
A2: 2027年4月 六本木開業 → 2028年 札幌・大阪 → 2029年 首都圏・政令指定都市 → 2030年以降 リゾート含め年2店舗
A3: 科 目 | B3: 対売上比 (FY2031) | C3: FY2027 | D3: FY2028 | E3: FY2029 | F3: FY2030 | G3: FY2031 | H3: 5年累計
A4: 期末店舗数（店） | C4: =経費前提!B54 -> 1 | D4: =経費前提!C54 -> 3 | E4: =経費前提!D54 -> 5 | F4: =経費前提!E54 -> 7 | G4: =経費前提!F54 -> 9
A5: 売上高 | B5: =IF($G$5=0,0,G5/$G$5) -> 1 | C5: =店舗群別PL!C9+店舗群別PL!C31+店舗群別PL!C53+店舗群別PL!C75+店舗群別PL!C97 -> 381.02204 | D5: =店舗群別PL!D9+店舗群別PL!D31+店舗群別PL!D53+店舗群別PL!D75+店舗群別PL!D97 -> 891.16822 | E5: =店舗群別PL!E9+店舗群別PL!E31+店舗群別PL!E53+店舗群別PL!E75+店舗群別PL!E97 -> 1729.4167 | F5: =店舗群別PL!F9+店舗群別PL!F31+店舗群別PL!F53+店舗群別PL!F75+店舗群別PL!F97 -> 2576.1324 | G5: =店舗群別PL!G9+店舗群別PL!G31+店舗群別PL!G53+店舗群別PL!G75+店舗群別PL!G97 -> 3422.848 | H5: =SUM(C5:G5) -> 9000.5874
A6: 売上原価 | B6: =IF($G$5=0,0,G6/$G$5) -> 0.3 | C6: =店舗群別PL!C10+店舗群別PL!C32+店舗群別PL!C54+店舗群別PL!C76+店舗群別PL!C98 -> 114.30661 | D6: =店舗群別PL!D10+店舗群別PL!D32+店舗群別PL!D54+店舗群別PL!D76+店舗群別PL!D98 -> 267.35047 | E6: =店舗群別PL!E10+店舗群別PL!E32+店舗群別PL!E54+店舗群別PL!E76+店舗群別PL!E98 -> 518.82501 | F6: =店舗群別PL!F10+店舗群別PL!F32+店舗群別PL!F54+店舗群別PL!F76+店舗群別PL!F98 -> 772.83971 | G6: =店舗群別PL!G10+店舗群別PL!G32+店舗群別PL!G54+店舗群別PL!G76+店舗群別PL!G98 -> 1026.8544 | H6: =SUM(C6:G6) -> 2700.1762
A7: 人件費 | B7: =IF($G$5=0,0,G7/$G$5) -> 0.33020717 | C7: =店舗群別PL!C11+店舗群別PL!C33+店舗群別PL!C55+店舗群別PL!C77+店舗群別PL!C99 -> 131.4526 | D7: =店舗群別PL!D11+店舗群別PL!D33+店舗群別PL!D55+店舗群別PL!D77+店舗群別PL!D99 -> 303.30413 | E7: =店舗群別PL!E11+店舗群別PL!E33+店舗群別PL!E55+店舗群別PL!E77+店舗群別PL!E99 -> 579.8838 | F7: =店舗群別PL!F11+店舗群別PL!F33+店舗群別PL!F55+店舗群別PL!F77+店舗群別PL!F99 -> 855.06638 | G7: =店舗群別PL!G11+店舗群別PL!G33+店舗群別PL!G55+店舗群別PL!G77+店舗群別PL!G99 -> 1130.249 | H7: =SUM(C7:G7) -> 2999.9559
A8: 業務委託費・消耗品他 | B8: =IF($G$5=0,0,G8/$G$5) -> 0.021041435 | C8: =店舗群別PL!C12+店舗群別PL!C34+店舗群別PL!C56+店舗群別PL!C78+店舗群別PL!C100 -> 9.144529 | D8: =店舗群別PL!D12+店舗群別PL!D34+店舗群別PL!D56+店舗群別PL!D78+店舗群別PL!D100 -> 20.558256 | E8: =店舗群別PL!E12+店舗群別PL!E34+店舗群別PL!E56+店舗群別PL!E78+店舗群別PL!E100 -> 38.153007 | F8: =店舗群別PL!F12+店舗群別PL!F34+店舗群別PL!F56+店舗群別PL!F78+店舗群別PL!F100 -> 55.08732 | G8: =店舗群別PL!G12+店舗群別PL!G34+店舗群別PL!G56+店舗群別PL!G78+店舗群別PL!G100 -> 72.021633 | H8: =SUM(C8:G8) -> 194.96475
A9: 部門利益 | B9: =IF($G$5=0,0,G9/$G$5) -> 0.34875139 | C9: =店舗群別PL!C13+店舗群別PL!C35+店舗群別PL!C57+店舗群別PL!C79+店舗群別PL!C101 -> 126.1183 | D9: =店舗群別PL!D13+店舗群別PL!D35+店舗群別PL!D57+店舗群別PL!D79+店舗群別PL!D101 -> 299.95537 | E9: =店舗群別PL!E13+店舗群別PL!E35+店舗群別PL!E57+店舗群別PL!E79+店舗群別PL!E101 -> 592.5549 | F9: =店舗群別PL!F13+店舗群別PL!F35+店舗群別PL!F57+店舗群別PL!F79+店舗群別PL!F101 -> 893.13895 | G9: =店舗群別PL!G13+店舗群別PL!G35+店舗群別PL!G57+店舗群別PL!G79+店舗群別PL!G101 -> 1193.723 | H9: =SUM(C9:G9) -> 3105.4905
A10: 広告宣伝費・販売促進費 | B10: =IF($G$5=0,0,G10/$G$5) -> 0.014 | C10: =店舗群別PL!C14+店舗群別PL!C36+店舗群別PL!C58+店舗群別PL!C80+店舗群別PL!C102 -> 5.3343086 | D10: =店舗群別PL!D14+店舗群別PL!D36+店舗群別PL!D58+店舗群別PL!D80+店舗群別PL!D102 -> 12.476355 | E10: =店舗群別PL!E14+店舗群別PL!E36+店舗群別PL!E58+店舗群別PL!E80+店舗群別PL!E102 -> 24.211834 | F10: =店舗群別PL!F14+店舗群別PL!F36+店舗群別PL!F58+店舗群別PL!F80+店舗群別PL!F102 -> 36.065853 | G10: =店舗群別PL!G14+店舗群別PL!G36+店舗群別PL!G58+店舗群別PL!G80+店舗群別PL!G102 -> 47.919872 | H10: =SUM(C10:G10) -> 126.00822
A11: その他経費 | B11: =IF($G$5=0,0,G11/$G$5) -> 0.005 | C11: =店舗群別PL!C15+店舗群別PL!C37+店舗群別PL!C59+店舗群別PL!C81+店舗群別PL!C103 -> 1.9051102 | D11: =店舗群別PL!D15+店舗群別PL!D37+店舗群別PL!D59+店舗群別PL!D81+店舗群別PL!D103 -> 4.4558411 | E11: =店舗群別PL!E15+店舗群別PL!E37+店舗群別PL!E59+店舗群別PL!E81+店舗群別PL!E103 -> 8.6470836 | F11: =店舗群別PL!F15+店舗群別PL!F37+店舗群別PL!F59+店舗群別PL!F81+店舗群別PL!F103 -> 12.880662 | G11: =店舗群別PL!G15+店舗群別PL!G37+店舗群別PL!G59+店舗群別PL!G81+店舗群別PL!G103 -> 17.11424 | H11: =SUM(C11:G11) -> 45.002937
A12: 水道光熱費 | B12: =IF($G$5=0,0,G12/$G$5) -> 0.037041435 | C12: =店舗群別PL!C16+店舗群別PL!C38+店舗群別PL!C60+店舗群別PL!C82+店舗群別PL!C104 -> 15.240882 | D12: =店舗群別PL!D16+店舗群別PL!D38+店舗群別PL!D60+店舗群別PL!D82+店舗群別PL!D104 -> 34.816948 | E12: =店舗群別PL!E16+店舗群別PL!E38+店舗群別PL!E60+店舗群別PL!E82+店舗群別PL!E104 -> 65.823675 | F12: =店舗群別PL!F16+店舗群別PL!F38+店舗群別PL!F60+店舗群別PL!F82+店舗群別PL!F104 -> 96.305438 | G12: =店舗群別PL!G16+店舗群別PL!G38+店舗群別PL!G60+店舗群別PL!G82+店舗群別PL!G104 -> 126.7872 | H12: =SUM(C12:G12) -> 338.97414
A13: GOP（店舗営業総利益） | B13: =IF($G$5=0,0,G13/$G$5) -> 0.29270996 | C13: =店舗群別PL!C17+店舗群別PL!C39+店舗群別PL!C61+店舗群別PL!C83+店舗群別PL!C105 -> 103.638 | D13: =店舗群別PL!D17+店舗群別PL!D39+店舗群別PL!D61+店舗群別PL!D83+店舗群別PL!D105 -> 248.20623 | E13: =店舗群別PL!E17+店舗群別PL!E39+店舗群別PL!E61+店舗群別PL!E83+店舗群別PL!E105 -> 493.8723 | F13: =店舗群別PL!F17+店舗群別PL!F39+店舗群別PL!F61+店舗群別PL!F83+店舗群別PL!F105 -> 747.887 | G13: =店舗群別PL!G17+店舗群別PL!G39+店舗群別PL!G61+店舗群別PL!G83+店舗群別PL!G105 -> 1001.9017 | H13: =SUM(C13:G13) -> 2595.5052
A14: ロイヤリティ | B14: =IF($G$5=0,0,G14/$G$5) -> 0.04 | C14: =店舗群別PL!C18+店舗群別PL!C40+店舗群別PL!C62+店舗群別PL!C84+店舗群別PL!C106 -> 15.240882 | D14: =店舗群別PL!D18+店舗群別PL!D40+店舗群別PL!D62+店舗群別PL!D84+店舗群別PL!D106 -> 35.646729 | E14: =店舗群別PL!E18+店舗群別PL!E40+店舗群別PL!E62+店舗群別PL!E84+店舗群別PL!E106 -> 69.176669 | F14: =店舗群別PL!F18+店舗群別PL!F40+店舗群別PL!F62+店舗群別PL!F84+店舗群別PL!F106 -> 103.04529 | G14: =店舗群別PL!G18+店舗群別PL!G40+店舗群別PL!G62+店舗群別PL!G84+店舗群別PL!G106 -> 136.91392 | H14: =SUM(C14:G14) -> 360.02349
A15: 保険・租税公課 | B15: =IF($G$5=0,0,G15/$G$5) -> 0.007 | C15: =店舗群別PL!C19+店舗群別PL!C41+店舗群別PL!C63+店舗群別PL!C85+店舗群別PL!C107 -> 2.6671543 | D15: =店舗群別PL!D19+店舗群別PL!D41+店舗群別PL!D63+店舗群別PL!D85+店舗群別PL!D107 -> 6.2381776 | E15: =店舗群別PL!E19+店舗群別PL!E41+店舗群別PL!E63+店舗群別PL!E85+店舗群別PL!E107 -> 12.105917 | F15: =店舗群別PL!F19+店舗群別PL!F41+店舗群別PL!F63+店舗群別PL!F85+店舗群別PL!F107 -> 18.032927 | G15: =店舗群別PL!G19+店舗群別PL!G41+店舗群別PL!G63+店舗群別PL!G85+店舗群別PL!G107 -> 23.959936 | H15: =SUM(C15:G15) -> 63.004112
A16: 地代家賃（固定） | B16: =IF($G$5=0,0,G16/$G$5) -> 0.064209687 | C16: =店舗群別PL!C20+店舗群別PL!C42+店舗群別PL!C64+店舗群別PL!C86+店舗群別PL!C108 -> 26.64 | D16: =店舗群別PL!D20+店舗群別PL!D42+店舗群別PL!D64+店舗群別PL!D86+店舗群別PL!D108 -> 59.94 | E16: =店舗群別PL!E20+店舗群別PL!E42+店舗群別PL!E64+店舗群別PL!E86+店舗群別PL!E108 -> 113.22 | F16: =店舗群別PL!F20+店舗群別PL!F42+店舗群別PL!F64+店舗群別PL!F86+店舗群別PL!F108 -> 166.5 | G16: =店舗群別PL!G20+店舗群別PL!G42+店舗群別PL!G64+店舗群別PL!G86+店舗群別PL!G108 -> 219.78 | H16: =SUM(C16:G16) -> 586.08
... A19: 店舗EBITDA 計 | B19: =IF($G$5=0,0,G19/$G$5) -> 0.1424138 | C19: =店舗群別PL!C23+店舗群別PL!C45+店舗群別PL!C67+店舗群別PL!C89+店舗群別PL!C111 -> 46.090866 | D19: =店舗群別PL!D23+店舗群別PL!D45+店舗群別PL!D67+店舗群別PL!D89+店舗群別PL!D111 -> 113.91584 | E19: =店舗群別PL!E23+店舗群別PL!E45+店舗群別PL!E67+店舗群別PL!E89+店舗群別PL!E111 -> 233.66663 | F19: =店舗群別PL!F23+店舗群別PL!F45+店舗群別PL!F67+店舗群別PL!F89+店舗群別PL!F111 -> 360.5637 | G19: =店舗群別PL!G23+店舗群別PL!G45+店舗群別PL!G67+店舗群別PL!G89+店舗群別PL!G111 -> 487.46078 | H19: =SUM(C19:G19) -> 1241.6978
A20: 本部費 | B20: =IF($G$5=0,0,G20/$G$5) -> 0.01606849 | C20: =経費前提!B55 -> 15 | D20: =経費前提!C55 -> 28 | E20: =経費前提!D55 -> 40 | F20: =経費前提!E55 -> 48 | G20: =経費前提!F55 -> 55 | H20: =SUM(C20:G20) -> 186
A21: 連結EBITDA | B21: =IF($G$5=0,0,G21/$G$5) -> 0.1263453 | C21: =C19-C20 -> 31.090866 | D21: =D19-D20 -> 85.915838 | E21: =E19-E20 -> 193.66663 | F21: =F19-F20 -> 312.5637 | G21: =G19-G20 -> 432.46078 | H21: =SUM(C21:G21) -> 1055.6978
A22: EBITDA率 | C22: =IF(C5=0,0,C21/C5) -> 0.081598601 | D22: =IF(D5=0,0,D21/D5) -> 0.096408104 | E22: =IF(E5=0,0,E21/E5) -> 0.11198379 | F22: =IF(F5=0,0,F21/F5) -> 0.12133061 | G22: =IF(G5=0,0,G21/G5) -> 0.1263453 | H22: =H21/H5 -> 0.1172921
A23: 減価償却費 | B23: =IF($G$5=0,0,G23/$G$5) -> 0.049427041 | C23: =店舗群別PL!C24+店舗群別PL!C46+店舗群別PL!C68+店舗群別PL!C90+店舗群別PL!C112 -> 20.825 | D23: =店舗群別PL!D24+店舗群別PL!D46+店舗群別PL!D68+店舗群別PL!D90+店舗群別PL!D112 -> 46.85625 | E23: =店舗群別PL!E24+店舗群別PL!E46+店舗群別PL!E68+店舗群別PL!E90+店舗群別PL!E112 -> 87.88125 | F23: =店舗群別PL!F24+店舗群別PL!F46+店舗群別PL!F68+店舗群別PL!F90+店舗群別PL!F112 -> 128.53125 | G23: =店舗群別PL!G24+店舗群別PL!G46+店舗群別PL!G68+店舗群別PL!G90+店舗群別PL!G112 -> 169.18125 | H23: =SUM(C23:G23) -> 453.275
A24: 営業利益 | B24: =IF($G$5=0,0,G24/$G$5) -> 0.076918264 | C24: =C21-C23 -> 10.265866 | D24: =D21-D23 -> 39.059588 | E24: =E21-E23 -> 105.78538 | F24: =F21-F23 -> 184.03245 | G24: =G21-G23 -> 263.27953 | H24: =SUM(C24:G24) -> 602.42281
A25: 営業利益率 | C25: =IF(C5=0,0,C24/C5) -> 0.02694297 | D25: =IF(D5=0,0,D24/D5) -> 0.043829647 | E25: =IF(E5=0,0,E24/E5) -> 0.061168242 | F25: =IF(F5=0,0,F24/F5) -> 0.071437499 | G25: =IF(G5=0,0,G24/G5) -> 0.076918264 | H25: =H24/H5 -> 0.0669315
A27: ※ FY＝4月〜3月。新店初年度は売上90%・開業7.5か月で計上。金利・税金は含まない。

Sheet 投資・CF
A1: 投資・キャッシュフロー（百万円）
A2: 上段＝1号店の投資回収、下段＝連結5か年のキャッシュフローと必要資金。
A4: ■ 1号店 キャッシュフロー推移
A5: 項 目 | B5: 開業時 | C5: 1年目 | D5: 2年目 | E5: 3年目 | F5: 4年目 | G5: 5年目
A6: EBITDA | B6: 0 | C6: =単店PL!C22 -> 46.090866 | D6: =単店PL!D22 -> 56.302256 | E6: =単店PL!E22 -> 63.448536 | F6: =単店PL!E22 -> 63.448536 | G6: =単店PL!E22 -> 63.448536
A7: 開業時 現金支出 | B7: =-経費前提!$B$48 -> -158.35 | C7: 0 | D7: 0 | E7: 0 | F7: 0 | G7: 0
A8: 分割弁済 | B8: 0 | C8: =-経費前提!$B$49 -> -15.557143 | D8: =-経費前提!$B$49 -> -15.557143 | E8: =-経費前提!$B$49 -> -15.557143 | F8: =-経費前提!$B$49 -> -15.557143 | G8: =-経費前提!$B$49 -> -15.557143
A9: 単店FCF | B9: =B6+B7+B8 -> -158.35 | C9: =C6+C7+C8 -> 30.533723 | D9: =D6+D7+D8 -> 40.745113 | E9: =E6+E7+E8 -> 47.891393 | F9: =F6+F7+F8 -> 47.891393 | G9: =G6+G7+G8 -> 47.891393
A10: 累計FCF | B10: =B9 -> -158.35 | C10: =B10+C9 -> -127.81628 | D10: =C10+D9 -> -87.071164 | E10: =D10+E9 -> -39.17977 | F10: =E10+F9 -> 8.7116231 | G10: =F10+G9 -> 56.603017
A12: 累計FCFが赤字の年数 | B12: =COUNTIF(C10:G10,"<0") -> 3
A13: 累計FCFの黒字転換 | B13: =IF(B12>=5,"5年内に未回収",B12+1&"年目") -> 4年目
A14: 投資回収年数（年） | B14: =IF(B12>=5,"",IF(INDEX(B9:G9,B12+2)=0,"",B12+(-INDEX(B10:G10,B12+1))/INDEX(B9:G9,B12+2))) -> 3.8180963
A16: ="→ 1号店は開業"&B13&"に累計FCFが黒字転換（投資回収 約"&TEXT(B14,"0.0")&"年）。" -> → 1号店は開業4年目に累計FCFが黒字転換（投資回収 約3.8年）。
A18: ■ 連結キャッシュフロー計画
A19: 項 目 | C19: FY2027 | D19: FY2028 | E19: FY2029 | F19: FY2030 | G19: FY2031 | H19: 5年累計
A20: 新規出店数（店） | C20: =経費前提!B53 -> 1 | D20: =経費前提!C53 -> 2 | E20: =経費前提!D53 -> 2 | F20: =経費前提!E53 -> 2 | G20: =経費前提!F53 -> 2 | H20: =SUM(C20:G20) -> 9
A21: 期末店舗数（店） | C21: =経費前提!B54 -> 1 | D21: =経費前提!C54 -> 3 | E21: =経費前提!D54 -> 5 | F21: =経費前提!E54 -> 7 | G21: =経費前提!F54 -> 9
A22: 初期投資（総額） | C22: =-C20*経費前提!$B$39 -> -297.25 | D22: =-D20*経費前提!$C$39 -> -514.5 | E22: =-E20*経費前提!$D$39 -> -504.5 | F22: =-F20*経費前提!$D$39 -> -504.5 | G22: =-G20*経費前提!$D$39 -> -504.5 | H22: =SUM(C22:G22) -> -2325.25
A23: うち 分割対象額 | C23: =C20*経費前提!$B$47 -> 138.9 | D23: =D20*経費前提!$C$47 -> 277.8 | E23: =E20*経費前提!$D$47 -> 277.8 | F23: =F20*経費前提!$D$47 -> 277.8 | G23: =G20*経費前提!$D$47 -> 277.8 | H23: =SUM(C23:G23) -> 1250.1
A24: 開業時 現金支出 | C24: =C22+C23 -> -158.35 | D24: =D22+D23 -> -236.7 | E24: =E22+E23 -> -226.7 | F24: =F22+F23 -> -226.7 | G24: =G22+G23 -> -226.7 | H24: =SUM(C24:G24) -> -1075.15
A25: 分割弁済額 | C25: =-(IF(店舗群別PL!C8=0,0,経費前提!$B$49*店舗群別PL!$B$6*IF(店舗群別PL!C8=1,店舗群別PL!$B$7/12,1))+IF(店舗群別PL!C30=0,0,経費前提!$C$49*店舗群別PL!$B$28*IF(店舗群別PL!C30=1,店舗群別PL!$B$29/12,1))+IF(店舗群別PL!C52=0,0,経費前提!$D$49*店舗群別PL!$B$50*IF(店舗群別PL!C52=1,店舗群別PL!$B$51/12,1))+IF(店舗群別PL!C74=0,0,経費前提!$D$49*店舗群別PL!$B$72*IF(店舗群別PL!C74=1,店舗群別PL!$B$73/12,1))+IF(店舗群別PL!C96=0,0,経費前提!$D$49*店舗群別PL!$B$94*IF(店舗群別PL!C96=1,店舗群別PL!$B$95/12,1))) -> -15.557143 | D25: =-(IF(店舗群別PL!D8=0,0,経費前提!$B$49*店舗群別PL!$B$6*IF(店舗群別PL!D8=1,店舗群別PL!$B$7/12,1))+IF(店舗群別PL!D30=0,0,経費前提!$C$49*店舗群別PL!$B$28*IF(店舗群別PL!D30=1,店舗群別PL!$B$29/12,1))+IF(店舗群別PL!D52=0,0,経費前提!$D$49*店舗群別PL!$B$50*IF(店舗群別PL!D52=1,店舗群別PL!$B$51/12,1))+IF(店舗群別PL!D74=0,0,経費前提!$D$49*店舗群別PL!$B$72*IF(店舗群別PL!D74=1,店舗群別PL!$B$73/12,1))+IF(店舗群別PL!D96=0,0,経費前提!$D$49*店舗群別PL!$B$94*IF(店舗群別PL!D96=1,店舗群別PL!$B$95/12,1))) -> -35.003571 | E25: =-(IF(店舗群別PL!E8=0,0,経費前提!$B$49*店舗群別PL!$B$6*IF(店舗群別PL!E8=1,店舗群別PL!$B$7/12,1))+IF(店舗群別PL!E30=0,0,経費前提!$C$49*店舗群別PL!$B$28*IF(店舗群別PL!E30=1,店舗群別PL!$B$29/12,1))+IF(店舗群別PL!E52=0,0,経費前提!$D$49*店舗群別PL!$B$50*IF(店舗群別PL!E52=1,店舗群別PL!$B$51/12,1))+IF(店舗群別PL!E74=0,0,経費前提!$D$49*店舗群別PL!$B$72*IF(店舗群別PL!E74=1,店舗群別PL!$B$73/12,1))+IF(店舗群別PL!E96=0,0,経費前提!$D$49*店舗群別PL!$B$94*IF(店舗群別PL!E96=1,店舗群別PL!$B$95/12,1))) -> -66.117857 | F25: =-(IF(店舗群別PL!F8=0,0,経費前提!$B$49*店舗群別PL!$B$6*IF(店舗群別PL!F8=1,店舗群別PL!$B$7/12,1))+IF(店舗群別PL!F30=0,0,経費前提!$C$49*店舗群別PL!$B$28*IF(店舗群別PL!F30=1,店舗群別PL!$B$29/12,1))+IF(店舗群別PL!F52=0,0,経費前提!$D$49*店舗群別PL!$B$50*IF(店舗群別PL!F52=1,店舗群別PL!$B$51/12,1))+IF(店舗群別PL!F74=0,0,経費前提!$D$49*店舗群別PL!$B$72*IF(店舗群別PL!F74=1,店舗群別PL!$B$73/12,1))+IF(店舗群別PL!F96=0,0,経費前提!$D$49*店舗群別PL!$B$94*IF(店舗群別PL!F96=1,店舗群別PL!$B$95/12,1))) -> -97.232143 | G25: =-(IF(店舗群別PL!G8=0,0,経費前提!$B$49*店舗群別PL!$B$6*IF(店舗群別PL!G8=1,店舗群別PL!$B$7/12,1))+IF(店舗群別PL!G30=0,0,経費前提!$C$49*店舗群別PL!$B$28*IF(店舗群別PL!G30=1,店舗群別PL!$B$29/12,1))+IF(店舗群別PL!G52=0,0,経費前提!$D$49*店舗群別PL!$B$50*IF(店舗群別PL!G52=1,店舗群別PL!$B$51/12,1))+IF(店舗群別PL!G74=0,0,経費前提!$D$49*店舗群別PL!$B$72*IF(店舗群別PL!G74=1,店舗群別PL!$B$73/12,1))+IF(店舗群別PL!G96=0,0,経費前提!$D$49*店舗群別PL!$B$94*IF(店舗群別PL!G96=1,店舗群別PL!$B$95/12,1))) -> -128.34643 | H25: =SUM(C25:G25) -> -342.25714
A26: 投資キャッシュアウト 計 | C26: =C24+C25 -> -173.90714 | D26: =D24+D25 -> -271.70357 | E26: =E24+E25 -> -292.81786 | F26: =F24+F25 -> -323.93214 | G26: =G24+G25 -> -355.04643 | H26: =SUM(C26:G26) -> -1417.4071
A27: 連結EBITDA | C27: =連結PL!C21 -> 31.090866 | D27: =連結PL!D21 -> 85.915838 | E27: =連結PL!E21 -> 193.66663 | F27: =連結PL!F21 -> 312.5637 | G27: =連結PL!G21 -> 432.46078 | H27: =SUM(C27:G27) -> 1055.6978
A28: 法人税等（推計） | C28: =-MAX(0,連結PL!C24)*$B$33 -> -3.0797597 | D28: =-MAX(0,連結PL!D24)*$B$33 -> -11.717876 | E28: =-MAX(0,連結PL!E24)*$B$33 -> -31.735614 | F28: =-MAX(0,連結PL!F24)*$B$33 -> -55.209736 | G28: =-MAX(0,連結PL!G24)*$B$33 -> -78.983858 | H28: =SUM(C28:G28) -> -180.72684
A29: 簡易フリーキャッシュフロー | C29: =C27+C28+C26 -> -145.89604 | D29: =D27+D28+D26 -> -197.50561 | E29: =E27+E28+E26 -> -130.88684 | F29: =F27+F28+F26 -> -66.578175 | G29: =G27+G28+G26 -> -1.5695102 | H29: =SUM(C29:G29) -> -542.43617
A30: 累計フリーキャッシュフロー | C30: =C29 -> -145.89604 | D30: =C30+D29 -> -343.40165 | E30: =D30+E29 -> -474.28849 | F30: =E30+F29 -> -540.86666 | G30: =F30+G29 -> -542.43617
A32: ■ 必要資金と調達
A33: 法人税 実効税率 | B33: 0.3 | J33: 簡易。繰越欠損金の控除は考慮せず
A34: 最大資金需要（累計FCFの最小値） | B34: =-MIN(C30:G30) -> 542.43617 | J34: 税引後ベース
A35: 既存調達のうち 今回ラウンドと重複しない現金 | B35: 0 | J35: 既存2億＝調達済9,000万＋内装・保証金の家主分割。現金分は下の調達済90と同一、分割分は開業時現金から控除済のため0（二重計上回避）
A36: 今回ラウンド アピシウス投資家（調達済） | B36: 70 | J36: 2026年10月時点でクローズ済
A37: 今回ラウンド エニーカラー創業者（調達済） | B37: 20 | J37: 2026年9月 合意書締結済
A38: 今回ラウンド 募集中 | B38: 90 | J38: ラウンド総額1.8億円 － 調達済9,000万円
A39: 調達額 計 | B39: =SUM(B35:B38) -> 180
A40: 過不足（マイナスが不足） | B40: =B39-B34 -> -362.43617 | J40: デット元本返済・分割払い金利は未考慮
A42: ※ 簡易FCF＝連結EBITDA－法人税等－投資キャッシュアウト。運転資本増減・借入返済は含まない。
A44: ■ 1号店（六本木）開業に必要な資金と過不足
A45: 項 目 | B45: 金額 | J45: 単位：百万円
A46: 契約金 | B46: =経費前提!$B$32 -> 10
A47: 事業費（設計・内装施工・OSE/FF&E） | B47: =経費前提!$B$35 -> 194.25
...

Sheet 感応度分析
A1: 感応度分析 店内席効率 × ディナー店内回転率（1号店・満年度）
A2: 原価は「経費前提」で選択中の方法に連動。軸の値（水色）は自由に変更できます。
A4: ■ 年間売上高（百万円）
A5: 店内席効率 ＼ ディナー回転率 | B5: 0.7 | C5: 0.8 | D5: 0.9 | E5: 1 | F5: 1.1
A6: 0.65 | B6: =((売上前提!$C$22*$A6*売上前提!$E$22*売上前提!$H$22+売上前提!$C$24*$A6*売上前提!$E$24*売上前提!$H$24+売上前提!$C$26*$A6*B$5*売上前提!$H$26)+(売上前提!$J$23+売上前提!$J$25+売上前提!$J$27))*売上前提!$B$5/1000000 -> 335.92201 | C6: =((売上前提!$C$22*$A6*売上前提!$E$22*売上前提!$H$22+売上前提!$C$24*$A6*売上前提!$E$24*売上前提!$H$24+売上前提!$C$26*$A6*C$5*売上前提!$H$26)+(売上前提!$J$23+売上前提!$J$25+売上前提!$J$27))*売上前提!$B$5/1000000 -> 357.86536 | D6: =((売上前提!$C$22*$A6*売上前提!$E$22*売上前提!$H$22+売上前提!$C$24*$A6*売上前提!$E$24*売上前提!$H$24+売上前提!$C$26*$A6*D$5*売上前提!$H$26)+(売上前提!$J$23+売上前提!$J$25+売上前提!$J$27))*売上前提!$B$5/1000000 -> 379.80872 | E6: =((売上前提!$C$22*$A6*売上前提!$E$22*売上前提!$H$22+売上前提!$C$24*$A6*売上前提!$E$24*売上前提!$H$24+売上前提!$C$26*$A6*E$5*売上前提!$H$26)+(売上前提!$J$23+売上前提!$J$25+売上前提!$J$27))*売上前提!$B$5/1000000 -> 401.75207 | F6: =((売上前提!$C$22*$A6*売上前提!$E$22*売上前提!$H$22+売上前提!$C$24*$A6*売上前提!$E$24*売上前提!$H$24+売上前提!$C$26*$A6*F$5*売上前提!$H$26)+(売上前提!$J$23+売上前提!$J$25+売上前提!$J$27))*売上前提!$B$5/1000000 -> 423.69542
A7: 0.7 | B7: =((売上前提!$C$22*$A7*売上前提!$E$22*売上前提!$H$22+売上前提!$C$24*$A7*売上前提!$E$24*売上前提!$H$24+売上前提!$C$26*$A7*B$5*売上前提!$H$26)+(売上前提!$J$23+売上前提!$J$25+売上前提!$J$27))*売上前提!$B$5/1000000 -> 354.32067 | C7: =((売上前提!$C$22*$A7*売上前提!$E$22*売上前提!$H$22+売上前提!$C$24*$A7*売上前提!$E$24*売上前提!$H$24+売上前提!$C$26*$A7*C$5*売上前提!$H$26)+(売上前提!$J$23+売上前提!$J$25+売上前提!$J$27))*売上前提!$B$5/1000000 -> 377.95197 | D7: =((売上前提!$C$22*$A7*売上前提!$E$22*売上前提!$H$22+売上前提!$C$24*$A7*売上前提!$E$24*売上前提!$H$24+売上前提!$C$26*$A7*D$5*売上前提!$H$26)+(売上前提!$J$23+売上前提!$J$25+売上前提!$J$27))*売上前提!$B$5/1000000 -> 401.58327 | E7: =((売上前提!$C$22*$A7*売上前提!$E$22*売上前提!$H$22+売上前提!$C$24*$A7*売上前提!$E$24*売上前提!$H$24+売上前提!$C$26*$A7*E$5*売上前提!$H$26)+(売上前提!$J$23+売上前提!$J$25+売上前提!$J$27))*売上前提!$B$5/1000000 -> 425.21457 | F7: =((売上前提!$C$22*$A7*売上前提!$E$22*売上前提!$H$22+売上前提!$C$24*$A7*売上前提!$E$24*売上前提!$H$24+売上前提!$C$26*$A7*F$5*売上前提!$H$26)+(売上前提!$J$23+売上前提!$J$25+売上前提!$J$27))*売上前提!$B$5/1000000 -> 448.84587
A8: 0.75 | B8: =((売上前提!$C$22*$A8*売上前提!$E$22*売上前提!$H$22+売上前提!$C$24*$A8*売上前提!$E$24*売上前提!$H$24+売上前提!$C$26*$A8*B$5*売上前提!$H$26)+(売上前提!$J$23+売上前提!$J$25+売上前提!$J$27))*売上前提!$B$5/1000000 -> 372.71933 | C8: =((売上前提!$C$22*$A8*売上前提!$E$22*売上前提!$H$22+売上前提!$C$24*$A8*売上前提!$E$24*売上前提!$H$24+売上前提!$C$26*$A8*C$5*売上前提!$H$26)+(売上前提!$J$23+売上前提!$J$25+売上前提!$J$27))*売上前提!$B$5/1000000 -> 398.03857 | D8: =((売上前提!$C$22*$A8*売上前提!$E$22*売上前提!$H$22+売上前提!$C$24*$A8*売上前提!$E$24*売上前提!$H$24+売上前提!$C$26*$A8*D$5*売上前提!$H$26)+(売上前提!$J$23+売上前提!$J$25+売上前提!$J$27))*売上前提!$B$5/1000000 -> 423.35782 | E8: =((売上前提!$C$22*$A8*売上前提!$E$22*売上前提!$H$22+売上前提!$C$24*$A8*売上前提!$E$24*売上前提!$H$24+売上前提!$C$26*$A8*E$5*売上前提!$H$26)+(売上前提!$J$23+売上前提!$J$25+売上前提!$J$27))*売上前提!$B$5/1000000 -> 448.67708 | F8: =((売上前提!$C$22*$A8*売上前提!$E$22*売上前提!$H$22+売上前提!$C$24*$A8*売上前提!$E$24*売上前提!$H$24+売上前提!$C$26*$A8*F$5*売上前提!$H$26)+(売上前提!$J$23+売上前提!$J$25+売上前提!$J$27))*売上前提!$B$5/1000000 -> 473.99633
A9: 0.8 | B9: =((売上前提!$C$22*$A9*売上前提!$E$22*売上前提!$H$22+売上前提!$C$24*$A9*売上前提!$E$24*売上前提!$H$24+売上前提!$C$26*$A9*B$5*売上前提!$H$26)+(売上前提!$J$23+売上前提!$J$25+売上前提!$J$27))*売上前提!$B$5/1000000 -> 391.11798 | C9: =((売上前提!$C$22*$A9*売上前提!$E$22*売上前提!$H$22+売上前提!$C$24*$A9*売上前提!$E$24*売上前提!$H$24+売上前提!$C$26*$A9*C$5*売上前提!$H$26)+(売上前提!$J$23+売上前提!$J$25+売上前提!$J$27))*売上前提!$B$5/1000000 -> 418.12518 | D9: =((売上前提!$C$22*$A9*売上前提!$E$22*売上前提!$H$22+売上前提!$C$24*$A9*売上前提!$E$24*売上前提!$H$24+売上前提!$C$26*$A9*D$5*売上前提!$H$26)+(売上前提!$J$23+売上前提!$J$25+売上前提!$J$27))*売上前提!$B$5/1000000 -> 445.13238 | E9: =((売上前提!$C$22*$A9*売上前提!$E$22*売上前提!$H$22+売上前提!$C$24*$A9*売上前提!$E$24*売上前提!$H$24+売上前提!$C$26*$A9*E$5*売上前提!$H$26)+(売上前提!$J$23+売上前提!$J$25+売上前提!$J$27))*売上前提!$B$5/1000000 -> 472.13958 | F9: =((売上前提!$C$22*$A9*売上前提!$E$22*売上前提!$H$22+売上前提!$C$24*$A9*売上前提!$E$24*売上前提!$H$24+売上前提!$C$26*$A9*F$5*売上前提!$H$26)+(売上前提!$J$23+売上前提!$J$25+売上前提!$J$27))*売上前提!$B$5/1000000 -> 499.14678
A10: 0.85 | B10: =((売上前提!$C$22*$A10*売上前提!$E$22*売上前提!$H$22+売上前提!$C$24*$A10*売上前提!$E$24*売上前提!$H$24+売上前提!$C$26*$A10*B$5*売上前提!$H$26)+(売上前提!$J$23+売上前提!$J$25+売上前提!$J$27))*売上前提!$B$5/1000000 -> 409.51664 | C10: =((売上前提!$C$22*$A10*売上前提!$E$22*売上前提!$H$22+売上前提!$C$24*$A10*売上前提!$E$24*売上前提!$H$24+売上前提!$C$26*$A10*C$5*売上前提!$H$26)+(売上前提!$J$23+売上前提!$J$25+売上前提!$J$27))*売上前提!$B$5/1000000 -> 438.21179 | D10: =((売上前提!$C$22*$A10*売上前提!$E$22*売上前提!$H$22+売上前提!$C$24*$A10*売上前提!$E$24*売上前提!$H$24+売上前提!$C$26*$A10*D$5*売上前提!$H$26)+(売上前提!$J$23+売上前提!$J$25+売上前提!$J$27))*売上前提!$B$5/1000000 -> 466.90693 | E10: =((売上前提!$C$22*$A10*売上前提!$E$22*売上前提!$H$22+売上前提!$C$24*$A10*売上前提!$E$24*売上前提!$H$24+売上前提!$C$26*$A10*E$5*売上前提!$H$26)+(売上前提!$J$23+売上前提!$J$25+売上前提!$J$27))*売上前提!$B$5/1000000 -> 495.60208 | F10: =((売上前提!$C$22*$A10*売上前提!$E$22*売上前提!$H$22+売上前提!$C$24*$A10*売上前提!$E$24*売上前提!$H$24+売上前提!$C$26*$A10*F$5*売上前提!$H$26)+(売上前提!$J$23+売上前提!$J$25+売上前提!$J$27))*売上前提!$B$5/1000000 -> 524.29724
A12: ■ 営業利益（百万円）
A13: 店内席効率 ＼ ディナー回転率 | B13: 0.7 | C13: 0.8 | D13: 0.9 | E13: 1 | F13: 1.1
A14: 0.65 | B14: =((((売上前提!$C$22*$A14*売上前提!$E$22*売上前提!$H$22+売上前提!$C$24*$A14*売上前提!$E$24*売上前提!$H$24+売上前提!$C$26*$A14*B$13*売上前提!$H$26)+(売上前提!$J$23+売上前提!$J$25+売上前提!$J$27))*売上前提!$B$5/1000000)*(1-経費前提!$B$21)-経費前提!$B$25-MAX(0,(((売上前提!$C$22*$A14*売上前提!$E$22*売上前提!$H$22+売上前提!$C$24*$A14*売上前提!$E$24*売上前提!$H$24+売上前提!$C$26*$A14*B$13*売上前提!$H$26)+(売上前提!$J$23+売上前提!$J$25+売上前提!$J$27))*売上前提!$B$5/1000000)-経費前提!$B$27)*経費前提!$B$26-経費前提!$B$42) -> 19.402862 | C14: =((((売上前提!$C$22*$A14*売上前提!$E$22*売上前提!$H$22+売上前提!$C$24*$A14*売上前提!$E$24*売上前提!$H$24+売上前提!$C$26*$A14*C$13*売上前提!$H$26)+(売上前提!$J$23+売上前提!$J$25+売上前提!$J$27))*売上前提!$B$5/1000000)*(1-経費前提!$B$21)-経費前提!$B$25-MAX(0,(((売上前提!$C$22*$A14*売上前提!$E$22*売上前提!$H$22+売上前提!$C$24*$A14*売上前提!$E$24*売上前提!$H$24+売上前提!$C$26*$A14*C$13*売上前提!$H$26)+(売上前提!$J$23+売上前提!$J$25+売上前提!$J$27))*売上前提!$B$5/1000000)-経費前提!$B$27)*経費前提!$B$26-経費前提!$B$42) -> 22.255497 | D14: =((((売上前提!$C$22*$A14*売上前提!$E$22*売上前提!$H$22+売上前提!$C$24*$A14*売上前提!$E$24*売上前提!$H$24+売上前提!$C$26*$A14*D$13*売上前提!$H$26)+(売上前提!$J$23+売上前提!$J$25+売上前提!$J$27))*売上前提!$B$5/1000000)*(1-経費前提!$B$21)-経費前提!$B$25-MAX(0,(((売上前提!$C$22*$A14*売上前提!$E$22*売上前提!$H$22+売上前提!$C$24*$A14*売上前提!$E$24*売上前提!$H$24+売上前提!$C$26*$A14*D$13*売上前提!$H$26)+(売上前提!$J$23+売上前提!$J$25+売上前提!$J$27))*売上前提!$B$5/1000000)-経費前提!$B$27)*経費前提!$B$26-経費前提!$B$42) -> 25.108133 | E14: =((((売上前提!$C$22*$A14*売上前提!$E$22*売上前提!$H$22+売上前提!$C$24*$A14*売上前提!$E$24*売上前提!$H$24+売上前提!$C$26*$A14*E$13*売上前提!$H$26)+(売上前提!$J$23+売上前提!$J$25+売上前提!$J$27))*売上前提!$B$5/1000000)*(1-経費前提!$B$21)-経費前提!$B$25-MAX(0,(((売上前提!$C$22*$A14*売上前提!$E$22*売上前提!$H$22+売上前提!$C$24*$A14*売上前提!$E$24*売上前提!$H$24+売上前提!$C$26*$A14*E$13*売上前提!$H$26)+(売上前提!$J$23+売上前提!$J$25+売上前提!$J$27))*売上前提!$B$5/1000000)-経費前提!$B$27)*経費前提!$B$26-経費前提!$B$42) -> 27.960768 | F14: =((((売上前提!$C$22*$A14*売上前提!$E$22*売上前提!$H$22+売上前提!$C$24*$A14*売上前提!$E$24*売上前提!$H$24+売上前提!$C$26*$A14*F$13*売上前提!$H$26)+(売上前提!$J$23+売上前提!$J$25+売上前提!$J$27))*売上前提!$B$5/1000000)*(1-経費前提!$B$21)-経費前提!$B$25-MAX(0,(((売上前提!$C$22*$A14*売上前提!$E$22*売上前提!$H$22+売上前提!$C$24*$A14*売上前提!$E$24*売上前提!$H$24+売上前提!$C$26*$A14*F$13*売上前提!$H$26)+(売上前提!$J$23+売上前提!$J$25+売上前提!$J$27))*売上前提!$B$5/1000000)-経費前提!$B$27)*経費前提!$B$26-経費前提!$B$42) -> 30.813404
A15: 0.7 | B15: =((((売上前提!$C$22*$A15*売上前提!$E$22*売上前提!$H$22+売上前提!$C$24*$A15*売上前提!$E$24*売上前提!$H$24+売上前提!$C$26*$A15*B$13*売上前提!$H$26)+(売上前提!$J$23+売上前提!$J$25+売上前提!$J$27))*売上前提!$B$5/1000000)*(1-経費前提!$B$21)-経費前提!$B$25-MAX(0,(((売上前提!$C$22*$A15*売上前提!$E$22*売上前提!$H$22+売上前提!$C$24*$A15*売上前提!$E$24*売上前提!$H$24+売上前提!$C$26*$A15*B$13*売上前提!$H$26)+(売上前提!$J$23+売上前提!$J$25+売上前提!$J$27))*売上前提!$B$5/1000000)-経費前提!$B$27)*経費前提!$B$26-経費前提!$B$42) -> 21.794687 | C15: =((((売上前提!$C$22*$A15*売上前提!$E$22*売上前提!$H$22+売上前提!$C$24*$A15*売上前提!$E$24*売上前提!$H$24+売上前提!$C$26*$A15*C$13*売上前提!$H$26)+(売上前提!$J$23+売上前提!$J$25+売上前提!$J$27))*売上前提!$B$5/1000000)*(1-経費前提!$B$21)-経費前提!$B$25-MAX(0,(((売上前提!$C$22*$A15*売上前提!$E$22*売上前提!$H$22+売上前提!$C$24*$A15*売上前提!$E$24*売上前提!$H$24+売上前提!$C$26*$A15*C$13*売上前提!$H$26)+(売上前提!$J$23+売上前提!$J$25+売上前提!$J$27))*売上前提!$B$5/1000000)-経費前提!$B$27)*経費前提!$B$26-経費前提!$B$42) -> 24.866756 | D15: =((((売上前提!$C$22*$A15*売上前提!$E$22*売上前提!$H$22+売上前提!$C$24*$A15*売上前提!$E$24*売上前提!$H$24+売上前提!$C$26*$A15*D$13*売上前提!$H$26)+(売上前提!$J$23+売上前提!$J$25+売上前提!$J$27))*売上前提!$B$5/1000000)*(1-経費前提!$B$21)-経費前提!$B$25-MAX(0,(((売上前提!$C$22*$A15*売上前提!$E$22*売上前提!$H$22+売上前提!$C$24*$A15*売上前提!$E$24*売上前提!$H$24+売上前提!$C$26*$A15*D$13*売上前提!$H$26)+(売上前提!$J$23+売上前提!$J$25+売上前提!$J$27))*売上前提!$B$5/1000000)-経費前提!$B$27)*経費前提!$B$26-経費前提!$B$42) -> 27.938825 | E15: =((((売上前提!$C$22*$A15*売上前提!$E$22*売上前提!$H$22+売上前提!$C$24*$A15*売上前提!$E$24*売上前提!$H$24+売上前提!$C$26*$A15*E$13*売上前提!$H$26)+(売上前提!$J$23+売上前提!$J$25+売上前提!$J$27))*売上前提!$B$5/1000000)*(1-経費前提!$B$21)-経費前提!$B$25-MAX(0,(((売上前提!$C$22*$A15*売上前提!$E$22*売上前提!$H$22+売上前提!$C$24*$A15*売上前提!$E$24*売上前提!$H$24+売上前提!$C$26*$A15*E$13*売上前提!$H$26)+(売上前提!$J$23+売上前提!$J$25+売上前提!$J$27))*売上前提!$B$5/1000000)-経費前提!$B$27)*経費前提!$B$26-経費前提!$B$42) -> 31.010894 | F15: =((((売上前提!$C$22*$A15*売上前提!$E$22*売上前提!$H$22+売上前提!$C$24*$A15*売上前提!$E$24*売上前提!$H$24+売上前提!$C$26*$A15*F$13*売上前提!$H$26)+(売上前提!$J$23+売上前提!$J$25+売上前提!$J$27))*売上前提!$B$5/1000000)*(1-経費前提!$B$21)-経費前提!$B$25-MAX(0,(((売上前提!$C$22*$A15*売上前提!$E$22*売上前提!$H$22+売上前提!$C$24*$A15*売上前提!$E$24*売上前提!$H$24+売上前提!$C$26*$A15*F$13*売上前提!$H$26)+(売上前提!$J$23+売上前提!$J$25+売上前提!$J$27))*売上前提!$B$5/1000000)-経費前提!$B$27)*経費前提!$B$26-経費前提!$B$42) -> 34.082963
A16: 0.75 | B16: =((((売上前提!$C$22*$A16*売上前提!$E$22*売上前提!$H$22+売上前提!$C$24*$A16*売上前提!$E$24*売上前提!$H$24+売上前提!$C$26*$A16*B$13*売上前提!$H$26)+(売上前提!$J$23+売上前提!$J$25+売上前提!$J$27))*売上前提!$B$5/1000000)*(1-経費前提!$B$21)-経費前提!$B$25-MAX(0,(((売上前提!$C$22*$A16*売上前提!$E$22*売上前提!$H$22+売上前提!$C$24*$A16*売上前提!$E$24*売上前提!$H$24+売上前提!$C$26*$A16*B$13*売上前提!$H$26)+(売上前提!$J$23+売上前提!$J$25+売上前提!$J$27))*売上前提!$B$5/1000000)-経費前提!$B$27)*経費前提!$B$26-経費前提!$B$42) -> 24.186512 | C16: =((((売上前提!$C$22*$A16*売上前提!$E$22*売上前提!$H$22+売上前提!$C$24*$A16*売上前提!$E$24*売上前提!$H$24+売上前提!$C$26*$A16*C$13*売上前提!$H$26)+(売上前提!$J$23+売上前提!$J$25+売上前提!$J$27))*売上前提!$B$5/1000000)*(1-経費前提!$B$21)-経費前提!$B$25-MAX(0,(((売上前提!$C$22*$A16*売上前提!$E$22*売上前提!$H$22+売上前提!$C$24*$A16*売上前提!$E$24*売上前提!$H$24+売上前提!$C$26*$A16*C$13*売上前提!$H$26)+(売上前提!$J$23+売上前提!$J$25+売上前提!$J$27))*売上前提!$B$5/1000000)-経費前提!$B$27)*経費前提!$B$26-経費前提!$B$42) -> 27.478015 | D16: =((((売上前提!$C$22*$A16*売上前提!$E$22*売上前提!$H$22+売上前提!$C$24*$A16*売上前提!$E$24*売上前提!$H$24+売上前提!$C$26*$A16*D$13*売上前提!$H$26)+(売上前提!$J$23+売上前提!$J$25+売上前提!$J$27))*売上前提!$B$5/1000000)*(1-経費前提!$B$21)-経費前提!$B$25-MAX(0,(((売上前提!$C$22*$A16*売上前提!$E$22*売上前提!$H$22+売上前提!$C$24*$A16*売上前提!$E$24*売上前提!$H$24+売上前提!$C$26*$A16*D$13*売上前提!$H$26)+(売上前提!$J$23+売上前提!$J$25+売上前提!$J$27))*売上前提!$B$5/1000000)-経費前提!$B$27)*経費前提!$B$26-経費前提!$B$42) -> 30.769517 | E16: =((((売上前提!$C$22*$A16*売上前提!$E$22*売上前提!$H$22+売上前提!$C$24*$A16*売上前提!$E$24*売上前提!$H$24+売上前提!$C$26*$A16*E$13*売上前提!$H$26)+(売上前提!$J$23+売上前提!$J$25+売上前提!$J$27))*売上前提!$B$5/1000000)*(1-経費前提!$B$21)-経費前提!$B$25-MAX(0,(((売上前提!$C$22*$A16*売上前提!$E$22*売上前提!$H$22+売上前提!$C$24*$A16*売上前提!$E$24*売上前提!$H$24+売上前提!$C$26*$A16*E$13*売上前提!$H$26)+(売上前提!$J$23+売上前提!$J$25+売上前提!$J$27))*売上前提!$B$5/1000000)-経費前提!$B$27)*経費前提!$B$26-経費前提!$B$42) -> 34.06102 | F16: =((((売上前提!$C$22*$A16*売上前提!$E$22*売上前提!$H$22+売上前提!$C$24*$A16*売上前提!$E$24*売上前提!$H$24+売上前提!$C$26*$A16*F$13*売上前提!$H$26)+(売上前提!$J$23+売上前提!$J$25+売上前提!$J$27))*売上前提!$B$5/1000000)*(1-経費前提!$B$21)-経費前提!$B$25-MAX(0,(((売上前提!$C$22*$A16*売上前提!$E$22*売上前提!$H$22+売上前提!$C$24*$A16*売上前提!$E$24*売上前提!$H$24+売上前提!$C$26*$A16*F$13*売上前提!$H$26)+(売上前提!$J$23+売上前提!$J$25+売上前提!$J$27))*売上前提!$B$5/1000000)-経費前提!$B$27)*経費前提!$B$26-経費前提!$B$42) -> 37.352522
A17: 0.8 | B17: =((((売上前提!$C$22*$A17*売上前提!$E$22*売上前提!$H$22+売上前提!$C$24*$A17*売上前提!$E$24*売上前提!$H$24+売上前提!$C$26*$A17*B$13*売上前提!$H$26)+(売上前提!$J$23+売上前提!$J$25+売上前提!$J$27))*売上前提!$B$5/1000000)*(1-経費前提!$B$21)-経費前提!$B$25-MAX(0,(((売上前提!$C$22*$A17*売上前提!$E$22*売上前提!$H$22+売上前提!$C$24*$A17*売上前提!$E$24*売上前提!$H$24+売上前提!$C$26*$A17*B$13*売上前提!$H$26)+(売上前提!$J$23+売上前提!$J$25+売上前提!$J$27))*売上前提!$B$5/1000000)-経費前提!$B$27)*経費前提!$B$26-経費前提!$B$42) -> 26.578337 | C17: =((((売上前提!$C$22*$A17*売上前提!$E$22*売上前提!$H$22+売上前提!$C$24*$A17*売上前提!$E$24*売上前提!$H$24+売上前提!$C$26*$A17*C$13*売上前提!$H$26)+(売上前提!$J$23+売上前提!$J$25+売上前提!$J$27))*売上前提!$B$5/1000000)*(1-経費前提!$B$21)-経費前提!$B$25-MAX(0,(((売上前提!$C$22*$A17*売上前提!$E$22*売上前提!$H$22+売上前提!$C$24*$A17*売上前提!$E$24*売上前提!$H$24+売上前提!$C$26*$A17*C$13*売上前提!$H$26)+(売上前提!$J$23+売上前提!$J$25+売上前提!$J$27))*売上前提!$B$5/1000000)-経費前提!$B$27)*経費前提!$B$26-経費前提!$B$42) -> 30.089273 | D17: =((((売上前提!$C$22*$A17*売上前提!$E$22*売上前提!$H$22+売上前提!$C$24*$A17*売上前提!$E$24*売上前提!$H$24+売上前提!$C$26*$A17*D$13*売上前提!$H$26)+(売上前提!$J$23+売上前提!$J$25+売上前提!$J$27))*売上前提!$B$5/1000000)*(1-経費前提!$B$21)-経費前提!$B$25-MAX(0,(((売上前提!$C$22*$A17*売上前提!$E$22*売上前提!$H$22+売上前提!$C$24*$A17*売上前提!$E$24*売上前提!$H$24+売上前提!$C$26*$A17*D$13*売上前提!$H$26)+(売上前提!$J$23+売上前提!$J$25+売上前提!$J$27))*売上前提!$B$5/1000000)-経費前提!$B$27)*経費前提!$B$26-経費前提!$B$42) -> 33.600209 | E17: =((((売上前提!$C$22*$A17*売上前提!$E$22*売上前提!$H$22+売上前提!$C$24*$A17*売上前提!$E$24*売上前提!$H$24+売上前提!$C$26*$A17*E$13*売上前提!$H$26)+(売上前提!$J$23+売上前提!$J$25+売上前提!$J$27))*売上前提!$B$5/1000000)*(1-経費前提!$B$21)-経費前提!$B$25-MAX(0,(((売上前提!$C$22*$A17*売上前提!$E$22*売上前提!$H$22+売上前提!$C$24*$A17*売上前提!$E$24*売上前提!$H$24+売上前提!$C$26*$A17*E$13*売上前提!$H$26)+(売上前提!$J$23+売上前提!$J$25+売上前提!$J$27))*売上前提!$B$5/1000000)-経費前提!$B$27)*経費前提!$B$26-経費前提!$B$42) -> 37.111145 | F17: =((((売上前提!$C$22*$A17*売上前提!$E$22*売上前提!$H$22+売上前提!$C$24*$A17*売上前提!$E$24*売上前提!$H$24+売上前提!$C$26*$A17*F$13*売上前提!$H$26)+(売上前提!$J$23+売上前提!$J$25+売上前提!$J$27))*売上前提!$B$5/1000000)*(1-経費前提!$B$21)-経費前提!$B$25-MAX(0,(((売上前提!$C$22*$A17*売上前提!$E$22*売上前提!$H$22+売上前提!$C$24*$A17*売上前提!$E$24*売上前提!$H$24+売上前提!$C$26*$A17*F$13*売上前提!$H$26)+(売上前提!$J$23+売上前提!$J$25+売上前提!$J$27))*売上前提!$B$5/1000000)-経費前提!$B$27)*経費前提!$B$26-経費前提!$B$42) -> 40.622081
A18: 0.85 | B18: =((((売上前提!$C$22*$A18*売上前提!$E$22*売上前提!$H$22+売上前提!$C$24*$A18*売上前提!$E$24*売上前提!$H$24+売上前提!$C$26*$A18*B$13*売上前提!$H$26)+(売上前提!$J$23+売上前提!$J$25+売上前提!$J$27))*売上前提!$B$5/1000000)*(1-経費前提!$B$21)-経費前提!$B$25-MAX(0,(((売上前提!$C$22*$A18*売上前提!$E$22*売上前提!$H$22+売上前提!$C$24*$A18*売上前提!$E$24*売上前提!$H$24+売上前提!$C$26*$A18*B$13*売上前提!$H$26)+(売上前提!$J$23+売上前提!$J$25+売上前提!$J$27))*売上前提!$B$5/1000000)-経費前提!$B$27)*経費前提!$B$26-経費前提!$B$42) -> 28.970163 | C18: =((((売上前提!$C$22*$A18*売上前提!$E$22*売上前提!$H$22+売上前提!$C$24*$A18*売上前提!$E$24*売上前提!$H$24+売上前提!$C$26*$A18*C$13*売上前提!$H$26)+(売上前提!$J$23+売上前提!$J$25+売上前提!$J$27))*売上前提!$B$5/1000000)*(1-経費前提!$B$21)-経費前提!$B$25-MAX(0,(((売上前提!$C$22*$A18*売上前提!$E$22*売上前提!$H$22+売上前提!$C$24*$A18*売上前提!$E$24*売上前提!$H$24+売上前提!$C$26*$A18*C$13*売上前提!$H$26)+(売上前提!$J$23+売上前提!$J$25+売上前提!$J$27))*売上前提!$B$5/1000000)-経費前提!$B$27)*経費前提!$B$26-経費前提!$B$42) -> 32.700532 | D18: =((((売上前提!$C$22*$A18*売上前提!$E$22*売上前提!$H$22+売上前提!$C$24*$A18*売上前提!$E$24*売上前提!$H$24+売上前提!$C$26*$A18*D$13*売上前提!$H$26)+(売上前提!$J$23+売上前提!$J$25+売上前提!$J$27))*売上前提!$B$5/1000000)*(1-経費前提!$B$21)-経費前提!$B$25-MAX(0,(((売上前提!$C$22*$A18*売上前提!$E$22*売上前提!$H$22+売上前提!$C$24*$A18*売上前提!$E$24*売上前提!$H$24+売上前提!$C$26*$A18*D$13*売上前提!$H$26)+(売上前提!$J$23+売上前提!$J$25+売上前提!$J$27))*売上前提!$B$5/1000000)-経費前提!$B$27)*経費前提!$B$26-経費前提!$B$42) -> 36.430902 | E18: =((((売上前提!$C$22*$A18*売上前提!$E$22*売上前提!$H$22+売上前提!$C$24*$A18*売上前提!$E$24*売上前提!$H$24+売上前提!$C$26*$A18*E$13*売上前提!$H$26)+(売上前提!$J$23+売上前提!$J$25+売上前提!$J$27))*売上前提!$B$5/1000000)*(1-経費前提!$B$21)-経費前提!$B$25-MAX(0,(((売上前提!$C$22*$A18*売上前提!$E$22*売上前提!$H$22+売上前提!$C$24*$A18*売上前提!$E$24*売上前提!$H$24+売上前提!$C$26*$A18*E$13*売上前提!$H$26)+(売上前提!$J$23+売上前提!$J$25+売上前提!$J$27))*売上前提!$B$5/1000000)-経費前提!$B$27)*経費前提!$B$26-経費前提!$B$42) -> 40.161271 | F18: =((((売上前提!$C$22*$A18*売上前提!$E$22*売上前提!$H$22+売上前提!$C$24*$A18*売上前提!$E$24*売上前提!$H$24+売上前提!$C$26*$A18*F$13*売上前提!$H$26)+(売上前提!$J$23+売上前提!$J$25+売上前提!$J$27))*売上前提!$B$5/1000000)*(1-経費前提!$B$21)-経費前提!$B$25-MAX(0,(((売上前提!$C$22*$A18*売上前提!$E$22*売上前提!$H$22+売上前提!$C$24*$A18*売上前提!$E$24*売上前提!$H$24+売上前提!$C$26*$A18*F$13*売上前提!$H$26)+(売上前提!$J$23+売上前提!$J$25+売上前提!$J$27))*売上前提!$B$5/1000000)-経費前提!$B$27)*経費前提!$B$26-経費前提!$B$42) -> 43.891641
A20: ■ 営業利益率
A21: 店内席効率 ＼ ディナー回転率 | B21: 0.7 | C21: 0.8 | D21: 0.9 | E21: 1 | F21: 1.1
A22: 0.65 | B22: =IF((((売上前提!$C$22*$A22*売上前提!$E$22*売上前提!$H$22+売上前提!$C$24*$A22*売上前提!$E$24*売上前提!$H$24+売上前提!$C$26*$A22*B$21*売上前提!$H$26)+(売上前提!$J$23+売上前提!$J$25+売上前提!$J$27))*売上前提!$B$5/1000000)=0,0,((((売上前提!$C$22*$A22*売上前提!$E$22*売上前提!$H$22+売上前提!$C$24*$A22*売上前提!$E$24*売上前提!$H$24+売上前提!$C$26*$A22*B$21*売上前提!$H$26)+(売上前提!$J$23+売上前提!$J$25+売上前提!$J$27))*売上前提!$B$5/1000000)*(1-経費前提!$B$21)-経費前提!$B$25-MAX(0,(((売上前提!$C$22*$A22*売上前提!$E$22*売上前提!$H$22+売上前提!$C$24*$A22*売上前提!$E$24*売上前提!$H$24+売上前提!$C$26*$A22*B$21*売上前提!$H$26)+(売上前提!$J$23+売上前提!$J$25+売上前提!$J$27))*売上前提!$B$5/1000000)-経費前提!$B$27)*経費前提!$B$26-経費前提!$B$42)/(((売上前提!$C$22*$A22*売上前提!$E$22*売上前提!$H$22+売上前提!$C$24*$A22*売上前提!$E$24*売上前提!$H$24+売上前提!$C$26*$A22*B$21*売上前提!$H$26)+(売上前提!$J$23+売上前提!$J$25+売上前提!$J$27))*売上前提!$B$5/1000000)) -> 0.057760019 | C22: =IF((((売上前提!$C$22*$A22*売上前提!$E$22*売上前提!$H$22+売上前提!$C$24*$A22*売上前提!$E$24*売上前提!$H$24+売上前提!$C$26*$A22*C$21*売上前提!$H$26)+(売上前提!$J$23+売上前提!$J$25+売上前提!$J$27))*売上前提!$B$5/1000000)=0,0,((((売上前提!$C$22*$A22*売上前提!$E$22*売上前提!$H$22+売上前提!$C$24*$A22*売上前提!$E$24*売上前提!$H$24+売上前提!$C$26*$A22*C$21*売上前提!$H$26)+(売上前提!$J$23+売上前提!$J$25+売上前提!$J$27))*売上前提!$B$5/1000000)*(1-経費前提!$B$21)-経費前提!$B$25-MAX(0,(((売上前提!$C$22*$A22*売上前提!$E$22*売上前提!$H$22+売上前提!$C$24*$A22*売上前提!$E$24*売上前提!$H$24+売上前提!$C$26*$A22*C$21*売上前提!$H$26)+(売上前提!$J$23+売上前提!$J$25+売上前提!$J$27))*売上前提!$B$5/1000000)-経費前提!$B$27)*経費前提!$B$26-経費前提!$B$42)/(((売上前提!$C$22*$A22*売上前提!$E$22*売上前提!$H$22+売上前提!$C$24*$A22*売上前提!$E$24*売上前提!$H$24+売上前提!$C$26*$A22*C$21*売上前提!$H$26)+(売上前提!$J$23+売上前提!$J$25+売上前提!$J$27))*売上前提!$B$5/1000000)) -> 0.062189582 | D22: =IF((((売上前提!$C$22*$A22*売上前提!$E$22*売上前提!$H$22+売上前提!$C$24*$A22*売上前提!$E$24*売上前提!$H$24+売上前提!$C$26*$A22*D$21*売上前提!$H$26)+(売上前提!$J$23+売上前提!$J$25+売上前提!$J$27))*売上前提!$B$5/1000000)=0,0,((((売上前提!$C$22*$A22*売上前提!$E$22*売上前提!$H$22+売上前提!$C$24*$A22*売上前提!$E$24*売上前提!$H$24+売上前提!$C$26*$A22*D$21*売上前提!$H$26)+(売上前提!$J$23+売上前提!$J$25+売上前提!$J$27))*売上前提!$B$5/1000000)*(1-経費前提!$B$21)-経費前提!$B$25-MAX(0,(((売上前提!$C$22*$A22*売上前提!$E$22*売上前提!$H$22+売上前提!$C$24*$A22*売上前提!$E$24*売上前提!$H$24+売上前提!$C$26*$A22*D$21*売上前提!$H$26)+(売上前提!$J$23+売上前提!$J$25+売上前提!$J$27))*売上前提!$B$5/1000000)-経費前提!$B$27)*経費前提!$B$26-経費前提!$B$42)/(((売上前提!$C$22*$A22*売上前提!$E$22*売上前提!$H$22+売上前提!$C$24*$A22*売上前提!$E$24*売上前提!$H$24+売上前提!$C$26*$A22*D$21*売上前提!$H$26)+(売上前提!$J$23+売上前提!$J$25+売上前提!$J$27))*売上前提!$B$5/1000000)) -> 0.066107311 | E22: =IF((((売上前提!$C$22*$A22*売上前提!$E$22*売上前提!$H$22+売上前提!$C$24*$A22*売上前提!$E$24*売上前提!$H$24+売上前提!$C$26*$A22*E$21*売上前提!$H$26)+(売上前提!$J$23+売上前提!$J$25+売上前提!$J$27))*売上前提!$B$5/1000000)=0,0,((((売上前提!$C$22*$A22*売上前提!$E$22*売上前提!$H$22+売上前提!$C$24*$A22*売上前提!$E$24*売上前提!$H$24+売上前提!$C$26*$A22*E$21*売上前提!$H$26)+(売上前提!$J$23+売上前提!$J$25+売上前提!$J$27))*売上前提!$B$5/1000000)*(1-経費前提!$B$21)-経費前提!$B$25-MAX(0,(((売上前提!$C$22*$A22*売上前提!$E$22*売上前提!$H$22+売上前提!$C$24*$A22*売上前提!$E$24*売上前提!$H$24+売上前提!$C$26*$A22*E$21*売上前提!$H$26)+(売上前提!$J$23+売上前提!$J$25+売上前提!$J$27))*売上前提!$B$5/1000000)-経費前提!$B$27)*経費前提!$B$26-経費前提!$B$42)/(((売上前提!$C$22*$A22*売上前提!$E$22*売上前提!$H$22+売上前提!$C$24*$A22*売上前提!$E$24*売上前提!$H$24+売上前提!$C$26*$A22*E$21*売上前提!$H$26)+(売上前提!$J$23+売上前提!$J$25+売上前提!$J$27))*売上前提!$B$5/1000000)) -> 0.069597075 | F22: =IF((((売上前提!$C$22*$A22*売上前提!$E$22*売上前提!$H$22+売上前提!$C$24*$A22*売上前提!$E$24*売上前提!$H$24+売上前提!$C$26*$A22*F$21*売上前提!$H$26)+(売上前提!$J$23+売上前提!$J$25+売上前提!$J$27))*売上前提!$B$5/1000000)=0,0,((((売上前提!$C$22*$A22*売上前提!$E$22*売上前提!$H$22+売上前提!$C$24*$A22*売上前提!$E$24*売上前提!$H$24+売上前提!$C$26*$A22*F$21*売上前提!$H$26)+(売上前提!$J$23+売上前提!$J$25+売上前提!$J$27))*売上前提!$B$5/1000000)*(1-経費前提!$B$21)-経費前提!$B$25-MAX(0,(((売上前提!$C$22*$A22*売上前提!$E$22*売上前提!$H$22+売上前提!$C$24*$A22*売上前提!$E$24*売上前提!$H$24+売上前提!$C$26*$A22*F$21*売上前提!$H$26)+(売上前提!$J$23+売上前提!$J$25+売上前提!$J$27))*売上前提!$B$5/1000000)-経費前提!$B$27)*経費前提!$B$26-経費前提!$B$42)/(((売上前提!$C$22*$A22*売上前提!$E$22*売上前提!$H$22+売上前提!$C$24*$A22*売上前提!$E$24*売上前提!$H$24+売上前提!$C$26*$A22*F$21*売上前提!$H$26)+(売上前提!$J$23+売上前提!$J$25+売上前提!$J$27))*売上前提!$B$5/1000000)) -> 0.072725366
