Workbook

Sheet サマリー
A1: BRASSERIE Thierry Marx 六本木ミッドタウン店 事業収支（2026年10月改定 rev2）
A2: 単位：百万円／183.59㎡(55.5坪)・年363日営業。水色セルを変えると全体が再計算されます。
A4: ■ よく変える前提
A5: 詳細は「売上前提」。時間帯×エリアごとの席効率・回転率・客単価はそちらで個別に設定できます。
A6: 総席数（店内＋テラス） | B6: =売上前提!$B$16 -> 115
A7: 店内 | B7: =売上前提!$B$14 -> 63
A8: テラス | B8: =売上前提!$B$15 -> 52
A9: 店内 席効率 | B9: =売上前提!$D$20 -> 0.75
A10: ディナー 回転率（店内） | B10: =売上前提!$E$24 -> 0.9
A11: 客単価 ランチ | B11: =売上前提!$H$20 -> 4000
A12: 客単価 カフェ | B12: =売上前提!$H$22 -> 2500
A13: 客単価 ディナー（店内） | B13: =売上前提!$H$24 -> 15000
A14: 客単価 ディナー（テラス） | B14: =売上前提!$H$25 -> 10000
A15: 営業日数（日／年） | B15: =売上前提!$B$5 -> 363
A17: ■ 単店PL サマリー
A18: 項 目 | B18: 満年度 | C18: 1年目 | D18: 2年目 | E18: 3年目以降
A19: 売上高 | B19: =単店PL!B6 -> 428.62586 | C19: =単店PL!C6 -> 385.76328 | D19: =単店PL!D6 -> 420.05335 | E19: =単店PL!E6 -> 428.62586
A20: 部門利益 | B20: =単店PL!B12 -> 141.87516 | C20: =単店PL!C12 -> 127.68764 | D20: =単店PL!D12 -> 144.0783 | E20: =単店PL!E12 -> 152.16218
A21: GOP（店舗営業総利益） | B21: =単店PL!B16 -> 116.58623 | C21: =単店PL!C16 -> 104.92761 | D21: =単店PL!D16 -> 120.13526 | E21: =単店PL!E16 -> 128.58776
A22: EBITDA | B22: =単店PL!B22 -> 52.279362 | C22: =単店PL!C22 -> 46.707226 | D22: =単店PL!D22 -> 57.045682 | E22: =単店PL!E22 -> 64.280886
A23: 減価償却費 | B23: =単店PL!B23 -> 20.825 | C23: =単店PL!C23 -> 20.825 | D23: =単店PL!D23 -> 20.825 | E23: =単店PL!E23 -> 20.825
A24: 営業利益 | B24: =単店PL!B24 -> 31.454362 | C24: =単店PL!C24 -> 25.882226 | D24: =単店PL!D24 -> 36.220682 | E24: =単店PL!E24 -> 43.455886
A25: EBITDA率 | B25: =IF(単店PL!B6=0,0,単店PL!B22/単店PL!B6) -> 0.12196969 | C25: =IF(単店PL!C6=0,0,単店PL!C22/単店PL!C6) -> 0.12107743 | D25: =IF(単店PL!D6=0,0,単店PL!D22/単店PL!D6) -> 0.1358058 | E25: =IF(単店PL!E6=0,0,単店PL!E22/単店PL!E6) -> 0.14996969
A26: 営業利益率 | B26: =IF(単店PL!B6=0,0,単店PL!B24/単店PL!B6) -> 0.073384191 | C26: =IF(単店PL!C6=0,0,単店PL!C24/単店PL!C6) -> 0.067093545 | D26: =IF(単店PL!D6=0,0,単店PL!D24/単店PL!D6) -> 0.086228766 | E26: =IF(単店PL!E6=0,0,単店PL!E24/単店PL!E6) -> 0.10138419
A28: ■ 売上の内訳（満年度）
A29: 時間帯 × エリア | B29: 年間売上 | C29: 構成比 | D29: 1日客数
A30: =売上前提!A20&" "&売上前提!B20 -> ランチ 店内 | B30: =売上前提!K20 -> 78.89805 | C30: =売上前提!L20 -> 0.18407207 | D30: =売上前提!I20 -> 54.3375
A31: =売上前提!A21&" "&売上前提!B21 -> ランチ テラス | B31: =売上前提!K21 -> 37.752 | C31: =売上前提!L21 -> 0.088076813 | D31: =売上前提!I21 -> 26
A32: =売上前提!A22&" "&売上前提!B22 -> カフェ（アイドルタイム） 店内 | B32: =売上前提!K22 -> 21.439688 | C32: =売上前提!L22 -> 0.050019584 | D32: =売上前提!I22 -> 23.625
A33: =売上前提!A23&" "&売上前提!B23 -> カフェ（アイドルタイム） テラス | B33: =売上前提!K23 -> 11.7975 | C33: =売上前提!L23 -> 0.027524004 | D33: =売上前提!I23 -> 13
A34: =売上前提!A24&" "&売上前提!B24 -> ディナー 店内 | B34: =売上前提!K24 -> 231.54862 | C34: =売上前提!L24 -> 0.54021151 | D34: =売上前提!I24 -> 42.525
A35: =売上前提!A25&" "&売上前提!B25 -> ディナー テラス | B35: =売上前提!K25 -> 47.19 | C35: =売上前提!L25 -> 0.11009602 | D35: =売上前提!I25 -> 13
A36: 合 計 | B36: =売上前提!K26 -> 428.62586 | C36: =売上前提!L26 -> 1 | D36: =売上前提!I26 -> 172.4875
A38: ■ 投資回収
A39: 初期投資 合計 | B39: =経費前提!$B$35 -> 297.25
A40: うち 償却対象資産 | B40: =経費前提!$B$36 -> 208.25
A41: うち ワイン＋美術品（非償却） | B41: =経費前提!$B$34 -> 50
A42: 開業時 現金支出（分割払い活用後） | B42: =経費前提!$B$44 -> 158.35
A43: 定常期の年間FCF | B43: =投資・CF!B29 -> 48.680886
A44: 累計FCFの黒字転換 | B44: =投資・CF!B27 -> 4年目
...

Sheet 売上前提
A1: 売上前提 ／ 席数 × 席効率 × 回転率 × 客単価 からの積上げ
A2: 水色セル＝入力値。ここを変えると全シートが自動再計算されます。単位：売上は百万円、客単価は円。
A4: ■ 基本条件
A5: 営業日数（日／年） | B5: 363 | N5: 年363日営業（提出P&L準拠）
A6: 立上り率 1年目 | B6: 0.9 | N6: 新店初年度は保守的に90%
A7: 立上り率 2年目 | B7: 0.98
A8: 立上り率 3年目以降（成熟） | B8: 1 | N8: 満年度＝この水準
A10: ■ 席数（席）
A11: カウンター | B11: 14 | N11: 2026年10月改定：ダイニング30→24、個室27→25（店内71→63席／合計123→115席）。面積は55.5坪で変更なし
A12: ダイニング | B12: 24
A13: 個室 | B13: 25
A14: 店内 小計 | B14: =SUM(B11:B13) -> 63
A15: テラス | B15: 52
A16: 合 計 | B16: =B14+B15 -> 115
A18: ■ 時間帯 × エリア 別の売上前提
A19: 時間帯 | B19: エリア | C19: 席数 | D19: 席効率 | E19: 回転率 (回/日) | F19: 客単価 料理(円) | G19: 客単価 飲料(円) | H19: 客単価 計(円) | I19: 1日 客数(人) | J19: 日商(円) | K19: 年間売上 (百万円) | L19: 構成比
A20: ランチ | B20: 店内 | C20: =$B$14 -> 63 | D20: 0.75 | E20: 1.15 | F20: 3000 | G20: 1000 | H20: =F20+G20 -> 4000 | I20: =C20*D20*E20 -> 54.3375 | J20: =I20*H20 -> 217350 | K20: =J20*$B$5/1000000 -> 78.89805 | L20: =IF($K$26=0,0,K20/$K$26) -> 0.18407207 | N20: 店内席効率は80%→75%に変更。ディナー店内回転率0.80→0.90
A21: ランチ | B21: テラス | C21: =$B$15 -> 52 | D21: 0.5 | E21: 1 | F21: 3000 | G21: 1000 | H21: =F21+G21 -> 4000 | I21: =C21*D21*E21 -> 26 | J21: =I21*H21 -> 104000 | K21: =J21*$B$5/1000000 -> 37.752 | L21: =IF($K$26=0,0,K21/$K$26) -> 0.088076813
A22: カフェ（アイドルタイム） | B22: 店内 | C22: =$B$14 -> 63 | D22: 0.75 | E22: 0.5 | F22: 1500 | G22: 1000 | H22: =F22+G22 -> 2500 | I22: =C22*D22*E22 -> 23.625 | J22: =I22*H22 -> 59062.5 | K22: =J22*$B$5/1000000 -> 21.439688 | L22: =IF($K$26=0,0,K22/$K$26) -> 0.050019584 | N22: カフェ客単価2,500円（料理1,500＋飲料1,000）に変更
A23: カフェ（アイドルタイム） | B23: テラス | C23: =$B$15 -> 52 | D23: 0.5 | E23: 0.5 | F23: 1500 | G23: 1000 | H23: =F23+G23 -> 2500 | I23: =C23*D23*E23 -> 13 | J23: =I23*H23 -> 32500 | K23: =J23*$B$5/1000000 -> 11.7975 | L23: =IF($K$26=0,0,K23/$K$26) -> 0.027524004
A24: ディナー | B24: 店内 | C24: =$B$14 -> 63 | D24: 0.75 | E24: 0.9 | F24: 9000 | G24: 6000 | H24: =F24+G24 -> 15000 | I24: =C24*D24*E24 -> 42.525 | J24: =I24*H24 -> 637875 | K24: =J24*$B$5/1000000 -> 231.54862 | L24: =IF($K$26=0,0,K24/$K$26) -> 0.54021151
A25: ディナー | B25: テラス | C25: =$B$15 -> 52 | D25: 0.5 | E25: 0.5 | F25: 5000 | G25: 5000 | H25: =F25+G25 -> 10000 | I25: =C25*D25*E25 -> 13 | J25: =I25*H25 -> 130000 | K25: =J25*$B$5/1000000 -> 47.19 | L25: =IF($K$26=0,0,K25/$K$26) -> 0.11009602 | N25: テラスのディナーは客単価10,000円（店内15,000円）・回転率0.50に変更
A26: 合 計 | I26: =SUM(I20:I25) -> 172.4875 | J26: =SUM(J20:J25) -> 1180787.5 | K26: =SUM(K20:K25) -> 428.62586 | L26: =SUM(L20:L25) -> 1
A28: ■ 料理・飲料別の年間売上（原価計算用）
A29: 料理売上 | B29: =SUMPRODUCT(I20:I25,F20:F25)*$B$5/1000000 -> 269.95403
A30: 飲料売上 | B30: =SUMPRODUCT(I20:I25,G20:G25)*$B$5/1000000 -> 158.67184
A31: 合 計 | B31: =B29+B30 -> 428.62586
A32: 料理 構成比 | B32: =IF($B$31=0,0,B29/$B$31) -> 0.62981273
A33: 飲料 構成比 | B33: =IF($B$31=0,0,B30/$B$31) -> 0.37018727
A35: ■ 参考指標
A36: 日商（円） | B36: =J26 -> 1180787.5
A37: 月商（百万円） | B37: =K26/12 -> 35.718822
A38: 年商（百万円・満年度） | B38: =K26 -> 428.62586 | N38: 提出P&L：4.60億円
A39: 1日あたり総客数（人） | B39: =I26 -> 172.4875
A40: 平均客単価（円） | B40: =IF(I26=0,0,J26/I26) -> 6845.641
A41: 延べ席回転率（回/日） | B41: =IF($B$16=0,0,I26/$B$16) -> 1.4998913 | N41: 総客数 ÷ 総席数
A42: 坪数（坪） | B42: 55.5 | N42: 183.59㎡
A43: 坪売上（百万円/坪・年） | B43: =IF(B42=0,0,K26/B42) -> 7.7229885
A44: 1席あたり年間売上（百万円） | B44: =IF($B$16=0,0,K26/$B$16) -> 3.7271814 | N44: 席数変更の効果を見る指標
A46: ■ 立上りを織り込んだ年間売上（百万円）
...

Sheet 経費前提
A1: 経費前提（水色セル＝入力値）
A2: 経費率は2026年8月3日提出P&L準拠。2026年10月改定で売上原価は料理・飲料別（各30.0%）に変更。
A4: ■ 売上原価の計算方法
A5: 計算方法（1＝売上比一括／2＝料理・飲料別） | B5: 2 | F5: 2026年10月改定で方法2を選択。下の変動費計・感応度分析もこの選択に連動します。
A7: ■ 経費率（対売上高）
A8: 費 目 | B8: 提出P&L水準 （満年度・1年目） | C8: 2年目 | D8: 3年目以降
A9: 売上原価（方法1：売上比一括） | B9: 0.295 | C9: 0.29 | D9: 0.285 | F9: 方法1を選んだ場合のみ使用
A10: 料理原価率（方法2） | B10: 0.3 | C10: 0.3 | D10: 0.3 | F10: 2026年10月改定：全年度30.0%で固定
A11: 飲料原価率（方法2） | B11: 0.3 | C11: 0.3 | D11: 0.3 | F11: 同上。直輸入ワインによる低減は織り込んでいない
A12: 人件費 | B12: 0.345 | C12: 0.335 | D12: 0.325 | F12: 本部集中化・多能工化。人員26名
A13: 業務委託費・消耗品他 | B13: 0.024 | C13: 0.022 | D13: 0.02 | F13: 本部集中購買・規格統一
A14: 広告宣伝費・販売促進費 | B14: 0.014 | C14: 0.014 | D14: 0.014 | F14: 据置
A15: その他経費 | B15: 0.005 | C15: 0.005 | D15: 0.005 | F15: 据置
A16: 水道光熱費 | B16: 0.04 | C16: 0.038 | D16: 0.036 | F16: 高効率厨房機器・営業時間最適化
A17: ロイヤリティ | B17: 0.04 | C17: 0.04 | D17: 0.04 | F17: 契約条件（ブラッスリー4.0%）
A18: 保険・租税公課 | B18: 0.007 | C18: 0.007 | D18: 0.007 | F18: 据置
A19: 修繕維持費（FFE） | B19: 0.025 | C19: 0.025 | D19: 0.025 | F19: 据置
A20: 変動費計（選択中の原価方法ベース） | B20: =IF($B$5=1,B9,売上前提!$B$32*B10+売上前提!$B$33*B11)+SUM(B12:B19) -> 0.8 | C20: =IF($B$5=1,C9,売上前提!$B$32*C10+売上前提!$B$33*C11)+SUM(C12:C19) -> 0.786 | D20: =IF($B$5=1,D9,売上前提!$B$32*D10+売上前提!$B$33*D11)+SUM(D12:D19) -> 0.772 | F20: 原価の計算方法（B5）に連動。感応度分析シートもこの値を参照します。
A22: ■ 固定費・家賃条件
A23: 地代家賃（固定）月額 | B23: 2.22 | F23: 月222万円（提出P&L）。席数を変えても面積は同じため不変
A24: 地代家賃（固定）年額 | B24: =B23*12 -> 26.64 | F24: ＝月額×12
A25: 歩合家賃率 | B25: 0.07 | F25: 閾値超過分に対して7%
A26: 歩合家賃 閾値（年商） | B26: 331.4 | F26: 満年度の歩合家賃9百万円から逆算（提出P&L時点）
A27: 人員数（名・参考） | B27: 26 | F27: 提出P&L。人件費は売上比で計算
A29: ■ 初期投資・減価償却（百万円）
A30: 契約金 | B30: 10 | F30: 契約金3,000万円÷3店舗
A31: 事業費（設計・内装施工・OSE/FF&E） | B31: =55.5*3.5 -> 194.25 | F31: 55.5坪×350万
A32: 開業準備金（広告・採用等） | B32: 4
A33: 保証金 | B33: 39 | F33: 非償却・退去時返還対象
A34: ワイン＋美術品 | B34: 50 | F34: 美術品は数百万前半。非償却（下記参照）
A35: 初期投資 合計 | B35: =SUM(B30:B34) -> 297.25
A36: 償却対象資産（＝合計－保証金－ワイン/美術品） | B36: =B35-B33-B34 -> 208.25 | F36: ワイン在庫は棚卸資産、美術品は取得価額100万円以上なら原則非償却のため除外（2026年10月修正）
A37: 償却年数（年） | B37: 10
A38: 年間減価償却費 | B38: =B36/B37 -> 20.825 | F38: 美術品のうち100万円未満で償却したい分があれば、その金額をB34から事業費（B31）へ移してください
A40: ■ 分割払いスキーム（百万円）
A41: 分割対象：内装工事費 | B41: 100 | F41: 月833千円 × 120回（10年）
A42: 分割対象：保証金 | B42: 38.9 | F42: 月463千円 × 84回（7年）
A43: 分割対象額 計 | B43: =B41+B42 -> 138.9
A44: 開業時 現金支出 | B44: =B35-B43 -> 158.35 | F44: ＝初期投資合計 － 分割対象額
A45: 年間分割弁済額 | B45: 15.6 | F45: 月額合計1,296千円 × 12か月

Sheet 単店PL
A1: 六本木ミッドタウン店 単店PL（百万円）
A2: 科目は2026年8月3日提出P&Lのまま。売上は「売上前提」、経費率は「経費前提」に連動。金利・税金は含まない。
A4: 科 目 | B4: 満年度 （提出P&L水準） | C4: 1年目 | D4: 2年目 | E4: 3年目以降
A5: 立上り率 | B5: =売上前提!B48 -> 1 | C5: =売上前提!C48 -> 0.9 | D5: =売上前提!D48 -> 0.98 | E5: =売上前提!E48 -> 1
A6: 売上高 | B6: =売上前提!B$49 -> 428.62586 | C6: =売上前提!C$49 -> 385.76328 | D6: =売上前提!D$49 -> 420.05335 | E6: =売上前提!E$49 -> 428.62586
A7: うち 料理売上 | B7: =B$6*売上前提!$B$32 -> 269.95403 | C7: =C$6*売上前提!$B$32 -> 242.95862 | D7: =D$6*売上前提!$B$32 -> 264.55494 | E7: =E$6*売上前提!$B$32 -> 269.95403
A8: うち 飲料売上 | B8: =B$6*売上前提!$B$33 -> 158.67184 | C8: =C$6*売上前提!$B$33 -> 142.80465 | D8: =D$6*売上前提!$B$33 -> 155.4984 | E8: =E$6*売上前提!$B$33 -> 158.67184
A9: 売上原価 | B9: =IF(経費前提!$B$5=1,B$6*経費前提!$B$9,B$7*経費前提!$B$10+B$8*経費前提!$B$11) -> 128.58776 | C9: =IF(経費前提!$B$5=1,C$6*経費前提!$B$9,C$7*経費前提!$B$10+C$8*経費前提!$B$11) -> 115.72898 | D9: =IF(経費前提!$B$5=1,D$6*経費前提!$C$9,D$7*経費前提!$C$10+D$8*経費前提!$C$11) -> 126.016 | E9: =IF(経費前提!$B$5=1,E$6*経費前提!$D$9,E$7*経費前提!$D$10+E$8*経費前提!$D$11) -> 128.58776
A10: 人件費 | B10: =B$6*経費前提!$B$12 -> 147.87592 | C10: =C$6*経費前提!$B$12 -> 133.08833 | D10: =D$6*経費前提!$C$12 -> 140.71787 | E10: =E$6*経費前提!$D$12 -> 139.30341
A11: 業務委託費・消耗品他 | B11: =B$6*経費前提!$B$13 -> 10.287021 | C11: =C$6*経費前提!$B$13 -> 9.2583186 | D11: =D$6*経費前提!$C$13 -> 9.2411736 | E11: =E$6*経費前提!$D$13 -> 8.5725173
A12: 部門利益 | B12: =B6-B9-B10-B11 -> 141.87516 | C12: =C6-C9-C10-C11 -> 127.68764 | D12: =D6-D9-D10-D11 -> 144.0783 | E12: =E6-E9-E10-E11 -> 152.16218
A13: 広告宣伝費・販売促進費 | B13: =B$6*経費前提!$B$14 -> 6.0007621 | C13: =C$6*経費前提!$B$14 -> 5.4006859 | D13: =D$6*経費前提!$C$14 -> 5.8807468 | E13: =E$6*経費前提!$D$14 -> 6.0007621
A14: その他経費 | B14: =B$6*経費前提!$B$15 -> 2.1431293 | C14: =C$6*経費前提!$B$15 -> 1.9288164 | D14: =D$6*経費前提!$C$15 -> 2.1002667 | E14: =E$6*経費前提!$D$15 -> 2.1431293
A15: 水道光熱費 | B15: =B$6*経費前提!$B$16 -> 17.145035 | C15: =C$6*経費前提!$B$16 -> 15.430531 | D15: =D$6*経費前提!$C$16 -> 15.962027 | E15: =E$6*経費前提!$D$16 -> 15.430531
A16: GOP（店舗営業総利益） | B16: =B12-B13-B14-B15 -> 116.58623 | C16: =C12-C13-C14-C15 -> 104.92761 | D16: =D12-D13-D14-D15 -> 120.13526 | E16: =E12-E13-E14-E15 -> 128.58776
A17: ロイヤリティ | B17: =B$6*経費前提!$B$17 -> 17.145035 | C17: =C$6*経費前提!$B$17 -> 15.430531 | D17: =D$6*経費前提!$C$17 -> 16.802134 | E17: =E$6*経費前提!$D$17 -> 17.145035
A18: 保険・租税公課 | B18: =B$6*経費前提!$B$18 -> 3.000381 | C18: =C$6*経費前提!$B$18 -> 2.7003429 | D18: =D$6*経費前提!$C$18 -> 2.9403734 | E18: =E$6*経費前提!$D$18 -> 3.000381
A19: 地代家賃（固定） | B19: =経費前提!$B$24 -> 26.64 | C19: =経費前提!$B$24 -> 26.64 | D19: =経費前提!$B$24 -> 26.64 | E19: =経費前提!$B$24 -> 26.64
A20: 歩合家賃 | B20: =MAX(0,B6-経費前提!$B$26)*経費前提!$B$25 -> 6.8058104 | C20: =MAX(0,C6-経費前提!$B$26)*経費前提!$B$25 -> 3.8054293 | D20: =MAX(0,D6-経費前提!$B$26)*経費前提!$B$25 -> 6.2057342 | E20: =MAX(0,E6-経費前提!$B$26)*経費前提!$B$25 -> 6.8058104
A21: 修繕維持費（FFE） | B21: =B$6*経費前提!$B$19 -> 10.715647 | C21: =C$6*経費前提!$B$19 -> 9.6440819 | D21: =D$6*経費前提!$C$19 -> 10.501334 | E21: =E$6*経費前提!$D$19 -> 10.715647
A22: EBITDA | B22: =B16-B17-B18-B19-B20-B21 -> 52.279362 | C22: =C16-C17-C18-C19-C20-C21 -> 46.707226 | D22: =D16-D17-D18-D19-D20-D21 -> 57.045682 | E22: =E16-E17-E18-E19-E20-E21 -> 64.280886 | G22: 提出P&L（旧前提）：満年度EBITDA 59百万円
A23: 減価償却費 | B23: =経費前提!$B$38 -> 20.825 | C23: =経費前提!$B$38 -> 20.825 | D23: =経費前提!$B$38 -> 20.825 | E23: =経費前提!$B$38 -> 20.825
A24: 営業利益 | B24: =B22-B23 -> 31.454362 | C24: =C22-C23 -> 25.882226 | D24: =D22-D23 -> 36.220682 | E24: =E22-E23 -> 43.455886 | G24: 提出P&L（旧前提）：満年度 営業利益 38百万円
A26: ■ 対売上比
A27: 科 目 | B27: 満年度 | C27: 1年目 | D27: 2年目 | E27: 3年目以降
A28: 売上高 | B28: =IF(B$6=0,0,B6/B$6) -> 1 | C28: =IF(C$6=0,0,C6/C$6) -> 1 | D28: =IF(D$6=0,0,D6/D$6) -> 1 | E28: =IF(E$6=0,0,E6/E$6) -> 1
A29: 売上原価 | B29: =IF(B$6=0,0,B9/B$6) -> 0.3 | C29: =IF(C$6=0,0,C9/C$6) -> 0.3 | D29: =IF(D$6=0,0,D9/D$6) -> 0.3 | E29: =IF(E$6=0,0,E9/E$6) -> 0.3
A30: 人件費 | B30: =IF(B$6=0,0,B10/B$6) -> 0.345 | C30: =IF(C$6=0,0,C10/C$6) -> 0.345 | D30: =IF(D$6=0,0,D10/D$6) -> 0.335 | E30: =IF(E$6=0,0,E10/E$6) -> 0.325
A31: 業務委託費・消耗品他 | B31: =IF(B$6=0,0,B11/B$6) -> 0.024 | C31: =IF(C$6=0,0,C11/C$6) -> 0.024 | D31: =IF(D$6=0,0,D11/D$6) -> 0.022 | E31: =IF(E$6=0,0,E11/E$6) -> 0.02
A32: 部門利益 | B32: =IF(B$6=0,0,B12/B$6) -> 0.331 | C32: =IF(C$6=0,0,C12/C$6) -> 0.331 | D32: =IF(D$6=0,0,D12/D$6) -> 0.343 | E32: =IF(E$6=0,0,E12/E$6) -> 0.355
A33: 広告宣伝費・販売促進費 | B33: =IF(B$6=0,0,B13/B$6) -> 0.014 | C33: =IF(C$6=0,0,C13/C$6) -> 0.014 | D33: =IF(D$6=0,0,D13/D$6) -> 0.014 | E33: =IF(E$6=0,0,E13/E$6) -> 0.014
A34: その他経費 | B34: =IF(B$6=0,0,B14/B$6) -> 0.005 | C34: =IF(C$6=0,0,C14/C$6) -> 0.005 | D34: =IF(D$6=0,0,D14/D$6) -> 0.005 | E34: =IF(E$6=0,0,E14/E$6) -> 0.005
A35: 水道光熱費 | B35: =IF(B$6=0,0,B15/B$6) -> 0.04 | C35: =IF(C$6=0,0,C15/C$6) -> 0.04 | D35: =IF(D$6=0,0,D15/D$6) -> 0.038 | E35: =IF(E$6=0,0,E15/E$6) -> 0.036
A36: GOP（店舗営業総利益） | B36: =IF(B$6=0,0,B16/B$6) -> 0.272 | C36: =IF(C$6=0,0,C16/C$6) -> 0.272 | D36: =IF(D$6=0,0,D16/D$6) -> 0.286 | E36: =IF(E$6=0,0,E16/E$6) -> 0.3
A37: ロイヤリティ | B37: =IF(B$6=0,0,B17/B$6) -> 0.04 | C37: =IF(C$6=0,0,C17/C$6) -> 0.04 | D37: =IF(D$6=0,0,D17/D$6) -> 0.04 | E37: =IF(E$6=0,0,E17/E$6) -> 0.04
A38: 保険・租税公課 | B38: =IF(B$6=0,0,B18/B$6) -> 0.007 | C38: =IF(C$6=0,0,C18/C$6) -> 0.007 | D38: =IF(D$6=0,0,D18/D$6) -> 0.007 | E38: =IF(E$6=0,0,E18/E$6) -> 0.007
A39: 地代家賃（固定） | B39: =IF(B$6=0,0,B19/B$6) -> 0.062152106 | C39: =IF(C$6=0,0,C19/C$6) -> 0.069057895 | D39: =IF(D$6=0,0,D19/D$6) -> 0.063420516 | E39: =IF(E$6=0,0,E19/E$6) -> 0.062152106
A40: 歩合家賃 | B40: =IF(B$6=0,0,B20/B$6) -> 0.015878207 | C40: =IF(C$6=0,0,C20/C$6) -> 0.009864675 | D40: =IF(D$6=0,0,D20/D$6) -> 0.014773681 | E40: =IF(E$6=0,0,E20/E$6) -> 0.015878207
... A44: 営業利益 | B44: =IF(B$6=0,0,B24/B$6) -> 0.073384191 | C44: =IF(C$6=0,0,C24/C$6) -> 0.067093545 | D44: =IF(D$6=0,0,D24/D$6) -> 0.086228766 | E44: =IF(E$6=0,0,E24/E$6) -> 0.10138419

Sheet 投資・CF
A1: 初期投資・キャッシュフロー（百万円）
A2: 分割払いスキーム活用後の開業時現金支出と、単店の投資回収を自動計算します。
A4: ■ 初期投資
A5: 契約金 | B5: =経費前提!$B$30 -> 10
A6: 事業費（設計・内装施工・OSE/FF&E） | B6: =経費前提!$B$31 -> 194.25
A7: 開業準備金（広告・採用等） | B7: =経費前提!$B$32 -> 4
A8: 保証金 | B8: =経費前提!$B$33 -> 39
A9: ワイン＋美術品 | B9: =経費前提!$B$34 -> 50 | I9: 2026年10月追加。減価償却の対象外（経費前提F36参照）
A10: 初期投資 合計 | B10: =経費前提!$B$35 -> 297.25
A11: うち 償却対象資産 | B11: =経費前提!$B$36 -> 208.25
A12: 分割対象額 | B12: =経費前提!$B$43 -> 138.9
A13: 開業時 現金支出 | B13: =経費前提!$B$44 -> 158.35
A14: 年間分割弁済額 | B14: =経費前提!$B$45 -> 15.6
A15: （検算）内訳合計と一致するか | B15: =SUM(B5:B9)-B10 -> 0 | I15: 0なら内訳と合計が一致
A17: ■ 単店キャッシュフロー推移
A18: 項 目 | B18: 開業時 | C18: 1年目 | D18: 2年目 | E18: 3年目 | F18: 4年目 | G18: 5年目
A19: EBITDA | B19: 0 | C19: =単店PL!C22 -> 46.707226 | D19: =単店PL!D22 -> 57.045682 | E19: =単店PL!E22 -> 64.280886 | F19: =単店PL!E22 -> 64.280886 | G19: =単店PL!E22 -> 64.280886
A20: 開業時 現金支出 | B20: =-経費前提!$B$44 -> -158.35 | C20: 0 | D20: 0 | E20: 0 | F20: 0 | G20: 0
A21: 分割弁済 | B21: 0 | C21: =-経費前提!$B$45 -> -15.6 | D21: =-経費前提!$B$45 -> -15.6 | E21: =-経費前提!$B$45 -> -15.6 | F21: =-経費前提!$B$45 -> -15.6 | G21: =-経費前提!$B$45 -> -15.6
A22: 単店FCF | B22: =B19+B20+B21 -> -158.35 | C22: =C19+C20+C21 -> 31.107226 | D22: =D19+D20+D21 -> 41.445682 | E22: =E19+E20+E21 -> 48.680886 | F22: =F19+F20+F21 -> 48.680886 | G22: =G19+G20+G21 -> 48.680886
A23: 累計FCF | B23: =B22 -> -158.35 | C23: =B23+C22 -> -127.24277 | D23: =C23+D22 -> -85.797092 | E23: =D23+E22 -> -37.116206 | F23: =E23+F22 -> 11.56468 | G23: =F23+G22 -> 60.245566
A25: ■ 投資回収（自動計算）
A26: 累計FCFが赤字の年数 | B26: =COUNTIF(C23:G23,"<0") -> 3 | I26: 固定文ではなく計算結果です。前提を変えると自動で更新されます。
A27: 累計FCFの黒字転換 | B27: =IF(B26>=5,"5年内に未回収",B26+1&"年目") -> 4年目
A28: 投資回収年数（年） | B28: =IF(B26>=5,"",IF(INDEX(B22:G22,B26+2)=0,"",B26+(-INDEX(B23:G23,B26+1))/INDEX(B22:G22,B26+2))) -> 3.762439
A29: 定常期の年間FCF | B29: =G22 -> 48.680886
A31: ="→ 開業"&B27&"に累計FCFが黒字転換（投資回収 約"&TEXT(B28,"0.0")&"年）。" -> → 開業4年目に累計FCFが黒字転換（投資回収 約3.8年）。
A32: ※ 税金・運転資本の増減・借入返済・分割払いに係る金利相当は含まない簡易ベース。
A33: ※ 保証金39百万円は退去時返還対象。ワイン在庫も換価可能なため、実質的な回収はさらに短期。

Sheet 感応度分析
A1: 感応度分析 店内席効率 × ディナー店内回転率
A2: 満年度・提出P&L水準。原価は「経費前提」で選択中の方法に連動。軸の値（水色）は自由に変更できます。
A4: ■ 年間売上高（百万円）
A5: 店内席効率 ＼ ディナー回転率 | B5: 0.7 | C5: 0.8 | D5: 0.9 | E5: 1 | F5: 1.1
A6: 0.65 | B6: =((売上前提!$C$20*$A6*売上前提!$E$20*売上前提!$H$20+売上前提!$C$22*$A6*売上前提!$E$22*売上前提!$H$22+売上前提!$C$24*$A6*B$5*売上前提!$H$24)+(売上前提!$J$21+売上前提!$J$23+売上前提!$J$25))*売上前提!$B$5/1000000 -> 339.7798 | C6: =((売上前提!$C$20*$A6*売上前提!$E$20*売上前提!$H$20+売上前提!$C$22*$A6*売上前提!$E$22*売上前提!$H$22+売上前提!$C$24*$A6*C$5*売上前提!$H$24)+(売上前提!$J$21+売上前提!$J$23+売上前提!$J$25))*売上前提!$B$5/1000000 -> 362.07707 | D6: =((売上前提!$C$20*$A6*売上前提!$E$20*売上前提!$H$20+売上前提!$C$22*$A6*売上前提!$E$22*売上前提!$H$22+売上前提!$C$24*$A6*D$5*売上前提!$H$24)+(売上前提!$J$21+売上前提!$J$23+売上前提!$J$25))*売上前提!$B$5/1000000 -> 384.37435 | E6: =((売上前提!$C$20*$A6*売上前提!$E$20*売上前提!$H$20+売上前提!$C$22*$A6*売上前提!$E$22*売上前提!$H$22+売上前提!$C$24*$A6*E$5*売上前提!$H$24)+(売上前提!$J$21+売上前提!$J$23+売上前提!$J$25))*売上前提!$B$5/1000000 -> 406.67162 | F6: =((売上前提!$C$20*$A6*売上前提!$E$20*売上前提!$H$20+売上前提!$C$22*$A6*売上前提!$E$22*売上前提!$H$22+売上前提!$C$24*$A6*F$5*売上前提!$H$24)+(売上前提!$J$21+売上前提!$J$23+売上前提!$J$25))*売上前提!$B$5/1000000 -> 428.9689
A7: 0.7 | B7: =((売上前提!$C$20*$A7*売上前提!$E$20*売上前提!$H$20+売上前提!$C$22*$A7*売上前提!$E$22*売上前提!$H$22+売上前提!$C$24*$A7*B$5*売上前提!$H$24)+(売上前提!$J$21+売上前提!$J$23+売上前提!$J$25))*売上前提!$B$5/1000000 -> 358.47521 | C7: =((売上前提!$C$20*$A7*売上前提!$E$20*売上前提!$H$20+売上前提!$C$22*$A7*売上前提!$E$22*売上前提!$H$22+売上前提!$C$24*$A7*C$5*売上前提!$H$24)+(売上前提!$J$21+売上前提!$J$23+売上前提!$J$25))*売上前提!$B$5/1000000 -> 382.48766 | D7: =((売上前提!$C$20*$A7*売上前提!$E$20*売上前提!$H$20+売上前提!$C$22*$A7*売上前提!$E$22*売上前提!$H$22+売上前提!$C$24*$A7*D$5*売上前提!$H$24)+(売上前提!$J$21+売上前提!$J$23+売上前提!$J$25))*売上前提!$B$5/1000000 -> 406.50011 | E7: =((売上前提!$C$20*$A7*売上前提!$E$20*売上前提!$H$20+売上前提!$C$22*$A7*売上前提!$E$22*売上前提!$H$22+売上前提!$C$24*$A7*E$5*売上前提!$H$24)+(売上前提!$J$21+売上前提!$J$23+売上前提!$J$25))*売上前提!$B$5/1000000 -> 430.51256 | F7: =((売上前提!$C$20*$A7*売上前提!$E$20*売上前提!$H$20+売上前提!$C$22*$A7*売上前提!$E$22*売上前提!$H$22+売上前提!$C$24*$A7*F$5*売上前提!$H$24)+(売上前提!$J$21+売上前提!$J$23+売上前提!$J$25))*売上前提!$B$5/1000000 -> 454.52501
A8: 0.75 | B8: =((売上前提!$C$20*$A8*売上前提!$E$20*売上前提!$H$20+売上前提!$C$22*$A8*売上前提!$E$22*売上前提!$H$22+売上前提!$C$24*$A8*B$5*売上前提!$H$24)+(売上前提!$J$21+売上前提!$J$23+売上前提!$J$25))*売上前提!$B$5/1000000 -> 377.17061 | C8: =((売上前提!$C$20*$A8*売上前提!$E$20*売上前提!$H$20+売上前提!$C$22*$A8*売上前提!$E$22*売上前提!$H$22+売上前提!$C$24*$A8*C$5*売上前提!$H$24)+(売上前提!$J$21+売上前提!$J$23+売上前提!$J$25))*売上前提!$B$5/1000000 -> 402.89824 | D8: =((売上前提!$C$20*$A8*売上前提!$E$20*売上前提!$H$20+売上前提!$C$22*$A8*売上前提!$E$22*売上前提!$H$22+売上前提!$C$24*$A8*D$5*売上前提!$H$24)+(売上前提!$J$21+売上前提!$J$23+売上前提!$J$25))*売上前提!$B$5/1000000 -> 428.62586 | E8: =((売上前提!$C$20*$A8*売上前提!$E$20*売上前提!$H$20+売上前提!$C$22*$A8*売上前提!$E$22*売上前提!$H$22+売上前提!$C$24*$A8*E$5*売上前提!$H$24)+(売上前提!$J$21+売上前提!$J$23+売上前提!$J$25))*売上前提!$B$5/1000000 -> 454.35349 | F8: =((売上前提!$C$20*$A8*売上前提!$E$20*売上前提!$H$20+売上前提!$C$22*$A8*売上前提!$E$22*売上前提!$H$22+売上前提!$C$24*$A8*F$5*売上前提!$H$24)+(売上前提!$J$21+売上前提!$J$23+売上前提!$J$25))*売上前提!$B$5/1000000 -> 480.08111
A9: 0.8 | B9: =((売上前提!$C$20*$A9*売上前提!$E$20*売上前提!$H$20+売上前提!$C$22*$A9*売上前提!$E$22*売上前提!$H$22+売上前提!$C$24*$A9*B$5*売上前提!$H$24)+(売上前提!$J$21+売上前提!$J$23+売上前提!$J$25))*売上前提!$B$5/1000000 -> 395.86602 | C9: =((売上前提!$C$20*$A9*売上前提!$E$20*売上前提!$H$20+売上前提!$C$22*$A9*売上前提!$E$22*売上前提!$H$22+売上前提!$C$24*$A9*C$5*売上前提!$H$24)+(売上前提!$J$21+売上前提!$J$23+売上前提!$J$25))*売上前提!$B$5/1000000 -> 423.30882 | D9: =((売上前提!$C$20*$A9*売上前提!$E$20*売上前提!$H$20+売上前提!$C$22*$A9*売上前提!$E$22*売上前提!$H$22+売上前提!$C$24*$A9*D$5*売上前提!$H$24)+(売上前提!$J$21+売上前提!$J$23+売上前提!$J$25))*売上前提!$B$5/1000000 -> 450.75162 | E9: =((売上前提!$C$20*$A9*売上前提!$E$20*売上前提!$H$20+売上前提!$C$22*$A9*売上前提!$E$22*売上前提!$H$22+売上前提!$C$24*$A9*E$5*売上前提!$H$24)+(売上前提!$J$21+売上前提!$J$23+売上前提!$J$25))*売上前提!$B$5/1000000 -> 478.19442 | F9: =((売上前提!$C$20*$A9*売上前提!$E$20*売上前提!$H$20+売上前提!$C$22*$A9*売上前提!$E$22*売上前提!$H$22+売上前提!$C$24*$A9*F$5*売上前提!$H$24)+(売上前提!$J$21+売上前提!$J$23+売上前提!$J$25))*売上前提!$B$5/1000000 -> 505.63722
A10: 0.85 | B10: =((売上前提!$C$20*$A10*売上前提!$E$20*売上前提!$H$20+売上前提!$C$22*$A10*売上前提!$E$22*売上前提!$H$22+売上前提!$C$24*$A10*B$5*売上前提!$H$24)+(売上前提!$J$21+売上前提!$J$23+売上前提!$J$25))*売上前提!$B$5/1000000 -> 414.56143 | C10: =((売上前提!$C$20*$A10*売上前提!$E$20*売上前提!$H$20+売上前提!$C$22*$A10*売上前提!$E$22*売上前提!$H$22+売上前提!$C$24*$A10*C$5*売上前提!$H$24)+(売上前提!$J$21+売上前提!$J$23+売上前提!$J$25))*売上前提!$B$5/1000000 -> 443.7194 | D10: =((売上前提!$C$20*$A10*売上前提!$E$20*売上前提!$H$20+売上前提!$C$22*$A10*売上前提!$E$22*売上前提!$H$22+売上前提!$C$24*$A10*D$5*売上前提!$H$24)+(売上前提!$J$21+売上前提!$J$23+売上前提!$J$25))*売上前提!$B$5/1000000 -> 472.87738 | E10: =((売上前提!$C$20*$A10*売上前提!$E$20*売上前提!$H$20+売上前提!$C$22*$A10*売上前提!$E$22*売上前提!$H$22+売上前提!$C$24*$A10*E$5*売上前提!$H$24)+(売上前提!$J$21+売上前提!$J$23+売上前提!$J$25))*売上前提!$B$5/1000000 -> 502.03535 | F10: =((売上前提!$C$20*$A10*売上前提!$E$20*売上前提!$H$20+売上前提!$C$22*$A10*売上前提!$E$22*売上前提!$H$22+売上前提!$C$24*$A10*F$5*売上前提!$H$24)+(売上前提!$J$21+売上前提!$J$23+売上前提!$J$25))*売上前提!$B$5/1000000 -> 531.19333
A12: ■ 営業利益（百万円）
A13: 店内席効率 ＼ ディナー回転率 | B13: 0.7 | C13: 0.8 | D13: 0.9 | E13: 1 | F13: 1.1
A14: 0.65 | B14: =((((売上前提!$C$20*$A14*売上前提!$E$20*売上前提!$H$20+売上前提!$C$22*$A14*売上前提!$E$22*売上前提!$H$22+売上前提!$C$24*$A14*B$13*売上前提!$H$24)+(売上前提!$J$21+売上前提!$J$23+売上前提!$J$25))*売上前提!$B$5/1000000)*(1-経費前提!$B$20)-経費前提!$B$24-MAX(0,(((売上前提!$C$20*$A14*売上前提!$E$20*売上前提!$H$20+売上前提!$C$22*$A14*売上前提!$E$22*売上前提!$H$22+売上前提!$C$24*$A14*B$13*売上前提!$H$24)+(売上前提!$J$21+売上前提!$J$23+売上前提!$J$25))*売上前提!$B$5/1000000)-経費前提!$B$26)*経費前提!$B$25-経費前提!$B$38) -> 19.904374 | C14: =((((売上前提!$C$20*$A14*売上前提!$E$20*売上前提!$H$20+売上前提!$C$22*$A14*売上前提!$E$22*売上前提!$H$22+売上前提!$C$24*$A14*C$13*売上前提!$H$24)+(売上前提!$J$21+売上前提!$J$23+売上前提!$J$25))*売上前提!$B$5/1000000)*(1-経費前提!$B$20)-経費前提!$B$24-MAX(0,(((売上前提!$C$20*$A14*売上前提!$E$20*売上前提!$H$20+売上前提!$C$22*$A14*売上前提!$E$22*売上前提!$H$22+売上前提!$C$24*$A14*C$13*売上前提!$H$24)+(売上前提!$J$21+売上前提!$J$23+売上前提!$J$25))*売上前提!$B$5/1000000)-経費前提!$B$26)*経費前提!$B$25-経費前提!$B$38) -> 22.803019 | D14: =((((売上前提!$C$20*$A14*売上前提!$E$20*売上前提!$H$20+売上前提!$C$22*$A14*売上前提!$E$22*売上前提!$H$22+売上前提!$C$24*$A14*D$13*売上前提!$H$24)+(売上前提!$J$21+売上前提!$J$23+売上前提!$J$25))*売上前提!$B$5/1000000)*(1-経費前提!$B$20)-経費前提!$B$24-MAX(0,(((売上前提!$C$20*$A14*売上前提!$E$20*売上前提!$H$20+売上前提!$C$22*$A14*売上前提!$E$22*売上前提!$H$22+売上前提!$C$24*$A14*D$13*売上前提!$H$24)+(売上前提!$J$21+売上前提!$J$23+売上前提!$J$25))*売上前提!$B$5/1000000)-経費前提!$B$26)*経費前提!$B$25-経費前提!$B$38) -> 25.701665 | E14: =((((売上前提!$C$20*$A14*売上前提!$E$20*売上前提!$H$20+売上前提!$C$22*$A14*売上前提!$E$22*売上前提!$H$22+売上前提!$C$24*$A14*E$13*売上前提!$H$24)+(売上前提!$J$21+売上前提!$J$23+売上前提!$J$25))*売上前提!$B$5/1000000)*(1-経費前提!$B$20)-経費前提!$B$24-MAX(0,(((売上前提!$C$20*$A14*売上前提!$E$20*売上前提!$H$20+売上前提!$C$22*$A14*売上前提!$E$22*売上前提!$H$22+売上前提!$C$24*$A14*E$13*売上前提!$H$24)+(売上前提!$J$21+売上前提!$J$23+売上前提!$J$25))*売上前提!$B$5/1000000)-経費前提!$B$26)*経費前提!$B$25-経費前提!$B$38) -> 28.600311 | F14: =((((売上前提!$C$20*$A14*売上前提!$E$20*売上前提!$H$20+売上前提!$C$22*$A14*売上前提!$E$22*売上前提!$H$22+売上前提!$C$24*$A14*F$13*売上前提!$H$24)+(売上前提!$J$21+売上前提!$J$23+売上前提!$J$25))*売上前提!$B$5/1000000)*(1-経費前提!$B$20)-経費前提!$B$24-MAX(0,(((売上前提!$C$20*$A14*売上前提!$E$20*売上前提!$H$20+売上前提!$C$22*$A14*売上前提!$E$22*売上前提!$H$22+売上前提!$C$24*$A14*F$13*売上前提!$H$24)+(売上前提!$J$21+売上前提!$J$23+売上前提!$J$25))*売上前提!$B$5/1000000)-経費前提!$B$26)*経費前提!$B$25-経費前提!$B$38) -> 31.498957
A15: 0.7 | B15: =((((売上前提!$C$20*$A15*売上前提!$E$20*売上前提!$H$20+売上前提!$C$22*$A15*売上前提!$E$22*売上前提!$H$22+売上前提!$C$24*$A15*B$13*売上前提!$H$24)+(売上前提!$J$21+売上前提!$J$23+売上前提!$J$25))*売上前提!$B$5/1000000)*(1-経費前提!$B$20)-経費前提!$B$24-MAX(0,(((売上前提!$C$20*$A15*売上前提!$E$20*売上前提!$H$20+売上前提!$C$22*$A15*売上前提!$E$22*売上前提!$H$22+売上前提!$C$24*$A15*B$13*売上前提!$H$24)+(売上前提!$J$21+売上前提!$J$23+売上前提!$J$25))*売上前提!$B$5/1000000)-経費前提!$B$26)*経費前提!$B$25-経費前提!$B$38) -> 22.334777 | C15: =((((売上前提!$C$20*$A15*売上前提!$E$20*売上前提!$H$20+売上前提!$C$22*$A15*売上前提!$E$22*売上前提!$H$22+売上前提!$C$24*$A15*C$13*売上前提!$H$24)+(売上前提!$J$21+売上前提!$J$23+売上前提!$J$25))*売上前提!$B$5/1000000)*(1-経費前提!$B$20)-経費前提!$B$24-MAX(0,(((売上前提!$C$20*$A15*売上前提!$E$20*売上前提!$H$20+売上前提!$C$22*$A15*売上前提!$E$22*売上前提!$H$22+売上前提!$C$24*$A15*C$13*売上前提!$H$24)+(売上前提!$J$21+売上前提!$J$23+売上前提!$J$25))*売上前提!$B$5/1000000)-経費前提!$B$26)*経費前提!$B$25-経費前提!$B$38) -> 25.456395 | D15: =((((売上前提!$C$20*$A15*売上前提!$E$20*売上前提!$H$20+売上前提!$C$22*$A15*売上前提!$E$22*売上前提!$H$22+売上前提!$C$24*$A15*D$13*売上前提!$H$24)+(売上前提!$J$21+売上前提!$J$23+売上前提!$J$25))*売上前提!$B$5/1000000)*(1-経費前提!$B$20)-経費前提!$B$24-MAX(0,(((売上前提!$C$20*$A15*売上前提!$E$20*売上前提!$H$20+売上前提!$C$22*$A15*売上前提!$E$22*売上前提!$H$22+売上前提!$C$24*$A15*D$13*売上前提!$H$24)+(売上前提!$J$21+売上前提!$J$23+売上前提!$J$25))*売上前提!$B$5/1000000)-経費前提!$B$26)*経費前提!$B$25-経費前提!$B$38) -> 28.578014 | E15: =((((売上前提!$C$20*$A15*売上前提!$E$20*売上前提!$H$20+売上前提!$C$22*$A15*売上前提!$E$22*売上前提!$H$22+売上前提!$C$24*$A15*E$13*売上前提!$H$24)+(売上前提!$J$21+売上前提!$J$23+売上前提!$J$25))*売上前提!$B$5/1000000)*(1-経費前提!$B$20)-経費前提!$B$24-MAX(0,(((売上前提!$C$20*$A15*売上前提!$E$20*売上前提!$H$20+売上前提!$C$22*$A15*売上前提!$E$22*売上前提!$H$22+売上前提!$C$24*$A15*E$13*売上前提!$H$24)+(売上前提!$J$21+売上前提!$J$23+売上前提!$J$25))*売上前提!$B$5/1000000)-経費前提!$B$26)*経費前提!$B$25-経費前提!$B$38) -> 31.699632 | F15: =((((売上前提!$C$20*$A15*売上前提!$E$20*売上前提!$H$20+売上前提!$C$22*$A15*売上前提!$E$22*売上前提!$H$22+売上前提!$C$24*$A15*F$13*売上前提!$H$24)+(売上前提!$J$21+売上前提!$J$23+売上前提!$J$25))*売上前提!$B$5/1000000)*(1-経費前提!$B$20)-経費前提!$B$24-MAX(0,(((売上前提!$C$20*$A15*売上前提!$E$20*売上前提!$H$20+売上前提!$C$22*$A15*売上前提!$E$22*売上前提!$H$22+売上前提!$C$24*$A15*F$13*売上前提!$H$24)+(売上前提!$J$21+売上前提!$J$23+売上前提!$J$25))*売上前提!$B$5/1000000)-経費前提!$B$26)*経費前提!$B$25-経費前提!$B$38) -> 34.821251
A16: 0.75 | B16: =((((売上前提!$C$20*$A16*売上前提!$E$20*売上前提!$H$20+売上前提!$C$22*$A16*売上前提!$E$22*売上前提!$H$22+売上前提!$C$24*$A16*B$13*売上前提!$H$24)+(売上前提!$J$21+売上前提!$J$23+売上前提!$J$25))*売上前提!$B$5/1000000)*(1-経費前提!$B$20)-経費前提!$B$24-MAX(0,(((売上前提!$C$20*$A16*売上前提!$E$20*売上前提!$H$20+売上前提!$C$22*$A16*売上前提!$E$22*売上前提!$H$22+売上前提!$C$24*$A16*B$13*売上前提!$H$24)+(売上前提!$J$21+売上前提!$J$23+売上前提!$J$25))*売上前提!$B$5/1000000)-経費前提!$B$26)*経費前提!$B$25-経費前提!$B$38) -> 24.76518 | C16: =((((売上前提!$C$20*$A16*売上前提!$E$20*売上前提!$H$20+売上前提!$C$22*$A16*売上前提!$E$22*売上前提!$H$22+売上前提!$C$24*$A16*C$13*売上前提!$H$24)+(売上前提!$J$21+売上前提!$J$23+売上前提!$J$25))*売上前提!$B$5/1000000)*(1-経費前提!$B$20)-経費前提!$B$24-MAX(0,(((売上前提!$C$20*$A16*売上前提!$E$20*売上前提!$H$20+売上前提!$C$22*$A16*売上前提!$E$22*売上前提!$H$22+売上前提!$C$24*$A16*C$13*売上前提!$H$24)+(売上前提!$J$21+売上前提!$J$23+売上前提!$J$25))*売上前提!$B$5/1000000)-経費前提!$B$26)*経費前提!$B$25-経費前提!$B$38) -> 28.109771 | D16: =((((売上前提!$C$20*$A16*売上前提!$E$20*売上前提!$H$20+売上前提!$C$22*$A16*売上前提!$E$22*売上前提!$H$22+売上前提!$C$24*$A16*D$13*売上前提!$H$24)+(売上前提!$J$21+売上前提!$J$23+売上前提!$J$25))*売上前提!$B$5/1000000)*(1-経費前提!$B$20)-経費前提!$B$24-MAX(0,(((売上前提!$C$20*$A16*売上前提!$E$20*売上前提!$H$20+売上前提!$C$22*$A16*売上前提!$E$22*売上前提!$H$22+売上前提!$C$24*$A16*D$13*売上前提!$H$24)+(売上前提!$J$21+売上前提!$J$23+売上前提!$J$25))*売上前提!$B$5/1000000)-経費前提!$B$26)*経費前提!$B$25-経費前提!$B$38) -> 31.454362 | E16: =((((売上前提!$C$20*$A16*売上前提!$E$20*売上前提!$H$20+売上前提!$C$22*$A16*売上前提!$E$22*売上前提!$H$22+売上前提!$C$24*$A16*E$13*売上前提!$H$24)+(売上前提!$J$21+売上前提!$J$23+売上前提!$J$25))*売上前提!$B$5/1000000)*(1-経費前提!$B$20)-経費前提!$B$24-MAX(0,(((売上前提!$C$20*$A16*売上前提!$E$20*売上前提!$H$20+売上前提!$C$22*$A16*売上前提!$E$22*売上前提!$H$22+売上前提!$C$24*$A16*E$13*売上前提!$H$24)+(売上前提!$J$21+売上前提!$J$23+売上前提!$J$25))*売上前提!$B$5/1000000)-経費前提!$B$26)*経費前提!$B$25-経費前提!$B$38) -> 34.798953 | F16: =((((売上前提!$C$20*$A16*売上前提!$E$20*売上前提!$H$20+売上前提!$C$22*$A16*売上前提!$E$22*売上前提!$H$22+売上前提!$C$24*$A16*F$13*売上前提!$H$24)+(売上前提!$J$21+売上前提!$J$23+売上前提!$J$25))*売上前提!$B$5/1000000)*(1-経費前提!$B$20)-経費前提!$B$24-MAX(0,(((売上前提!$C$20*$A16*売上前提!$E$20*売上前提!$H$20+売上前提!$C$22*$A16*売上前提!$E$22*売上前提!$H$22+売上前提!$C$24*$A16*F$13*売上前提!$H$24)+(売上前提!$J$21+売上前提!$J$23+売上前提!$J$25))*売上前提!$B$5/1000000)-経費前提!$B$26)*経費前提!$B$25-経費前提!$B$38) -> 38.143545
A17: 0.8 | B17: =((((売上前提!$C$20*$A17*売上前提!$E$20*売上前提!$H$20+売上前提!$C$22*$A17*売上前提!$E$22*売上前提!$H$22+売上前提!$C$24*$A17*B$13*売上前提!$H$24)+(売上前提!$J$21+売上前提!$J$23+売上前提!$J$25))*売上前提!$B$5/1000000)*(1-経費前提!$B$20)-経費前提!$B$24-MAX(0,(((売上前提!$C$20*$A17*売上前提!$E$20*売上前提!$H$20+売上前提!$C$22*$A17*売上前提!$E$22*売上前提!$H$22+売上前提!$C$24*$A17*B$13*売上前提!$H$24)+(売上前提!$J$21+売上前提!$J$23+売上前提!$J$25))*売上前提!$B$5/1000000)-経費前提!$B$26)*経費前提!$B$25-経費前提!$B$38) -> 27.195583 | C17: =((((売上前提!$C$20*$A17*売上前提!$E$20*売上前提!$H$20+売上前提!$C$22*$A17*売上前提!$E$22*売上前提!$H$22+売上前提!$C$24*$A17*C$13*売上前提!$H$24)+(売上前提!$J$21+売上前提!$J$23+売上前提!$J$25))*売上前提!$B$5/1000000)*(1-経費前提!$B$20)-経費前提!$B$24-MAX(0,(((売上前提!$C$20*$A17*売上前提!$E$20*売上前提!$H$20+売上前提!$C$22*$A17*売上前提!$E$22*売上前提!$H$22+売上前提!$C$24*$A17*C$13*売上前提!$H$24)+(売上前提!$J$21+売上前提!$J$23+売上前提!$J$25))*売上前提!$B$5/1000000)-経費前提!$B$26)*経費前提!$B$25-経費前提!$B$38) -> 30.763147 | D17: =((((売上前提!$C$20*$A17*売上前提!$E$20*売上前提!$H$20+売上前提!$C$22*$A17*売上前提!$E$22*売上前提!$H$22+売上前提!$C$24*$A17*D$13*売上前提!$H$24)+(売上前提!$J$21+売上前提!$J$23+売上前提!$J$25))*売上前提!$B$5/1000000)*(1-経費前提!$B$20)-経費前提!$B$24-MAX(0,(((売上前提!$C$20*$A17*売上前提!$E$20*売上前提!$H$20+売上前提!$C$22*$A17*売上前提!$E$22*売上前提!$H$22+売上前提!$C$24*$A17*D$13*売上前提!$H$24)+(売上前提!$J$21+売上前提!$J$23+売上前提!$J$25))*売上前提!$B$5/1000000)-経費前提!$B$26)*経費前提!$B$25-経費前提!$B$38) -> 34.330711 | E17: =((((売上前提!$C$20*$A17*売上前提!$E$20*売上前提!$H$20+売上前提!$C$22*$A17*売上前提!$E$22*売上前提!$H$22+売上前提!$C$24*$A17*E$13*売上前提!$H$24)+(売上前提!$J$21+売上前提!$J$23+売上前提!$J$25))*売上前提!$B$5/1000000)*(1-経費前提!$B$20)-経費前提!$B$24-MAX(0,(((売上前提!$C$20*$A17*売上前提!$E$20*売上前提!$H$20+売上前提!$C$22*$A17*売上前提!$E$22*売上前提!$H$22+売上前提!$C$24*$A17*E$13*売上前提!$H$24)+(売上前提!$J$21+売上前提!$J$23+売上前提!$J$25))*売上前提!$B$5/1000000)-経費前提!$B$26)*経費前提!$B$25-経費前提!$B$38) -> 37.898275 | F17: =((((売上前提!$C$20*$A17*売上前提!$E$20*売上前提!$H$20+売上前提!$C$22*$A17*売上前提!$E$22*売上前提!$H$22+売上前提!$C$24*$A17*F$13*売上前提!$H$24)+(売上前提!$J$21+売上前提!$J$23+売上前提!$J$25))*売上前提!$B$5/1000000)*(1-経費前提!$B$20)-経費前提!$B$24-MAX(0,(((売上前提!$C$20*$A17*売上前提!$E$20*売上前提!$H$20+売上前提!$C$22*$A17*売上前提!$E$22*売上前提!$H$22+売上前提!$C$24*$A17*F$13*売上前提!$H$24)+(売上前提!$J$21+売上前提!$J$23+売上前提!$J$25))*売上前提!$B$5/1000000)-経費前提!$B$26)*経費前提!$B$25-経費前提!$B$38) -> 41.465839
A18: 0.85 | B18: =((((売上前提!$C$20*$A18*売上前提!$E$20*売上前提!$H$20+売上前提!$C$22*$A18*売上前提!$E$22*売上前提!$H$22+売上前提!$C$24*$A18*B$13*売上前提!$H$24)+(売上前提!$J$21+売上前提!$J$23+売上前提!$J$25))*売上前提!$B$5/1000000)*(1-経費前提!$B$20)-経費前提!$B$24-MAX(0,(((売上前提!$C$20*$A18*売上前提!$E$20*売上前提!$H$20+売上前提!$C$22*$A18*売上前提!$E$22*売上前提!$H$22+売上前提!$C$24*$A18*B$13*売上前提!$H$24)+(売上前提!$J$21+売上前提!$J$23+売上前提!$J$25))*売上前提!$B$5/1000000)-経費前提!$B$26)*経費前提!$B$25-経費前提!$B$38) -> 29.625986 | C18: =((((売上前提!$C$20*$A18*売上前提!$E$20*売上前提!$H$20+売上前提!$C$22*$A18*売上前提!$E$22*売上前提!$H$22+売上前提!$C$24*$A18*C$13*売上前提!$H$24)+(売上前提!$J$21+売上前提!$J$23+売上前提!$J$25))*売上前提!$B$5/1000000)*(1-経費前提!$B$20)-経費前提!$B$24-MAX(0,(((売上前提!$C$20*$A18*売上前提!$E$20*売上前提!$H$20+売上前提!$C$22*$A18*売上前提!$E$22*売上前提!$H$22+売上前提!$C$24*$A18*C$13*売上前提!$H$24)+(売上前提!$J$21+売上前提!$J$23+売上前提!$J$25))*売上前提!$B$5/1000000)-経費前提!$B$26)*経費前提!$B$25-経費前提!$B$38) -> 33.416522 | D18: =((((売上前提!$C$20*$A18*売上前提!$E$20*売上前提!$H$20+売上前提!$C$22*$A18*売上前提!$E$22*売上前提!$H$22+売上前提!$C$24*$A18*D$13*売上前提!$H$24)+(売上前提!$J$21+売上前提!$J$23+売上前提!$J$25))*売上前提!$B$5/1000000)*(1-経費前提!$B$20)-経費前提!$B$24-MAX(0,(((売上前提!$C$20*$A18*売上前提!$E$20*売上前提!$H$20+売上前提!$C$22*$A18*売上前提!$E$22*売上前提!$H$22+売上前提!$C$24*$A18*D$13*売上前提!$H$24)+(売上前提!$J$21+売上前提!$J$23+売上前提!$J$25))*売上前提!$B$5/1000000)-経費前提!$B$26)*経費前提!$B$25-経費前提!$B$38) -> 37.207059 | E18: =((((売上前提!$C$20*$A18*売上前提!$E$20*売上前提!$H$20+売上前提!$C$22*$A18*売上前提!$E$22*売上前提!$H$22+売上前提!$C$24*$A18*E$13*売上前提!$H$24)+(売上前提!$J$21+売上前提!$J$23+売上前提!$J$25))*売上前提!$B$5/1000000)*(1-経費前提!$B$20)-経費前提!$B$24-MAX(0,(((売上前提!$C$20*$A18*売上前提!$E$20*売上前提!$H$20+売上前提!$C$22*$A18*売上前提!$E$22*売上前提!$H$22+売上前提!$C$24*$A18*E$13*売上前提!$H$24)+(売上前提!$J$21+売上前提!$J$23+売上前提!$J$25))*売上前提!$B$5/1000000)-経費前提!$B$26)*経費前提!$B$25-経費前提!$B$38) -> 40.997596 | F18: =((((売上前提!$C$20*$A18*売上前提!$E$20*売上前提!$H$20+売上前提!$C$22*$A18*売上前提!$E$22*売上前提!$H$22+売上前提!$C$24*$A18*F$13*売上前提!$H$24)+(売上前提!$J$21+売上前提!$J$23+売上前提!$J$25))*売上前提!$B$5/1000000)*(1-経費前提!$B$20)-経費前提!$B$24-MAX(0,(((売上前提!$C$20*$A18*売上前提!$E$20*売上前提!$H$20+売上前提!$C$22*$A18*売上前提!$E$22*売上前提!$H$22+売上前提!$C$24*$A18*F$13*売上前提!$H$24)+(売上前提!$J$21+売上前提!$J$23+売上前提!$J$25))*売上前提!$B$5/1000000)-経費前提!$B$26)*経費前提!$B$25-経費前提!$B$38) -> 44.788133
A20: ■ 営業利益率
A21: 店内席効率 ＼ ディナー回転率 | B21: 0.7 | C21: 0.8 | D21: 0.9 | E21: 1 | F21: 1.1
A22: 0.65 | B22: =IF((((売上前提!$C$20*$A22*売上前提!$E$20*売上前提!$H$20+売上前提!$C$22*$A22*売上前提!$E$22*売上前提!$H$22+売上前提!$C$24*$A22*B$21*売上前提!$H$24)+(売上前提!$J$21+売上前提!$J$23+売上前提!$J$25))*売上前提!$B$5/1000000)=0,0,((((売上前提!$C$20*$A22*売上前提!$E$20*売上前提!$H$20+売上前提!$C$22*$A22*売上前提!$E$22*売上前提!$H$22+売上前提!$C$24*$A22*B$21*売上前提!$H$24)+(売上前提!$J$21+売上前提!$J$23+売上前提!$J$25))*売上前提!$B$5/1000000)*(1-経費前提!$B$20)-経費前提!$B$24-MAX(0,(((売上前提!$C$20*$A22*売上前提!$E$20*売上前提!$H$20+売上前提!$C$22*$A22*売上前提!$E$22*売上前提!$H$22+売上前提!$C$24*$A22*B$21*売上前提!$H$24)+(売上前提!$J$21+売上前提!$J$23+売上前提!$J$25))*売上前提!$B$5/1000000)-経費前提!$B$26)*経費前提!$B$25-経費前提!$B$38)/(((売上前提!$C$20*$A22*売上前提!$E$20*売上前提!$H$20+売上前提!$C$22*$A22*売上前提!$E$22*売上前提!$H$22+売上前提!$C$24*$A22*B$21*売上前提!$H$24)+(売上前提!$J$21+売上前提!$J$23+売上前提!$J$25))*売上前提!$B$5/1000000)) -> 0.058580215 | C22: =IF((((売上前提!$C$20*$A22*売上前提!$E$20*売上前提!$H$20+売上前提!$C$22*$A22*売上前提!$E$22*売上前提!$H$22+売上前提!$C$24*$A22*C$21*売上前提!$H$24)+(売上前提!$J$21+売上前提!$J$23+売上前提!$J$25))*売上前提!$B$5/1000000)=0,0,((((売上前提!$C$20*$A22*売上前提!$E$20*売上前提!$H$20+売上前提!$C$22*$A22*売上前提!$E$22*売上前提!$H$22+売上前提!$C$24*$A22*C$21*売上前提!$H$24)+(売上前提!$J$21+売上前提!$J$23+売上前提!$J$25))*売上前提!$B$5/1000000)*(1-経費前提!$B$20)-経費前提!$B$24-MAX(0,(((売上前提!$C$20*$A22*売上前提!$E$20*売上前提!$H$20+売上前提!$C$22*$A22*売上前提!$E$22*売上前提!$H$22+売上前提!$C$24*$A22*C$21*売上前提!$H$24)+(売上前提!$J$21+売上前提!$J$23+売上前提!$J$25))*売上前提!$B$5/1000000)-経費前提!$B$26)*経費前提!$B$25-経費前提!$B$38)/(((売上前提!$C$20*$A22*売上前提!$E$20*売上前提!$H$20+売上前提!$C$22*$A22*売上前提!$E$22*売上前提!$H$22+売上前提!$C$24*$A22*C$21*売上前提!$H$24)+(売上前提!$J$21+売上前提!$J$23+売上前提!$J$25))*売上前提!$B$5/1000000)) -> 0.062978358 | D22: =IF((((売上前提!$C$20*$A22*売上前提!$E$20*売上前提!$H$20+売上前提!$C$22*$A22*売上前提!$E$22*売上前提!$H$22+売上前提!$C$24*$A22*D$21*売上前提!$H$24)+(売上前提!$J$21+売上前提!$J$23+売上前提!$J$25))*売上前提!$B$5/1000000)=0,0,((((売上前提!$C$20*$A22*売上前提!$E$20*売上前提!$H$20+売上前提!$C$22*$A22*売上前提!$E$22*売上前提!$H$22+売上前提!$C$24*$A22*D$21*売上前提!$H$24)+(売上前提!$J$21+売上前提!$J$23+売上前提!$J$25))*売上前提!$B$5/1000000)*(1-経費前提!$B$20)-経費前提!$B$24-MAX(0,(((売上前提!$C$20*$A22*売上前提!$E$20*売上前提!$H$20+売上前提!$C$22*$A22*売上前提!$E$22*売上前提!$H$22+売上前提!$C$24*$A22*D$21*売上前提!$H$24)+(売上前提!$J$21+売上前提!$J$23+売上前提!$J$25))*売上前提!$B$5/1000000)-経費前提!$B$26)*経費前提!$B$25-経費前提!$B$38)/(((売上前提!$C$20*$A22*売上前提!$E$20*売上前提!$H$20+売上前提!$C$22*$A22*売上前提!$E$22*売上前提!$H$22+売上前提!$C$24*$A22*D$21*売上前提!$H$24)+(売上前提!$J$21+売上前提!$J$23+売上前提!$J$25))*売上前提!$B$5/1000000)) -> 0.066866234 | E22: =IF((((売上前提!$C$20*$A22*売上前提!$E$20*売上前提!$H$20+売上前提!$C$22*$A22*売上前提!$E$22*売上前提!$H$22+売上前提!$C$24*$A22*E$21*売上前提!$H$24)+(売上前提!$J$21+売上前提!$J$23+売上前提!$J$25))*売上前提!$B$5/1000000)=0,0,((((売上前提!$C$20*$A22*売上前提!$E$20*売上前提!$H$20+売上前提!$C$22*$A22*売上前提!$E$22*売上前提!$H$22+売上前提!$C$24*$A22*E$21*売上前提!$H$24)+(売上前提!$J$21+売上前提!$J$23+売上前提!$J$25))*売上前提!$B$5/1000000)*(1-経費前提!$B$20)-経費前提!$B$24-MAX(0,(((売上前提!$C$20*$A22*売上前提!$E$20*売上前提!$H$20+売上前提!$C$22*$A22*売上前提!$E$22*売上前提!$H$22+売上前提!$C$24*$A22*E$21*売上前提!$H$24)+(売上前提!$J$21+売上前提!$J$23+売上前提!$J$25))*売上前提!$B$5/1000000)-経費前提!$B$26)*経費前提!$B$25-経費前提!$B$38)/(((売上前提!$C$20*$A22*売上前提!$E$20*売上前提!$H$20+売上前提!$C$22*$A22*売上前提!$E$22*売上前提!$H$22+売上前提!$C$24*$A22*E$21*売上前提!$H$24)+(売上前提!$J$21+売上前提!$J$23+売上前提!$J$25))*売上前提!$B$5/1000000)) -> 0.070327776 | F22: =IF((((売上前提!$C$20*$A22*売上前提!$E$20*売上前提!$H$20+売上前提!$C$22*$A22*売上前提!$E$22*売上前提!$H$22+売上前提!$C$24*$A22*F$21*売上前提!$H$24)+(売上前提!$J$21+売上前提!$J$23+売上前提!$J$25))*売上前提!$B$5/1000000)=0,0,((((売上前提!$C$20*$A22*売上前提!$E$20*売上前提!$H$20+売上前提!$C$22*$A22*売上前提!$E$22*売上前提!$H$22+売上前提!$C$24*$A22*F$21*売上前提!$H$24)+(売上前提!$J$21+売上前提!$J$23+売上前提!$J$25))*売上前提!$B$5/1000000)*(1-経費前提!$B$20)-経費前提!$B$24-MAX(0,(((売上前提!$C$20*$A22*売上前提!$E$20*売上前提!$H$20+売上前提!$C$22*$A22*売上前提!$E$22*売上前提!$H$22+売上前提!$C$24*$A22*F$21*売上前提!$H$24)+(売上前提!$J$21+売上前提!$J$23+売上前提!$J$25))*売上前提!$B$5/1000000)-経費前提!$B$26)*経費前提!$B$25-経費前提!$B$38)/(((売上前提!$C$20*$A22*売上前提!$E$20*売上前提!$H$20+売上前提!$C$22*$A22*売上前提!$E$22*売上前提!$H$22+売上前提!$C$24*$A22*F$21*売上前提!$H$24)+(売上前提!$J$21+売上前提!$J$23+売上前提!$J$25))*売上前提!$B$5/1000000)) -> 0.073429465
A23: 0.7 | B23: =IF((((売上前提!$C$20*$A23*売上前提!$E$20*売上前提!$H$20+売上前提!$C$22*$A23*売上前提!$E$22*売上前提!$H$22+売上前提!$C$24*$A23*B$21*売上前提!$H$24)+(売上前提!$J$21+売上前提!$J$23+売上前提!$J$25))*売上前提!$B$5/1000000)=0,0,((((売上前提!$C$20*$A23*売上前提!$E$20*売上前提!$H$20+売上前提!$C$22*$A23*売上前提!$E$22*売上前提!$H$22+売上前提!$C$24*$A23*B$21*売上前提!$H$24)+(売上前提!$J$21+売上前提!$J$23+売上前提!$J$25))*売上前提!$B$5/1000000)*(1-経費前提!$B$20)-経費前提!$B$24-MAX(0,(((売上前提!$C$20*$A23*売上前提!$E$20*売上前提!$H$20+売上前提!$C$22*$A23*売上前提!$E$22*売上前提!$H$22+売上前提!$C$24*$A23*B$21*売上前提!$H$24)+(売上前提!$J$21+売上前提!$J$23+売上前提!$J$25))*売上前提!$B$5/1000000)-経費前提!$B$26)*経費前提!$B$25-経費前提!$B$38)/(((売上前提!$C$20*$A23*売上前提!$E$20*売上前提!$H$20+売上前提!$C$22*$A23*売上前提!$E$22*売上前提!$H$22+売上前提!$C$24*$A23*B$21*売上前提!$H$24)+(売上前提!$J$21+売上前提!$J$23+売上前提!$J$25))*売上前提!$B$5/1000000)) -> 0.062304941 | C23: =IF((((売上前提!$C$20*$A23*売上前提!$E$20*売上前提!$H$20+売上前提!$C$22*$A23*売上前提!$E$22*売上前提!$H$22+売上前提!$C$24*$A23*C$21*売上前提!$H$24)+(売上前提!$J$21+売上前提!$J$23+売上前提!$J$25))*売上前提!$B$5/1000000)=0,0,((((売上前提!$C$20*$A23*売上前提!$E$20*売上前提!$H$20+売上前提!$C$22*$A23*売上前提!$E$22*売上前提!$H$22+売上前提!$C$24*$A23*C$21*売上前提!$H$24)+(売上前提!$J$21+売上前提!$J$23+売上前提!$J$25))*売上前提!$B$5/1000000)*(1-経費前提!$B$20)-経費前提!$B$24-MAX(0,(((売上前提!$C$20*$A23*売上前提!$E$20*売上前提!$H$20+売上前提!$C$22*$A23*売上前提!$E$22*売上前提!$H$22+売上前提!$C$24*$A23*C$21*売上前提!$H$24)+(売上前提!$J$21+売上前提!$J$23+売上前提!$J$25))*売上前提!$B$5/1000000)-経費前提!$B$26)*経費前提!$B$25-経費前提!$B$38)/(((売上前提!$C$20*$A23*売上前提!$E$20*売上前提!$H$20+売上前提!$C$22*$A23*売上前提!$E$22*売上前提!$H$22+売上前提!$C$24*$A23*C$21*売上前提!$H$24)+(売上前提!$J$21+売上前提!$J$23+売上前提!$J$25))*売上前提!$B$5/1000000)) -> 0.066554815 | D23: =IF((((売上前提!$C$20*$A23*売上前提!$E$20*売上前提!$H$20+売上前提!$C$22*$A23*売上前提!$E$22*売上前提!$H$22+売上前提!$C$24*$A23*D$21*売上前提!$H$24)+(売上前提!$J$21+売上前提!$J$23+売上前提!$J$25))*売上前提!$B$5/1000000)=0,0,((((売上前提!$C$20*$A23*売上前提!$E$20*売上前提!$H$20+売上前提!$C$22*$A23*売上前提!$E$22*売上前提!$H$22+売上前提!$C$24*$A23*D$21*売上前提!$H$24)+(売上前提!$J$21+売上前提!$J$23+売上前提!$J$25))*売上前提!$B$5/1000000)*(1-経費前提!$B$20)-経費前提!$B$24-MAX(0,(((売上前提!$C$20*$A23*売上前提!$E$20*売上前提!$H$20+売上前提!$C$22*$A23*売上前提!$E$22*売上前提!$H$22+売上前提!$C$24*$A23*D$21*売上前提!$H$24)+(売上前提!$J$21+売上前提!$J$23+売上前提!$J$25))*売上前提!$B$5/1000000)-経費前提!$B$26)*経費前提!$B$25-経費前提!$B$38)/(((売上前提!$C$20*$A23*売上前提!$E$20*売上前提!$H$20+売上前提!$C$22*$A23*売上前提!$E$22*売上前提!$H$22+売上前提!$C$24*$A23*D$21*売上前提!$H$24)+(売上前提!$J$21+売上前提!$J$23+売上前提!$J$25))*売上前提!$B$5/1000000)) -> 0.070302598 | E23: =IF((((売上前提!$C$20*$A23*売上前提!$E$20*売上前提!$H$20+売上前提!$C$22*$A23*売上前提!$E$22*売上前提!$H$22+売上前提!$C$24*$A23*E$21*売上前提!$H$24)+(売上前提!$J$21+売上前提!$J$23+売上前提!$J$25))*売上前提!$B$5/1000000)=0,0,((((売上前提!$C$20*$A23*売上前提!$E$20*売上前提!$H$20+売上前提!$C$22*$A23*売上前提!$E$22*売上前提!$H$22+売上前提!$C$24*$A23*E$21*売上前提!$H$24)+(売上前提!$J$21+売上前提!$J$23+売上前提!$J$25))*売上前提!$B$5/1000000)*(1-経費前提!$B$20)-経費前提!$B$24-MAX(0,(((売上前提!$C$20*$A23*売上前提!$E$20*売上前提!$H$20+売上前提!$C$22*$A23*売上前提!$E$22*売上前提!$H$22+売上前提!$C$24*$A23*E$21*売上前提!$H$24)+(売上前提!$J$21+売上前提!$J$23+売上前提!$J$25))*売上前提!$B$5/1000000)-経費前提!$B$26)*経費前提!$B$25-経費前提!$B$38)/(((売上前提!$C$20*$A23*売上前提!$E$20*売上前提!$H$20+売上前提!$C$22*$A23*売上前提!$E$22*売上前提!$H$22+売上前提!$C$24*$A23*E$21*売上前提!$H$24)+(売上前提!$J$21+売上前提!$J$23+売上前提!$J$25))*売上前提!$B$5/1000000)) -> 0.073632306 | F23: =IF((((売上前提!$C$20*$A23*売上前提!$E$20*売上前提!$H$20+売上前提!$C$22*$A23*売上前提!$E$22*売上前提!$H$22+売上前提!$C$24*$A23*F$21*売上前提!$H$24)+(売上前提!$J$21+売上前提!$J$23+売上前提!$J$25))*売上前提!$B$5/1000000)=0,0,((((売上前提!$C$20*$A23*売上前提!$E$20*売上前提!$H$20+売上前提!$C$22*$A23*売上前提!$E$22*売上前提!$H$22+売上前提!$C$24*$A23*F$21*売上前提!$H$24)+(売上前提!$J$21+売上前提!$J$23+売上前提!$J$25))*売上前提!$B$5/1000000)*(1-経費前提!$B$20)-経費前提!$B$24-MAX(0,(((売上前提!$C$20*$A23*売上前提!$E$20*売上前提!$H$20+売上前提!$C$22*$A23*売上前提!$E$22*売上前提!$H$22+売上前提!$C$24*$A23*F$21*売上前提!$H$24)+(売上前提!$J$21+売上前提!$J$23+売上前提!$J$25))*売上前提!$B$5/1000000)-経費前提!$B$26)*経費前提!$B$25-経費前提!$B$38)/(((売上前提!$C$20*$A23*売上前提!$E$20*売上前提!$H$20+売上前提!$C$22*$A23*売上前提!$E$22*売上前提!$H$22+売上前提!$C$24*$A23*F$21*売上前提!$H$24)+(売上前提!$J$21+売上前提!$J$23+売上前提!$J$25))*売上前提!$B$5/1000000)) -> 0.076610198
A24: 0.75 | B24: =IF((((売上前提!$C$20*$A24*売上前提!$E$20*売上前提!$H$20+売上前提!$C$22*$A24*売上前提!$E$22*売上前提!$H$22+売上前提!$C$24*$A24*B$21*売上前提!$H$24)+(売上前提!$J$21+売上前提!$J$23+売上前提!$J$25))*売上前提!$B$5/1000000)=0,0,((((売上前提!$C$20*$A24*売上前提!$E$20*売上前提!$H$20+売上前提!$C$22*$A24*売上前提!$E$22*売上前提!$H$22+売上前提!$C$24*$A24*B$21*売上前提!$H$24)+(売上前提!$J$21+売上前提!$J$23+売上前提!$J$25))*売上前提!$B$5/1000000)*(1-経費前提!$B$20)-経費前提!$B$24-MAX(0,(((売上前提!$C$20*$A24*売上前提!$E$20*売上前提!$H$20+売上前提!$C$22*$A24*売上前提!$E$22*売上前提!$H$22+売上前提!$C$24*$A24*B$21*売上前提!$H$24)+(売上前提!$J$21+売上前提!$J$23+売上前提!$J$25))*売上前提!$B$5/1000000)-経費前提!$B$26)*経費前提!$B$25-経費前提!$B$38)/(((売上前提!$C$20*$A24*売上前提!$E$20*売上前提!$H$20+売上前提!$C$22*$A24*売上前提!$E$22*売上前提!$H$22+売上前提!$C$24*$A24*B$21*売上前提!$H$24)+(売上前提!$J$21+売上前提!$J$23+売上前提!$J$25))*売上前提!$B$5/1000000)) -> 0.065660417 | C24: =IF((((売上前提!$C$20*$A24*売上前提!$E$20*売上前提!$H$20+売上前提!$C$22*$A24*売上前提!$E$22*売上前提!$H$22+売上前提!$C$24*$A24*C$21*売上前提!$H$24)+(売上前提!$J$21+売上前提!$J$23+売上前提!$J$25))*売上前提!$B$5/1000000)=0,0,((((売上前提!$C$20*$A24*売上前提!$E$20*売上前提!$H$20+売上前提!$C$22*$A24*売上前提!$E$22*売上前提!$H$22+売上前提!$C$24*$A24*C$21*売上前提!$H$24)+(売上前提!$J$21+売上前提!$J$23+売上前提!$J$25))*売上前提!$B$5/1000000)*(1-経費前提!$B$20)-経費前提!$B$24-MAX(0,(((売上前提!$C$20*$A24*売上前提!$E$20*売上前提!$H$20+売上前提!$C$22*$A24*売上前提!$E$22*売上前提!$H$22+売上前提!$C$24*$A24*C$21*売上前提!$H$24)+(売上前提!$J$21+売上前提!$J$23+売上前提!$J$25))*売上前提!$B$5/1000000)-経費前提!$B$26)*経費前提!$B$25-経費前提!$B$38)/(((売上前提!$C$20*$A24*売上前提!$E$20*売上前提!$H$20+売上前提!$C$22*$A24*売上前提!$E$22*売上前提!$H$22+売上前提!$C$24*$A24*C$21*売上前提!$H$24)+(売上前提!$J$21+売上前提!$J$23+売上前提!$J$25))*売上前提!$B$5/1000000)) -> 0.06976891 | D24: =IF((((売上前提!$C$20*$A24*売上前提!$E$20*売上前提!$H$20+売上前提!$C$22*$A24*売上前提!$E$22*売上前提!$H$22+売上前提!$C$24*$A24*D$21*売上前提!$H$24)+(売上前提!$J$21+売上前提!$J$23+売上前提!$J$25))*売上前提!$B$5/1000000)=0,0,((((売上前提!$C$20*$A24*売上前提!$E$20*売上前提!$H$20+売上前提!$C$22*$A24*売上前提!$E$22*売上前提!$H$22+売上前提!$C$24*$A24*D$21*売上前提!$H$24)+(売上前提!$J$21+売上前提!$J$23+売上前提!$J$25))*売上前提!$B$5/1000000)*(1-経費前提!$B$20)-経費前提!$B$24-MAX(0,(((売上前提!$C$20*$A24*売上前提!$E$20*売上前提!$H$20+売上前提!$C$22*$A24*売上前提!$E$22*売上前提!$H$22+売上前提!$C$24*$A24*D$21*売上前提!$H$24)+(売上前提!$J$21+売上前提!$J$23+売上前提!$J$25))*売上前提!$B$5/1000000)-経費前提!$B$26)*経費前提!$B$25-経費前提!$B$38)/(((売上前提!$C$20*$A24*売上前提!$E$20*売上前提!$H$20+売上前提!$C$22*$A24*売上前提!$E$22*売上前提!$H$22+売上前提!$C$24*$A24*D$21*売上前提!$H$24)+(売上前提!$J$21+売上前提!$J$23+売上前提!$J$25))*売上前提!$B$5/1000000)) -> 0.073384191 | E24: =IF((((売上前提!$C$20*$A24*売上前提!$E$20*売上前提!$H$20+売上前提!$C$22*$A24*売上前提!$E$22*売上前提!$H$22+売上前提!$C$24*$A24*E$21*売上前提!$H$24)+(売上前提!$J$21+売上前提!$J$23+売上前提!$J$25))*売上前提!$B$5/1000000)=0,0,((((売上前提!$C$20*$A24*売上前提!$E$20*売上前提!$H$20+売上前提!$C$22*$A24*売上前提!$E$22*売上前提!$H$22+売上前提!$C$24*$A24*E$21*売上前提!$H$24)+(売上前提!$J$21+売上前提!$J$23+売上前提!$J$25))*売上前提!$B$5/1000000)*(1-経費前提!$B$20)-経費前提!$B$24-MAX(0,(((売上前提!$C$20*$A24*売上前提!$E$20*売上前提!$H$20+売上前提!$C$22*$A24*売上前提!$E$22*売上前提!$H$22+売上前提!$C$24*$A24*E$21*売上前提!$H$24)+(売上前提!$J$21+売上前提!$J$23+売上前提!$J$25))*売上前提!$B$5/1000000)-経費前提!$B$26)*経費前提!$B$25-経費前提!$B$38)/(((売上前提!$C$20*$A24*売上前提!$E$20*売上前提!$H$20+売上前提!$C$22*$A24*売上前提!$E$22*売上前提!$H$22+売上前提!$C$24*$A24*E$21*売上前提!$H$24)+(売上前提!$J$21+売上前提!$J$23+売上前提!$J$25))*売上前提!$B$5/1000000)) -> 0.076590044 | F24: =IF((((売上前提!$C$20*$A24*売上前提!$E$20*売上前提!$H$20+売上前提!$C$22*$A24*売上前提!$E$22*売上前提!$H$22+売上前提!$C$24*$A24*F$21*売上前提!$H$24)+(売上前提!$J$21+売上前提!$J$23+売上前提!$J$25))*売上前提!$B$5/1000000)=0,0,((((売上前提!$C$20*$A24*売上前提!$E$20*売上前提!$H$20+売上前提!$C$22*$A24*売上前提!$E$22*売上前提!$H$22+売上前提!$C$24*$A24*F$21*売上前提!$H$24)+(売上前提!$J$21+売上前提!$J$23+売上前提!$J$25))*売上前提!$B$5/1000000)*(1-経費前提!$B$20)-経費前提!$B$24-MAX(0,(((売上前提!$C$20*$A24*売上前提!$E$20*売上前提!$H$20+売上前提!$C$22*$A24*売上前提!$E$22*売上前提!$H$22+売上前提!$C$24*$A24*F$21*売上前提!$H$24)+(売上前提!$J$21+売上前提!$J$23+売上前提!$J$25))*売上前提!$B$5/1000000)-経費前提!$B$26)*経費前提!$B$25-経費前提!$B$38)/(((売上前提!$C$20*$A24*売上前提!$E$20*売上前提!$H$20+売上前提!$C$22*$A24*売上前提!$E$22*売上前提!$H$22+売上前提!$C$24*$A24*F$21*売上前提!$H$24)+(売上前提!$J$21+売上前提!$J$23+売上前提!$J$25))*売上前提!$B$5/1000000)) -> 0.079452292
A25: 0.8 | B25: =IF((((売上前提!$C$20*$A25*売上前提!$E$20*売上前提!$H$20+売上前提!$C$22*$A25*売上前提!$E$22*売上前提!$H$22+売上前提!$C$24*$A25*B$21*売上前提!$H$24)+(売上前提!$J$21+売上前提!$J$23+売上前提!$J$25))*売上前提!$B$5/1000000)=0,0,((((売上前提!$C$20*$A25*売上前提!$E$20*売上前提!$H$20+売上前提!$C$22*$A25*売上前提!$E$22*売上前提!$H$22+売上前提!$C$24*$A25*B$21*売上前提!$H$24)+(売上前提!$J$21+売上前提!$J$23+売上前提!$J$25))*売上前提!$B$5/1000000)*(1-経費前提!$B$20)-経費前提!$B$24-MAX(0,(((売上前提!$C$20*$A25*売上前提!$E$20*売上前提!$H$20+売上前提!$C$22*$A25*売上前提!$E$22*売上前提!$H$22+売上前提!$C$24*$A25*B$21*売上前提!$H$24)+(売上前提!$J$21+売上前提!$J$23+売上前提!$J$25))*売上前提!$B$5/1000000)-経費前提!$B$26)*経費前提!$B$25-経費前提!$B$38)/(((売上前提!$C$20*$A25*売上前提!$E$20*売上前提!$H$20+売上前提!$C$22*$A25*売上前提!$E$22*売上前提!$H$22+売上前提!$C$24*$A25*B$21*売上前提!$H$24)+(売上前提!$J$21+売上前提!$J$23+売上前提!$J$25))*売上前提!$B$5/1000000)) -> 0.068698957 | C25: =IF((((売上前提!$C$20*$A25*売上前提!$E$20*売上前提!$H$20+売上前提!$C$22*$A25*売上前提!$E$22*売上前提!$H$22+売上前提!$C$24*$A25*C$21*売上前提!$H$24)+(売上前提!$J$21+売上前提!$J$23+売上前提!$J$25))*売上前提!$B$5/1000000)=0,0,((((売上前提!$C$20*$A25*売上前提!$E$20*売上前提!$H$20+売上前提!$C$22*$A25*売上前提!$E$22*売上前提!$H$22+売上前提!$C$24*$A25*C$21*売上前提!$H$24)+(売上前提!$J$21+売上前提!$J$23+売上前提!$J$25))*売上前提!$B$5/1000000)*(1-経費前提!$B$20)-経費前提!$B$24-MAX(0,(((売上前提!$C$20*$A25*売上前提!$E$20*売上前提!$H$20+売上前提!$C$22*$A25*売上前提!$E$22*売上前提!$H$22+売上前提!$C$24*$A25*C$21*売上前提!$H$24)+(売上前提!$J$21+売上前提!$J$23+売上前提!$J$25))*売上前提!$B$5/1000000)-経費前提!$B$26)*経費前提!$B$25-経費前提!$B$38)/(((売上前提!$C$20*$A25*売上前提!$E$20*売上前提!$H$20+売上前提!$C$22*$A25*売上前提!$E$22*売上前提!$H$22+売上前提!$C$24*$A25*C$21*売上前提!$H$24)+(売上前提!$J$21+売上前提!$J$23+売上前提!$J$25))*売上前提!$B$5/1000000)) -> 0.072673058 | D25: =IF((((売上前提!$C$20*$A25*売上前提!$E$20*売上前提!$H$20+売上前提!$C$22*$A25*売上前提!$E$22*売上前提!$H$22+売上前提!$C$24*$A25*D$21*売上前提!$H$24)+(売上前提!$J$21+売上前提!$J$23+売上前提!$J$25))*売上前提!$B$5/1000000)=0,0,((((売上前提!$C$20*$A25*売上前提!$E$20*売上前提!$H$20+売上前提!$C$22*$A25*売上前提!$E$22*売上前提!$H$22+売上前提!$C$24*$A25*D$21*売上前提!$H$24)+(売上前提!$J$21+売上前提!$J$23+売上前提!$J$25))*売上前提!$B$5/1000000)*(1-経費前提!$B$20)-経費前提!$B$24-MAX(0,(((売上前提!$C$20*$A25*売上前提!$E$20*売上前提!$H$20+売上前提!$C$22*$A25*売上前提!$E$22*売上前提!$H$22+売上前提!$C$24*$A25*D$21*売上前提!$H$24)+(売上前提!$J$21+売上前提!$J$23+売上前提!$J$25))*売上前提!$B$5/1000000)-経費前提!$B$26)*経費前提!$B$25-経費前提!$B$38)/(((売上前提!$C$20*$A25*売上前提!$E$20*売上前提!$H$20+売上前提!$C$22*$A25*売上前提!$E$22*売上前提!$H$22+売上前提!$C$24*$A25*D$21*売上前提!$H$24)+(売上前提!$J$21+売上前提!$J$23+売上前提!$J$25))*売上前提!$B$5/1000000)) -> 0.076163255 | E25: =IF((((売上前提!$C$20*$A25*売上前提!$E$20*売上前提!$H$20+売上前提!$C$22*$A25*売上前提!$E$22*売上前提!$H$22+売上前提!$C$24*$A25*E$21*売上前提!$H$24)+(売上前提!$J$21+売上前提!$J$23+売上前提!$J$25))*売上前提!$B$5/1000000)=0,0,((((売上前提!$C$20*$A25*売上前提!$E$20*売上前提!$H$20+売上前提!$C$22*$A25*売上前提!$E$22*売上前提!$H$22+売上前提!$C$24*$A25*E$21*売上前提!$H$24)+(売上前提!$J$21+売上前提!$J$23+売上前提!$J$25))*売上前提!$B$5/1000000)*(1-経費前提!$B$20)-経費前提!$B$24-MAX(0,(((売上前提!$C$20*$A25*売上前提!$E$20*売上前提!$H$20+売上前提!$C$22*$A25*売上前提!$E$22*売上前提!$H$22+売上前提!$C$24*$A25*E$21*売上前提!$H$24)+(売上前提!$J$21+売上前提!$J$23+売上前提!$J$25))*売上前提!$B$5/1000000)-経費前提!$B$26)*経費前提!$B$25-経費前提!$B$38)/(((売上前提!$C$20*$A25*売上前提!$E$20*売上前提!$H$20+売上前提!$C$22*$A25*売上前提!$E$22*売上前提!$H$22+売上前提!$C$24*$A25*E$21*売上前提!$H$24)+(売上前提!$J$21+売上前提!$J$23+売上前提!$J$25))*売上前提!$B$5/1000000)) -> 0.079252858 | F25: =IF((((売上前提!$C$20*$A25*売上前提!$E$20*売上前提!$H$20+売上前提!$C$22*$A25*売上前提!$E$22*売上前提!$H$22+売上前提!$C$24*$A25*F$21*売上前提!$H$24)+(売上前提!$J$21+売上前提!$J$23+売上前提!$J$25))*売上前提!$B$5/1000000)=0,0,((((売上前提!$C$20*$A25*売上前提!$E$20*売上前提!$H$20+売上前提!$C$22*$A25*売上前提!$E$22*売上前提!$H$22+売上前提!$C$24*$A25*F$21*売上前提!$H$24)+(売上前提!$J$21+売上前提!$J$23+売上前提!$J$25))*売上前提!$B$5/1000000)*(1-経費前提!$B$20)-経費前提!$B$24-MAX(0,(((売上前提!$C$20*$A25*売上前提!$E$20*売上前提!$H$20+売上前提!$C$22*$A25*売上前提!$E$22*売上前提!$H$22+売上前提!$C$24*$A25*F$21*売上前提!$H$24)+(売上前提!$J$21+売上前提!$J$23+売上前提!$J$25))*売上前提!$B$5/1000000)-経費前提!$B$26)*経費前提!$B$25-経費前提!$B$38)/(((売上前提!$C$20*$A25*売上前提!$E$20*売上前提!$H$20+売上前提!$C$22*$A25*売上前提!$E$22*売上前提!$H$22+売上前提!$C$24*$A25*F$21*売上前提!$H$24)+(売上前提!$J$21+売上前提!$J$23+売上前提!$J$25))*売上前提!$B$5/1000000)) -> 0.082007093
A26: 0.85 | B26: =IF((((売上前提!$C$20*$A26*売上前提!$E$20*売上前提!$H$20+売上前提!$C$22*$A26*売上前提!$E$22*売上前提!$H$22+売上前提!$C$24*$A26*B$21*売上前提!$H$24)+(売上前提!$J$21+売上前提!$J$23+売上前提!$J$25))*売上前提!$B$5/1000000)=0,0,((((売上前提!$C$20*$A26*売上前提!$E$20*売上前提!$H$20+売上前提!$C$22*$A26*売上前提!$E$22*売上前提!$H$22+売上前提!$C$24*$A26*B$21*売上前提!$H$24)+(売上前提!$J$21+売上前提!$J$23+売上前提!$J$25))*売上前提!$B$5/1000000)*(1-経費前提!$B$20)-経費前提!$B$24-MAX(0,(((売上前提!$C$20*$A26*売上前提!$E$20*売上前提!$H$20+売上前提!$C$22*$A26*売上前提!$E$22*売上前提!$H$22+売上前提!$C$24*$A26*B$21*売上前提!$H$24)+(売上前提!$J$21+売上前提!$J$23+売上前提!$J$25))*売上前提!$B$5/1000000)-経費前提!$B$26)*経費前提!$B$25-経費前提!$B$38)/(((売上前提!$C$20*$A26*売上前提!$E$20*売上前提!$H$20+売上前提!$C$22*$A26*売上前提!$E$22*売上前提!$H$22+売上前提!$C$24*$A26*B$21*売上前提!$H$24)+(売上前提!$J$21+売上前提!$J$23+売上前提!$J$25))*売上前提!$B$5/1000000)) -> 0.07146344 | C26: =IF((((売上前提!$C$20*$A26*売上前提!$E$20*売上前提!$H$20+売上前提!$C$22*$A26*売上前提!$E$22*売上前提!$H$22+売上前提!$C$24*$A26*C$21*売上前提!$H$24)+(売上前提!$J$21+売上前提!$J$23+売上前提!$J$25))*売上前提!$B$5/1000000)=0,0,((((売上前提!$C$20*$A26*売上前提!$E$20*売上前提!$H$20+売上前提!$C$22*$A26*売上前提!$E$22*売上前提!$H$22+売上前提!$C$24*$A26*C$21*売上前提!$H$24)+(売上前提!$J$21+売上前提!$J$23+売上前提!$J$25))*売上前提!$B$5/1000000)*(1-経費前提!$B$20)-経費前提!$B$24-MAX(0,(((売上前提!$C$20*$A26*売上前提!$E$20*売上前提!$H$20+売上前提!$C$22*$A26*売上前提!$E$22*売上前提!$H$22+売上前提!$C$24*$A26*C$21*売上前提!$H$24)+(売上前提!$J$21+売上前提!$J$23+売上前提!$J$25))*売上前提!$B$5/1000000)-経費前提!$B$26)*経費前提!$B$25-経費前提!$B$38)/(((売上前提!$C$20*$A26*売上前提!$E$20*売上前提!$H$20+売上前提!$C$22*$A26*売上前提!$E$22*売上前提!$H$22+売上前提!$C$24*$A26*C$21*売上前提!$H$24)+(売上前提!$J$21+売上前提!$J$23+売上前提!$J$25))*売上前提!$B$5/1000000)) -> 0.075310032 | D26: =IF((((売上前提!$C$20*$A26*売上前提!$E$20*売上前提!$H$20+売上前提!$C$22*$A26*売上前提!$E$22*売上前提!$H$22+売上前提!$C$24*$A26*D$21*売上前提!$H$24)+(売上前提!$J$21+売上前提!$J$23+売上前提!$J$25))*売上前提!$B$5/1000000)=0,0,((((売上前提!$C$20*$A26*売上前提!$E$20*売上前提!$H$20+売上前提!$C$22*$A26*売上前提!$E$22*売上前提!$H$22+売上前提!$C$24*$A26*D$21*売上前提!$H$24)+(売上前提!$J$21+売上前提!$J$23+売上前提!$J$25))*売上前提!$B$5/1000000)*(1-経費前提!$B$20)-経費前提!$B$24-MAX(0,(((売上前提!$C$20*$A26*売上前提!$E$20*売上前提!$H$20+売上前提!$C$22*$A26*売上前提!$E$22*売上前提!$H$22+売上前提!$C$24*$A26*D$21*売上前提!$H$24)+(売上前提!$J$21+売上前提!$J$23+売上前提!$J$25))*売上前提!$B$5/1000000)-経費前提!$B$26)*経費前提!$B$25-経費前提!$B$38)/(((売上前提!$C$20*$A26*売上前提!$E$20*売上前提!$H$20+売上前提!$C$22*$A26*売上前提!$E$22*売上前提!$H$22+売上前提!$C$24*$A26*D$21*売上前提!$H$24)+(売上前提!$J$21+売上前提!$J$23+売上前提!$J$25))*売上前提!$B$5/1000000)) -> 0.078682256 | E26: =IF((((売上前提!$C$20*$A26*売上前提!$E$20*売上前提!$H$20+売上前提!$C$22*$A26*売上前提!$E$22*売上前提!$H$22+売上前提!$C$24*$A26*E$21*売上前提!$H$24)+(売上前提!$J$21+売上前提!$J$23+売上前提!$J$25))*売上前提!$B$5/1000000)=0,0,((((売上前提!$C$20*$A26*売上前提!$E$20*売上前提!$H$20+売上前提!$C$22*$A26*売上前提!$E$22*売上前提!$H$22+売上前提!$C$24*$A26*E$21*売上前提!$H$24)+(売上前提!$J$21+売上前提!$J$23+売上前提!$J$25))*売上前提!$B$5/1000000)*(1-経費前提!$B$20)-経費前提!$B$24-MAX(0,(((売上前提!$C$20*$A26*売上前提!$E$20*売上前提!$H$20+売上前提!$C$22*$A26*売上前提!$E$22*売上前提!$H$22+売上前提!$C$24*$A26*E$21*売上前提!$H$24)+(売上前提!$J$21+売上前提!$J$23+売上前提!$J$25))*売上前提!$B$5/1000000)-経費前提!$B$26)*経費前提!$B$25-経費前提!$B$38)/(((売上前提!$C$20*$A26*売上前提!$E$20*売上前提!$H$20+売上前提!$C$22*$A26*売上前提!$E$22*売上前提!$H$22+売上前提!$C$24*$A26*E$21*売上前提!$H$24)+(売上前提!$J$21+売上前提!$J$23+売上前提!$J$25))*売上前提!$B$5/1000000)) -> 0.081662767 | F26: =IF((((売上前提!$C$20*$A26*売上前提!$E$20*売上前提!$H$20+売上前提!$C$22*$A26*売上前提!$E$22*売上前提!$H$22+売上前提!$C$24*$A26*F$21*売上前提!$H$24)+(売上前提!$J$21+売上前提!$J$23+売上前提!$J$25))*売上前提!$B$5/1000000)=0,0,((((売上前提!$C$20*$A26*売上前提!$E$20*売上前提!$H$20+売上前提!$C$22*$A26*売上前提!$E$22*売上前提!$H$22+売上前提!$C$24*$A26*F$21*売上前提!$H$24)+(売上前提!$J$21+売上前提!$J$23+売上前提!$J$25))*売上前提!$B$5/1000000)*(1-経費前提!$B$20)-経費前提!$B$24-MAX(0,(((売上前提!$C$20*$A26*売上前提!$E$20*売上前提!$H$20+売上前提!$C$22*$A26*売上前提!$E$22*売上前提!$H$22+売上前提!$C$24*$A26*F$21*売上前提!$H$24)+(売上前提!$J$21+売上前提!$J$23+売上前提!$J$25))*売上前提!$B$5/1000000)-経費前提!$B$26)*経費前提!$B$25-経費前提!$B$38)/(((売上前提!$C$20*$A26*売上前提!$E$20*売上前提!$H$20+売上前提!$C$22*$A26*売上前提!$E$22*売上前提!$H$22+売上前提!$C$24*$A26*F$21*売上前提!$H$24)+(売上前提!$J$21+売上前提!$J$23+売上前提!$J$25))*売上前提!$B$5/1000000)) -> 0.084316068
A28: 薄黄色＝現在の前提に一致するセル（席効率・回転率を変えると自動で移動します）。
A29: ※ 料理・飲料の構成比は基準ケースの比率を用いた近似。地代家賃と減価償却は売上非連動のため、売上増で利益率が加速的に改善します。
