Workbook

Sheet サマリー
A1: BRASSERIE Thierry Marx 六本木ミッドタウン店 事業収支
A2: 単位：百万円／2026年8月3日提出P&L準拠。183.59㎡(55.5坪)・年363日営業。水色セルを変えると全体が再計算されます。
A4: ■ よく変える前提（ここだけ変えれば全体が動きます）
A5: 詳細は「売上前提」シート。時間帯×エリアごとの席効率・回転率・客単価はそちらで個別に設定できます。
A6: 総席数（店内＋テラス） | B6: =売上前提!$B$16 -> 123
A7: 店内 | B7: =売上前提!$B$14 -> 71
A8: テラス | B8: =売上前提!$B$15 -> 52
A9: 店内 席効率（ランチ） | B9: =売上前提!$D$20 -> 0.8
A10: ディナー 回転率（店内） | B10: =売上前提!$E$24 -> 0.8
A11: 客単価 ランチ | B11: =売上前提!$H$20 -> 4000
A12: 客単価 カフェ | B12: =売上前提!$H$22 -> 1500
A13: 客単価 ディナー | B13: =売上前提!$H$24 -> 15000
A14: 営業日数（日／年） | B14: =売上前提!$B$5 -> 363
A16: ■ 単店PL サマリー
A17: 項 目 | B17: 満年度 | C17: 1年目 | D17: 2年目 | E17: 3年目以降
A18: 売上高 | B18: =単店PL!B6 -> 460.60344 | C18: =単店PL!C6 -> 414.5431 | D18: =単店PL!D6 -> 451.39137 | E18: =単店PL!E6 -> 460.60344
A19: 部門利益 | B19: =単店PL!B12 -> 154.76276 | C19: =単店PL!C12 -> 139.28648 | D19: =単店PL!D12 -> 159.34115 | E19: =単店PL!E12 -> 170.42327
A20: GOP（店舗営業総利益） | B20: =単店PL!B16 -> 127.58715 | C20: =単店PL!C16 -> 114.82844 | D20: =単店PL!D16 -> 133.61185 | E20: =単店PL!E16 -> 145.09008
A21: EBITDA | B21: =単店PL!B22 -> 58.739464 | C21: =単店PL!C22 -> 52.521318 | D21: =単店PL!D22 -> 66.072271 | E21: =単店PL!E22 -> 76.242395
A22: 営業利益 | B22: =単店PL!B24 -> 37.939464 | C22: =単店PL!C24 -> 31.721318 | D22: =単店PL!D24 -> 45.272271 | E22: =単店PL!E24 -> 55.442395
A23: EBITDA率 | B23: =IF(単店PL!B6=0,0,単店PL!B22/単店PL!B6) -> 0.12752719 | C23: =IF(単店PL!C6=0,0,単店PL!C22/単店PL!C6) -> 0.12669688 | D23: =IF(単店PL!D6=0,0,単店PL!D22/単店PL!D6) -> 0.14637469 | E23: =IF(単店PL!E6=0,0,単店PL!E22/単店PL!E6) -> 0.16552719
A24: 営業利益率 | B24: =IF(単店PL!B6=0,0,単店PL!B24/単店PL!B6) -> 0.082369043 | C24: =IF(単店PL!C6=0,0,単店PL!C24/単店PL!C6) -> 0.076521159 | D24: =IF(単店PL!D6=0,0,単店PL!D24/単店PL!D6) -> 0.10029494 | E24: =IF(単店PL!E6=0,0,単店PL!E24/単店PL!E6) -> 0.12036904
A26: ■ 売上の内訳（満年度）
A27: 時間帯 × エリア | B27: 年間売上 | C27: 構成比 | D27: 1日客数
A28: =売上前提!A20&" "&売上前提!B20 -> ランチ 店内 | B28: =売上前提!K20 -> 94.84464 | C28: =売上前提!L20 -> 0.20591388 | D28: =売上前提!I20 -> 65.32
A29: =売上前提!A21&" "&売上前提!B21 -> ランチ テラス | B29: =売上前提!K21 -> 37.752 | C29: =売上前提!L21 -> 0.081962045 | D29: =売上前提!I21 -> 26
A30: =売上前提!A22&" "&売上前提!B22 -> カフェ（アイドルタイム） 店内 | B30: =売上前提!K22 -> 15.4638 | C30: =売上前提!L22 -> 0.033572915 | D30: =売上前提!I22 -> 28.4
A31: =売上前提!A23&" "&売上前提!B23 -> カフェ（アイドルタイム） テラス | B31: =売上前提!K23 -> 8.4942 | C31: =売上前提!L23 -> 0.01844146 | D31: =売上前提!I23 -> 15.6
A32: =売上前提!A24&" "&売上前提!B24 -> ディナー 店内 | B32: =売上前提!K24 -> 247.4208 | C32: =売上前提!L24 -> 0.53716664 | D32: =売上前提!I24 -> 45.44
A33: =売上前提!A25&" "&売上前提!B25 -> ディナー テラス | B33: =売上前提!K25 -> 56.628 | C33: =売上前提!L25 -> 0.12294307 | D33: =売上前提!I25 -> 10.4
A34: 合 計 | B34: =売上前提!K26 -> 460.60344 | C34: =売上前提!L26 -> 1 | D34: =売上前提!I26 -> 191.16
A36: ■ 投資回収
A37: 初期投資 合計 | B37: =経費前提!$B$34 -> 247
A38: 開業時 現金支出（分割払い活用後） | B38: =経費前提!$B$43 -> 108.1
A39: 定常期の年間FCF | B39: =投資・CF!E19 -> 60.642395
A40: 累計FCFの黒字転換 | B40: =投資・CF!E20 -> 39.935984
A42: → 開業3年目に累計FCFが黒字転換（投資回収 約2.8年）。

Sheet 売上前提
A1: 売上前提 ／ 席数 × 席効率 × 回転率 × 客単価 からの積上げ
A2: 水色セル＝入力値。ここを変えると全シートが自動再計算されます。単位：売上は百万円、客単価は円。
A4: ■ 基本条件
A5: 営業日数（日／年） | B5: 363 | N5: 年363日営業（提出P&L準拠）
A6: 立上り率 1年目 | B6: 0.9 | N6: 新店初年度は保守的に90%
A7: 立上り率 2年目 | B7: 0.98
A8: 立上り率 3年目以降（成熟） | B8: 1 | N8: 満年度＝この水準
A10: ■ 席数（席）
A11: カウンター | B11: 14 | N11: 提出P&L：123席（カウンター14・ダイニング30・個室27・テラス52）／183.59㎡＝55.5坪
A12: ダイニング | B12: 30
A13: 個室 | B13: 27
A14: 店内 小計 | B14: =SUM(B11:B13) -> 71
A15: テラス | B15: 52
A16: 合 計 | B16: =B14+B15 -> 123
A18: ■ 時間帯 × エリア 別の売上前提
A19: 時間帯 | B19: エリア | C19: 席数 | D19: 席効率 | E19: 回転率 (回/日) | F19: 客単価 料理(円) | G19: 客単価 飲料(円) | H19: 客単価 計(円) | I19: 1日 客数(人) | J19: 日商(円) | K19: 年間売上 (百万円) | L19: 構成比
A20: ランチ | B20: 店内 | C20: =$B$14 -> 71 | D20: 0.8 | E20: 1.15 | F20: 3000 | G20: 1000 | H20: =F20+G20 -> 4000 | I20: =C20*D20*E20 -> 65.32 | J20: =I20*H20 -> 261280 | K20: =J20*$B$5/1000000 -> 94.84464 | L20: =IF($K$26=0,0,K20/$K$26) -> 0.20591388 | N20: 客単価は提出P&L準拠（ランチ4,000円＝料理3,000＋飲料1,000／ディナー15,000円＝料理9,000＋飲料6,000）
A21: ランチ | B21: テラス | C21: =$B$15 -> 52 | D21: 0.5 | E21: 1 | F21: 3000 | G21: 1000 | H21: =F21+G21 -> 4000 | I21: =C21*D21*E21 -> 26 | J21: =I21*H21 -> 104000 | K21: =J21*$B$5/1000000 -> 37.752 | L21: =IF($K$26=0,0,K21/$K$26) -> 0.081962045
A22: カフェ（アイドルタイム） | B22: 店内 | C22: =$B$14 -> 71 | D22: 0.8 | E22: 0.5 | F22: 1000 | G22: 500 | H22: =F22+G22 -> 1500 | I22: =C22*D22*E22 -> 28.4 | J22: =I22*H22 -> 42600 | K22: =J22*$B$5/1000000 -> 15.4638 | L22: =IF($K$26=0,0,K22/$K$26) -> 0.033572915 | N22: カフェ（アイドルタイム）はブーランジェリー併設を前提に1,500円で設定
A23: カフェ（アイドルタイム） | B23: テラス | C23: =$B$15 -> 52 | D23: 0.5 | E23: 0.6 | F23: 1000 | G23: 500 | H23: =F23+G23 -> 1500 | I23: =C23*D23*E23 -> 15.6 | J23: =I23*H23 -> 23400 | K23: =J23*$B$5/1000000 -> 8.4942 | L23: =IF($K$26=0,0,K23/$K$26) -> 0.01844146
A24: ディナー | B24: 店内 | C24: =$B$14 -> 71 | D24: 0.8 | E24: 0.8 | F24: 9000 | G24: 6000 | H24: =F24+G24 -> 15000 | I24: =C24*D24*E24 -> 45.44 | J24: =I24*H24 -> 681600 | K24: =J24*$B$5/1000000 -> 247.4208 | L24: =IF($K$26=0,0,K24/$K$26) -> 0.53716664 | N24: テラスは天候・季節の影響を見て席効率50%。店内は提出P&Lの稼働率80%
A25: ディナー | B25: テラス | C25: =$B$15 -> 52 | D25: 0.5 | E25: 0.4 | F25: 9000 | G25: 6000 | H25: =F25+G25 -> 15000 | I25: =C25*D25*E25 -> 10.4 | J25: =I25*H25 -> 156000 | K25: =J25*$B$5/1000000 -> 56.628 | L25: =IF($K$26=0,0,K25/$K$26) -> 0.12294307
A26: 合 計 | I26: =SUM(I20:I25) -> 191.16 | J26: =SUM(J20:J25) -> 1268880 | K26: =SUM(K20:K25) -> 460.60344 | L26: =SUM(L20:L25) -> 1
A28: ■ 料理・飲料別の年間売上（原価計算用）
A29: 料理売上 | B29: =SUMPRODUCT(I20:I25,F20:F25)*$B$5/1000000 -> 297.84876
A30: 飲料売上 | B30: =SUMPRODUCT(I20:I25,G20:G25)*$B$5/1000000 -> 162.75468
A31: 合 計 | B31: =B29+B30 -> 460.60344
A32: 料理 構成比 | B32: =IF($B$31=0,0,B29/$B$31) -> 0.64664901
A33: 飲料 構成比 | B33: =IF($B$31=0,0,B30/$B$31) -> 0.35335099
A35: ■ 参考指標
A36: 日商（円） | B36: =J26 -> 1268880
A37: 月商（百万円） | B37: =K26/12 -> 38.38362
A38: 年商（百万円・満年度） | B38: =K26 -> 460.60344 | N38: 提出P&L：4.60億円
A39: 1日あたり総客数（人） | B39: =I26 -> 191.16
A40: 平均客単価（円） | B40: =IF(I26=0,0,J26/I26) -> 6637.7903
A41: 延べ席回転率（回/日） | B41: =IF($B$16=0,0,I26/$B$16) -> 1.5541463 | N41: 総客数 ÷ 総席数
A42: 坪数（坪） | B42: 55.5 | N42: 183.59㎡
A43: 坪売上（百万円/坪・年） | B43: =IF(B42=0,0,K26/B42) -> 8.2991611
A45: ■ 立上りを織り込んだ年間売上（百万円）
A46: 項 目 | B46: 満年度 | C46: 1年目 | D46: 2年目 | E46: 3年目以降
...

Sheet 経費前提
A1: 経費前提（水色セル＝入力値）
A2: 経費率は2026年8月3日提出P&L準拠。2年目以降は一括仕入・本部集中による改善を織り込む。
A4: ■ 売上原価の計算方法
A5: 計算方法（1＝売上比一括／2＝料理・飲料別） | B5: 1 | F5: 1＝提出P&Lどおり売上高に原価率を乗じる。2＝料理・飲料それぞれの原価率で計算（直輸入ワインの効果を分けて見たい場合）
A7: ■ 経費率（対売上高）
A8: 費 目 | B8: 提出P&L水準 （満年度・1年目） | C8: 2年目 | D8: 3年目以降
A9: 売上原価（方法1：売上比一括） | B9: 0.295 | C9: 0.29 | D9: 0.285 | F9: 直輸入ワイン活用・複数店一括仕入
A10: 料理原価率（方法2） | B10: 0.32 | C10: 0.319 | D10: 0.318 | F10: 方法2を選んだ場合のみ使用
A11: 飲料原価率（方法2） | B11: 0.248 | C11: 0.2365 | D11: 0.225 | F11: WineBank直輸入による低減余地が大きい
A12: 人件費 | B12: 0.345 | C12: 0.335 | D12: 0.325 | F12: 本部集中化・多能工化。人員26名
A13: 業務委託費・消耗品他 | B13: 0.024 | C13: 0.022 | D13: 0.02 | F13: 本部集中購買・規格統一
A14: 広告宣伝費・販売促進費 | B14: 0.014 | C14: 0.014 | D14: 0.014 | F14: 据置
A15: その他経費 | B15: 0.005 | C15: 0.005 | D15: 0.005 | F15: 据置
A16: 水道光熱費 | B16: 0.04 | C16: 0.038 | D16: 0.036 | F16: 高効率厨房機器・営業時間最適化
A17: ロイヤリティ | B17: 0.04 | C17: 0.04 | D17: 0.04 | F17: 契約条件（ブラッスリー4.0%）
A18: 保険・租税公課 | B18: 0.007 | C18: 0.007 | D18: 0.007 | F18: 据置
A19: 修繕維持費（FFE） | B19: 0.025 | C19: 0.025 | D19: 0.025 | F19: 据置
A20: 変動費計（方法1ベース・対売上） | B20: =B9+SUM(B12:B19) -> 0.795 | C20: =C9+SUM(C12:C19) -> 0.776 | D20: =D9+SUM(D12:D19) -> 0.757
A22: ■ 固定費・家賃条件
A23: 地代家賃（固定）月額 | B23: 2.22 | F23: 月222万円（提出P&L）
A24: 地代家賃（固定）年額 | B24: =B23*12 -> 26.64 | F24: ＝月額×12
A25: 歩合家賃率 | B25: 0.07 | F25: 閾値超過分に対して7%
A26: 歩合家賃 閾値（年商） | B26: 331.4 | F26: 満年度の歩合家賃9百万円（対売上1.9%）から逆算
A27: 人員数（名・参考） | B27: 26 | F27: 提出P&L。人件費は売上比で計算
A29: ■ 初期投資・減価償却（百万円）
A30: 契約金 | B30: 10 | F30: 契約金3,000万円÷3店舗
A31: 事業費（設計・内装施工・OSE/FF&E） | B31: 194
A32: 開業準備金（広告・採用等） | B32: 4
A33: 保証金 | B33: 39 | F33: 非償却・退去時返還対象
A34: 初期投資 合計 | B34: =SUM(B30:B33) -> 247
A35: 償却対象資産（＝合計－保証金） | B35: =B34-B33 -> 208
A36: 償却年数（年） | B36: 10
A37: 年間減価償却費 | B37: =B35/B36 -> 20.8
A39: ■ 分割払いスキーム（百万円）
A40: 分割対象：内装工事費 | B40: 100 | F40: 月833千円 × 120回（10年）
A41: 分割対象：保証金 | B41: 38.9 | F41: 月463千円 × 84回（7年）
A42: 分割対象額 計 | B42: =B40+B41 -> 138.9
A43: 開業時 現金支出 | B43: =B34-B42 -> 108.1 | F43: ＝初期投資合計 － 分割対象額
A44: 年間分割弁済額 | B44: 15.6 | F44: 月額合計1,296千円 × 12か月

Sheet 単店PL
A1: 六本木ミッドタウン店 単店PL（百万円）
A2: 科目は2026年8月3日提出P&Lのまま。売上は「売上前提」、経費率は「経費前提」に連動。金利・税金は含まない。
A4: 科 目 | B4: 満年度 （提出P&L） | C4: 1年目 | D4: 2年目 | E4: 3年目以降
A5: 立上り率 | B5: =売上前提!B47 -> 1 | C5: =売上前提!C47 -> 0.9 | D5: =売上前提!D47 -> 0.98 | E5: =売上前提!E47 -> 1
A6: 売上高 | B6: =売上前提!B$48 -> 460.60344 | C6: =売上前提!C$48 -> 414.5431 | D6: =売上前提!D$48 -> 451.39137 | E6: =売上前提!E$48 -> 460.60344
A7: うち 料理売上 | B7: =B$6*売上前提!$B$32 -> 297.84876 | C7: =C$6*売上前提!$B$32 -> 268.06388 | D7: =D$6*売上前提!$B$32 -> 291.89178 | E7: =E$6*売上前提!$B$32 -> 297.84876
A8: うち 飲料売上 | B8: =B$6*売上前提!$B$33 -> 162.75468 | C8: =C$6*売上前提!$B$33 -> 146.47921 | D8: =D$6*売上前提!$B$33 -> 159.49959 | E8: =E$6*売上前提!$B$33 -> 162.75468
A9: 売上原価 | B9: =IF(経費前提!$B$5=1,B$6*経費前提!$B$9,B$7*経費前提!$B$10+B$8*経費前提!$B$11) -> 135.87801 | C9: =IF(経費前提!$B$5=1,C$6*経費前提!$B$9,C$7*経費前提!$B$10+C$8*経費前提!$B$11) -> 122.29021 | D9: =IF(経費前提!$B$5=1,D$6*経費前提!$C$9,D$7*経費前提!$C$10+D$8*経費前提!$C$11) -> 130.9035 | E9: =IF(経費前提!$B$5=1,E$6*経費前提!$D$9,E$7*経費前提!$D$10+E$8*経費前提!$D$11) -> 131.27198
A10: 人件費 | B10: =B$6*経費前提!$B$12 -> 158.90819 | C10: =C$6*経費前提!$B$12 -> 143.01737 | D10: =D$6*経費前提!$C$12 -> 151.21611 | E10: =E$6*経費前提!$D$12 -> 149.69612
A11: 業務委託費・消耗品他 | B11: =B$6*経費前提!$B$13 -> 11.054483 | C11: =C$6*経費前提!$B$13 -> 9.9490343 | D11: =D$6*経費前提!$C$13 -> 9.9306102 | E11: =E$6*経費前提!$D$13 -> 9.2120688
A12: 部門利益 | B12: =B6-B9-B10-B11 -> 154.76276 | C12: =C6-C9-C10-C11 -> 139.28648 | D12: =D6-D9-D10-D11 -> 159.34115 | E12: =E6-E9-E10-E11 -> 170.42327
A13: 広告宣伝費・販売促進費 | B13: =B$6*経費前提!$B$14 -> 6.4484482 | C13: =C$6*経費前提!$B$14 -> 5.8036033 | D13: =D$6*経費前提!$C$14 -> 6.3194792 | E13: =E$6*経費前提!$D$14 -> 6.4484482
A14: その他経費 | B14: =B$6*経費前提!$B$15 -> 2.3030172 | C14: =C$6*経費前提!$B$15 -> 2.0727155 | D14: =D$6*経費前提!$C$15 -> 2.2569569 | E14: =E$6*経費前提!$D$15 -> 2.3030172
A15: 水道光熱費 | B15: =B$6*経費前提!$B$16 -> 18.424138 | C15: =C$6*経費前提!$B$16 -> 16.581724 | D15: =D$6*経費前提!$C$16 -> 17.152872 | E15: =E$6*経費前提!$D$16 -> 16.581724
A16: GOP（店舗営業総利益） | B16: =B12-B13-B14-B15 -> 127.58715 | C16: =C12-C13-C14-C15 -> 114.82844 | D16: =D12-D13-D14-D15 -> 133.61185 | E16: =E12-E13-E14-E15 -> 145.09008
A17: ロイヤリティ | B17: =B$6*経費前提!$B$17 -> 18.424138 | C17: =C$6*経費前提!$B$17 -> 16.581724 | D17: =D$6*経費前提!$C$17 -> 18.055655 | E17: =E$6*経費前提!$D$17 -> 18.424138
A18: 保険・租税公課 | B18: =B$6*経費前提!$B$18 -> 3.2242241 | C18: =C$6*経費前提!$B$18 -> 2.9018017 | D18: =D$6*経費前提!$C$18 -> 3.1597396 | E18: =E$6*経費前提!$D$18 -> 3.2242241
A19: 地代家賃（固定） | B19: =経費前提!$B$24 -> 26.64 | C19: =経費前提!$B$24 -> 26.64 | D19: =経費前提!$B$24 -> 26.64 | E19: =経費前提!$B$24 -> 26.64
A20: 歩合家賃 | B20: =MAX(0,B6-経費前提!$B$26)*経費前提!$B$25 -> 9.0442408 | C20: =MAX(0,C6-経費前提!$B$26)*経費前提!$B$25 -> 5.8200167 | D20: =MAX(0,D6-経費前提!$B$26)*経費前提!$B$25 -> 8.399396 | E20: =MAX(0,E6-経費前提!$B$26)*経費前提!$B$25 -> 9.0442408
A21: 修繕維持費（FFE） | B21: =B$6*経費前提!$B$19 -> 11.515086 | C21: =C$6*経費前提!$B$19 -> 10.363577 | D21: =D$6*経費前提!$C$19 -> 11.284784 | E21: =E$6*経費前提!$D$19 -> 11.515086
A22: EBITDA | B22: =B16-B17-B18-B19-B20-B21 -> 58.739464 | C22: =C16-C17-C18-C19-C20-C21 -> 52.521318 | D22: =D16-D17-D18-D19-D20-D21 -> 66.072271 | E22: =E16-E17-E18-E19-E20-E21 -> 76.242395 | G22: 提出P&L：満年度EBITDA 59百万円（12.8%）
A23: 減価償却費 | B23: =経費前提!$B$37 -> 20.8 | C23: =経費前提!$B$37 -> 20.8 | D23: =経費前提!$B$37 -> 20.8 | E23: =経費前提!$B$37 -> 20.8
A24: 営業利益 | B24: =B22-B23 -> 37.939464 | C24: =C22-C23 -> 31.721318 | D24: =D22-D23 -> 45.272271 | E24: =E22-E23 -> 55.442395 | G24: 提出P&L：満年度 営業利益 38百万円（8.3%）
A26: ■ 対売上比
A27: 科 目 | B27: 満年度 | C27: 1年目 | D27: 2年目 | E27: 3年目以降
A28: 売上高 | B28: =IF(B$6=0,0,B6/B$6) -> 1 | C28: =IF(C$6=0,0,C6/C$6) -> 1 | D28: =IF(D$6=0,0,D6/D$6) -> 1 | E28: =IF(E$6=0,0,E6/E$6) -> 1
A29: 売上原価 | B29: =IF(B$6=0,0,B9/B$6) -> 0.295 | C29: =IF(C$6=0,0,C9/C$6) -> 0.295 | D29: =IF(D$6=0,0,D9/D$6) -> 0.29 | E29: =IF(E$6=0,0,E9/E$6) -> 0.285
A30: 人件費 | B30: =IF(B$6=0,0,B10/B$6) -> 0.345 | C30: =IF(C$6=0,0,C10/C$6) -> 0.345 | D30: =IF(D$6=0,0,D10/D$6) -> 0.335 | E30: =IF(E$6=0,0,E10/E$6) -> 0.325
A31: 業務委託費・消耗品他 | B31: =IF(B$6=0,0,B11/B$6) -> 0.024 | C31: =IF(C$6=0,0,C11/C$6) -> 0.024 | D31: =IF(D$6=0,0,D11/D$6) -> 0.022 | E31: =IF(E$6=0,0,E11/E$6) -> 0.02
A32: 部門利益 | B32: =IF(B$6=0,0,B12/B$6) -> 0.336 | C32: =IF(C$6=0,0,C12/C$6) -> 0.336 | D32: =IF(D$6=0,0,D12/D$6) -> 0.353 | E32: =IF(E$6=0,0,E12/E$6) -> 0.37
A33: 広告宣伝費・販売促進費 | B33: =IF(B$6=0,0,B13/B$6) -> 0.014 | C33: =IF(C$6=0,0,C13/C$6) -> 0.014 | D33: =IF(D$6=0,0,D13/D$6) -> 0.014 | E33: =IF(E$6=0,0,E13/E$6) -> 0.014
A34: その他経費 | B34: =IF(B$6=0,0,B14/B$6) -> 0.005 | C34: =IF(C$6=0,0,C14/C$6) -> 0.005 | D34: =IF(D$6=0,0,D14/D$6) -> 0.005 | E34: =IF(E$6=0,0,E14/E$6) -> 0.005
A35: 水道光熱費 | B35: =IF(B$6=0,0,B15/B$6) -> 0.04 | C35: =IF(C$6=0,0,C15/C$6) -> 0.04 | D35: =IF(D$6=0,0,D15/D$6) -> 0.038 | E35: =IF(E$6=0,0,E15/E$6) -> 0.036
A36: GOP（店舗営業総利益） | B36: =IF(B$6=0,0,B16/B$6) -> 0.277 | C36: =IF(C$6=0,0,C16/C$6) -> 0.277 | D36: =IF(D$6=0,0,D16/D$6) -> 0.296 | E36: =IF(E$6=0,0,E16/E$6) -> 0.315
A37: ロイヤリティ | B37: =IF(B$6=0,0,B17/B$6) -> 0.04 | C37: =IF(C$6=0,0,C17/C$6) -> 0.04 | D37: =IF(D$6=0,0,D17/D$6) -> 0.04 | E37: =IF(E$6=0,0,E17/E$6) -> 0.04
A38: 保険・租税公課 | B38: =IF(B$6=0,0,B18/B$6) -> 0.007 | C38: =IF(C$6=0,0,C18/C$6) -> 0.007 | D38: =IF(D$6=0,0,D18/D$6) -> 0.007 | E38: =IF(E$6=0,0,E18/E$6) -> 0.007
A39: 地代家賃（固定） | B39: =IF(B$6=0,0,B19/B$6) -> 0.057837171 | C39: =IF(C$6=0,0,C19/C$6) -> 0.064263524 | D39: =IF(D$6=0,0,D19/D$6) -> 0.059017522 | E39: =IF(E$6=0,0,E19/E$6) -> 0.057837171
A40: 歩合家賃 | B40: =IF(B$6=0,0,B20/B$6) -> 0.019635635 | C40: =IF(C$6=0,0,C20/C$6) -> 0.014039594 | D40: =IF(D$6=0,0,D20/D$6) -> 0.01860779 | E40: =IF(E$6=0,0,E20/E$6) -> 0.019635635
... A44: 営業利益 | B44: =IF(B$6=0,0,B24/B$6) -> 0.082369043 | C44: =IF(C$6=0,0,C24/C$6) -> 0.076521159 | D44: =IF(D$6=0,0,D24/D$6) -> 0.10029494 | E44: =IF(E$6=0,0,E24/E$6) -> 0.12036904

Sheet 投資・CF
A1: 初期投資・キャッシュフロー（百万円）
A2: 分割払いスキーム活用により、開業時の現金支出を247百万円 → 108百万円に圧縮。
A4: ■ 初期投資
A5: 契約金 | B5: =経費前提!$B$30 -> 10
A6: 事業費（設計・内装施工・OSE/FF&E） | B6: =経費前提!$B$31 -> 194
A7: 開業準備金（広告・採用等） | B7: =経費前提!$B$32 -> 4
A8: 保証金 | B8: =経費前提!$B$33 -> 39
A9: 初期投資 合計 | B9: =経費前提!$B$34 -> 247
A10: 分割対象額 | B10: =経費前提!$B$42 -> 138.9
A11: 開業時 現金支出 | B11: =経費前提!$B$43 -> 108.1
A12: 年間分割弁済額 | B12: =経費前提!$B$44 -> 15.6
A14: ■ 単店キャッシュフロー推移
A15: 項 目 | B15: 開業時 | C15: 1年目 | D15: 2年目 | E15: 3年目 | F15: 4年目 | G15: 5年目
A16: EBITDA | B16: 0 | C16: =単店PL!C22 -> 52.521318 | D16: =単店PL!D22 -> 66.072271 | E16: =単店PL!E22 -> 76.242395 | F16: =単店PL!E22 -> 76.242395 | G16: =単店PL!E22 -> 76.242395
A17: 開業時 現金支出 | B17: =-経費前提!$B$43 -> -108.1 | C17: 0 | D17: 0 | E17: 0 | F17: 0 | G17: 0
A18: 分割弁済 | B18: 0 | C18: =-経費前提!$B$44 -> -15.6 | D18: =-経費前提!$B$44 -> -15.6 | E18: =-経費前提!$B$44 -> -15.6 | F18: =-経費前提!$B$44 -> -15.6 | G18: =-経費前提!$B$44 -> -15.6
A19: 単店FCF | B19: =B16+B17+B18 -> -108.1 | C19: =C16+C17+C18 -> 36.921318 | D19: =D16+D17+D18 -> 50.472271 | E19: =E16+E17+E18 -> 60.642395 | F19: =F16+F17+F18 -> 60.642395 | G19: =G16+G17+G18 -> 60.642395
A20: 累計FCF | B20: =B19 -> -108.1 | C20: =B20+C19 -> -71.178682 | D20: =C20+D19 -> -20.706411 | E20: =D20+E19 -> 39.935984 | F20: =E20+F19 -> 100.57838 | G20: =F20+G19 -> 161.22077
A22: ※ 税金・運転資本の増減・借入返済・分割払いに係る金利相当は含まない簡易ベース。
A23: ※ 保証金39百万円は退去時返還対象のため、実質的な投資回収はさらに短期になる。

Sheet 感応度分析
A1: 感応度分析 店内席効率 × ディナー店内回転率
A2: 満年度・提出P&L水準の経費率ベース。テラスとランチ・カフェの前提は「売上前提」のまま固定。
A4: ■ 年間売上高（百万円）
A5: 店内席効率 ＼ ディナー回転率 | B5: 0.6 | C5: 0.7 | D5: 0.8 | E5: 0.9 | F5: 1
A6: 0.6 | B6: =((売上前提!$C$20*$A6*売上前提!$E$20*売上前提!$H$20+売上前提!$C$22*$A6*売上前提!$E$22*売上前提!$H$22+売上前提!$C$24*$A6*B$5*売上前提!$H$24)+(売上前提!$J$21+売上前提!$J$23+売上前提!$J$25))*売上前提!$B$5/1000000 -> 324.77973 | C6: =((売上前提!$C$20*$A6*売上前提!$E$20*売上前提!$H$20+売上前提!$C$22*$A6*売上前提!$E$22*売上前提!$H$22+売上前提!$C$24*$A6*C$5*売上前提!$H$24)+(売上前提!$J$21+売上前提!$J$23+売上前提!$J$25))*売上前提!$B$5/1000000 -> 347.97543 | D6: =((売上前提!$C$20*$A6*売上前提!$E$20*売上前提!$H$20+売上前提!$C$22*$A6*売上前提!$E$22*売上前提!$H$22+売上前提!$C$24*$A6*D$5*売上前提!$H$24)+(売上前提!$J$21+売上前提!$J$23+売上前提!$J$25))*売上前提!$B$5/1000000 -> 371.17113 | E6: =((売上前提!$C$20*$A6*売上前提!$E$20*売上前提!$H$20+売上前提!$C$22*$A6*売上前提!$E$22*売上前提!$H$22+売上前提!$C$24*$A6*E$5*売上前提!$H$24)+(売上前提!$J$21+売上前提!$J$23+売上前提!$J$25))*売上前提!$B$5/1000000 -> 394.36683 | F6: =((売上前提!$C$20*$A6*売上前提!$E$20*売上前提!$H$20+売上前提!$C$22*$A6*売上前提!$E$22*売上前提!$H$22+売上前提!$C$24*$A6*F$5*売上前提!$H$24)+(売上前提!$J$21+売上前提!$J$23+売上前提!$J$25))*売上前提!$B$5/1000000 -> 417.56253
A7: 0.7 | B7: =((売上前提!$C$20*$A7*売上前提!$E$20*売上前提!$H$20+売上前提!$C$22*$A7*売上前提!$E$22*売上前提!$H$22+売上前提!$C$24*$A7*B$5*売上前提!$H$24)+(売上前提!$J$21+売上前提!$J$23+売上前提!$J$25))*売上前提!$B$5/1000000 -> 361.76398 | C7: =((売上前提!$C$20*$A7*売上前提!$E$20*売上前提!$H$20+売上前提!$C$22*$A7*売上前提!$E$22*売上前提!$H$22+売上前提!$C$24*$A7*C$5*売上前提!$H$24)+(売上前提!$J$21+売上前提!$J$23+売上前提!$J$25))*売上前提!$B$5/1000000 -> 388.82563 | D7: =((売上前提!$C$20*$A7*売上前提!$E$20*売上前提!$H$20+売上前提!$C$22*$A7*売上前提!$E$22*売上前提!$H$22+売上前提!$C$24*$A7*D$5*売上前提!$H$24)+(売上前提!$J$21+売上前提!$J$23+売上前提!$J$25))*売上前提!$B$5/1000000 -> 415.88729 | E7: =((売上前提!$C$20*$A7*売上前提!$E$20*売上前提!$H$20+売上前提!$C$22*$A7*売上前提!$E$22*売上前提!$H$22+売上前提!$C$24*$A7*E$5*売上前提!$H$24)+(売上前提!$J$21+売上前提!$J$23+売上前提!$J$25))*売上前提!$B$5/1000000 -> 442.94894 | F7: =((売上前提!$C$20*$A7*売上前提!$E$20*売上前提!$H$20+売上前提!$C$22*$A7*売上前提!$E$22*売上前提!$H$22+売上前提!$C$24*$A7*F$5*売上前提!$H$24)+(売上前提!$J$21+売上前提!$J$23+売上前提!$J$25))*売上前提!$B$5/1000000 -> 470.01058
A8: 0.8 | B8: =((売上前提!$C$20*$A8*売上前提!$E$20*売上前提!$H$20+売上前提!$C$22*$A8*売上前提!$E$22*売上前提!$H$22+売上前提!$C$24*$A8*B$5*売上前提!$H$24)+(売上前提!$J$21+売上前提!$J$23+売上前提!$J$25))*売上前提!$B$5/1000000 -> 398.74824 | C8: =((売上前提!$C$20*$A8*売上前提!$E$20*売上前提!$H$20+売上前提!$C$22*$A8*売上前提!$E$22*売上前提!$H$22+売上前提!$C$24*$A8*C$5*売上前提!$H$24)+(売上前提!$J$21+売上前提!$J$23+売上前提!$J$25))*売上前提!$B$5/1000000 -> 429.67584 | D8: =((売上前提!$C$20*$A8*売上前提!$E$20*売上前提!$H$20+売上前提!$C$22*$A8*売上前提!$E$22*売上前提!$H$22+売上前提!$C$24*$A8*D$5*売上前提!$H$24)+(売上前提!$J$21+売上前提!$J$23+売上前提!$J$25))*売上前提!$B$5/1000000 -> 460.60344 | E8: =((売上前提!$C$20*$A8*売上前提!$E$20*売上前提!$H$20+売上前提!$C$22*$A8*売上前提!$E$22*売上前提!$H$22+売上前提!$C$24*$A8*E$5*売上前提!$H$24)+(売上前提!$J$21+売上前提!$J$23+売上前提!$J$25))*売上前提!$B$5/1000000 -> 491.53104 | F8: =((売上前提!$C$20*$A8*売上前提!$E$20*売上前提!$H$20+売上前提!$C$22*$A8*売上前提!$E$22*売上前提!$H$22+売上前提!$C$24*$A8*F$5*売上前提!$H$24)+(売上前提!$J$21+売上前提!$J$23+売上前提!$J$25))*売上前提!$B$5/1000000 -> 522.45864
A9: 0.9 | B9: =((売上前提!$C$20*$A9*売上前提!$E$20*売上前提!$H$20+売上前提!$C$22*$A9*売上前提!$E$22*売上前提!$H$22+売上前提!$C$24*$A9*B$5*売上前提!$H$24)+(売上前提!$J$21+売上前提!$J$23+売上前提!$J$25))*売上前提!$B$5/1000000 -> 435.73249 | C9: =((売上前提!$C$20*$A9*売上前提!$E$20*売上前提!$H$20+売上前提!$C$22*$A9*売上前提!$E$22*売上前提!$H$22+売上前提!$C$24*$A9*C$5*売上前提!$H$24)+(売上前提!$J$21+売上前提!$J$23+売上前提!$J$25))*売上前提!$B$5/1000000 -> 470.52605 | D9: =((売上前提!$C$20*$A9*売上前提!$E$20*売上前提!$H$20+売上前提!$C$22*$A9*売上前提!$E$22*売上前提!$H$22+売上前提!$C$24*$A9*D$5*売上前提!$H$24)+(売上前提!$J$21+売上前提!$J$23+売上前提!$J$25))*売上前提!$B$5/1000000 -> 505.31959 | E9: =((売上前提!$C$20*$A9*売上前提!$E$20*売上前提!$H$20+売上前提!$C$22*$A9*売上前提!$E$22*売上前提!$H$22+売上前提!$C$24*$A9*E$5*売上前提!$H$24)+(売上前提!$J$21+売上前提!$J$23+売上前提!$J$25))*売上前提!$B$5/1000000 -> 540.11315 | F9: =((売上前提!$C$20*$A9*売上前提!$E$20*売上前提!$H$20+売上前提!$C$22*$A9*売上前提!$E$22*売上前提!$H$22+売上前提!$C$24*$A9*F$5*売上前提!$H$24)+(売上前提!$J$21+売上前提!$J$23+売上前提!$J$25))*売上前提!$B$5/1000000 -> 574.9067
A10: 1 | B10: =((売上前提!$C$20*$A10*売上前提!$E$20*売上前提!$H$20+売上前提!$C$22*$A10*売上前提!$E$22*売上前提!$H$22+売上前提!$C$24*$A10*B$5*売上前提!$H$24)+(売上前提!$J$21+売上前提!$J$23+売上前提!$J$25))*売上前提!$B$5/1000000 -> 472.71675 | C10: =((売上前提!$C$20*$A10*売上前提!$E$20*売上前提!$H$20+売上前提!$C$22*$A10*売上前提!$E$22*売上前提!$H$22+売上前提!$C$24*$A10*C$5*売上前提!$H$24)+(売上前提!$J$21+売上前提!$J$23+売上前提!$J$25))*売上前提!$B$5/1000000 -> 511.37625 | D10: =((売上前提!$C$20*$A10*売上前提!$E$20*売上前提!$H$20+売上前提!$C$22*$A10*売上前提!$E$22*売上前提!$H$22+売上前提!$C$24*$A10*D$5*売上前提!$H$24)+(売上前提!$J$21+売上前提!$J$23+売上前提!$J$25))*売上前提!$B$5/1000000 -> 550.03575 | E10: =((売上前提!$C$20*$A10*売上前提!$E$20*売上前提!$H$20+売上前提!$C$22*$A10*売上前提!$E$22*売上前提!$H$22+売上前提!$C$24*$A10*E$5*売上前提!$H$24)+(売上前提!$J$21+売上前提!$J$23+売上前提!$J$25))*売上前提!$B$5/1000000 -> 588.69525 | F10: =((売上前提!$C$20*$A10*売上前提!$E$20*売上前提!$H$20+売上前提!$C$22*$A10*売上前提!$E$22*売上前提!$H$22+売上前提!$C$24*$A10*F$5*売上前提!$H$24)+(売上前提!$J$21+売上前提!$J$23+売上前提!$J$25))*売上前提!$B$5/1000000 -> 627.35475
A12: ■ 営業利益（百万円）
A13: 店内席効率 ＼ ディナー回転率 | B13: 0.6 | C13: 0.7 | D13: 0.8 | E13: 0.9 | F13: 1
A14: 0.6 | B14: =((((売上前提!$C$20*$A14*売上前提!$E$20*売上前提!$H$20+売上前提!$C$22*$A14*売上前提!$E$22*売上前提!$H$22+売上前提!$C$24*$A14*B$13*売上前提!$H$24)+(売上前提!$J$21+売上前提!$J$23+売上前提!$J$25))*売上前提!$B$5/1000000)*(1-経費前提!$B$20)-経費前提!$B$24-MAX(0,(((売上前提!$C$20*$A14*売上前提!$E$20*売上前提!$H$20+売上前提!$C$22*$A14*売上前提!$E$22*売上前提!$H$22+売上前提!$C$24*$A14*B$13*売上前提!$H$24)+(売上前提!$J$21+売上前提!$J$23+売上前提!$J$25))*売上前提!$B$5/1000000)-経費前提!$B$26)*経費前提!$B$25-経費前提!$B$37) -> 19.139845 | C14: =((((売上前提!$C$20*$A14*売上前提!$E$20*売上前提!$H$20+売上前提!$C$22*$A14*売上前提!$E$22*売上前提!$H$22+売上前提!$C$24*$A14*C$13*売上前提!$H$24)+(売上前提!$J$21+売上前提!$J$23+売上前提!$J$25))*売上前提!$B$5/1000000)*(1-経費前提!$B$20)-経費前提!$B$24-MAX(0,(((売上前提!$C$20*$A14*売上前提!$E$20*売上前提!$H$20+売上前提!$C$22*$A14*売上前提!$E$22*売上前提!$H$22+売上前提!$C$24*$A14*C$13*売上前提!$H$24)+(売上前提!$J$21+売上前提!$J$23+売上前提!$J$25))*売上前提!$B$5/1000000)-経費前提!$B$26)*経費前提!$B$25-経費前提!$B$37) -> 22.734683 | D14: =((((売上前提!$C$20*$A14*売上前提!$E$20*売上前提!$H$20+売上前提!$C$22*$A14*売上前提!$E$22*売上前提!$H$22+売上前提!$C$24*$A14*D$13*売上前提!$H$24)+(売上前提!$J$21+売上前提!$J$23+売上前提!$J$25))*売上前提!$B$5/1000000)*(1-経費前提!$B$20)-経費前提!$B$24-MAX(0,(((売上前提!$C$20*$A14*売上前提!$E$20*売上前提!$H$20+売上前提!$C$22*$A14*売上前提!$E$22*売上前提!$H$22+売上前提!$C$24*$A14*D$13*売上前提!$H$24)+(売上前提!$J$21+売上前提!$J$23+売上前提!$J$25))*売上前提!$B$5/1000000)-経費前提!$B$26)*経費前提!$B$25-経費前提!$B$37) -> 25.866103 | E14: =((((売上前提!$C$20*$A14*売上前提!$E$20*売上前提!$H$20+売上前提!$C$22*$A14*売上前提!$E$22*売上前提!$H$22+売上前提!$C$24*$A14*E$13*売上前提!$H$24)+(売上前提!$J$21+売上前提!$J$23+売上前提!$J$25))*売上前提!$B$5/1000000)*(1-経費前提!$B$20)-経費前提!$B$24-MAX(0,(((売上前提!$C$20*$A14*売上前提!$E$20*売上前提!$H$20+売上前提!$C$22*$A14*売上前提!$E$22*売上前提!$H$22+売上前提!$C$24*$A14*E$13*売上前提!$H$24)+(売上前提!$J$21+売上前提!$J$23+売上前提!$J$25))*売上前提!$B$5/1000000)-経費前提!$B$26)*経費前提!$B$25-経費前提!$B$37) -> 28.997522 | F14: =((((売上前提!$C$20*$A14*売上前提!$E$20*売上前提!$H$20+売上前提!$C$22*$A14*売上前提!$E$22*売上前提!$H$22+売上前提!$C$24*$A14*F$13*売上前提!$H$24)+(売上前提!$J$21+売上前提!$J$23+売上前提!$J$25))*売上前提!$B$5/1000000)*(1-経費前提!$B$20)-経費前提!$B$24-MAX(0,(((売上前提!$C$20*$A14*売上前提!$E$20*売上前提!$H$20+売上前提!$C$22*$A14*売上前提!$E$22*売上前提!$H$22+売上前提!$C$24*$A14*F$13*売上前提!$H$24)+(売上前提!$J$21+売上前提!$J$23+売上前提!$J$25))*売上前提!$B$5/1000000)-経費前提!$B$26)*経費前提!$B$25-経費前提!$B$37) -> 32.128942
A15: 0.7 | B15: =((((売上前提!$C$20*$A15*売上前提!$E$20*売上前提!$H$20+売上前提!$C$22*$A15*売上前提!$E$22*売上前提!$H$22+売上前提!$C$24*$A15*B$13*売上前提!$H$24)+(売上前提!$J$21+売上前提!$J$23+売上前提!$J$25))*売上前提!$B$5/1000000)*(1-経費前提!$B$20)-経費前提!$B$24-MAX(0,(((売上前提!$C$20*$A15*売上前提!$E$20*売上前提!$H$20+売上前提!$C$22*$A15*売上前提!$E$22*売上前提!$H$22+売上前提!$C$24*$A15*B$13*売上前提!$H$24)+(売上前提!$J$21+売上前提!$J$23+売上前提!$J$25))*売上前提!$B$5/1000000)-経費前提!$B$26)*経費前提!$B$25-経費前提!$B$37) -> 24.596138 | C15: =((((売上前提!$C$20*$A15*売上前提!$E$20*売上前提!$H$20+売上前提!$C$22*$A15*売上前提!$E$22*売上前提!$H$22+売上前提!$C$24*$A15*C$13*売上前提!$H$24)+(売上前提!$J$21+売上前提!$J$23+売上前提!$J$25))*売上前提!$B$5/1000000)*(1-経費前提!$B$20)-経費前提!$B$24-MAX(0,(((売上前提!$C$20*$A15*売上前提!$E$20*売上前提!$H$20+売上前提!$C$22*$A15*売上前提!$E$22*売上前提!$H$22+売上前提!$C$24*$A15*C$13*売上前提!$H$24)+(売上前提!$J$21+売上前提!$J$23+売上前提!$J$25))*売上前提!$B$5/1000000)-経費前提!$B$26)*経費前提!$B$25-経費前提!$B$37) -> 28.249461 | D15: =((((売上前提!$C$20*$A15*売上前提!$E$20*売上前提!$H$20+売上前提!$C$22*$A15*売上前提!$E$22*売上前提!$H$22+売上前提!$C$24*$A15*D$13*売上前提!$H$24)+(売上前提!$J$21+売上前提!$J$23+売上前提!$J$25))*売上前提!$B$5/1000000)*(1-経費前提!$B$20)-経費前提!$B$24-MAX(0,(((売上前提!$C$20*$A15*売上前提!$E$20*売上前提!$H$20+売上前提!$C$22*$A15*売上前提!$E$22*売上前提!$H$22+売上前提!$C$24*$A15*D$13*売上前提!$H$24)+(売上前提!$J$21+売上前提!$J$23+売上前提!$J$25))*売上前提!$B$5/1000000)-経費前提!$B$26)*経費前提!$B$25-経費前提!$B$37) -> 31.902783 | E15: =((((売上前提!$C$20*$A15*売上前提!$E$20*売上前提!$H$20+売上前提!$C$22*$A15*売上前提!$E$22*売上前提!$H$22+売上前提!$C$24*$A15*E$13*売上前提!$H$24)+(売上前提!$J$21+売上前提!$J$23+売上前提!$J$25))*売上前提!$B$5/1000000)*(1-経費前提!$B$20)-経費前提!$B$24-MAX(0,(((売上前提!$C$20*$A15*売上前提!$E$20*売上前提!$H$20+売上前提!$C$22*$A15*売上前提!$E$22*売上前提!$H$22+売上前提!$C$24*$A15*E$13*売上前提!$H$24)+(売上前提!$J$21+売上前提!$J$23+売上前提!$J$25))*売上前提!$B$5/1000000)-経費前提!$B$26)*経費前提!$B$25-経費前提!$B$37) -> 35.556106 | F15: =((((売上前提!$C$20*$A15*売上前提!$E$20*売上前提!$H$20+売上前提!$C$22*$A15*売上前提!$E$22*売上前提!$H$22+売上前提!$C$24*$A15*F$13*売上前提!$H$24)+(売上前提!$J$21+売上前提!$J$23+売上前提!$J$25))*売上前提!$B$5/1000000)*(1-経費前提!$B$20)-経費前提!$B$24-MAX(0,(((売上前提!$C$20*$A15*売上前提!$E$20*売上前提!$H$20+売上前提!$C$22*$A15*売上前提!$E$22*売上前提!$H$22+売上前提!$C$24*$A15*F$13*売上前提!$H$24)+(売上前提!$J$21+売上前提!$J$23+売上前提!$J$25))*売上前提!$B$5/1000000)-経費前提!$B$26)*経費前提!$B$25-経費前提!$B$37) -> 39.209429
A16: 0.8 | B16: =((((売上前提!$C$20*$A16*売上前提!$E$20*売上前提!$H$20+売上前提!$C$22*$A16*売上前提!$E$22*売上前提!$H$22+売上前提!$C$24*$A16*B$13*売上前提!$H$24)+(売上前提!$J$21+売上前提!$J$23+売上前提!$J$25))*売上前提!$B$5/1000000)*(1-経費前提!$B$20)-経費前提!$B$24-MAX(0,(((売上前提!$C$20*$A16*売上前提!$E$20*売上前提!$H$20+売上前提!$C$22*$A16*売上前提!$E$22*売上前提!$H$22+売上前提!$C$24*$A16*B$13*売上前提!$H$24)+(売上前提!$J$21+売上前提!$J$23+売上前提!$J$25))*売上前提!$B$5/1000000)-経費前提!$B$26)*経費前提!$B$25-経費前提!$B$37) -> 29.589012 | C16: =((((売上前提!$C$20*$A16*売上前提!$E$20*売上前提!$H$20+売上前提!$C$22*$A16*売上前提!$E$22*売上前提!$H$22+売上前提!$C$24*$A16*C$13*売上前提!$H$24)+(売上前提!$J$21+売上前提!$J$23+売上前提!$J$25))*売上前提!$B$5/1000000)*(1-経費前提!$B$20)-経費前提!$B$24-MAX(0,(((売上前提!$C$20*$A16*売上前提!$E$20*売上前提!$H$20+売上前提!$C$22*$A16*売上前提!$E$22*売上前提!$H$22+売上前提!$C$24*$A16*C$13*売上前提!$H$24)+(売上前提!$J$21+売上前提!$J$23+売上前提!$J$25))*売上前提!$B$5/1000000)-経費前提!$B$26)*経費前提!$B$25-経費前提!$B$37) -> 33.764238 | D16: =((((売上前提!$C$20*$A16*売上前提!$E$20*売上前提!$H$20+売上前提!$C$22*$A16*売上前提!$E$22*売上前提!$H$22+売上前提!$C$24*$A16*D$13*売上前提!$H$24)+(売上前提!$J$21+売上前提!$J$23+売上前提!$J$25))*売上前提!$B$5/1000000)*(1-経費前提!$B$20)-経費前提!$B$24-MAX(0,(((売上前提!$C$20*$A16*売上前提!$E$20*売上前提!$H$20+売上前提!$C$22*$A16*売上前提!$E$22*売上前提!$H$22+売上前提!$C$24*$A16*D$13*売上前提!$H$24)+(売上前提!$J$21+売上前提!$J$23+売上前提!$J$25))*売上前提!$B$5/1000000)-経費前提!$B$26)*経費前提!$B$25-経費前提!$B$37) -> 37.939464 | E16: =((((売上前提!$C$20*$A16*売上前提!$E$20*売上前提!$H$20+売上前提!$C$22*$A16*売上前提!$E$22*売上前提!$H$22+売上前提!$C$24*$A16*E$13*売上前提!$H$24)+(売上前提!$J$21+売上前提!$J$23+売上前提!$J$25))*売上前提!$B$5/1000000)*(1-経費前提!$B$20)-経費前提!$B$24-MAX(0,(((売上前提!$C$20*$A16*売上前提!$E$20*売上前提!$H$20+売上前提!$C$22*$A16*売上前提!$E$22*売上前提!$H$22+売上前提!$C$24*$A16*E$13*売上前提!$H$24)+(売上前提!$J$21+売上前提!$J$23+売上前提!$J$25))*売上前提!$B$5/1000000)-経費前提!$B$26)*経費前提!$B$25-経費前提!$B$37) -> 42.11469 | F16: =((((売上前提!$C$20*$A16*売上前提!$E$20*売上前提!$H$20+売上前提!$C$22*$A16*売上前提!$E$22*売上前提!$H$22+売上前提!$C$24*$A16*F$13*売上前提!$H$24)+(売上前提!$J$21+売上前提!$J$23+売上前提!$J$25))*売上前提!$B$5/1000000)*(1-経費前提!$B$20)-経費前提!$B$24-MAX(0,(((売上前提!$C$20*$A16*売上前提!$E$20*売上前提!$H$20+売上前提!$C$22*$A16*売上前提!$E$22*売上前提!$H$22+売上前提!$C$24*$A16*F$13*売上前提!$H$24)+(売上前提!$J$21+売上前提!$J$23+売上前提!$J$25))*売上前提!$B$5/1000000)-経費前提!$B$26)*経費前提!$B$25-経費前提!$B$37) -> 46.289916
A17: 0.9 | B17: =((((売上前提!$C$20*$A17*売上前提!$E$20*売上前提!$H$20+売上前提!$C$22*$A17*売上前提!$E$22*売上前提!$H$22+売上前提!$C$24*$A17*B$13*売上前提!$H$24)+(売上前提!$J$21+売上前提!$J$23+売上前提!$J$25))*売上前提!$B$5/1000000)*(1-経費前提!$B$20)-経費前提!$B$24-MAX(0,(((売上前提!$C$20*$A17*売上前提!$E$20*売上前提!$H$20+売上前提!$C$22*$A17*売上前提!$E$22*売上前提!$H$22+売上前提!$C$24*$A17*B$13*売上前提!$H$24)+(売上前提!$J$21+売上前提!$J$23+売上前提!$J$25))*売上前提!$B$5/1000000)-経費前提!$B$26)*経費前提!$B$25-経費前提!$B$37) -> 34.581887 | C17: =((((売上前提!$C$20*$A17*売上前提!$E$20*売上前提!$H$20+売上前提!$C$22*$A17*売上前提!$E$22*売上前提!$H$22+売上前提!$C$24*$A17*C$13*売上前提!$H$24)+(売上前提!$J$21+売上前提!$J$23+売上前提!$J$25))*売上前提!$B$5/1000000)*(1-経費前提!$B$20)-経費前提!$B$24-MAX(0,(((売上前提!$C$20*$A17*売上前提!$E$20*売上前提!$H$20+売上前提!$C$22*$A17*売上前提!$E$22*売上前提!$H$22+売上前提!$C$24*$A17*C$13*売上前提!$H$24)+(売上前提!$J$21+売上前提!$J$23+売上前提!$J$25))*売上前提!$B$5/1000000)-経費前提!$B$26)*経費前提!$B$25-経費前提!$B$37) -> 39.279016 | D17: =((((売上前提!$C$20*$A17*売上前提!$E$20*売上前提!$H$20+売上前提!$C$22*$A17*売上前提!$E$22*売上前提!$H$22+売上前提!$C$24*$A17*D$13*売上前提!$H$24)+(売上前提!$J$21+売上前提!$J$23+売上前提!$J$25))*売上前提!$B$5/1000000)*(1-経費前提!$B$20)-経費前提!$B$24-MAX(0,(((売上前提!$C$20*$A17*売上前提!$E$20*売上前提!$H$20+売上前提!$C$22*$A17*売上前提!$E$22*売上前提!$H$22+売上前提!$C$24*$A17*D$13*売上前提!$H$24)+(売上前提!$J$21+売上前提!$J$23+売上前提!$J$25))*売上前提!$B$5/1000000)-経費前提!$B$26)*経費前提!$B$25-経費前提!$B$37) -> 43.976145 | E17: =((((売上前提!$C$20*$A17*売上前提!$E$20*売上前提!$H$20+売上前提!$C$22*$A17*売上前提!$E$22*売上前提!$H$22+売上前提!$C$24*$A17*E$13*売上前提!$H$24)+(売上前提!$J$21+売上前提!$J$23+売上前提!$J$25))*売上前提!$B$5/1000000)*(1-経費前提!$B$20)-経費前提!$B$24-MAX(0,(((売上前提!$C$20*$A17*売上前提!$E$20*売上前提!$H$20+売上前提!$C$22*$A17*売上前提!$E$22*売上前提!$H$22+売上前提!$C$24*$A17*E$13*売上前提!$H$24)+(売上前提!$J$21+売上前提!$J$23+売上前提!$J$25))*売上前提!$B$5/1000000)-経費前提!$B$26)*経費前提!$B$25-経費前提!$B$37) -> 48.673275 | F17: =((((売上前提!$C$20*$A17*売上前提!$E$20*売上前提!$H$20+売上前提!$C$22*$A17*売上前提!$E$22*売上前提!$H$22+売上前提!$C$24*$A17*F$13*売上前提!$H$24)+(売上前提!$J$21+売上前提!$J$23+売上前提!$J$25))*売上前提!$B$5/1000000)*(1-経費前提!$B$20)-経費前提!$B$24-MAX(0,(((売上前提!$C$20*$A17*売上前提!$E$20*売上前提!$H$20+売上前提!$C$22*$A17*売上前提!$E$22*売上前提!$H$22+売上前提!$C$24*$A17*F$13*売上前提!$H$24)+(売上前提!$J$21+売上前提!$J$23+売上前提!$J$25))*売上前提!$B$5/1000000)-経費前提!$B$26)*経費前提!$B$25-経費前提!$B$37) -> 53.370404
A18: 1 | B18: =((((売上前提!$C$20*$A18*売上前提!$E$20*売上前提!$H$20+売上前提!$C$22*$A18*売上前提!$E$22*売上前提!$H$22+売上前提!$C$24*$A18*B$13*売上前提!$H$24)+(売上前提!$J$21+売上前提!$J$23+売上前提!$J$25))*売上前提!$B$5/1000000)*(1-経費前提!$B$20)-経費前提!$B$24-MAX(0,(((売上前提!$C$20*$A18*売上前提!$E$20*売上前提!$H$20+売上前提!$C$22*$A18*売上前提!$E$22*売上前提!$H$22+売上前提!$C$24*$A18*B$13*売上前提!$H$24)+(売上前提!$J$21+売上前提!$J$23+売上前提!$J$25))*売上前提!$B$5/1000000)-経費前提!$B$26)*経費前提!$B$25-経費前提!$B$37) -> 39.574761 | C18: =((((売上前提!$C$20*$A18*売上前提!$E$20*売上前提!$H$20+売上前提!$C$22*$A18*売上前提!$E$22*売上前提!$H$22+売上前提!$C$24*$A18*C$13*売上前提!$H$24)+(売上前提!$J$21+売上前提!$J$23+売上前提!$J$25))*売上前提!$B$5/1000000)*(1-経費前提!$B$20)-経費前提!$B$24-MAX(0,(((売上前提!$C$20*$A18*売上前提!$E$20*売上前提!$H$20+売上前提!$C$22*$A18*売上前提!$E$22*売上前提!$H$22+売上前提!$C$24*$A18*C$13*売上前提!$H$24)+(売上前提!$J$21+売上前提!$J$23+売上前提!$J$25))*売上前提!$B$5/1000000)-経費前提!$B$26)*経費前提!$B$25-経費前提!$B$37) -> 44.793794 | D18: =((((売上前提!$C$20*$A18*売上前提!$E$20*売上前提!$H$20+売上前提!$C$22*$A18*売上前提!$E$22*売上前提!$H$22+売上前提!$C$24*$A18*D$13*売上前提!$H$24)+(売上前提!$J$21+売上前提!$J$23+売上前提!$J$25))*売上前提!$B$5/1000000)*(1-経費前提!$B$20)-経費前提!$B$24-MAX(0,(((売上前提!$C$20*$A18*売上前提!$E$20*売上前提!$H$20+売上前提!$C$22*$A18*売上前提!$E$22*売上前提!$H$22+売上前提!$C$24*$A18*D$13*売上前提!$H$24)+(売上前提!$J$21+売上前提!$J$23+売上前提!$J$25))*売上前提!$B$5/1000000)-経費前提!$B$26)*経費前提!$B$25-経費前提!$B$37) -> 50.012826 | E18: =((((売上前提!$C$20*$A18*売上前提!$E$20*売上前提!$H$20+売上前提!$C$22*$A18*売上前提!$E$22*売上前提!$H$22+売上前提!$C$24*$A18*E$13*売上前提!$H$24)+(売上前提!$J$21+売上前提!$J$23+売上前提!$J$25))*売上前提!$B$5/1000000)*(1-経費前提!$B$20)-経費前提!$B$24-MAX(0,(((売上前提!$C$20*$A18*売上前提!$E$20*売上前提!$H$20+売上前提!$C$22*$A18*売上前提!$E$22*売上前提!$H$22+売上前提!$C$24*$A18*E$13*売上前提!$H$24)+(売上前提!$J$21+売上前提!$J$23+売上前提!$J$25))*売上前提!$B$5/1000000)-経費前提!$B$26)*経費前提!$B$25-経費前提!$B$37) -> 55.231859 | F18: =((((売上前提!$C$20*$A18*売上前提!$E$20*売上前提!$H$20+売上前提!$C$22*$A18*売上前提!$E$22*売上前提!$H$22+売上前提!$C$24*$A18*F$13*売上前提!$H$24)+(売上前提!$J$21+売上前提!$J$23+売上前提!$J$25))*売上前提!$B$5/1000000)*(1-経費前提!$B$20)-経費前提!$B$24-MAX(0,(((売上前提!$C$20*$A18*売上前提!$E$20*売上前提!$H$20+売上前提!$C$22*$A18*売上前提!$E$22*売上前提!$H$22+売上前提!$C$24*$A18*F$13*売上前提!$H$24)+(売上前提!$J$21+売上前提!$J$23+売上前提!$J$25))*売上前提!$B$5/1000000)-経費前提!$B$26)*経費前提!$B$25-経費前提!$B$37) -> 60.450891
A20: ■ 営業利益率
A21: 店内席効率 ＼ ディナー回転率 | B21: 0.6 | C21: 0.7 | D21: 0.8 | E21: 0.9 | F21: 1
A22: 0.6 | B22: =IF((((売上前提!$C$20*$A22*売上前提!$E$20*売上前提!$H$20+売上前提!$C$22*$A22*売上前提!$E$22*売上前提!$H$22+売上前提!$C$24*$A22*B$21*売上前提!$H$24)+(売上前提!$J$21+売上前提!$J$23+売上前提!$J$25))*売上前提!$B$5/1000000)=0,0,((((売上前提!$C$20*$A22*売上前提!$E$20*売上前提!$H$20+売上前提!$C$22*$A22*売上前提!$E$22*売上前提!$H$22+売上前提!$C$24*$A22*B$21*売上前提!$H$24)+(売上前提!$J$21+売上前提!$J$23+売上前提!$J$25))*売上前提!$B$5/1000000)*(1-経費前提!$B$20)-経費前提!$B$24-MAX(0,(((売上前提!$C$20*$A22*売上前提!$E$20*売上前提!$H$20+売上前提!$C$22*$A22*売上前提!$E$22*売上前提!$H$22+売上前提!$C$24*$A22*B$21*売上前提!$H$24)+(売上前提!$J$21+売上前提!$J$23+売上前提!$J$25))*売上前提!$B$5/1000000)-経費前提!$B$26)*経費前提!$B$25-経費前提!$B$37)/(((売上前提!$C$20*$A22*売上前提!$E$20*売上前提!$H$20+売上前提!$C$22*$A22*売上前提!$E$22*売上前提!$H$22+売上前提!$C$24*$A22*B$21*売上前提!$H$24)+(売上前提!$J$21+売上前提!$J$23+売上前提!$J$25))*売上前提!$B$5/1000000)) -> 0.058931771 | C22: =IF((((売上前提!$C$20*$A22*売上前提!$E$20*売上前提!$H$20+売上前提!$C$22*$A22*売上前提!$E$22*売上前提!$H$22+売上前提!$C$24*$A22*C$21*売上前提!$H$24)+(売上前提!$J$21+売上前提!$J$23+売上前提!$J$25))*売上前提!$B$5/1000000)=0,0,((((売上前提!$C$20*$A22*売上前提!$E$20*売上前提!$H$20+売上前提!$C$22*$A22*売上前提!$E$22*売上前提!$H$22+売上前提!$C$24*$A22*C$21*売上前提!$H$24)+(売上前提!$J$21+売上前提!$J$23+売上前提!$J$25))*売上前提!$B$5/1000000)*(1-経費前提!$B$20)-経費前提!$B$24-MAX(0,(((売上前提!$C$20*$A22*売上前提!$E$20*売上前提!$H$20+売上前提!$C$22*$A22*売上前提!$E$22*売上前提!$H$22+売上前提!$C$24*$A22*C$21*売上前提!$H$24)+(売上前提!$J$21+売上前提!$J$23+売上前提!$J$25))*売上前提!$B$5/1000000)-経費前提!$B$26)*経費前提!$B$25-経費前提!$B$37)/(((売上前提!$C$20*$A22*売上前提!$E$20*売上前提!$H$20+売上前提!$C$22*$A22*売上前提!$E$22*売上前提!$H$22+売上前提!$C$24*$A22*C$21*売上前提!$H$24)+(売上前提!$J$21+売上前提!$J$23+売上前提!$J$25))*売上前提!$B$5/1000000)) -> 0.065334162 | D22: =IF((((売上前提!$C$20*$A22*売上前提!$E$20*売上前提!$H$20+売上前提!$C$22*$A22*売上前提!$E$22*売上前提!$H$22+売上前提!$C$24*$A22*D$21*売上前提!$H$24)+(売上前提!$J$21+売上前提!$J$23+売上前提!$J$25))*売上前提!$B$5/1000000)=0,0,((((売上前提!$C$20*$A22*売上前提!$E$20*売上前提!$H$20+売上前提!$C$22*$A22*売上前提!$E$22*売上前提!$H$22+売上前提!$C$24*$A22*D$21*売上前提!$H$24)+(売上前提!$J$21+売上前提!$J$23+売上前提!$J$25))*売上前提!$B$5/1000000)*(1-経費前提!$B$20)-経費前提!$B$24-MAX(0,(((売上前提!$C$20*$A22*売上前提!$E$20*売上前提!$H$20+売上前提!$C$22*$A22*売上前提!$E$22*売上前提!$H$22+売上前提!$C$24*$A22*D$21*売上前提!$H$24)+(売上前提!$J$21+売上前提!$J$23+売上前提!$J$25))*売上前提!$B$5/1000000)-経費前提!$B$26)*経費前提!$B$25-経費前提!$B$37)/(((売上前提!$C$20*$A22*売上前提!$E$20*売上前提!$H$20+売上前提!$C$22*$A22*売上前提!$E$22*売上前提!$H$22+売上前提!$C$24*$A22*D$21*売上前提!$H$24)+(売上前提!$J$21+売上前提!$J$23+売上前提!$J$25))*売上前提!$B$5/1000000)) -> 0.069687808 | E22: =IF((((売上前提!$C$20*$A22*売上前提!$E$20*売上前提!$H$20+売上前提!$C$22*$A22*売上前提!$E$22*売上前提!$H$22+売上前提!$C$24*$A22*E$21*売上前提!$H$24)+(売上前提!$J$21+売上前提!$J$23+売上前提!$J$25))*売上前提!$B$5/1000000)=0,0,((((売上前提!$C$20*$A22*売上前提!$E$20*売上前提!$H$20+売上前提!$C$22*$A22*売上前提!$E$22*売上前提!$H$22+売上前提!$C$24*$A22*E$21*売上前提!$H$24)+(売上前提!$J$21+売上前提!$J$23+売上前提!$J$25))*売上前提!$B$5/1000000)*(1-経費前提!$B$20)-経費前提!$B$24-MAX(0,(((売上前提!$C$20*$A22*売上前提!$E$20*売上前提!$H$20+売上前提!$C$22*$A22*売上前提!$E$22*売上前提!$H$22+売上前提!$C$24*$A22*E$21*売上前提!$H$24)+(売上前提!$J$21+売上前提!$J$23+売上前提!$J$25))*売上前提!$B$5/1000000)-経費前提!$B$26)*経費前提!$B$25-経費前提!$B$37)/(((売上前提!$C$20*$A22*売上前提!$E$20*売上前提!$H$20+売上前提!$C$22*$A22*売上前提!$E$22*売上前提!$H$22+売上前提!$C$24*$A22*E$21*売上前提!$H$24)+(売上前提!$J$21+売上前提!$J$23+売上前提!$J$25))*売上前提!$B$5/1000000)) -> 0.073529313 | F22: =IF((((売上前提!$C$20*$A22*売上前提!$E$20*売上前提!$H$20+売上前提!$C$22*$A22*売上前提!$E$22*売上前提!$H$22+売上前提!$C$24*$A22*F$21*売上前提!$H$24)+(売上前提!$J$21+売上前提!$J$23+売上前提!$J$25))*売上前提!$B$5/1000000)=0,0,((((売上前提!$C$20*$A22*売上前提!$E$20*売上前提!$H$20+売上前提!$C$22*$A22*売上前提!$E$22*売上前提!$H$22+売上前提!$C$24*$A22*F$21*売上前提!$H$24)+(売上前提!$J$21+売上前提!$J$23+売上前提!$J$25))*売上前提!$B$5/1000000)*(1-経費前提!$B$20)-経費前提!$B$24-MAX(0,(((売上前提!$C$20*$A22*売上前提!$E$20*売上前提!$H$20+売上前提!$C$22*$A22*売上前提!$E$22*売上前提!$H$22+売上前提!$C$24*$A22*F$21*売上前提!$H$24)+(売上前提!$J$21+売上前提!$J$23+売上前提!$J$25))*売上前提!$B$5/1000000)-経費前提!$B$26)*経費前提!$B$25-経費前提!$B$37)/(((売上前提!$C$20*$A22*売上前提!$E$20*売上前提!$H$20+売上前提!$C$22*$A22*売上前提!$E$22*売上前提!$H$22+売上前提!$C$24*$A22*F$21*売上前提!$H$24)+(売上前提!$J$21+売上前提!$J$23+売上前提!$J$25))*売上前提!$B$5/1000000)) -> 0.076944025
A23: 0.7 | B23: =IF((((売上前提!$C$20*$A23*売上前提!$E$20*売上前提!$H$20+売上前提!$C$22*$A23*売上前提!$E$22*売上前提!$H$22+売上前提!$C$24*$A23*B$21*売上前提!$H$24)+(売上前提!$J$21+売上前提!$J$23+売上前提!$J$25))*売上前提!$B$5/1000000)=0,0,((((売上前提!$C$20*$A23*売上前提!$E$20*売上前提!$H$20+売上前提!$C$22*$A23*売上前提!$E$22*売上前提!$H$22+売上前提!$C$24*$A23*B$21*売上前提!$H$24)+(売上前提!$J$21+売上前提!$J$23+売上前提!$J$25))*売上前提!$B$5/1000000)*(1-経費前提!$B$20)-経費前提!$B$24-MAX(0,(((売上前提!$C$20*$A23*売上前提!$E$20*売上前提!$H$20+売上前提!$C$22*$A23*売上前提!$E$22*売上前提!$H$22+売上前提!$C$24*$A23*B$21*売上前提!$H$24)+(売上前提!$J$21+売上前提!$J$23+売上前提!$J$25))*売上前提!$B$5/1000000)-経費前提!$B$26)*経費前提!$B$25-経費前提!$B$37)/(((売上前提!$C$20*$A23*売上前提!$E$20*売上前提!$H$20+売上前提!$C$22*$A23*売上前提!$E$22*売上前提!$H$22+売上前提!$C$24*$A23*B$21*売上前提!$H$24)+(売上前提!$J$21+売上前提!$J$23+売上前提!$J$25))*売上前提!$B$5/1000000)) -> 0.06798946 | C23: =IF((((売上前提!$C$20*$A23*売上前提!$E$20*売上前提!$H$20+売上前提!$C$22*$A23*売上前提!$E$22*売上前提!$H$22+売上前提!$C$24*$A23*C$21*売上前提!$H$24)+(売上前提!$J$21+売上前提!$J$23+売上前提!$J$25))*売上前提!$B$5/1000000)=0,0,((((売上前提!$C$20*$A23*売上前提!$E$20*売上前提!$H$20+売上前提!$C$22*$A23*売上前提!$E$22*売上前提!$H$22+売上前提!$C$24*$A23*C$21*売上前提!$H$24)+(売上前提!$J$21+売上前提!$J$23+売上前提!$J$25))*売上前提!$B$5/1000000)*(1-経費前提!$B$20)-経費前提!$B$24-MAX(0,(((売上前提!$C$20*$A23*売上前提!$E$20*売上前提!$H$20+売上前提!$C$22*$A23*売上前提!$E$22*売上前提!$H$22+売上前提!$C$24*$A23*C$21*売上前提!$H$24)+(売上前提!$J$21+売上前提!$J$23+売上前提!$J$25))*売上前提!$B$5/1000000)-経費前提!$B$26)*経費前提!$B$25-経費前提!$B$37)/(((売上前提!$C$20*$A23*売上前提!$E$20*売上前提!$H$20+売上前提!$C$22*$A23*売上前提!$E$22*売上前提!$H$22+売上前提!$C$24*$A23*C$21*売上前提!$H$24)+(売上前提!$J$21+売上前提!$J$23+売上前提!$J$25))*売上前提!$B$5/1000000)) -> 0.072653288 | D23: =IF((((売上前提!$C$20*$A23*売上前提!$E$20*売上前提!$H$20+売上前提!$C$22*$A23*売上前提!$E$22*売上前提!$H$22+売上前提!$C$24*$A23*D$21*売上前提!$H$24)+(売上前提!$J$21+売上前提!$J$23+売上前提!$J$25))*売上前提!$B$5/1000000)=0,0,((((売上前提!$C$20*$A23*売上前提!$E$20*売上前提!$H$20+売上前提!$C$22*$A23*売上前提!$E$22*売上前提!$H$22+売上前提!$C$24*$A23*D$21*売上前提!$H$24)+(売上前提!$J$21+売上前提!$J$23+売上前提!$J$25))*売上前提!$B$5/1000000)*(1-経費前提!$B$20)-経費前提!$B$24-MAX(0,(((売上前提!$C$20*$A23*売上前提!$E$20*売上前提!$H$20+売上前提!$C$22*$A23*売上前提!$E$22*売上前提!$H$22+売上前提!$C$24*$A23*D$21*売上前提!$H$24)+(売上前提!$J$21+売上前提!$J$23+売上前提!$J$25))*売上前提!$B$5/1000000)-経費前提!$B$26)*経費前提!$B$25-経費前提!$B$37)/(((売上前提!$C$20*$A23*売上前提!$E$20*売上前提!$H$20+売上前提!$C$22*$A23*売上前提!$E$22*売上前提!$H$22+売上前提!$C$24*$A23*D$21*売上前提!$H$24)+(売上前提!$J$21+売上前提!$J$23+売上前提!$J$25))*売上前提!$B$5/1000000)) -> 0.076710168 | E23: =IF((((売上前提!$C$20*$A23*売上前提!$E$20*売上前提!$H$20+売上前提!$C$22*$A23*売上前提!$E$22*売上前提!$H$22+売上前提!$C$24*$A23*E$21*売上前提!$H$24)+(売上前提!$J$21+売上前提!$J$23+売上前提!$J$25))*売上前提!$B$5/1000000)=0,0,((((売上前提!$C$20*$A23*売上前提!$E$20*売上前提!$H$20+売上前提!$C$22*$A23*売上前提!$E$22*売上前提!$H$22+売上前提!$C$24*$A23*E$21*売上前提!$H$24)+(売上前提!$J$21+売上前提!$J$23+売上前提!$J$25))*売上前提!$B$5/1000000)*(1-経費前提!$B$20)-経費前提!$B$24-MAX(0,(((売上前提!$C$20*$A23*売上前提!$E$20*売上前提!$H$20+売上前提!$C$22*$A23*売上前提!$E$22*売上前提!$H$22+売上前提!$C$24*$A23*E$21*売上前提!$H$24)+(売上前提!$J$21+売上前提!$J$23+売上前提!$J$25))*売上前提!$B$5/1000000)-経費前提!$B$26)*経費前提!$B$25-経費前提!$B$37)/(((売上前提!$C$20*$A23*売上前提!$E$20*売上前提!$H$20+売上前提!$C$22*$A23*売上前提!$E$22*売上前提!$H$22+売上前提!$C$24*$A23*E$21*売上前提!$H$24)+(売上前提!$J$21+売上前提!$J$23+売上前提!$J$25))*売上前提!$B$5/1000000)) -> 0.080271344 | F23: =IF((((売上前提!$C$20*$A23*売上前提!$E$20*売上前提!$H$20+売上前提!$C$22*$A23*売上前提!$E$22*売上前提!$H$22+売上前提!$C$24*$A23*F$21*売上前提!$H$24)+(売上前提!$J$21+売上前提!$J$23+売上前提!$J$25))*売上前提!$B$5/1000000)=0,0,((((売上前提!$C$20*$A23*売上前提!$E$20*売上前提!$H$20+売上前提!$C$22*$A23*売上前提!$E$22*売上前提!$H$22+売上前提!$C$24*$A23*F$21*売上前提!$H$24)+(売上前提!$J$21+売上前提!$J$23+売上前提!$J$25))*売上前提!$B$5/1000000)*(1-経費前提!$B$20)-経費前提!$B$24-MAX(0,(((売上前提!$C$20*$A23*売上前提!$E$20*売上前提!$H$20+売上前提!$C$22*$A23*売上前提!$E$22*売上前提!$H$22+売上前提!$C$24*$A23*F$21*売上前提!$H$24)+(売上前提!$J$21+売上前提!$J$23+売上前提!$J$25))*売上前提!$B$5/1000000)-経費前提!$B$26)*経費前提!$B$25-経費前提!$B$37)/(((売上前提!$C$20*$A23*売上前提!$E$20*売上前提!$H$20+売上前提!$C$22*$A23*売上前提!$E$22*売上前提!$H$22+売上前提!$C$24*$A23*F$21*売上前提!$H$24)+(売上前提!$J$21+売上前提!$J$23+売上前提!$J$25))*売上前提!$B$5/1000000)) -> 0.083422438
A24: 0.8 | B24: =IF((((売上前提!$C$20*$A24*売上前提!$E$20*売上前提!$H$20+売上前提!$C$22*$A24*売上前提!$E$22*売上前提!$H$22+売上前提!$C$24*$A24*B$21*売上前提!$H$24)+(売上前提!$J$21+売上前提!$J$23+売上前提!$J$25))*売上前提!$B$5/1000000)=0,0,((((売上前提!$C$20*$A24*売上前提!$E$20*売上前提!$H$20+売上前提!$C$22*$A24*売上前提!$E$22*売上前提!$H$22+売上前提!$C$24*$A24*B$21*売上前提!$H$24)+(売上前提!$J$21+売上前提!$J$23+売上前提!$J$25))*売上前提!$B$5/1000000)*(1-経費前提!$B$20)-経費前提!$B$24-MAX(0,(((売上前提!$C$20*$A24*売上前提!$E$20*売上前提!$H$20+売上前提!$C$22*$A24*売上前提!$E$22*売上前提!$H$22+売上前提!$C$24*$A24*B$21*売上前提!$H$24)+(売上前提!$J$21+売上前提!$J$23+売上前提!$J$25))*売上前提!$B$5/1000000)-経費前提!$B$26)*経費前提!$B$25-経費前提!$B$37)/(((売上前提!$C$20*$A24*売上前提!$E$20*売上前提!$H$20+売上前提!$C$22*$A24*売上前提!$E$22*売上前提!$H$22+売上前提!$C$24*$A24*B$21*売上前提!$H$24)+(売上前提!$J$21+売上前提!$J$23+売上前提!$J$25))*売上前提!$B$5/1000000)) -> 0.074204747 | C24: =IF((((売上前提!$C$20*$A24*売上前提!$E$20*売上前提!$H$20+売上前提!$C$22*$A24*売上前提!$E$22*売上前提!$H$22+売上前提!$C$24*$A24*C$21*売上前提!$H$24)+(売上前提!$J$21+売上前提!$J$23+売上前提!$J$25))*売上前提!$B$5/1000000)=0,0,((((売上前提!$C$20*$A24*売上前提!$E$20*売上前提!$H$20+売上前提!$C$22*$A24*売上前提!$E$22*売上前提!$H$22+売上前提!$C$24*$A24*C$21*売上前提!$H$24)+(売上前提!$J$21+売上前提!$J$23+売上前提!$J$25))*売上前提!$B$5/1000000)*(1-経費前提!$B$20)-経費前提!$B$24-MAX(0,(((売上前提!$C$20*$A24*売上前提!$E$20*売上前提!$H$20+売上前提!$C$22*$A24*売上前提!$E$22*売上前提!$H$22+売上前提!$C$24*$A24*C$21*売上前提!$H$24)+(売上前提!$J$21+売上前提!$J$23+売上前提!$J$25))*売上前提!$B$5/1000000)-経費前提!$B$26)*経費前提!$B$25-経費前提!$B$37)/(((売上前提!$C$20*$A24*売上前提!$E$20*売上前提!$H$20+売上前提!$C$22*$A24*売上前提!$E$22*売上前提!$H$22+売上前提!$C$24*$A24*C$21*売上前提!$H$24)+(売上前提!$J$21+売上前提!$J$23+売上前提!$J$25))*売上前提!$B$5/1000000)) -> 0.078580724 | D24: =IF((((売上前提!$C$20*$A24*売上前提!$E$20*売上前提!$H$20+売上前提!$C$22*$A24*売上前提!$E$22*売上前提!$H$22+売上前提!$C$24*$A24*D$21*売上前提!$H$24)+(売上前提!$J$21+売上前提!$J$23+売上前提!$J$25))*売上前提!$B$5/1000000)=0,0,((((売上前提!$C$20*$A24*売上前提!$E$20*売上前提!$H$20+売上前提!$C$22*$A24*売上前提!$E$22*売上前提!$H$22+売上前提!$C$24*$A24*D$21*売上前提!$H$24)+(売上前提!$J$21+売上前提!$J$23+売上前提!$J$25))*売上前提!$B$5/1000000)*(1-経費前提!$B$20)-経費前提!$B$24-MAX(0,(((売上前提!$C$20*$A24*売上前提!$E$20*売上前提!$H$20+売上前提!$C$22*$A24*売上前提!$E$22*売上前提!$H$22+売上前提!$C$24*$A24*D$21*売上前提!$H$24)+(売上前提!$J$21+売上前提!$J$23+売上前提!$J$25))*売上前提!$B$5/1000000)-経費前提!$B$26)*経費前提!$B$25-経費前提!$B$37)/(((売上前提!$C$20*$A24*売上前提!$E$20*売上前提!$H$20+売上前提!$C$22*$A24*売上前提!$E$22*売上前提!$H$22+売上前提!$C$24*$A24*D$21*売上前提!$H$24)+(売上前提!$J$21+売上前提!$J$23+売上前提!$J$25))*売上前提!$B$5/1000000)) -> 0.082369043 | E24: =IF((((売上前提!$C$20*$A24*売上前提!$E$20*売上前提!$H$20+売上前提!$C$22*$A24*売上前提!$E$22*売上前提!$H$22+売上前提!$C$24*$A24*E$21*売上前提!$H$24)+(売上前提!$J$21+売上前提!$J$23+売上前提!$J$25))*売上前提!$B$5/1000000)=0,0,((((売上前提!$C$20*$A24*売上前提!$E$20*売上前提!$H$20+売上前提!$C$22*$A24*売上前提!$E$22*売上前提!$H$22+売上前提!$C$24*$A24*E$21*売上前提!$H$24)+(売上前提!$J$21+売上前提!$J$23+売上前提!$J$25))*売上前提!$B$5/1000000)*(1-経費前提!$B$20)-経費前提!$B$24-MAX(0,(((売上前提!$C$20*$A24*売上前提!$E$20*売上前提!$H$20+売上前提!$C$22*$A24*売上前提!$E$22*売上前提!$H$22+売上前提!$C$24*$A24*E$21*売上前提!$H$24)+(売上前提!$J$21+売上前提!$J$23+売上前提!$J$25))*売上前提!$B$5/1000000)-経費前提!$B$26)*経費前提!$B$25-経費前提!$B$37)/(((売上前提!$C$20*$A24*売上前提!$E$20*売上前提!$H$20+売上前提!$C$22*$A24*売上前提!$E$22*売上前提!$H$22+売上前提!$C$24*$A24*E$21*売上前提!$H$24)+(売上前提!$J$21+売上前提!$J$23+売上前提!$J$25))*売上前提!$B$5/1000000)) -> 0.085680632 | F24: =IF((((売上前提!$C$20*$A24*売上前提!$E$20*売上前提!$H$20+売上前提!$C$22*$A24*売上前提!$E$22*売上前提!$H$22+売上前提!$C$24*$A24*F$21*売上前提!$H$24)+(売上前提!$J$21+売上前提!$J$23+売上前提!$J$25))*売上前提!$B$5/1000000)=0,0,((((売上前提!$C$20*$A24*売上前提!$E$20*売上前提!$H$20+売上前提!$C$22*$A24*売上前提!$E$22*売上前提!$H$22+売上前提!$C$24*$A24*F$21*売上前提!$H$24)+(売上前提!$J$21+売上前提!$J$23+売上前提!$J$25))*売上前提!$B$5/1000000)*(1-経費前提!$B$20)-経費前提!$B$24-MAX(0,(((売上前提!$C$20*$A24*売上前提!$E$20*売上前提!$H$20+売上前提!$C$22*$A24*売上前提!$E$22*売上前提!$H$22+売上前提!$C$24*$A24*F$21*売上前提!$H$24)+(売上前提!$J$21+売上前提!$J$23+売上前提!$J$25))*売上前提!$B$5/1000000)-経費前提!$B$26)*経費前提!$B$25-経費前提!$B$37)/(((売上前提!$C$20*$A24*売上前提!$E$20*売上前提!$H$20+売上前提!$C$22*$A24*売上前提!$E$22*売上前提!$H$22+売上前提!$C$24*$A24*F$21*売上前提!$H$24)+(売上前提!$J$21+売上前提!$J$23+売上前提!$J$25))*売上前提!$B$5/1000000)) -> 0.088600155
A25: 0.9 | B25: =IF((((売上前提!$C$20*$A25*売上前提!$E$20*売上前提!$H$20+売上前提!$C$22*$A25*売上前提!$E$22*売上前提!$H$22+売上前提!$C$24*$A25*B$21*売上前提!$H$24)+(売上前提!$J$21+売上前提!$J$23+売上前提!$J$25))*売上前提!$B$5/1000000)=0,0,((((売上前提!$C$20*$A25*売上前提!$E$20*売上前提!$H$20+売上前提!$C$22*$A25*売上前提!$E$22*売上前提!$H$22+売上前提!$C$24*$A25*B$21*売上前提!$H$24)+(売上前提!$J$21+売上前提!$J$23+売上前提!$J$25))*売上前提!$B$5/1000000)*(1-経費前提!$B$20)-経費前提!$B$24-MAX(0,(((売上前提!$C$20*$A25*売上前提!$E$20*売上前提!$H$20+売上前提!$C$22*$A25*売上前提!$E$22*売上前提!$H$22+売上前提!$C$24*$A25*B$21*売上前提!$H$24)+(売上前提!$J$21+売上前提!$J$23+売上前提!$J$25))*売上前提!$B$5/1000000)-経費前提!$B$26)*経費前提!$B$25-経費前提!$B$37)/(((売上前提!$C$20*$A25*売上前提!$E$20*売上前提!$H$20+売上前提!$C$22*$A25*売上前提!$E$22*売上前提!$H$22+売上前提!$C$24*$A25*B$21*売上前提!$H$24)+(売上前提!$J$21+売上前提!$J$23+売上前提!$J$25))*売上前提!$B$5/1000000)) -> 0.079364948 | C25: =IF((((売上前提!$C$20*$A25*売上前提!$E$20*売上前提!$H$20+売上前提!$C$22*$A25*売上前提!$E$22*売上前提!$H$22+売上前提!$C$24*$A25*C$21*売上前提!$H$24)+(売上前提!$J$21+売上前提!$J$23+売上前提!$J$25))*売上前提!$B$5/1000000)=0,0,((((売上前提!$C$20*$A25*売上前提!$E$20*売上前提!$H$20+売上前提!$C$22*$A25*売上前提!$E$22*売上前提!$H$22+売上前提!$C$24*$A25*C$21*売上前提!$H$24)+(売上前提!$J$21+売上前提!$J$23+売上前提!$J$25))*売上前提!$B$5/1000000)*(1-経費前提!$B$20)-経費前提!$B$24-MAX(0,(((売上前提!$C$20*$A25*売上前提!$E$20*売上前提!$H$20+売上前提!$C$22*$A25*売上前提!$E$22*売上前提!$H$22+売上前提!$C$24*$A25*C$21*売上前提!$H$24)+(売上前提!$J$21+売上前提!$J$23+売上前提!$J$25))*売上前提!$B$5/1000000)-経費前提!$B$26)*経費前提!$B$25-経費前提!$B$37)/(((売上前提!$C$20*$A25*売上前提!$E$20*売上前提!$H$20+売上前提!$C$22*$A25*売上前提!$E$22*売上前提!$H$22+売上前提!$C$24*$A25*C$21*売上前提!$H$24)+(売上前提!$J$21+売上前提!$J$23+売上前提!$J$25))*売上前提!$B$5/1000000)) -> 0.083478941 | D25: =IF((((売上前提!$C$20*$A25*売上前提!$E$20*売上前提!$H$20+売上前提!$C$22*$A25*売上前提!$E$22*売上前提!$H$22+売上前提!$C$24*$A25*D$21*売上前提!$H$24)+(売上前提!$J$21+売上前提!$J$23+売上前提!$J$25))*売上前提!$B$5/1000000)=0,0,((((売上前提!$C$20*$A25*売上前提!$E$20*売上前提!$H$20+売上前提!$C$22*$A25*売上前提!$E$22*売上前提!$H$22+売上前提!$C$24*$A25*D$21*売上前提!$H$24)+(売上前提!$J$21+売上前提!$J$23+売上前提!$J$25))*売上前提!$B$5/1000000)*(1-経費前提!$B$20)-経費前提!$B$24-MAX(0,(((売上前提!$C$20*$A25*売上前提!$E$20*売上前提!$H$20+売上前提!$C$22*$A25*売上前提!$E$22*売上前提!$H$22+売上前提!$C$24*$A25*D$21*売上前提!$H$24)+(売上前提!$J$21+売上前提!$J$23+売上前提!$J$25))*売上前提!$B$5/1000000)-経費前提!$B$26)*経費前提!$B$25-経費前提!$B$37)/(((売上前提!$C$20*$A25*売上前提!$E$20*売上前提!$H$20+売上前提!$C$22*$A25*売上前提!$E$22*売上前提!$H$22+売上前提!$C$24*$A25*D$21*売上前提!$H$24)+(売上前提!$J$21+売上前提!$J$23+売上前提!$J$25))*売上前提!$B$5/1000000)) -> 0.0870264 | E25: =IF((((売上前提!$C$20*$A25*売上前提!$E$20*売上前提!$H$20+売上前提!$C$22*$A25*売上前提!$E$22*売上前提!$H$22+売上前提!$C$24*$A25*E$21*売上前提!$H$24)+(売上前提!$J$21+売上前提!$J$23+売上前提!$J$25))*売上前提!$B$5/1000000)=0,0,((((売上前提!$C$20*$A25*売上前提!$E$20*売上前提!$H$20+売上前提!$C$22*$A25*売上前提!$E$22*売上前提!$H$22+売上前提!$C$24*$A25*E$21*売上前提!$H$24)+(売上前提!$J$21+売上前提!$J$23+売上前提!$J$25))*売上前提!$B$5/1000000)*(1-経費前提!$B$20)-経費前提!$B$24-MAX(0,(((売上前提!$C$20*$A25*売上前提!$E$20*売上前提!$H$20+売上前提!$C$22*$A25*売上前提!$E$22*売上前提!$H$22+売上前提!$C$24*$A25*E$21*売上前提!$H$24)+(売上前提!$J$21+売上前提!$J$23+売上前提!$J$25))*売上前提!$B$5/1000000)-経費前提!$B$26)*経費前提!$B$25-経費前提!$B$37)/(((売上前提!$C$20*$A25*売上前提!$E$20*売上前提!$H$20+売上前提!$C$22*$A25*売上前提!$E$22*売上前提!$H$22+売上前提!$C$24*$A25*E$21*売上前提!$H$24)+(売上前提!$J$21+売上前提!$J$23+売上前提!$J$25))*売上前提!$B$5/1000000)) -> 0.090116812 | F25: =IF((((売上前提!$C$20*$A25*売上前提!$E$20*売上前提!$H$20+売上前提!$C$22*$A25*売上前提!$E$22*売上前提!$H$22+売上前提!$C$24*$A25*F$21*売上前提!$H$24)+(売上前提!$J$21+売上前提!$J$23+売上前提!$J$25))*売上前提!$B$5/1000000)=0,0,((((売上前提!$C$20*$A25*売上前提!$E$20*売上前提!$H$20+売上前提!$C$22*$A25*売上前提!$E$22*売上前提!$H$22+売上前提!$C$24*$A25*F$21*売上前提!$H$24)+(売上前提!$J$21+売上前提!$J$23+売上前提!$J$25))*売上前提!$B$5/1000000)*(1-経費前提!$B$20)-経費前提!$B$24-MAX(0,(((売上前提!$C$20*$A25*売上前提!$E$20*売上前提!$H$20+売上前提!$C$22*$A25*売上前提!$E$22*売上前提!$H$22+売上前提!$C$24*$A25*F$21*売上前提!$H$24)+(売上前提!$J$21+売上前提!$J$23+売上前提!$J$25))*売上前提!$B$5/1000000)-経費前提!$B$26)*経費前提!$B$25-経費前提!$B$37)/(((売上前提!$C$20*$A25*売上前提!$E$20*売上前提!$H$20+売上前提!$C$22*$A25*売上前提!$E$22*売上前提!$H$22+売上前提!$C$24*$A25*F$21*売上前提!$H$24)+(売上前提!$J$21+売上前提!$J$23+売上前提!$J$25))*売上前提!$B$5/1000000)) -> 0.092833158
A26: 1 | B26: =IF((((売上前提!$C$20*$A26*売上前提!$E$20*売上前提!$H$20+売上前提!$C$22*$A26*売上前提!$E$22*売上前提!$H$22+売上前提!$C$24*$A26*B$21*売上前提!$H$24)+(売上前提!$J$21+売上前提!$J$23+売上前提!$J$25))*売上前提!$B$5/1000000)=0,0,((((売上前提!$C$20*$A26*売上前提!$E$20*売上前提!$H$20+売上前提!$C$22*$A26*売上前提!$E$22*売上前提!$H$22+売上前提!$C$24*$A26*B$21*売上前提!$H$24)+(売上前提!$J$21+売上前提!$J$23+売上前提!$J$25))*売上前提!$B$5/1000000)*(1-経費前提!$B$20)-経費前提!$B$24-MAX(0,(((売上前提!$C$20*$A26*売上前提!$E$20*売上前提!$H$20+売上前提!$C$22*$A26*売上前提!$E$22*売上前提!$H$22+売上前提!$C$24*$A26*B$21*売上前提!$H$24)+(売上前提!$J$21+売上前提!$J$23+売上前提!$J$25))*売上前提!$B$5/1000000)-経費前提!$B$26)*経費前提!$B$25-経費前提!$B$37)/(((売上前提!$C$20*$A26*売上前提!$E$20*売上前提!$H$20+売上前提!$C$22*$A26*売上前提!$E$22*売上前提!$H$22+売上前提!$C$24*$A26*B$21*売上前提!$H$24)+(売上前提!$J$21+売上前提!$J$23+売上前提!$J$25))*売上前提!$B$5/1000000)) -> 0.083717705 | C26: =IF((((売上前提!$C$20*$A26*売上前提!$E$20*売上前提!$H$20+売上前提!$C$22*$A26*売上前提!$E$22*売上前提!$H$22+売上前提!$C$24*$A26*C$21*売上前提!$H$24)+(売上前提!$J$21+売上前提!$J$23+売上前提!$J$25))*売上前提!$B$5/1000000)=0,0,((((売上前提!$C$20*$A26*売上前提!$E$20*売上前提!$H$20+売上前提!$C$22*$A26*売上前提!$E$22*売上前提!$H$22+売上前提!$C$24*$A26*C$21*売上前提!$H$24)+(売上前提!$J$21+売上前提!$J$23+売上前提!$J$25))*売上前提!$B$5/1000000)*(1-経費前提!$B$20)-経費前提!$B$24-MAX(0,(((売上前提!$C$20*$A26*売上前提!$E$20*売上前提!$H$20+売上前提!$C$22*$A26*売上前提!$E$22*売上前提!$H$22+売上前提!$C$24*$A26*C$21*売上前提!$H$24)+(売上前提!$J$21+売上前提!$J$23+売上前提!$J$25))*売上前提!$B$5/1000000)-経費前提!$B$26)*経費前提!$B$25-経費前提!$B$37)/(((売上前提!$C$20*$A26*売上前提!$E$20*売上前提!$H$20+売上前提!$C$22*$A26*売上前提!$E$22*売上前提!$H$22+売上前提!$C$24*$A26*C$21*売上前提!$H$24)+(売上前提!$J$21+売上前提!$J$23+売上前提!$J$25))*売上前提!$B$5/1000000)) -> 0.087594592 | D26: =IF((((売上前提!$C$20*$A26*売上前提!$E$20*売上前提!$H$20+売上前提!$C$22*$A26*売上前提!$E$22*売上前提!$H$22+売上前提!$C$24*$A26*D$21*売上前提!$H$24)+(売上前提!$J$21+売上前提!$J$23+売上前提!$J$25))*売上前提!$B$5/1000000)=0,0,((((売上前提!$C$20*$A26*売上前提!$E$20*売上前提!$H$20+売上前提!$C$22*$A26*売上前提!$E$22*売上前提!$H$22+売上前提!$C$24*$A26*D$21*売上前提!$H$24)+(売上前提!$J$21+売上前提!$J$23+売上前提!$J$25))*売上前提!$B$5/1000000)*(1-経費前提!$B$20)-経費前提!$B$24-MAX(0,(((売上前提!$C$20*$A26*売上前提!$E$20*売上前提!$H$20+売上前提!$C$22*$A26*売上前提!$E$22*売上前提!$H$22+売上前提!$C$24*$A26*D$21*売上前提!$H$24)+(売上前提!$J$21+売上前提!$J$23+売上前提!$J$25))*売上前提!$B$5/1000000)-経費前提!$B$26)*経費前提!$B$25-経費前提!$B$37)/(((売上前提!$C$20*$A26*売上前提!$E$20*売上前提!$H$20+売上前提!$C$22*$A26*売上前提!$E$22*売上前提!$H$22+売上前提!$C$24*$A26*D$21*売上前提!$H$24)+(売上前提!$J$21+売上前提!$J$23+売上前提!$J$25))*売上前提!$B$5/1000000)) -> 0.090926501 | E26: =IF((((売上前提!$C$20*$A26*売上前提!$E$20*売上前提!$H$20+売上前提!$C$22*$A26*売上前提!$E$22*売上前提!$H$22+売上前提!$C$24*$A26*E$21*売上前提!$H$24)+(売上前提!$J$21+売上前提!$J$23+売上前提!$J$25))*売上前提!$B$5/1000000)=0,0,((((売上前提!$C$20*$A26*売上前提!$E$20*売上前提!$H$20+売上前提!$C$22*$A26*売上前提!$E$22*売上前提!$H$22+売上前提!$C$24*$A26*E$21*売上前提!$H$24)+(売上前提!$J$21+売上前提!$J$23+売上前提!$J$25))*売上前提!$B$5/1000000)*(1-経費前提!$B$20)-経費前提!$B$24-MAX(0,(((売上前提!$C$20*$A26*売上前提!$E$20*売上前提!$H$20+売上前提!$C$22*$A26*売上前提!$E$22*売上前提!$H$22+売上前提!$C$24*$A26*E$21*売上前提!$H$24)+(売上前提!$J$21+売上前提!$J$23+売上前提!$J$25))*売上前提!$B$5/1000000)-経費前提!$B$26)*経費前提!$B$25-経費前提!$B$37)/(((売上前提!$C$20*$A26*売上前提!$E$20*売上前提!$H$20+売上前提!$C$22*$A26*売上前提!$E$22*売上前提!$H$22+売上前提!$C$24*$A26*E$21*売上前提!$H$24)+(売上前提!$J$21+売上前提!$J$23+売上前提!$J$25))*売上前提!$B$5/1000000)) -> 0.093820799 | F26: =IF((((売上前提!$C$20*$A26*売上前提!$E$20*売上前提!$H$20+売上前提!$C$22*$A26*売上前提!$E$22*売上前提!$H$22+売上前提!$C$24*$A26*F$21*売上前提!$H$24)+(売上前提!$J$21+売上前提!$J$23+売上前提!$J$25))*売上前提!$B$5/1000000)=0,0,((((売上前提!$C$20*$A26*売上前提!$E$20*売上前提!$H$20+売上前提!$C$22*$A26*売上前提!$E$22*売上前提!$H$22+売上前提!$C$24*$A26*F$21*売上前提!$H$24)+(売上前提!$J$21+売上前提!$J$23+売上前提!$J$25))*売上前提!$B$5/1000000)*(1-経費前提!$B$20)-経費前提!$B$24-MAX(0,(((売上前提!$C$20*$A26*売上前提!$E$20*売上前提!$H$20+売上前提!$C$22*$A26*売上前提!$E$22*売上前提!$H$22+売上前提!$C$24*$A26*F$21*売上前提!$H$24)+(売上前提!$J$21+売上前提!$J$23+売上前提!$J$25))*売上前提!$B$5/1000000)-経費前提!$B$26)*経費前提!$B$25-経費前提!$B$37)/(((売上前提!$C$20*$A26*売上前提!$E$20*売上前提!$H$20+売上前提!$C$22*$A26*売上前提!$E$22*売上前提!$H$22+売上前提!$C$24*$A26*F$21*売上前提!$H$24)+(売上前提!$J$21+売上前提!$J$23+売上前提!$J$25))*売上前提!$B$5/1000000)) -> 0.096358386
A28: 黄色セル＝現在の前提（店内席効率80%・ディナー店内回転率0.80）。
A29: ※ 地代家賃（固定）と減価償却費は売上に連動しないため、売上が伸びるほど利益率が加速的に改善する。
